File: XRD/Data/20200918_mix_12.ras
*RAS_DATA_START
*RAS_HEADER_START
*DISP_FMT_X "%.2f"
*DISP_FMT_Y "%.0f"
*DISP_FULLSCALE "89818.0000000000"
*DISP_LINE_COLOR "255.0000000000"
*DISP_LINE_STYLE "0.0000000000"
*DISP_LINE_WIDTH "0.2500000000"
*DISP_NOTE "測定データ-3"
*DISP_OFFSET_Y "0.0000000000"
*DISP_PEAKSEARCH_UNIT_Y "cps"
*DISP_RANGE_BOTTOM "0.0000000000"
*DISP_RANGE_LEFT "20.0000000000"
*DISP_RANGE_LOGCUTOFF "0.0100000000"
*DISP_RANGE_RIGHT "90.0000000000"
*DISP_RANGE_TOP "89818.0000000000"
*DISP_SCALE_MODE_Y "0.0000000000"
*DISP_TAB_NAME "2θ/θ"
*DISP_TITLE_Y "強度"
*DISP_UNIT_Y "cps"
*DISP_WINDOW_NAME "MSG_MACROENGINE"
*FILE_COMMENT " "
*FILE_MD5 ""
*FILE_MEMO " "
*FILE_OPERATOR "Administrator"
*FILE_SAMPLE " "
*FILE_TYPE "RAS_RAW"
*FILE_USERGROUP "システムマネージャ"
*FILE_VERSION "1.0000000000"
*HW_ATTACHMENT_ID "ATT0025"
*HW_ATTACHMENT_NAME "標準|Standard"
*HW_COUNTER_ID-0 "CUT0025"
*HW_COUNTER_ID-1 "CUT0020"
*HW_COUNTER_ID-2 "CUT0020"
*HW_COUNTER_ID-3 "CSL0021"
*HW_COUNTER_ID-4 "CMC0021"
*HW_COUNTER_NAME-0 "D/teX Ultra|D/teX Ultra"
*HW_COUNTER_NAME-1 "None|None"
*HW_COUNTER_NAME-2 "None|None"
*HW_COUNTER_NAME-3 "BBM|BBM"
*HW_COUNTER_NAME-4 "検出器モノクロメータ|Detector monochromator"
*HW_COUNTER_SELECT_NAME "D/teX Ultra|D/teX Ultra"
*HW_GONIOMETER_ID "GON0023"
*HW_GONIOMETER_NAME "SmartLab|SmartLab"
*HW_GONIOMETER_RADIUS-0 "90.0"
*HW_GONIOMETER_RADIUS-1 "114.0"
*HW_GONIOMETER_RADIUS-2 "190.0"
*HW_GONIOMETER_RADIUS-3 "300.0"
*HW_GONIOMETER_RADIUS-4 "187.0"
*HW_GONIOMETER_RADIUS-5 "300.0"
*HW_GONIOMETER_RADIUS-6 "113.0"
*HW_GONIOMETER_RADIUS-7 "331.0"
*HW_I_OPT_ID-0 "CBO0021"
*HW_I_OPT_ID-1 "ICR0023"
*HW_I_OPT_ID-2 "ISL0021"
*HW_I_OPT_ID-3 "ISO0021"
*HW_I_OPT_ID-4 "IAD0021"
*HW_I_OPT_ID-5 "IPR0001"
*HW_I_OPT_NAME-0 "CBOユニット|CBO unit"
*HW_I_OPT_NAME-1 "標準入射光学ユニット|Standard incident optical unit"
*HW_I_OPT_NAME-2 "標準入射スリットボックス|Standard incident slit box"
*HW_I_OPT_NAME-3 "入射平行スリット|Incident parallel slit"
*HW_I_OPT_NAME-4 "長手制限スリット|Length limiting slit"
*HW_I_OPT_NAME-5 "None|None"
*HW_R_ATTENUATER_AUTOMODE "0"
*HW_R_OPT_ID-0 "RSS0021"
*HW_R_OPT_ID-1 "RCR0023"
*HW_R_OPT_ID-2 "RSO0021"
*HW_R_OPT_ID-3 "RRS0021"
*HW_R_OPT_ID-4 "ATN0021"
*HW_R_OPT_ID-5 "RFL0021"
*HW_R_OPT_ID-6 "RAD0021"
*HW_R_OPT_NAME-0 "標準受光スリットボックス1|Standard receiving slit box # 1"
*HW_R_OPT_NAME-1 "標準受光光学ユニット1|Standard receiving unit # 1"
*HW_R_OPT_NAME-2 "標準受光光学ユニット2|Standard receiving optical unit # 2"
*HW_R_OPT_NAME-3 "標準受光スリットボックス2|Standard receiving slit box # 2"
*HW_R_OPT_NAME-4 "標準アッテネータ|Standard Attenuator"
*HW_R_OPT_NAME-5 "Cu Kβ|Cu K-beta"
*HW_R_OPT_NAME-6 "調整用受光スリット|Alignment receiving slit"
*HW_SAMPLE_HOLDER_ID "SMP0023"
*HW_SAMPLE_HOLDER_NAME "標準Zステージ|Standard Z stage"
*HW_XG_CURRENT_MAX "50"
*HW_XG_CURRENT_MIN "2"
*HW_XG_CURRENT_RESOLUTION "2"
*HW_XG_CURRENT_UNIT "mA"
*HW_XG_FOCUS "1mm x 10mm"
*HW_XG_FOCUS_TYPE "Normal"
*HW_XG_ID ""
*HW_XG_NAME "3kW 封入管(ID:1200)|3kW Sealed tube(ID:1200)"
*HW_XG_TARGET_ATOMIC_NUMBER "29.0000000000"
*HW_XG_TARGET_NAME "Cu"
*HW_XG_TYPE "Hermetic"
*HW_XG_VOLTAGE_MAX "60"
*HW_XG_VOLTAGE_MIN "20"
*HW_XG_VOLTAGE_RESOLUTION "2"
*HW_XG_VOLTAGE_UNIT "kV"
*HW_XG_WATT_MAX "2"
*HW_XG_WATT_UNIT "kW"
*HW_XG_WAVE_LENGTH_ALPHA1 "1.540593"
*HW_XG_WAVE_LENGTH_ALPHA2 "1.544414"
*HW_XG_WAVE_LENGTH_BETA "1.392250"
*MEAS_COND_AXIS_NAME-0 "2θ/θ"
*MEAS_COND_AXIS_NAME-1 "2θ"
*MEAS_COND_AXIS_NAME-2 "ω"
*MEAS_COND_AXIS_NAME-3 "Z"
*MEAS_COND_AXIS_NAME-4 "2θ/ω"
*MEAS_COND_AXIS_NAME-5 "θs"
*MEAS_COND_AXIS_NAME-6 "θd"
*MEAS_COND_AXIS_NAME-7 "Ts"
*MEAS_COND_AXIS_NAME-8 "CBO選択スリット"
*MEAS_COND_AXIS_NAME-9 "M"
*MEAS_COND_AXIS_NAME-10 "入射平行スリット"
*MEAS_COND_AXIS_NAME-11 "入射スリット"
*MEAS_COND_AXIS_NAME-12 ""
*MEAS_COND_AXIS_NAME-13 "Zs"
*MEAS_COND_AXIS_NAME-14 "入射光学素子"
*MEAS_COND_AXIS_NAME-15 "長手制限スリット"
*MEAS_COND_AXIS_NAME-16 "センタースリット"
*MEAS_COND_AXIS_NAME-17 "フィルター"
*MEAS_COND_AXIS_NAME-18 "受光スリット1"
*MEAS_COND_AXIS_NAME-19 "受光スリット2"
*MEAS_COND_AXIS_NAME-20 "受光光学素子"
*MEAS_COND_AXIS_NAME-21 "受光平行スリット"
*MEAS_COND_AXIS_NAME-22 "調整用受光スリット"
*MEAS_COND_AXIS_NAME-23 ""
*MEAS_COND_AXIS_NAME-24 ""
*MEAS_COND_AXIS_NAME-25 "Zd"
*MEAS_COND_AXIS_NAME-26 "アッテネータ"
*MEAS_COND_AXIS_NAME-27 "検出器モノクロメータ"
*MEAS_COND_AXIS_NAME-28 "モノクロメータスリット"
*MEAS_COND_AXIS_NAME-29 "プライマリビーム"
*MEAS_COND_AXIS_NAME-30 "PHA"
*MEAS_COND_AXIS_NAME_INTERNAL-0 "TwoThetaTheta"
*MEAS_COND_AXIS_NAME_INTERNAL-1 "TwoTheta"
*MEAS_COND_AXIS_NAME_INTERNAL-2 "Omega"
*MEAS_COND_AXIS_NAME_INTERNAL-3 "Z"
*MEAS_COND_AXIS_NAME_INTERNAL-4 "TwoThetaOmega"
*MEAS_COND_AXIS_NAME_INTERNAL-5 "ThetaS"
*MEAS_COND_AXIS_NAME_INTERNAL-6 "ThetaD"
*MEAS_COND_AXIS_NAME_INTERNAL-7 "Ts"
*MEAS_COND_AXIS_NAME_INTERNAL-8 "CBO"
*MEAS_COND_AXIS_NAME_INTERNAL-9 "CBO-M"
*MEAS_COND_AXIS_NAME_INTERNAL-10 "IncidentSollerSlit"
*MEAS_COND_AXIS_NAME_INTERNAL-11 "IncidentSlitBox"
*MEAS_COND_AXIS_NAME_INTERNAL-12 "IncidentSlitBox-_Axis"
*MEAS_COND_AXIS_NAME_INTERNAL-13 "Zs"
*MEAS_COND_AXIS_NAME_INTERNAL-14 "IncidentMonochromator"
*MEAS_COND_AXIS_NAME_INTERNAL-15 "IncidentAxdSlit"
*MEAS_COND_AXIS_NAME_INTERNAL-16 "CenterSlit"
*MEAS_COND_AXIS_NAME_INTERNAL-17 "Filter"
*MEAS_COND_AXIS_NAME_INTERNAL-18 "ReceivingSlitBox1"
*MEAS_COND_AXIS_NAME_INTERNAL-19 "ReceivingSlitBox2"
*MEAS_COND_AXIS_NAME_INTERNAL-20 "ReceivingOptics"
*MEAS_COND_AXIS_NAME_INTERNAL-21 "ReceivingSollerSlit"
*MEAS_COND_AXIS_NAME_INTERNAL-22 "ReceivingAxdSlit"
*MEAS_COND_AXIS_NAME_INTERNAL-23 "ReceivingSlitBox1-_Axis"
*MEAS_COND_AXIS_NAME_INTERNAL-24 "ReceivingSlitBox2-_Axis"
*MEAS_COND_AXIS_NAME_INTERNAL-25 "ReceivingSlitBox2-Zd"
*MEAS_COND_AXIS_NAME_INTERNAL-26 "Attenuator"
*MEAS_COND_AXIS_NAME_INTERNAL-27 "CounterMonochromator"
*MEAS_COND_AXIS_NAME_INTERNAL-28 "CounterSlit"
*MEAS_COND_AXIS_NAME_INTERNAL-29 "IncidentPrimary"
*MEAS_COND_AXIS_NAME_INTERNAL-30 "PHA"
*MEAS_COND_AXIS_NAME_MAGICNO-0 "83951616.0000000000"
*MEAS_COND_AXIS_NAME_MAGICNO-1 "268632064.0000000000"
*MEAS_COND_AXIS_NAME_MAGICNO-2 "268500992.0000000000"
*MEAS_COND_AXIS_NAME_MAGICNO-3 "285278208.0000000000"
*MEAS_COND_AXIS_NAME_MAGICNO-4 "83951616.0000000000"
*MEAS_COND_AXIS_NAME_MAGICNO-5 "131072.0000000000"
*MEAS_COND_AXIS_NAME_MAGICNO-6 "131072.0000000000"
*MEAS_COND_AXIS_NAME_MAGICNO-7 "318898176.0000000000"
*MEAS_COND_AXIS_NAME_MAGICNO-8 "20971521.0000000000"
*MEAS_COND_AXIS_NAME_MAGICNO-9 "285343744.0000000000"
*MEAS_COND_AXIS_NAME_MAGICNO-10 "20971521.0000000000"
*MEAS_COND_AXIS_NAME_MAGICNO-11 "22020097.0000000000"
*MEAS_COND_AXIS_NAME_MAGICNO-12 "25165824.0000000000"
*MEAS_COND_AXIS_NAME_MAGICNO-13 "318898176.0000000000"
*MEAS_COND_AXIS_NAME_MAGICNO-14 "1.0000000000"
*MEAS_COND_AXIS_NAME_MAGICNO-15 "20971521.0000000000"
*MEAS_COND_AXIS_NAME_MAGICNO-16 "20971521.0000000000"
*MEAS_COND_AXIS_NAME_MAGICNO-17 "20971521.0000000000"
*MEAS_COND_AXIS_NAME_MAGICNO-18 "23068673.0000000000"
*MEAS_COND_AXIS_NAME_MAGICNO-19 "23068673.0000000000"
*MEAS_COND_AXIS_NAME_MAGICNO-20 "20971521.0000000000"
*MEAS_COND_AXIS_NAME_MAGICNO-21 "20971521.0000000000"
*MEAS_COND_AXIS_NAME_MAGICNO-22 "20971521.0000000000"
*MEAS_COND_AXIS_NAME_MAGICNO-23 "25165824.0000000000"
*MEAS_COND_AXIS_NAME_MAGICNO-24 "25165824.0000000000"
*MEAS_COND_AXIS_NAME_MAGICNO-25 "285343744.0000000000"
*MEAS_COND_AXIS_NAME_MAGICNO-26 "17301505.0000000000"
*MEAS_COND_AXIS_NAME_MAGICNO-27 "20971521.0000000000"
*MEAS_COND_AXIS_NAME_MAGICNO-28 "20971521.0000000000"
*MEAS_COND_AXIS_NAME_MAGICNO-29 "20971521.0000000000"
*MEAS_COND_AXIS_NAME_MAGICNO-30 "0.0000000000"
*MEAS_COND_AXIS_OFFSET-0 "-"
*MEAS_COND_AXIS_OFFSET-1 "-0.1081000000"
*MEAS_COND_AXIS_OFFSET-2 "0.3758000000"
*MEAS_COND_AXIS_OFFSET-3 "-"
*MEAS_COND_AXIS_OFFSET-4 "-"
*MEAS_COND_AXIS_OFFSET-5 "0.3758000000"
*MEAS_COND_AXIS_OFFSET-6 "-0.4839000000"
*MEAS_COND_AXIS_OFFSET-7 "-"
*MEAS_COND_AXIS_OFFSET-8 "-"
*MEAS_COND_AXIS_OFFSET-9 "-"
*MEAS_COND_AXIS_OFFSET-10 "-"
*MEAS_COND_AXIS_OFFSET-11 "-"
*MEAS_COND_AXIS_OFFSET-12 "-"
*MEAS_COND_AXIS_OFFSET-13 "-"
*MEAS_COND_AXIS_OFFSET-14 "-"
*MEAS_COND_AXIS_OFFSET-15 "-"
*MEAS_COND_AXIS_OFFSET-16 "-"
*MEAS_COND_AXIS_OFFSET-17 "-"
*MEAS_COND_AXIS_OFFSET-18 "-"
*MEAS_COND_AXIS_OFFSET-19 "-"
*MEAS_COND_AXIS_OFFSET-20 "-"
*MEAS_COND_AXIS_OFFSET-21 "-"
*MEAS_COND_AXIS_OFFSET-22 "-"
*MEAS_COND_AXIS_OFFSET-23 "-"
*MEAS_COND_AXIS_OFFSET-24 "-"
*MEAS_COND_AXIS_OFFSET-25 "-"
*MEAS_COND_AXIS_OFFSET-26 "-"
*MEAS_COND_AXIS_OFFSET-27 "-"
*MEAS_COND_AXIS_OFFSET-28 "-"
*MEAS_COND_AXIS_OFFSET-29 "-"
*MEAS_COND_AXIS_OFFSET-30 "-"
*MEAS_COND_AXIS_POSITION-0 "0.0000000000"
*MEAS_COND_AXIS_POSITION-1 "0.0000000000"
*MEAS_COND_AXIS_POSITION-2 "0.0000000000"
*MEAS_COND_AXIS_POSITION-3 "-0.5500000000"
*MEAS_COND_AXIS_POSITION-4 "0.0000000000"
*MEAS_COND_AXIS_POSITION-5 "0.0000000000"
*MEAS_COND_AXIS_POSITION-6 "0.0000000000"
*MEAS_COND_AXIS_POSITION-7 "-0.4278800000"
*MEAS_COND_AXIS_POSITION-8 "BB"
*MEAS_COND_AXIS_POSITION-9 "0.0000000000"
*MEAS_COND_AXIS_POSITION-10 "Soller_slit_5.0deg"
*MEAS_COND_AXIS_POSITION-11 "2/3deg"
*MEAS_COND_AXIS_POSITION-12 "2.2088000000"
*MEAS_COND_AXIS_POSITION-13 "-0.4140600000"
*MEAS_COND_AXIS_POSITION-14 "0.0000000000"
*MEAS_COND_AXIS_POSITION-15 "10.0mm"
*MEAS_COND_AXIS_POSITION-16 "None"
*MEAS_COND_AXIS_POSITION-17 "Cu_K-beta"
*MEAS_COND_AXIS_POSITION-18 "13.000mm"
*MEAS_COND_AXIS_POSITION-19 "13.000mm"
*MEAS_COND_AXIS_POSITION-20 "No_unit"
*MEAS_COND_AXIS_POSITION-21 "Soller_slit_5.0deg"
*MEAS_COND_AXIS_POSITION-22 "None"
*MEAS_COND_AXIS_POSITION-23 "13.0000000000"
*MEAS_COND_AXIS_POSITION-24 "13.0000000000"
*MEAS_COND_AXIS_POSITION-25 "0.0109400000"
*MEAS_COND_AXIS_POSITION-26 "Open"
*MEAS_COND_AXIS_POSITION-27 "None"
*MEAS_COND_AXIS_POSITION-28 "None"
*MEAS_COND_AXIS_POSITION-29 "None"
*MEAS_COND_AXIS_POSITION-30 "38.0000000000"
*MEAS_COND_AXIS_UNIT-0 "deg"
*MEAS_COND_AXIS_UNIT-1 "deg"
*MEAS_COND_AXIS_UNIT-2 "deg"
*MEAS_COND_AXIS_UNIT-3 "mm"
*MEAS_COND_AXIS_UNIT-4 "deg"
*MEAS_COND_AXIS_UNIT-5 "deg"
*MEAS_COND_AXIS_UNIT-6 "deg"
*MEAS_COND_AXIS_UNIT-7 "mm"
*MEAS_COND_AXIS_UNIT-8 ""
*MEAS_COND_AXIS_UNIT-9 "pulse"
*MEAS_COND_AXIS_UNIT-10 ""
*MEAS_COND_AXIS_UNIT-11 ""
*MEAS_COND_AXIS_UNIT-12 "mm"
*MEAS_COND_AXIS_UNIT-13 "mm"
*MEAS_COND_AXIS_UNIT-14 ""
*MEAS_COND_AXIS_UNIT-15 ""
*MEAS_COND_AXIS_UNIT-16 ""
*MEAS_COND_AXIS_UNIT-17 ""
*MEAS_COND_AXIS_UNIT-18 ""
*MEAS_COND_AXIS_UNIT-19 ""
*MEAS_COND_AXIS_UNIT-20 ""
*MEAS_COND_AXIS_UNIT-21 ""
*MEAS_COND_AXIS_UNIT-22 ""
*MEAS_COND_AXIS_UNIT-23 "mm"
*MEAS_COND_AXIS_UNIT-24 "mm"
*MEAS_COND_AXIS_UNIT-25 "mm"
*MEAS_COND_AXIS_UNIT-26 ""
*MEAS_COND_AXIS_UNIT-27 ""
*MEAS_COND_AXIS_UNIT-28 ""
*MEAS_COND_AXIS_UNIT-29 ""
*MEAS_COND_AXIS_UNIT-30 "div"
*MEAS_COND_COUNTER_CNTLOSS_CORR "0.0000000000"
*MEAS_COND_COUNTER_PHABASE "38.0000000000"
*MEAS_COND_COUNTER_PHAWINDOW "16.0000000000"
*MEAS_COND_COUNTER_PHA_UNIT "div"
*MEAS_COND_COUNTER_TAUDIFF "30.0000000000"
*MEAS_COND_COUNTER_TAUINT "0.0000000000"
*MEAS_COND_IRRADIATION_MODE "OFF"
*MEAS_COND_IRRADIATION_WIDTH ""
*MEAS_COND_OPT_ATTR "集中法"
*MEAS_COND_OPT_NAME "@集中法"
*MEAS_COND_UNSYMMETRIC_MODE "OFF"
*MEAS_COND_XG_CURRENT "30.0000000000"
*MEAS_COND_XG_VOLTAGE "40.0000000000"
*MEAS_COND_XG_WAVE_TYPE "Ka"
*MEAS_DATA_COUNT "3501.0000000000"
*MEAS_SCAN_AXIS_X "2θ/θ"
*MEAS_SCAN_AXIS_X_INTERNAL "TwoThetaTheta"
*MEAS_SCAN_END_TIME "09/18/20 16:19:51"
*MEAS_SCAN_MODE "CONTINUOUS"
*MEAS_SCAN_MONITOR "0"
*MEAS_SCAN_RESOLUTION_X "0.0002"
*MEAS_SCAN_SPEED "1.0"
*MEAS_SCAN_SPEED_UNIT "deg/min"
*MEAS_SCAN_START "20.0000000000"
*MEAS_SCAN_START_TIME "09/18/20 15:06:58"
*MEAS_SCAN_STEP "0.0200000000"
*MEAS_SCAN_STOP "90.0000000000"
*MEAS_SCAN_UNIT_X "deg"
*MEAS_SCAN_UNIT_Y "counts"
*RAS_HEADER_END
*RAS_INT_START
20.0000 9083.0000 1.0000
20.0600 8983.0000 1.0000
20.1200 8995.0000 1.0000
20.1800 8931.0000 1.0000
20.2400 8996.0000 1.0000
20.3000 9181.0000 1.0000
20.3600 8902.0000 1.0000
20.4200 8916.0000 1.0000
20.4800 9224.0000 1.0000
20.5400 9209.0000 1.0000
20.6000 9694.0000 1.0000
20.6600 10715.0000 1.0000
20.7200 11863.0000 1.0000
20.7800 13442.0000 1.0000
20.8400 21530.0000 1.0000
20.9000 21562.0000 1.0000
20.9600 12759.0000 1.0000
21.0200 9578.0000 1.0000
21.0800 8939.0000 1.0000
21.1400 9060.0000 1.0000
21.2000 8975.0000 1.0000
21.2600 8970.0000 1.0000
21.3200 8921.0000 1.0000
21.3800 8875.0000 1.0000
21.4400 8946.0000 1.0000
21.5000 8828.0000 1.0000
21.5600 8924.0000 1.0000
21.6200 8986.0000 1.0000
21.6800 8921.0000 1.0000
21.7400 8993.0000 1.0000
21.8000 8746.0000 1.0000
21.8600 8798.0000 1.0000
21.9200 8879.0000 1.0000
21.9800 8825.0000 1.0000
22.0400 8810.0000 1.0000
22.1000 8880.0000 1.0000
22.1600 8879.0000 1.0000
22.2200 8765.0000 1.0000
22.2800 8889.0000 1.0000
22.3400 8814.0000 1.0000
22.4000 8681.0000 1.0000
22.4600 8756.0000 1.0000
22.5200 8799.0000 1.0000
22.5800 8764.0000 1.0000
22.6400 8759.0000 1.0000
22.7000 8852.0000 1.0000
22.7600 8747.0000 1.0000
22.8200 8781.0000 1.0000
22.8800 8631.0000 1.0000
22.9400 8692.0000 1.0000
23.0000 8752.0000 1.0000
23.0600 8872.0000 1.0000
23.1200 8588.0000 1.0000
23.1800 8714.0000 1.0000
23.2400 8608.0000 1.0000
23.3000 8748.0000 1.0000
23.3600 8742.0000 1.0000
23.4200 8739.0000 1.0000
23.4800 8683.0000 1.0000
23.5400 8707.0000 1.0000
23.6000 8715.0000 1.0000
23.6600 8578.0000 1.0000
23.7200 8429.0000 1.0000
23.7800 8767.0000 1.0000
23.8400 8816.0000 1.0000
23.9000 8980.0000 1.0000
23.9600 9008.0000 1.0000
24.0200 9742.0000 1.0000
24.0800 9575.0000 1.0000
24.1400 10138.0000 1.0000
24.2000 9874.0000 1.0000
24.2600 9107.0000 1.0000
24.3200 8818.0000 1.0000
24.3800 8721.0000 1.0000
24.4400 8623.0000 1.0000
24.5000 8629.0000 1.0000
24.5600 8768.0000 1.0000
24.6200 8619.0000 1.0000
24.6800 8439.0000 1.0000
24.7400 8536.0000 1.0000
24.8000 8535.0000 1.0000
24.8600 8622.0000 1.0000
24.9200 8446.0000 1.0000
24.9800 8635.0000 1.0000
25.0400 8502.0000 1.0000
25.1000 8613.0000 1.0000
25.1600 8444.0000 1.0000
25.2200 8742.0000 1.0000
25.2800 8773.0000 1.0000
25.3400 9016.0000 1.0000
25.4000 9460.0000 1.0000
25.4600 10169.0000 1.0000
25.5200 11895.0000 1.0000
25.5800 13953.0000 1.0000
25.6400 12194.0000 1.0000
25.7000 10122.0000 1.0000
25.7600 9406.0000 1.0000
25.8200 9216.0000 1.0000
25.8800 9007.0000 1.0000
25.9400 8929.0000 1.0000
26.0000 8895.0000 1.0000
26.0600 9037.0000 1.0000
26.1200 8982.0000 1.0000
26.1800 8882.0000 1.0000
26.2400 8933.0000 1.0000
26.3000 9356.0000 1.0000
26.3600 10215.0000 1.0000
26.4200 12280.0000 1.0000
26.4800 16127.0000 1.0000
26.5400 24350.0000 1.0000
26.6000 52025.0000 1.0000
26.6600 89818.0000 1.0000
26.7200 50358.0000 1.0000
26.7800 15850.0000 1.0000
26.8400 11417.0000 1.0000
26.9000 9590.0000 1.0000
26.9600 8908.0000 1.0000
27.0200 8918.0000 1.0000
27.0800 8844.0000 1.0000
27.1400 8699.0000 1.0000
27.2000 8801.0000 1.0000
27.2600 8767.0000 1.0000
27.3200 8632.0000 1.0000
27.3800 8498.0000 1.0000
27.4400 8529.0000 1.0000
27.5000 8483.0000 1.0000
27.5600 8451.0000 1.0000
27.6200 8394.0000 1.0000
27.6800 8413.0000 1.0000
27.7400 8421.0000 1.0000
27.8000 8515.0000 1.0000
27.8600 8532.0000 1.0000
27.9200 8543.0000 1.0000
27.9800 8485.0000 1.0000
28.0400 8461.0000 1.0000
28.1000 8405.0000 1.0000
28.1600 8355.0000 1.0000
28.2200 8464.0000 1.0000
28.2800 8250.0000 1.0000
28.3400 8224.0000 1.0000
28.4000 8320.0000 1.0000
28.4600 8421.0000 1.0000
28.5200 8223.0000 1.0000
28.5800 8325.0000 1.0000
28.6400 8365.0000 1.0000
28.7000 8252.0000 1.0000
28.7600 8367.0000 1.0000
28.8200 8241.0000 1.0000
28.8800 8342.0000 1.0000
28.9400 8267.0000 1.0000
29.0000 8325.0000 1.0000
29.0600 8347.0000 1.0000
29.1200 8288.0000 1.0000
29.1800 8210.0000 1.0000
29.2400 8388.0000 1.0000
29.3000 8219.0000 1.0000
29.3600 8378.0000 1.0000
29.4200 8299.0000 1.0000
29.4800 8350.0000 1.0000
29.5400 8142.0000 1.0000
29.6000 8250.0000 1.0000
29.6600 8276.0000 1.0000
29.7200 8337.0000 1.0000
29.7800 8217.0000 1.0000
29.8400 8614.0000 1.0000
29.9000 8701.0000 1.0000
29.9600 8992.0000 1.0000
30.0200 9522.0000 1.0000
30.0800 11233.0000 1.0000
30.1400 12736.0000 1.0000
30.2000 11551.0000 1.0000
30.2600 9937.0000 1.0000
30.3200 8776.0000 1.0000
30.3800 8456.0000 1.0000
30.4400 8452.0000 1.0000
30.5000 8335.0000 1.0000
30.5600 8156.0000 1.0000
30.6200 8242.0000 1.0000
30.6800 8047.0000 1.0000
30.7400 8214.0000 1.0000
30.8000 8097.0000 1.0000
30.8600 8065.0000 1.0000
30.9200 8072.0000 1.0000
30.9800 8052.0000 1.0000
31.0400 7973.0000 1.0000
31.1000 8034.0000 1.0000
31.1600 8140.0000 1.0000
31.2200 8076.0000 1.0000
31.2800 7914.0000 1.0000
31.3400 8047.0000 1.0000
31.4000 8084.0000 1.0000
31.4600 7984.0000 1.0000
31.5200 7993.0000 1.0000
31.5800 8121.0000 1.0000
31.6400 8061.0000 1.0000
31.7000 8177.0000 1.0000
31.7600 8102.0000 1.0000
31.8200 8005.0000 1.0000
31.8800 8098.0000 1.0000
31.9400 8004.0000 1.0000
32.0000 8104.0000 1.0000
32.0600 7932.0000 1.0000
32.1200 8067.0000 1.0000
32.1800 8080.0000 1.0000
32.2400 7911.0000 1.0000
32.3000 7914.0000 1.0000
32.3600 7876.0000 1.0000
32.4200 7932.0000 1.0000
32.4800 7851.0000 1.0000
32.5400 7986.0000 1.0000
32.6000 8028.0000 1.0000
32.6600 8158.0000 1.0000
32.7200 8020.0000 1.0000
32.7800 8152.0000 1.0000
32.8400 8117.0000 1.0000
32.9000 8218.0000 1.0000
32.9600 8592.0000 1.0000
33.0200 8967.0000 1.0000
33.0800 10058.0000 1.0000
33.1400 13008.0000 1.0000
33.2000 12474.0000 1.0000
33.2600 10831.0000 1.0000
33.3200 9127.0000 1.0000
33.3800 8321.0000 1.0000
33.4400 8141.0000 1.0000
33.5000 7945.0000 1.0000
33.5600 7847.0000 1.0000
33.6200 7792.0000 1.0000
33.6800 7835.0000 1.0000
33.7400 7869.0000 1.0000
33.8000 7932.0000 1.0000
33.8600 7879.0000 1.0000
33.9200 7808.0000 1.0000
33.9800 7945.0000 1.0000
34.0400 7983.0000 1.0000
34.1000 7927.0000 1.0000
34.1600 7806.0000 1.0000
34.2200 7808.0000 1.0000
34.2800 7864.0000 1.0000
34.3400 7701.0000 1.0000
34.4000 7934.0000 1.0000
34.4600 8105.0000 1.0000
34.5200 7867.0000 1.0000
34.5800 8045.0000 1.0000
34.6400 7943.0000 1.0000
34.7000 8064.0000 1.0000
34.7600 8004.0000 1.0000
34.8200 8049.0000 1.0000
34.8800 8364.0000 1.0000
34.9400 8661.0000 1.0000
35.0000 9703.0000 1.0000
35.0600 11134.0000 1.0000
35.1200 15091.0000 1.0000
35.1800 15577.0000 1.0000
35.2400 13993.0000 1.0000
35.3000 11738.0000 1.0000
35.3600 12473.0000 1.0000
35.4200 16807.0000 1.0000
35.4800 22954.0000 1.0000
35.5400 21722.0000 1.0000
35.6000 19449.0000 1.0000
35.6600 15264.0000 1.0000
35.7200 12194.0000 1.0000
35.7800 9838.0000 1.0000
35.8400 8815.0000 1.0000
35.9000 8295.0000 1.0000
35.9600 8132.0000 1.0000
36.0200 7959.0000 1.0000
36.0800 7847.0000 1.0000
36.1400 7934.0000 1.0000
36.2000 7937.0000 1.0000
36.2600 7928.0000 1.0000
36.3200 8049.0000 1.0000
36.3800 8154.0000 1.0000
36.4400 8955.0000 1.0000
36.5000 10761.0000 1.0000
36.5600 13399.0000 1.0000
36.6200 10366.0000 1.0000
36.6800 9154.0000 1.0000
36.7400 8045.0000 1.0000
36.8000 7845.0000 1.0000
36.8600 7747.0000 1.0000
36.9200 7616.0000 1.0000
36.9800 7963.0000 1.0000
37.0400 8187.0000 1.0000
37.1000 8430.0000 1.0000
37.1600 8463.0000 1.0000
37.2200 8206.0000 1.0000
37.2800 8050.0000 1.0000
37.3400 7632.0000 1.0000
37.4000 7777.0000 1.0000
37.4600 7691.0000 1.0000
37.5200 7818.0000 1.0000
37.5800 8091.0000 1.0000
37.6400 8377.0000 1.0000
37.7000 9134.0000 1.0000
37.7600 10900.0000 1.0000
37.8200 10204.0000 1.0000
37.8800 9662.0000 1.0000
37.9400 8311.0000 1.0000
38.0000 7982.0000 1.0000
38.0600 7851.0000 1.0000
38.1200 7704.0000 1.0000
38.1800 7540.0000 1.0000
38.2400 7724.0000 1.0000
38.3000 7620.0000 1.0000
38.3600 7582.0000 1.0000
38.4200 7502.0000 1.0000
38.4800 7557.0000 1.0000
38.5400 7508.0000 1.0000
38.6000 7499.0000 1.0000
38.6600 7515.0000 1.0000
38.7200 7543.0000 1.0000
38.7800 7678.0000 1.0000
38.8400 7519.0000 1.0000
38.9000 7513.0000 1.0000
38.9600 7563.0000 1.0000
39.0200 7543.0000 1.0000
39.0800 7534.0000 1.0000
39.1400 7641.0000 1.0000
39.2000 7691.0000 1.0000
39.2600 7838.0000 1.0000
39.3200 8034.0000 1.0000
39.3800 8427.0000 1.0000
39.4400 10799.0000 1.0000
39.5000 11395.0000 1.0000
39.5600 9920.0000 1.0000
39.6200 8496.0000 1.0000
39.6800 7789.0000 1.0000
39.7400 7541.0000 1.0000
39.8000 7478.0000 1.0000
39.8600 7491.0000 1.0000
39.9200 7609.0000 1.0000
39.9800 7451.0000 1.0000
40.0400 7499.0000 1.0000
40.1000 7661.0000 1.0000
40.1600 7720.0000 1.0000
40.2200 8125.0000 1.0000
40.2800 10211.0000 1.0000
40.3400 9191.0000 1.0000
40.4000 9375.0000 1.0000
40.4600 7796.0000 1.0000
40.5200 7613.0000 1.0000
40.5800 7517.0000 1.0000
40.6400 7493.0000 1.0000
40.7000 7426.0000 1.0000
40.7600 7755.0000 1.0000
40.8200 8060.0000 1.0000
40.8800 8662.0000 1.0000
40.9400 8213.0000 1.0000
41.0000 7869.0000 1.0000
41.0600 7580.0000 1.0000
41.1200 7433.0000 1.0000
41.1800 7355.0000 1.0000
41.2400 7520.0000 1.0000
41.3000 7400.0000 1.0000
41.3600 7473.0000 1.0000
41.4200 7352.0000 1.0000
41.4800 7457.0000 1.0000
41.5400 7533.0000 1.0000
41.6000 7410.0000 1.0000
41.6600 7589.0000 1.0000
41.7200 7459.0000 1.0000
41.7800 7495.0000 1.0000
41.8400 7345.0000 1.0000
41.9000 7395.0000 1.0000
41.9600 7444.0000 1.0000
42.0200 7446.0000 1.0000
42.0800 7469.0000 1.0000
42.1400 7410.0000 1.0000
42.2000 7605.0000 1.0000
42.2600 7798.0000 1.0000
42.3200 7767.0000 1.0000
42.3800 8660.0000 1.0000
42.4400 10482.0000 1.0000
42.5000 9712.0000 1.0000
42.5600 9118.0000 1.0000
42.6200 8055.0000 1.0000
42.6800 7672.0000 1.0000
42.7400 7627.0000 1.0000
42.8000 7581.0000 1.0000
42.8600 7808.0000 1.0000
42.9200 7851.0000 1.0000
42.9800 8168.0000 1.0000
43.0400 8937.0000 1.0000
43.1000 10849.0000 1.0000
43.1600 11192.0000 1.0000
43.2200 11618.0000 1.0000
43.2800 13083.0000 1.0000
43.3400 16722.0000 1.0000
43.4000 13899.0000 1.0000
43.4600 12977.0000 1.0000
43.5200 10149.0000 1.0000
43.5800 8576.0000 1.0000
43.6400 8196.0000 1.0000
43.7000 7869.0000 1.0000
43.7600 7640.0000 1.0000
43.8200 7541.0000 1.0000
43.8800 7525.0000 1.0000
43.9400 7276.0000 1.0000
44.0000 7289.0000 1.0000
44.0600 7259.0000 1.0000
44.1200 7310.0000 1.0000
44.1800 7492.0000 1.0000
44.2400 7265.0000 1.0000
44.3000 7268.0000 1.0000
44.3600 7354.0000 1.0000
44.4200 7212.0000 1.0000
44.4800 7218.0000 1.0000
44.5400 7347.0000 1.0000
44.6000 7222.0000 1.0000
44.6600 7278.0000 1.0000
44.7200 7117.0000 1.0000
44.7800 7175.0000 1.0000
44.8400 7138.0000 1.0000
44.9000 7207.0000 1.0000
44.9600 7187.0000 1.0000
45.0200 7374.0000 1.0000
45.0800 7397.0000 1.0000
45.1400 7185.0000 1.0000
45.2000 7218.0000 1.0000
45.2600 7251.0000 1.0000
45.3200 7169.0000 1.0000
45.3800 7102.0000 1.0000
45.4400 7268.0000 1.0000
45.5000 7178.0000 1.0000
45.5600 7463.0000 1.0000
45.6200 7370.0000 1.0000
45.6800 7428.0000 1.0000
45.7400 8305.0000 1.0000
45.8000 10496.0000 1.0000
45.8600 8246.0000 1.0000
45.9200 8861.0000 1.0000
45.9800 7435.0000 1.0000
46.0400 7271.0000 1.0000
46.1000 7225.0000 1.0000
46.1600 7280.0000 1.0000
46.2200 7280.0000 1.0000
46.2800 6987.0000 1.0000
46.3400 7231.0000 1.0000
46.4000 7093.0000 1.0000
46.4600 7076.0000 1.0000
46.5200 7135.0000 1.0000
46.5800 7189.0000 1.0000
46.6400 7194.0000 1.0000
46.7000 7197.0000 1.0000
46.7600 7081.0000 1.0000
46.8200 7083.0000 1.0000
46.8800 7111.0000 1.0000
46.9400 7193.0000 1.0000
47.0000 7291.0000 1.0000
47.0600 7195.0000 1.0000
47.1200 7336.0000 1.0000
47.1800 7217.0000 1.0000
47.2400 7252.0000 1.0000
47.3000 7016.0000 1.0000
47.3600 7257.0000 1.0000
47.4200 7106.0000 1.0000
47.4800 7028.0000 1.0000
47.5400 7289.0000 1.0000
47.6000 7184.0000 1.0000
47.6600 7093.0000 1.0000
47.7200 7050.0000 1.0000
47.7800 7107.0000 1.0000
47.8400 7210.0000 1.0000
47.9000 7067.0000 1.0000
47.9600 7104.0000 1.0000
48.0200 7087.0000 1.0000
48.0800 7073.0000 1.0000
48.1400 7073.0000 1.0000
48.2000 7070.0000 1.0000
48.2600 7037.0000 1.0000
48.3200 7052.0000 1.0000
48.3800 7055.0000 1.0000
48.4400 6995.0000 1.0000
48.5000 7292.0000 1.0000
48.5600 7157.0000 1.0000
48.6200 7112.0000 1.0000
48.6800 7136.0000 1.0000
48.7400 6982.0000 1.0000
48.8000 7260.0000 1.0000
48.8600 7030.0000 1.0000
48.9200 7194.0000 1.0000
48.9800 7165.0000 1.0000
49.0400 7103.0000 1.0000
49.1000 7044.0000 1.0000
49.1600 7228.0000 1.0000
49.2200 7359.0000 1.0000
49.2800 7445.0000 1.0000
49.3400 7534.0000 1.0000
49.4000 8100.0000 1.0000
49.4600 8939.0000 1.0000
49.5200 8409.0000 1.0000
49.5800 8236.0000 1.0000
49.6400 7808.0000 1.0000
49.7000 7505.0000 1.0000
49.7600 7424.0000 1.0000
49.8200 7342.0000 1.0000
49.8800 7518.0000 1.0000
49.9400 7596.0000 1.0000
50.0000 8025.0000 1.0000
50.0600 9326.0000 1.0000
50.1200 17536.0000 1.0000
50.1800 12487.0000 1.0000
50.2400 11533.0000 1.0000
50.3000 11133.0000 1.0000
50.3600 7748.0000 1.0000
50.4200 7310.0000 1.0000
50.4800 7314.0000 1.0000
50.5400 7158.0000 1.0000
50.6000 7352.0000 1.0000
50.6600 7104.0000 1.0000
50.7200 7290.0000 1.0000
50.7800 7053.0000 1.0000
50.8400 7074.0000 1.0000
50.9000 7086.0000 1.0000
50.9600 7021.0000 1.0000
51.0200 7066.0000 1.0000
51.0800 7174.0000 1.0000
51.1400 7093.0000 1.0000
51.2000 7037.0000 1.0000
51.2600 7272.0000 1.0000
51.3200 7108.0000 1.0000
51.3800 7054.0000 1.0000
51.4400 7109.0000 1.0000
51.5000 7145.0000 1.0000
51.5600 7109.0000 1.0000
51.6200 6973.0000 1.0000
51.6800 7156.0000 1.0000
51.7400 7089.0000 1.0000
51.8000 7183.0000 1.0000
51.8600 7126.0000 1.0000
51.9200 7021.0000 1.0000
51.9800 7183.0000 1.0000
52.0400 7126.0000 1.0000
52.1000 7304.0000 1.0000
52.1600 7227.0000 1.0000
52.2200 7217.0000 1.0000
52.2800 7396.0000 1.0000
52.3400 7576.0000 1.0000
52.4000 7877.0000 1.0000
52.4600 8621.0000 1.0000
52.5200 10373.0000 1.0000
52.5800 10240.0000 1.0000
52.6400 9009.0000 1.0000
52.7000 9277.0000 1.0000
52.7600 7989.0000 1.0000
52.8200 7586.0000 1.0000
52.8800 7363.0000 1.0000
52.9400 7135.0000 1.0000
53.0000 7152.0000 1.0000
53.0600 7200.0000 1.0000
53.1200 7157.0000 1.0000
53.1800 7186.0000 1.0000
53.2400 7320.0000 1.0000
53.3000 7254.0000 1.0000
53.3600 7348.0000 1.0000
53.4200 7580.0000 1.0000
53.4800 8199.0000 1.0000
53.5400 8026.0000 1.0000
53.6000 7981.0000 1.0000
53.6600 8005.0000 1.0000
53.7200 7762.0000 1.0000
53.7800 7253.0000 1.0000
53.8400 7273.0000 1.0000
53.9000 7405.0000 1.0000
53.9600 7744.0000 1.0000
54.0200 8391.0000 1.0000
54.0800 9104.0000 1.0000
54.1400 8273.0000 1.0000
54.2000 8198.0000 1.0000
54.2600 7949.0000 1.0000
54.3200 7331.0000 1.0000
54.3800 7227.0000 1.0000
54.4400 7160.0000 1.0000
54.5000 7194.0000 1.0000
54.5600 7067.0000 1.0000
54.6200 7290.0000 1.0000
54.6800 7431.0000 1.0000
54.7400 7438.0000 1.0000
54.8000 7793.0000 1.0000
54.8600 9844.0000 1.0000
54.9200 8769.0000 1.0000
54.9800 7986.0000 1.0000
55.0400 8549.0000 1.0000
55.1000 7431.0000 1.0000
55.1600 7175.0000 1.0000
55.2200 7271.0000 1.0000
55.2800 7546.0000 1.0000
55.3400 8107.0000 1.0000
55.4000 7328.0000 1.0000
55.4600 7661.0000 1.0000
55.5200 7205.0000 1.0000
55.5800 7086.0000 1.0000
55.6400 7064.0000 1.0000
55.7000 7104.0000 1.0000
55.7600 7064.0000 1.0000
55.8200 7142.0000 1.0000
55.8800 6981.0000 1.0000
55.9400 7126.0000 1.0000
56.0000 7233.0000 1.0000
56.0600 7057.0000 1.0000
56.1200 7122.0000 1.0000
56.1800 7114.0000 1.0000
56.2400 7001.0000 1.0000
56.3000 7092.0000 1.0000
56.3600 7165.0000 1.0000
56.4200 7091.0000 1.0000
56.4800 7122.0000 1.0000
56.5400 7115.0000 1.0000
56.6000 7126.0000 1.0000
56.6600 6983.0000 1.0000
56.7200 7246.0000 1.0000
56.7800 7219.0000 1.0000
56.8400 7605.0000 1.0000
56.9000 7906.0000 1.0000
56.9600 9067.0000 1.0000
57.0200 10537.0000 1.0000
57.0800 10181.0000 1.0000
57.1400 9988.0000 1.0000
57.2000 10066.0000 1.0000
57.2600 9586.0000 1.0000
57.3200 9223.0000 1.0000
57.3800 9947.0000 1.0000
57.4400 12180.0000 1.0000
57.5000 14924.0000 1.0000
57.5600 11797.0000 1.0000
57.6200 11812.0000 1.0000
57.6800 11010.0000 1.0000
57.7400 8636.0000 1.0000
57.8000 7966.0000 1.0000
57.8600 7644.0000 1.0000
57.9200 7446.0000 1.0000
57.9800 7267.0000 1.0000
58.0400 7213.0000 1.0000
58.1000 7103.0000 1.0000
58.1600 7210.0000 1.0000
58.2200 6967.0000 1.0000
58.2800 7033.0000 1.0000
58.3400 7116.0000 1.0000
58.4000 7023.0000 1.0000
58.4600 7160.0000 1.0000
58.5200 6968.0000 1.0000
58.5800 7097.0000 1.0000
58.6400 7158.0000 1.0000
58.7000 6993.0000 1.0000
58.7600 6958.0000 1.0000
58.8200 7100.0000 1.0000
58.8800 7073.0000 1.0000
58.9400 7017.0000 1.0000
59.0000 6958.0000 1.0000
59.0600 7001.0000 1.0000
59.1200 6952.0000 1.0000
59.1800 7073.0000 1.0000
59.2400 6918.0000 1.0000
59.3000 7059.0000 1.0000
59.3600 7106.0000 1.0000
59.4200 7237.0000 1.0000
59.4800 7131.0000 1.0000
59.5400 7029.0000 1.0000
59.6000 6984.0000 1.0000
59.6600 7113.0000 1.0000
59.7200 7554.0000 1.0000
59.7800 7484.0000 1.0000
59.8400 7926.0000 1.0000
59.9000 9852.0000 1.0000
59.9600 15203.0000 1.0000
60.0200 9255.0000 1.0000
60.0800 9638.0000 1.0000
60.1400 10430.0000 1.0000
60.2000 7667.0000 1.0000
60.2600 7215.0000 1.0000
60.3200 7110.0000 1.0000
60.3800 7039.0000 1.0000
60.4400 7026.0000 1.0000
60.5000 7052.0000 1.0000
60.5600 7107.0000 1.0000
60.6200 7041.0000 1.0000
60.6800 7090.0000 1.0000
60.7400 7042.0000 1.0000
60.8000 6968.0000 1.0000
60.8600 7093.0000 1.0000
60.9200 7030.0000 1.0000
60.9800 6936.0000 1.0000
61.0400 7121.0000 1.0000
61.1000 7313.0000 1.0000
61.1600 7193.0000 1.0000
61.2200 7506.0000 1.0000
61.2800 7520.0000 1.0000
61.3400 7424.0000 1.0000
61.4000 7259.0000 1.0000
61.4600 7406.0000 1.0000
61.5200 7159.0000 1.0000
61.5800 7148.0000 1.0000
61.6400 7105.0000 1.0000
61.7000 7014.0000 1.0000
61.7600 6958.0000 1.0000
61.8200 7075.0000 1.0000
61.8800 7018.0000 1.0000
61.9400 6914.0000 1.0000
62.0000 7131.0000 1.0000
62.0600 6890.0000 1.0000
62.1200 7217.0000 1.0000
62.1800 7031.0000 1.0000
62.2400 7109.0000 1.0000
62.3000 7545.0000 1.0000
62.3600 7871.0000 1.0000
62.4200 8711.0000 1.0000
62.4800 8913.0000 1.0000
62.5400 9824.0000 1.0000
62.6000 12248.0000 1.0000
62.6600 11602.0000 1.0000
62.7200 10271.0000 1.0000
62.7800 10489.0000 1.0000
62.8400 9495.0000 1.0000
62.9000 8398.0000 1.0000
62.9600 7878.0000 1.0000
63.0200 7358.0000 1.0000
63.0800 7182.0000 1.0000
63.1400 7129.0000 1.0000
63.2000 7091.0000 1.0000
63.2600 6980.0000 1.0000
63.3200 7137.0000 1.0000
63.3800 6984.0000 1.0000
63.4400 7055.0000 1.0000
63.5000 6959.0000 1.0000
63.5600 6974.0000 1.0000
63.6200 6997.0000 1.0000
63.6800 7013.0000 1.0000
63.7400 6956.0000 1.0000
63.8000 7058.0000 1.0000
63.8600 7282.0000 1.0000
63.9200 7685.0000 1.0000
63.9800 8460.0000 1.0000
64.0400 9270.0000 1.0000
64.1000 7861.0000 1.0000
64.1600 7856.0000 1.0000
64.2200 8164.0000 1.0000
64.2800 7360.0000 1.0000
64.3400 7092.0000 1.0000
64.4000 6956.0000 1.0000
64.4600 7126.0000 1.0000
64.5200 6948.0000 1.0000
64.5800 6955.0000 1.0000
64.6400 6937.0000 1.0000
64.7000 6931.0000 1.0000
64.7600 7053.0000 1.0000
64.8200 6806.0000 1.0000
64.8800 6751.0000 1.0000
64.9400 6936.0000 1.0000
65.0000 7108.0000 1.0000
65.0600 6789.0000 1.0000
65.1200 6759.0000 1.0000
65.1800 6901.0000 1.0000
65.2400 6880.0000 1.0000
65.3000 6932.0000 1.0000
65.3600 6999.0000 1.0000
65.4200 6926.0000 1.0000
65.4800 6802.0000 1.0000
65.5400 6880.0000 1.0000
65.6000 6931.0000 1.0000
65.6600 7034.0000 1.0000
65.7200 6974.0000 1.0000
65.7800 7184.0000 1.0000
65.8400 7088.0000 1.0000
65.9000 6984.0000 1.0000
65.9600 7099.0000 1.0000
66.0200 7099.0000 1.0000
66.0800 7015.0000 1.0000
66.1400 7225.0000 1.0000
66.2000 7134.0000 1.0000
66.2600 7261.0000 1.0000
66.3200 7419.0000 1.0000
66.3800 7686.0000 1.0000
66.4400 8422.0000 1.0000
66.5000 9565.0000 1.0000
66.5600 8626.0000 1.0000
66.6200 8156.0000 1.0000
66.6800 8499.0000 1.0000
66.7400 7910.0000 1.0000
66.8000 7424.0000 1.0000
66.8600 7333.0000 1.0000
66.9200 7251.0000 1.0000
66.9800 7007.0000 1.0000
67.0400 7028.0000 1.0000
67.1000 6957.0000 1.0000
67.1600 6852.0000 1.0000
67.2200 7042.0000 1.0000
67.2800 6978.0000 1.0000
67.3400 7019.0000 1.0000
67.4000 7113.0000 1.0000
67.4600 7216.0000 1.0000
67.5200 7223.0000 1.0000
67.5800 7361.0000 1.0000
67.6400 7619.0000 1.0000
67.7000 9354.0000 1.0000
67.7600 11213.0000 1.0000
67.8200 8066.0000 1.0000
67.8800 8494.0000 1.0000
67.9400 10019.0000 1.0000
68.0000 8452.0000 1.0000
68.0600 9100.0000 1.0000
68.1200 13132.0000 1.0000
68.1800 14338.0000 1.0000
68.2400 11741.0000 1.0000
68.3000 13083.0000 1.0000
68.3600 12434.0000 1.0000
68.4200 9965.0000 1.0000
68.4800 9198.0000 1.0000
68.5400 8163.0000 1.0000
68.6000 7615.0000 1.0000
68.6600 7117.0000 1.0000
68.7200 7073.0000 1.0000
68.7800 7046.0000 1.0000
68.8400 7050.0000 1.0000
68.9000 6962.0000 1.0000
68.9600 6945.0000 1.0000
69.0200 7000.0000 1.0000
69.0800 7010.0000 1.0000
69.1400 6927.0000 1.0000
69.2000 6766.0000 1.0000
69.2600 6978.0000 1.0000
69.3200 6845.0000 1.0000
69.3800 6870.0000 1.0000
69.4400 6889.0000 1.0000
69.5000 6878.0000 1.0000
69.5600 7030.0000 1.0000
69.6200 7154.0000 1.0000
69.6800 6969.0000 1.0000
69.7400 7073.0000 1.0000
69.8000 6899.0000 1.0000
69.8600 6960.0000 1.0000
69.9200 6824.0000 1.0000
69.9800 6803.0000 1.0000
70.0400 6883.0000 1.0000
70.1000 6780.0000 1.0000
70.1600 6913.0000 1.0000
70.2200 6901.0000 1.0000
70.2800 6834.0000 1.0000
70.3400 6826.0000 1.0000
70.4000 6956.0000 1.0000
70.4600 6942.0000 1.0000
70.5200 6819.0000 1.0000
70.5800 6851.0000 1.0000
70.6400 6783.0000 1.0000
70.7000 6753.0000 1.0000
70.7600 6718.0000 1.0000
70.8200 6957.0000 1.0000
70.8800 6815.0000 1.0000
70.9400 6949.0000 1.0000
71.0000 7078.0000 1.0000
71.0600 7143.0000 1.0000
71.1200 7057.0000 1.0000
71.1800 7146.0000 1.0000
71.2400 7128.0000 1.0000
71.3000 6924.0000 1.0000
71.3600 6918.0000 1.0000
71.4200 6942.0000 1.0000
71.4800 6779.0000 1.0000
71.5400 6919.0000 1.0000
71.6000 6850.0000 1.0000
71.6600 6793.0000 1.0000
71.7200 6706.0000 1.0000
71.7800 6946.0000 1.0000
71.8400 7025.0000 1.0000
71.9000 7198.0000 1.0000
71.9600 7345.0000 1.0000
72.0200 7161.0000 1.0000
72.0800 6996.0000 1.0000
72.1400 6971.0000 1.0000
72.2000 6937.0000 1.0000
72.2600 6966.0000 1.0000
72.3200 6917.0000 1.0000
72.3800 6870.0000 1.0000
72.4400 6902.0000 1.0000
72.5000 6929.0000 1.0000
72.5600 6661.0000 1.0000
72.6200 6823.0000 1.0000
72.6800 6754.0000 1.0000
72.7400 6788.0000 1.0000
72.8000 6792.0000 1.0000
72.8600 6870.0000 1.0000
72.9200 6654.0000 1.0000
72.9800 6693.0000 1.0000
73.0400 6765.0000 1.0000
73.1000 6927.0000 1.0000
73.1600 6937.0000 1.0000
73.2200 6900.0000 1.0000
73.2800 6912.0000 1.0000
73.3400 7094.0000 1.0000
73.4000 7300.0000 1.0000
73.4600 8334.0000 1.0000
73.5200 7116.0000 1.0000
73.5800 6958.0000 1.0000
73.6400 7225.0000 1.0000
73.7000 7368.0000 1.0000
73.7600 7028.0000 1.0000
73.8200 7054.0000 1.0000
73.8800 6903.0000 1.0000
73.9400 7137.0000 1.0000
74.0000 7029.0000 1.0000
74.0600 7452.0000 1.0000
74.1200 7704.0000 1.0000
74.1800 7318.0000 1.0000
74.2400 7298.0000 1.0000
74.3000 7357.0000 1.0000
74.3600 7196.0000 1.0000
74.4200 7030.0000 1.0000
74.4800 7090.0000 1.0000
74.5400 6931.0000 1.0000
74.6000 6720.0000 1.0000
74.6600 6798.0000 1.0000
74.7200 6911.0000 1.0000
74.7800 6895.0000 1.0000
74.8400 6794.0000 1.0000
74.9000 6899.0000 1.0000
74.9600 6927.0000 1.0000
75.0200 6890.0000 1.0000
75.0800 7127.0000 1.0000
75.1400 7096.0000 1.0000
75.2000 6952.0000 1.0000
75.2600 7003.0000 1.0000
75.3200 7103.0000 1.0000
75.3800 7001.0000 1.0000
75.4400 7359.0000 1.0000
75.5000 7206.0000 1.0000
75.5600 7175.0000 1.0000
75.6200 8027.0000 1.0000
75.6800 8035.0000 1.0000
75.7400 7216.0000 1.0000
75.8000 7151.0000 1.0000
75.8600 7569.0000 1.0000
75.9200 7286.0000 1.0000
75.9800 6740.0000 1.0000
76.0400 6817.0000 1.0000
76.1000 6676.0000 1.0000
76.1600 6667.0000 1.0000
76.2200 6839.0000 1.0000
76.2800 6810.0000 1.0000
76.3400 6808.0000 1.0000
76.4000 6863.0000 1.0000
76.4600 6833.0000 1.0000
76.5200 6974.0000 1.0000
76.5800 6932.0000 1.0000
76.6400 6911.0000 1.0000
76.7000 7040.0000 1.0000
76.7600 7166.0000 1.0000
76.8200 7706.0000 1.0000
76.8800 7799.0000 1.0000
76.9400 7403.0000 1.0000
77.0000 7252.0000 1.0000
77.0600 7359.0000 1.0000
77.1200 7446.0000 1.0000
77.1800 7445.0000 1.0000
77.2400 7505.0000 1.0000
77.3000 7259.0000 1.0000
77.3600 6937.0000 1.0000
77.4200 7031.0000 1.0000
77.4800 7000.0000 1.0000
77.5400 7104.0000 1.0000
77.6000 7068.0000 1.0000
77.6600 7975.0000 1.0000
77.7200 7218.0000 1.0000
77.7800 6894.0000 1.0000
77.8400 7073.0000 1.0000
77.9000 7277.0000 1.0000
77.9600 6881.0000 1.0000
78.0200 6761.0000 1.0000
78.0800 6754.0000 1.0000
78.1400 6635.0000 1.0000
78.2000 6737.0000 1.0000
78.2600 6774.0000 1.0000
78.3200 6760.0000 1.0000
78.3800 6809.0000 1.0000
78.4400 6681.0000 1.0000
78.5000 6629.0000 1.0000
78.5600 6772.0000 1.0000
78.6200 6672.0000 1.0000
78.6800 6763.0000 1.0000
78.7400 6823.0000 1.0000
78.8000 6651.0000 1.0000
78.8600 6804.0000 1.0000
78.9200 6793.0000 1.0000
78.9800 7019.0000 1.0000
79.0400 6835.0000 1.0000
79.1000 6903.0000 1.0000
79.1600 6807.0000 1.0000
79.2200 6847.0000 1.0000
79.2800 6934.0000 1.0000
79.3400 6792.0000 1.0000
79.4000 6783.0000 1.0000
79.4600 6548.0000 1.0000
79.5200 6794.0000 1.0000
79.5800 6839.0000 1.0000
79.6400 6708.0000 1.0000
79.7000 6810.0000 1.0000
79.7600 6853.0000 1.0000
79.8200 7536.0000 1.0000
79.8800 8873.0000 1.0000
79.9400 7302.0000 1.0000
80.0000 7346.0000 1.0000
80.0600 7563.0000 1.0000
80.1200 7910.0000 1.0000
80.1800 6917.0000 1.0000
80.2400 7092.0000 1.0000
80.3000 7062.0000 1.0000
80.3600 6758.0000 1.0000
80.4200 6914.0000 1.0000
80.4800 6856.0000 1.0000
80.5400 6861.0000 1.0000
80.6000 7042.0000 1.0000
80.6600 7215.0000 1.0000
80.7200 7292.0000 1.0000
80.7800 7014.0000 1.0000
80.8400 7041.0000 1.0000
80.9000 6906.0000 1.0000
80.9600 6917.0000 1.0000
81.0200 6857.0000 1.0000
81.0800 7018.0000 1.0000
81.1400 7815.0000 1.0000
81.2000 7681.0000 1.0000
81.2600 7020.0000 1.0000
81.3200 7131.0000 1.0000
81.3800 7511.0000 1.0000
81.4400 8130.0000 1.0000
81.5000 8071.0000 1.0000
81.5600 6981.0000 1.0000
81.6200 6977.0000 1.0000
81.6800 7153.0000 1.0000
81.7400 7486.0000 1.0000
81.8000 6831.0000 1.0000
81.8600 6708.0000 1.0000
81.9200 6706.0000 1.0000
81.9800 6726.0000 1.0000
82.0400 6614.0000 1.0000
82.1000 6714.0000 1.0000
82.1600 6731.0000 1.0000
82.2200 6525.0000 1.0000
82.2800 6674.0000 1.0000
82.3400 6683.0000 1.0000
82.4000 6823.0000 1.0000
82.4600 6706.0000 1.0000
82.5200 6701.0000 1.0000
82.5800 6712.0000 1.0000
82.6400 6422.0000 1.0000
82.7000 6748.0000 1.0000
82.7600 6605.0000 1.0000
82.8200 6761.0000 1.0000
82.8800 6934.0000 1.0000
82.9400 7032.0000 1.0000
83.0000 6833.0000 1.0000
83.0600 6771.0000 1.0000
83.1200 6607.0000 1.0000
83.1800 6793.0000 1.0000
83.2400 6916.0000 1.0000
83.3000 6881.0000 1.0000
83.3600 6718.0000 1.0000
83.4200 6604.0000 1.0000
83.4800 6616.0000 1.0000
83.5400 6668.0000 1.0000
83.6000 6753.0000 1.0000
83.6600 6692.0000 1.0000
83.7200 6761.0000 1.0000
83.7800 7263.0000 1.0000
83.8400 7620.0000 1.0000
83.9000 6892.0000 1.0000
83.9600 6726.0000 1.0000
84.0200 6826.0000 1.0000
84.0800 7163.0000 1.0000
84.1400 6982.0000 1.0000
84.2000 6620.0000 1.0000
84.2600 6881.0000 1.0000
84.3200 6841.0000 1.0000
84.3800 6873.0000 1.0000
84.4400 6859.0000 1.0000
84.5000 6812.0000 1.0000
84.5600 6667.0000 1.0000
84.6200 6834.0000 1.0000
84.6800 6764.0000 1.0000
84.7400 6828.0000 1.0000
84.8000 6717.0000 1.0000
84.8600 6773.0000 1.0000
84.9200 7137.0000 1.0000
84.9800 7133.0000 1.0000
85.0400 6818.0000 1.0000
85.1000 6856.0000 1.0000
85.1600 7023.0000 1.0000
85.2200 6966.0000 1.0000
85.2800 6816.0000 1.0000
85.3400 6656.0000 1.0000
85.4000 6681.0000 1.0000
85.4600 6578.0000 1.0000
85.5200 6544.0000 1.0000
85.5800 6595.0000 1.0000
85.6400 6708.0000 1.0000
85.7000 6684.0000 1.0000
85.7600 6636.0000 1.0000
85.8200 6663.0000 1.0000
85.8800 6718.0000 1.0000
85.9400 6606.0000 1.0000
86.0000 6628.0000 1.0000
86.0600 6644.0000 1.0000
86.1200 6602.0000 1.0000
86.1800 6716.0000 1.0000
86.2400 6648.0000 1.0000
86.3000 6826.0000 1.0000
86.3600 6862.0000 1.0000
86.4200 6883.0000 1.0000
86.4800 6748.0000 1.0000
86.5400 6818.0000 1.0000
86.6000 6678.0000 1.0000
86.6600 6803.0000 1.0000
86.7200 6866.0000 1.0000
86.7800 6810.0000 1.0000
86.8400 6969.0000 1.0000
86.9000 6829.0000 1.0000
86.9600 6926.0000 1.0000
87.0200 6830.0000 1.0000
87.0800 6864.0000 1.0000
87.1400 6891.0000 1.0000
87.2000 6842.0000 1.0000
87.2600 6657.0000 1.0000
87.3200 6777.0000 1.0000
87.3800 6759.0000 1.0000
87.4400 6805.0000 1.0000
87.5000 6587.0000 1.0000
87.5600 6716.0000 1.0000
87.6200 6584.0000 1.0000
87.6800 6557.0000 1.0000
87.7400 6692.0000 1.0000
87.8000 6505.0000 1.0000
87.8600 6561.0000 1.0000
87.9200 6728.0000 1.0000
87.9800 6674.0000 1.0000
88.0400 6551.0000 1.0000
88.1000 6566.0000 1.0000
88.1600 6510.0000 1.0000
88.2200 6538.0000 1.0000
88.2800 6680.0000 1.0000
88.3400 6645.0000 1.0000
88.4000 6794.0000 1.0000
88.4600 6783.0000 1.0000
88.5200 6836.0000 1.0000
88.5800 6773.0000 1.0000
88.6400 6783.0000 1.0000
88.7000 6823.0000 1.0000
88.7600 6720.0000 1.0000
88.8200 6699.0000 1.0000
88.8800 6963.0000 1.0000
88.9400 6952.0000 1.0000
89.0000 7089.0000 1.0000
89.0600 6939.0000 1.0000
89.1200 6800.0000 1.0000
89.1800 6890.0000 1.0000
89.2400 6920.0000 1.0000
89.3000 7052.0000 1.0000
89.3600 6914.0000 1.0000
89.4200 6751.0000 1.0000
89.4800 6895.0000 1.0000
89.5400 6821.0000 1.0000
89.6000 6806.0000 1.0000
89.6600 7152.0000 1.0000
89.7200 7544.0000 1.0000
89.7800 7643.0000 1.0000
89.8400 7502.0000 1.0000
89.9000 7327.0000 1.0000
89.9600 7254.0000 1.0000
90.0000 7154.0000 1.0000
*RAS_INT_END
*RAS_TEMPERATURE_START
*RAS_TEMPERATURE_END
*RAS_DATA_END