File: XRD/Data/20200826_mix_04.ras
*RAS_DATA_START
*RAS_HEADER_START
*DISP_FMT_X "%.2f"
*DISP_FMT_Y "%.0f"
*DISP_FULLSCALE "42681.0000000000"
*DISP_LINE_COLOR "255.0000000000"
*DISP_LINE_STYLE "0.0000000000"
*DISP_LINE_WIDTH "0.2500000000"
*DISP_NOTE "測定データ-3"
*DISP_OFFSET_Y "0.0000000000"
*DISP_PEAKSEARCH_UNIT_Y "cps"
*DISP_RANGE_BOTTOM "0.0000000000"
*DISP_RANGE_LEFT "20.0000000000"
*DISP_RANGE_LOGCUTOFF "0.0100000000"
*DISP_RANGE_RIGHT "90.0000000000"
*DISP_RANGE_TOP "42681.0000000000"
*DISP_SCALE_MODE_Y "0.0000000000"
*DISP_TAB_NAME "2θ/θ"
*DISP_TITLE_Y "強度"
*DISP_UNIT_Y "cps"
*DISP_WINDOW_NAME "MSG_MACROENGINE"
*FILE_COMMENT " "
*FILE_MD5 ""
*FILE_MEMO " "
*FILE_OPERATOR "Administrator"
*FILE_SAMPLE " "
*FILE_TYPE "RAS_RAW"
*FILE_USERGROUP "システムマネージャ"
*FILE_VERSION "1.0000000000"
*HW_ATTACHMENT_ID "ATT0025"
*HW_ATTACHMENT_NAME "標準|Standard"
*HW_COUNTER_ID-0 "CUT0025"
*HW_COUNTER_ID-1 "CUT0020"
*HW_COUNTER_ID-2 "CUT0020"
*HW_COUNTER_ID-3 "CSL0021"
*HW_COUNTER_ID-4 "CMC0021"
*HW_COUNTER_NAME-0 "D/teX Ultra|D/teX Ultra"
*HW_COUNTER_NAME-1 "None|None"
*HW_COUNTER_NAME-2 "None|None"
*HW_COUNTER_NAME-3 "BBM|BBM"
*HW_COUNTER_NAME-4 "検出器モノクロメータ|Detector monochromator"
*HW_COUNTER_SELECT_NAME "D/teX Ultra|D/teX Ultra"
*HW_GONIOMETER_ID "GON0023"
*HW_GONIOMETER_NAME "SmartLab|SmartLab"
*HW_GONIOMETER_RADIUS-0 "90.0"
*HW_GONIOMETER_RADIUS-1 "114.0"
*HW_GONIOMETER_RADIUS-2 "190.0"
*HW_GONIOMETER_RADIUS-3 "300.0"
*HW_GONIOMETER_RADIUS-4 "187.0"
*HW_GONIOMETER_RADIUS-5 "300.0"
*HW_GONIOMETER_RADIUS-6 "113.0"
*HW_GONIOMETER_RADIUS-7 "331.0"
*HW_I_OPT_ID-0 "CBO0021"
*HW_I_OPT_ID-1 "ICR0023"
*HW_I_OPT_ID-2 "ISL0021"
*HW_I_OPT_ID-3 "ISO0021"
*HW_I_OPT_ID-4 "IAD0021"
*HW_I_OPT_ID-5 "IPR0001"
*HW_I_OPT_NAME-0 "CBOユニット|CBO unit"
*HW_I_OPT_NAME-1 "標準入射光学ユニット|Standard incident optical unit"
*HW_I_OPT_NAME-2 "標準入射スリットボックス|Standard incident slit box"
*HW_I_OPT_NAME-3 "入射平行スリット|Incident parallel slit"
*HW_I_OPT_NAME-4 "長手制限スリット|Length limiting slit"
*HW_I_OPT_NAME-5 "None|None"
*HW_R_ATTENUATER_AUTOMODE "0"
*HW_R_OPT_ID-0 "RSS0021"
*HW_R_OPT_ID-1 "RCR0023"
*HW_R_OPT_ID-2 "RSO0021"
*HW_R_OPT_ID-3 "RRS0021"
*HW_R_OPT_ID-4 "ATN0021"
*HW_R_OPT_ID-5 "RFL0021"
*HW_R_OPT_ID-6 "RAD0021"
*HW_R_OPT_NAME-0 "標準受光スリットボックス1|Standard receiving slit box # 1"
*HW_R_OPT_NAME-1 "標準受光光学ユニット1|Standard receiving unit # 1"
*HW_R_OPT_NAME-2 "標準受光光学ユニット2|Standard receiving optical unit # 2"
*HW_R_OPT_NAME-3 "標準受光スリットボックス2|Standard receiving slit box # 2"
*HW_R_OPT_NAME-4 "標準アッテネータ|Standard Attenuator"
*HW_R_OPT_NAME-5 "Cu Kβ|Cu K-beta"
*HW_R_OPT_NAME-6 "調整用受光スリット|Alignment receiving slit"
*HW_SAMPLE_HOLDER_ID "SMP0023"
*HW_SAMPLE_HOLDER_NAME "標準Zステージ|Standard Z stage"
*HW_XG_CURRENT_MAX "50"
*HW_XG_CURRENT_MIN "2"
*HW_XG_CURRENT_RESOLUTION "2"
*HW_XG_CURRENT_UNIT "mA"
*HW_XG_FOCUS "1mm x 10mm"
*HW_XG_FOCUS_TYPE "Normal"
*HW_XG_ID ""
*HW_XG_NAME "3kW 封入管(ID:1200)|3kW Sealed tube(ID:1200)"
*HW_XG_TARGET_ATOMIC_NUMBER "29.0000000000"
*HW_XG_TARGET_NAME "Cu"
*HW_XG_TYPE "Hermetic"
*HW_XG_VOLTAGE_MAX "60"
*HW_XG_VOLTAGE_MIN "20"
*HW_XG_VOLTAGE_RESOLUTION "2"
*HW_XG_VOLTAGE_UNIT "kV"
*HW_XG_WATT_MAX "2"
*HW_XG_WATT_UNIT "kW"
*HW_XG_WAVE_LENGTH_ALPHA1 "1.540593"
*HW_XG_WAVE_LENGTH_ALPHA2 "1.544414"
*HW_XG_WAVE_LENGTH_BETA "1.392250"
*MEAS_COND_AXIS_NAME-0 "2θ/θ"
*MEAS_COND_AXIS_NAME-1 "2θ"
*MEAS_COND_AXIS_NAME-2 "ω"
*MEAS_COND_AXIS_NAME-3 "Z"
*MEAS_COND_AXIS_NAME-4 "2θ/ω"
*MEAS_COND_AXIS_NAME-5 "θs"
*MEAS_COND_AXIS_NAME-6 "θd"
*MEAS_COND_AXIS_NAME-7 "Ts"
*MEAS_COND_AXIS_NAME-8 "CBO選択スリット"
*MEAS_COND_AXIS_NAME-9 "M"
*MEAS_COND_AXIS_NAME-10 "入射平行スリット"
*MEAS_COND_AXIS_NAME-11 "入射スリット"
*MEAS_COND_AXIS_NAME-12 ""
*MEAS_COND_AXIS_NAME-13 "Zs"
*MEAS_COND_AXIS_NAME-14 "入射光学素子"
*MEAS_COND_AXIS_NAME-15 "長手制限スリット"
*MEAS_COND_AXIS_NAME-16 "センタースリット"
*MEAS_COND_AXIS_NAME-17 "フィルター"
*MEAS_COND_AXIS_NAME-18 "受光スリット1"
*MEAS_COND_AXIS_NAME-19 "受光スリット2"
*MEAS_COND_AXIS_NAME-20 "受光光学素子"
*MEAS_COND_AXIS_NAME-21 "受光平行スリット"
*MEAS_COND_AXIS_NAME-22 "調整用受光スリット"
*MEAS_COND_AXIS_NAME-23 ""
*MEAS_COND_AXIS_NAME-24 ""
*MEAS_COND_AXIS_NAME-25 "Zd"
*MEAS_COND_AXIS_NAME-26 "アッテネータ"
*MEAS_COND_AXIS_NAME-27 "検出器モノクロメータ"
*MEAS_COND_AXIS_NAME-28 "モノクロメータスリット"
*MEAS_COND_AXIS_NAME-29 "プライマリビーム"
*MEAS_COND_AXIS_NAME-30 "PHA"
*MEAS_COND_AXIS_NAME_INTERNAL-0 "TwoThetaTheta"
*MEAS_COND_AXIS_NAME_INTERNAL-1 "TwoTheta"
*MEAS_COND_AXIS_NAME_INTERNAL-2 "Omega"
*MEAS_COND_AXIS_NAME_INTERNAL-3 "Z"
*MEAS_COND_AXIS_NAME_INTERNAL-4 "TwoThetaOmega"
*MEAS_COND_AXIS_NAME_INTERNAL-5 "ThetaS"
*MEAS_COND_AXIS_NAME_INTERNAL-6 "ThetaD"
*MEAS_COND_AXIS_NAME_INTERNAL-7 "Ts"
*MEAS_COND_AXIS_NAME_INTERNAL-8 "CBO"
*MEAS_COND_AXIS_NAME_INTERNAL-9 "CBO-M"
*MEAS_COND_AXIS_NAME_INTERNAL-10 "IncidentSollerSlit"
*MEAS_COND_AXIS_NAME_INTERNAL-11 "IncidentSlitBox"
*MEAS_COND_AXIS_NAME_INTERNAL-12 "IncidentSlitBox-_Axis"
*MEAS_COND_AXIS_NAME_INTERNAL-13 "Zs"
*MEAS_COND_AXIS_NAME_INTERNAL-14 "IncidentMonochromator"
*MEAS_COND_AXIS_NAME_INTERNAL-15 "IncidentAxdSlit"
*MEAS_COND_AXIS_NAME_INTERNAL-16 "CenterSlit"
*MEAS_COND_AXIS_NAME_INTERNAL-17 "Filter"
*MEAS_COND_AXIS_NAME_INTERNAL-18 "ReceivingSlitBox1"
*MEAS_COND_AXIS_NAME_INTERNAL-19 "ReceivingSlitBox2"
*MEAS_COND_AXIS_NAME_INTERNAL-20 "ReceivingOptics"
*MEAS_COND_AXIS_NAME_INTERNAL-21 "ReceivingSollerSlit"
*MEAS_COND_AXIS_NAME_INTERNAL-22 "ReceivingAxdSlit"
*MEAS_COND_AXIS_NAME_INTERNAL-23 "ReceivingSlitBox1-_Axis"
*MEAS_COND_AXIS_NAME_INTERNAL-24 "ReceivingSlitBox2-_Axis"
*MEAS_COND_AXIS_NAME_INTERNAL-25 "ReceivingSlitBox2-Zd"
*MEAS_COND_AXIS_NAME_INTERNAL-26 "Attenuator"
*MEAS_COND_AXIS_NAME_INTERNAL-27 "CounterMonochromator"
*MEAS_COND_AXIS_NAME_INTERNAL-28 "CounterSlit"
*MEAS_COND_AXIS_NAME_INTERNAL-29 "IncidentPrimary"
*MEAS_COND_AXIS_NAME_INTERNAL-30 "PHA"
*MEAS_COND_AXIS_NAME_MAGICNO-0 "83951616.0000000000"
*MEAS_COND_AXIS_NAME_MAGICNO-1 "268632064.0000000000"
*MEAS_COND_AXIS_NAME_MAGICNO-2 "268500992.0000000000"
*MEAS_COND_AXIS_NAME_MAGICNO-3 "285278208.0000000000"
*MEAS_COND_AXIS_NAME_MAGICNO-4 "83951616.0000000000"
*MEAS_COND_AXIS_NAME_MAGICNO-5 "131072.0000000000"
*MEAS_COND_AXIS_NAME_MAGICNO-6 "131072.0000000000"
*MEAS_COND_AXIS_NAME_MAGICNO-7 "318898176.0000000000"
*MEAS_COND_AXIS_NAME_MAGICNO-8 "20971521.0000000000"
*MEAS_COND_AXIS_NAME_MAGICNO-9 "285343744.0000000000"
*MEAS_COND_AXIS_NAME_MAGICNO-10 "20971521.0000000000"
*MEAS_COND_AXIS_NAME_MAGICNO-11 "22020097.0000000000"
*MEAS_COND_AXIS_NAME_MAGICNO-12 "25165824.0000000000"
*MEAS_COND_AXIS_NAME_MAGICNO-13 "318898176.0000000000"
*MEAS_COND_AXIS_NAME_MAGICNO-14 "1.0000000000"
*MEAS_COND_AXIS_NAME_MAGICNO-15 "20971521.0000000000"
*MEAS_COND_AXIS_NAME_MAGICNO-16 "20971521.0000000000"
*MEAS_COND_AXIS_NAME_MAGICNO-17 "20971521.0000000000"
*MEAS_COND_AXIS_NAME_MAGICNO-18 "23068673.0000000000"
*MEAS_COND_AXIS_NAME_MAGICNO-19 "23068673.0000000000"
*MEAS_COND_AXIS_NAME_MAGICNO-20 "20971521.0000000000"
*MEAS_COND_AXIS_NAME_MAGICNO-21 "20971521.0000000000"
*MEAS_COND_AXIS_NAME_MAGICNO-22 "20971521.0000000000"
*MEAS_COND_AXIS_NAME_MAGICNO-23 "25165824.0000000000"
*MEAS_COND_AXIS_NAME_MAGICNO-24 "25165824.0000000000"
*MEAS_COND_AXIS_NAME_MAGICNO-25 "285343744.0000000000"
*MEAS_COND_AXIS_NAME_MAGICNO-26 "17301505.0000000000"
*MEAS_COND_AXIS_NAME_MAGICNO-27 "20971521.0000000000"
*MEAS_COND_AXIS_NAME_MAGICNO-28 "20971521.0000000000"
*MEAS_COND_AXIS_NAME_MAGICNO-29 "20971521.0000000000"
*MEAS_COND_AXIS_NAME_MAGICNO-30 "0.0000000000"
*MEAS_COND_AXIS_OFFSET-0 "-"
*MEAS_COND_AXIS_OFFSET-1 "-0.1081000000"
*MEAS_COND_AXIS_OFFSET-2 "0.3758000000"
*MEAS_COND_AXIS_OFFSET-3 "-"
*MEAS_COND_AXIS_OFFSET-4 "-"
*MEAS_COND_AXIS_OFFSET-5 "0.3758000000"
*MEAS_COND_AXIS_OFFSET-6 "-0.4839000000"
*MEAS_COND_AXIS_OFFSET-7 "-"
*MEAS_COND_AXIS_OFFSET-8 "-"
*MEAS_COND_AXIS_OFFSET-9 "-"
*MEAS_COND_AXIS_OFFSET-10 "-"
*MEAS_COND_AXIS_OFFSET-11 "-"
*MEAS_COND_AXIS_OFFSET-12 "-"
*MEAS_COND_AXIS_OFFSET-13 "-"
*MEAS_COND_AXIS_OFFSET-14 "-"
*MEAS_COND_AXIS_OFFSET-15 "-"
*MEAS_COND_AXIS_OFFSET-16 "-"
*MEAS_COND_AXIS_OFFSET-17 "-"
*MEAS_COND_AXIS_OFFSET-18 "-"
*MEAS_COND_AXIS_OFFSET-19 "-"
*MEAS_COND_AXIS_OFFSET-20 "-"
*MEAS_COND_AXIS_OFFSET-21 "-"
*MEAS_COND_AXIS_OFFSET-22 "-"
*MEAS_COND_AXIS_OFFSET-23 "-"
*MEAS_COND_AXIS_OFFSET-24 "-"
*MEAS_COND_AXIS_OFFSET-25 "-"
*MEAS_COND_AXIS_OFFSET-26 "-"
*MEAS_COND_AXIS_OFFSET-27 "-"
*MEAS_COND_AXIS_OFFSET-28 "-"
*MEAS_COND_AXIS_OFFSET-29 "-"
*MEAS_COND_AXIS_OFFSET-30 "-"
*MEAS_COND_AXIS_POSITION-0 "0.0000000000"
*MEAS_COND_AXIS_POSITION-1 "0.0000000000"
*MEAS_COND_AXIS_POSITION-2 "0.0000000000"
*MEAS_COND_AXIS_POSITION-3 "-0.5500000000"
*MEAS_COND_AXIS_POSITION-4 "0.0000000000"
*MEAS_COND_AXIS_POSITION-5 "0.0000000000"
*MEAS_COND_AXIS_POSITION-6 "0.0000000000"
*MEAS_COND_AXIS_POSITION-7 "-0.4278800000"
*MEAS_COND_AXIS_POSITION-8 "BB"
*MEAS_COND_AXIS_POSITION-9 "0.0000000000"
*MEAS_COND_AXIS_POSITION-10 "Soller_slit_5.0deg"
*MEAS_COND_AXIS_POSITION-11 "2/3deg"
*MEAS_COND_AXIS_POSITION-12 "2.2088000000"
*MEAS_COND_AXIS_POSITION-13 "-0.4140600000"
*MEAS_COND_AXIS_POSITION-14 "0.0000000000"
*MEAS_COND_AXIS_POSITION-15 "10.0mm"
*MEAS_COND_AXIS_POSITION-16 "None"
*MEAS_COND_AXIS_POSITION-17 "Cu_K-beta"
*MEAS_COND_AXIS_POSITION-18 "13.000mm"
*MEAS_COND_AXIS_POSITION-19 "13.000mm"
*MEAS_COND_AXIS_POSITION-20 "No_unit"
*MEAS_COND_AXIS_POSITION-21 "Soller_slit_5.0deg"
*MEAS_COND_AXIS_POSITION-22 "None"
*MEAS_COND_AXIS_POSITION-23 "13.0000000000"
*MEAS_COND_AXIS_POSITION-24 "13.0000000000"
*MEAS_COND_AXIS_POSITION-25 "0.0109400000"
*MEAS_COND_AXIS_POSITION-26 "Open"
*MEAS_COND_AXIS_POSITION-27 "None"
*MEAS_COND_AXIS_POSITION-28 "None"
*MEAS_COND_AXIS_POSITION-29 "None"
*MEAS_COND_AXIS_POSITION-30 "38.0000000000"
*MEAS_COND_AXIS_UNIT-0 "deg"
*MEAS_COND_AXIS_UNIT-1 "deg"
*MEAS_COND_AXIS_UNIT-2 "deg"
*MEAS_COND_AXIS_UNIT-3 "mm"
*MEAS_COND_AXIS_UNIT-4 "deg"
*MEAS_COND_AXIS_UNIT-5 "deg"
*MEAS_COND_AXIS_UNIT-6 "deg"
*MEAS_COND_AXIS_UNIT-7 "mm"
*MEAS_COND_AXIS_UNIT-8 ""
*MEAS_COND_AXIS_UNIT-9 "pulse"
*MEAS_COND_AXIS_UNIT-10 ""
*MEAS_COND_AXIS_UNIT-11 ""
*MEAS_COND_AXIS_UNIT-12 "mm"
*MEAS_COND_AXIS_UNIT-13 "mm"
*MEAS_COND_AXIS_UNIT-14 ""
*MEAS_COND_AXIS_UNIT-15 ""
*MEAS_COND_AXIS_UNIT-16 ""
*MEAS_COND_AXIS_UNIT-17 ""
*MEAS_COND_AXIS_UNIT-18 ""
*MEAS_COND_AXIS_UNIT-19 ""
*MEAS_COND_AXIS_UNIT-20 ""
*MEAS_COND_AXIS_UNIT-21 ""
*MEAS_COND_AXIS_UNIT-22 ""
*MEAS_COND_AXIS_UNIT-23 "mm"
*MEAS_COND_AXIS_UNIT-24 "mm"
*MEAS_COND_AXIS_UNIT-25 "mm"
*MEAS_COND_AXIS_UNIT-26 ""
*MEAS_COND_AXIS_UNIT-27 ""
*MEAS_COND_AXIS_UNIT-28 ""
*MEAS_COND_AXIS_UNIT-29 ""
*MEAS_COND_AXIS_UNIT-30 "div"
*MEAS_COND_COUNTER_CNTLOSS_CORR "0.0000000000"
*MEAS_COND_COUNTER_PHABASE "38.0000000000"
*MEAS_COND_COUNTER_PHAWINDOW "16.0000000000"
*MEAS_COND_COUNTER_PHA_UNIT "div"
*MEAS_COND_COUNTER_TAUDIFF "30.0000000000"
*MEAS_COND_COUNTER_TAUINT "0.0000000000"
*MEAS_COND_IRRADIATION_MODE "OFF"
*MEAS_COND_IRRADIATION_WIDTH ""
*MEAS_COND_OPT_ATTR "集中法"
*MEAS_COND_OPT_NAME "@集中法"
*MEAS_COND_UNSYMMETRIC_MODE "OFF"
*MEAS_COND_XG_CURRENT "30.0000000000"
*MEAS_COND_XG_VOLTAGE "40.0000000000"
*MEAS_COND_XG_WAVE_TYPE "Ka"
*MEAS_DATA_COUNT "3501.0000000000"
*MEAS_SCAN_AXIS_X "2θ/θ"
*MEAS_SCAN_AXIS_X_INTERNAL "TwoThetaTheta"
*MEAS_SCAN_END_TIME "08/26/20 15:47:57"
*MEAS_SCAN_MODE "CONTINUOUS"
*MEAS_SCAN_MONITOR "0"
*MEAS_SCAN_RESOLUTION_X "0.0002"
*MEAS_SCAN_SPEED "1.0"
*MEAS_SCAN_SPEED_UNIT "deg/min"
*MEAS_SCAN_START "20.0000000000"
*MEAS_SCAN_START_TIME "08/26/20 14:35:02"
*MEAS_SCAN_STEP "0.0200000000"
*MEAS_SCAN_STOP "90.0000000000"
*MEAS_SCAN_UNIT_X "deg"
*MEAS_SCAN_UNIT_Y "counts"
*RAS_HEADER_END
*RAS_INT_START
20.0000 10685.0000 1.0000
20.0600 10810.0000 1.0000
20.1200 10778.0000 1.0000
20.1800 10861.0000 1.0000
20.2400 10841.0000 1.0000
20.3000 10856.0000 1.0000
20.3600 11026.0000 1.0000
20.4200 10777.0000 1.0000
20.4800 10956.0000 1.0000
20.5400 11000.0000 1.0000
20.6000 11140.0000 1.0000
20.6600 11237.0000 1.0000
20.7200 11577.0000 1.0000
20.7800 12453.0000 1.0000
20.8400 14991.0000 1.0000
20.9000 19218.0000 1.0000
20.9600 14493.0000 1.0000
21.0200 11285.0000 1.0000
21.0800 11020.0000 1.0000
21.1400 10828.0000 1.0000
21.2000 10825.0000 1.0000
21.2600 10794.0000 1.0000
21.3200 10688.0000 1.0000
21.3800 10697.0000 1.0000
21.4400 10956.0000 1.0000
21.5000 10847.0000 1.0000
21.5600 10788.0000 1.0000
21.6200 10855.0000 1.0000
21.6800 10829.0000 1.0000
21.7400 10821.0000 1.0000
21.8000 10807.0000 1.0000
21.8600 10644.0000 1.0000
21.9200 10883.0000 1.0000
21.9800 10907.0000 1.0000
22.0400 10917.0000 1.0000
22.1000 10797.0000 1.0000
22.1600 10785.0000 1.0000
22.2200 10733.0000 1.0000
22.2800 10753.0000 1.0000
22.3400 10670.0000 1.0000
22.4000 10690.0000 1.0000
22.4600 10653.0000 1.0000
22.5200 10776.0000 1.0000
22.5800 10789.0000 1.0000
22.6400 10800.0000 1.0000
22.7000 10751.0000 1.0000
22.7600 10727.0000 1.0000
22.8200 10694.0000 1.0000
22.8800 10678.0000 1.0000
22.9400 10668.0000 1.0000
23.0000 10641.0000 1.0000
23.0600 10758.0000 1.0000
23.1200 10735.0000 1.0000
23.1800 10635.0000 1.0000
23.2400 10705.0000 1.0000
23.3000 10734.0000 1.0000
23.3600 10679.0000 1.0000
23.4200 10983.0000 1.0000
23.4800 10653.0000 1.0000
23.5400 10639.0000 1.0000
23.6000 10756.0000 1.0000
23.6600 10615.0000 1.0000
23.7200 10925.0000 1.0000
23.7800 10821.0000 1.0000
23.8400 10821.0000 1.0000
23.9000 10855.0000 1.0000
23.9600 11085.0000 1.0000
24.0200 11478.0000 1.0000
24.0800 12275.0000 1.0000
24.1400 13662.0000 1.0000
24.2000 14007.0000 1.0000
24.2600 12490.0000 1.0000
24.3200 11318.0000 1.0000
24.3800 10712.0000 1.0000
24.4400 10489.0000 1.0000
24.5000 10674.0000 1.0000
24.5600 10681.0000 1.0000
24.6200 10721.0000 1.0000
24.6800 10486.0000 1.0000
24.7400 10659.0000 1.0000
24.8000 10483.0000 1.0000
24.8600 10554.0000 1.0000
24.9200 10857.0000 1.0000
24.9800 10376.0000 1.0000
25.0400 10693.0000 1.0000
25.1000 10610.0000 1.0000
25.1600 10577.0000 1.0000
25.2200 10686.0000 1.0000
25.2800 10461.0000 1.0000
25.3400 10752.0000 1.0000
25.4000 10688.0000 1.0000
25.4600 10721.0000 1.0000
25.5200 11056.0000 1.0000
25.5800 11520.0000 1.0000
25.6400 11478.0000 1.0000
25.7000 11089.0000 1.0000
25.7600 10788.0000 1.0000
25.8200 10605.0000 1.0000
25.8800 10654.0000 1.0000
25.9400 10756.0000 1.0000
26.0000 10650.0000 1.0000
26.0600 10770.0000 1.0000
26.1200 10448.0000 1.0000
26.1800 10581.0000 1.0000
26.2400 10835.0000 1.0000
26.3000 10742.0000 1.0000
26.3600 11102.0000 1.0000
26.4200 11611.0000 1.0000
26.4800 13135.0000 1.0000
26.5400 14895.0000 1.0000
26.6000 21807.0000 1.0000
26.6600 42681.0000 1.0000
26.7200 30732.0000 1.0000
26.7800 17176.0000 1.0000
26.8400 12226.0000 1.0000
26.9000 11258.0000 1.0000
26.9600 10886.0000 1.0000
27.0200 10696.0000 1.0000
27.0800 10555.0000 1.0000
27.1400 10440.0000 1.0000
27.2000 10678.0000 1.0000
27.2600 10634.0000 1.0000
27.3200 10474.0000 1.0000
27.3800 10366.0000 1.0000
27.4400 10367.0000 1.0000
27.5000 10365.0000 1.0000
27.5600 10252.0000 1.0000
27.6200 10285.0000 1.0000
27.6800 10425.0000 1.0000
27.7400 10187.0000 1.0000
27.8000 10391.0000 1.0000
27.8600 10357.0000 1.0000
27.9200 10367.0000 1.0000
27.9800 10302.0000 1.0000
28.0400 10448.0000 1.0000
28.1000 10157.0000 1.0000
28.1600 10315.0000 1.0000
28.2200 10291.0000 1.0000
28.2800 10218.0000 1.0000
28.3400 10154.0000 1.0000
28.4000 10208.0000 1.0000
28.4600 10287.0000 1.0000
28.5200 10315.0000 1.0000
28.5800 10337.0000 1.0000
28.6400 10324.0000 1.0000
28.7000 10115.0000 1.0000
28.7600 10225.0000 1.0000
28.8200 10165.0000 1.0000
28.8800 10362.0000 1.0000
28.9400 10329.0000 1.0000
29.0000 10406.0000 1.0000
29.0600 10291.0000 1.0000
29.1200 10282.0000 1.0000
29.1800 10192.0000 1.0000
29.2400 10322.0000 1.0000
29.3000 10399.0000 1.0000
29.3600 10270.0000 1.0000
29.4200 10302.0000 1.0000
29.4800 10198.0000 1.0000
29.5400 10491.0000 1.0000
29.6000 10264.0000 1.0000
29.6600 10170.0000 1.0000
29.7200 10356.0000 1.0000
29.7800 10237.0000 1.0000
29.8400 10446.0000 1.0000
29.9000 10252.0000 1.0000
29.9600 10613.0000 1.0000
30.0200 10857.0000 1.0000
30.0800 11528.0000 1.0000
30.1400 12510.0000 1.0000
30.2000 12196.0000 1.0000
30.2600 11432.0000 1.0000
30.3200 10762.0000 1.0000
30.3800 10570.0000 1.0000
30.4400 10465.0000 1.0000
30.5000 10249.0000 1.0000
30.5600 10359.0000 1.0000
30.6200 10457.0000 1.0000
30.6800 10273.0000 1.0000
30.7400 10299.0000 1.0000
30.8000 10324.0000 1.0000
30.8600 10121.0000 1.0000
30.9200 10118.0000 1.0000
30.9800 9978.0000 1.0000
31.0400 10261.0000 1.0000
31.1000 10265.0000 1.0000
31.1600 10194.0000 1.0000
31.2200 10061.0000 1.0000
31.2800 10105.0000 1.0000
31.3400 10228.0000 1.0000
31.4000 10135.0000 1.0000
31.4600 10206.0000 1.0000
31.5200 10215.0000 1.0000
31.5800 10161.0000 1.0000
31.6400 10237.0000 1.0000
31.7000 10341.0000 1.0000
31.7600 10357.0000 1.0000
31.8200 10319.0000 1.0000
31.8800 10294.0000 1.0000
31.9400 10268.0000 1.0000
32.0000 10410.0000 1.0000
32.0600 10147.0000 1.0000
32.1200 10245.0000 1.0000
32.1800 10168.0000 1.0000
32.2400 10333.0000 1.0000
32.3000 10232.0000 1.0000
32.3600 10285.0000 1.0000
32.4200 10130.0000 1.0000
32.4800 10074.0000 1.0000
32.5400 10174.0000 1.0000
32.6000 10415.0000 1.0000
32.6600 10278.0000 1.0000
32.7200 10157.0000 1.0000
32.7800 10483.0000 1.0000
32.8400 10683.0000 1.0000
32.9000 10950.0000 1.0000
32.9600 11150.0000 1.0000
33.0200 11809.0000 1.0000
33.0800 13665.0000 1.0000
33.1400 18733.0000 1.0000
33.2000 22747.0000 1.0000
33.2600 18928.0000 1.0000
33.3200 14645.0000 1.0000
33.3800 11680.0000 1.0000
33.4400 10722.0000 1.0000
33.5000 10691.0000 1.0000
33.5600 10456.0000 1.0000
33.6200 10231.0000 1.0000
33.6800 10157.0000 1.0000
33.7400 10286.0000 1.0000
33.8000 10067.0000 1.0000
33.8600 10107.0000 1.0000
33.9200 10206.0000 1.0000
33.9800 10188.0000 1.0000
34.0400 10052.0000 1.0000
34.1000 10148.0000 1.0000
34.1600 10282.0000 1.0000
34.2200 10265.0000 1.0000
34.2800 10121.0000 1.0000
34.3400 10225.0000 1.0000
34.4000 10220.0000 1.0000
34.4600 10247.0000 1.0000
34.5200 10413.0000 1.0000
34.5800 10149.0000 1.0000
34.6400 10194.0000 1.0000
34.7000 10209.0000 1.0000
34.7600 10201.0000 1.0000
34.8200 10250.0000 1.0000
34.8800 10305.0000 1.0000
34.9400 10579.0000 1.0000
35.0000 10598.0000 1.0000
35.0600 11039.0000 1.0000
35.1200 11586.0000 1.0000
35.1800 12491.0000 1.0000
35.2400 12060.0000 1.0000
35.3000 11923.0000 1.0000
35.3600 12040.0000 1.0000
35.4200 13819.0000 1.0000
35.4800 17898.0000 1.0000
35.5400 19542.0000 1.0000
35.6000 20930.0000 1.0000
35.6600 22337.0000 1.0000
35.7200 18252.0000 1.0000
35.7800 15241.0000 1.0000
35.8400 12062.0000 1.0000
35.9000 10881.0000 1.0000
35.9600 10519.0000 1.0000
36.0200 10363.0000 1.0000
36.0800 10346.0000 1.0000
36.1400 10209.0000 1.0000
36.2000 10088.0000 1.0000
36.2600 10172.0000 1.0000
36.3200 10295.0000 1.0000
36.3800 10279.0000 1.0000
36.4400 10425.0000 1.0000
36.5000 10730.0000 1.0000
36.5600 12439.0000 1.0000
36.6200 11301.0000 1.0000
36.6800 11275.0000 1.0000
36.7400 10270.0000 1.0000
36.8000 10357.0000 1.0000
36.8600 10148.0000 1.0000
36.9200 10308.0000 1.0000
36.9800 10186.0000 1.0000
37.0400 10263.0000 1.0000
37.1000 10431.0000 1.0000
37.1600 10495.0000 1.0000
37.2200 10410.0000 1.0000
37.2800 10178.0000 1.0000
37.3400 10028.0000 1.0000
37.4000 10079.0000 1.0000
37.4600 9992.0000 1.0000
37.5200 9973.0000 1.0000
37.5800 10159.0000 1.0000
37.6400 10227.0000 1.0000
37.7000 10423.0000 1.0000
37.7600 10781.0000 1.0000
37.8200 10982.0000 1.0000
37.8800 10705.0000 1.0000
37.9400 10360.0000 1.0000
38.0000 10268.0000 1.0000
38.0600 10093.0000 1.0000
38.1200 9985.0000 1.0000
38.1800 10135.0000 1.0000
38.2400 10217.0000 1.0000
38.3000 9920.0000 1.0000
38.3600 10201.0000 1.0000
38.4200 10144.0000 1.0000
38.4800 9914.0000 1.0000
38.5400 9975.0000 1.0000
38.6000 10094.0000 1.0000
38.6600 10087.0000 1.0000
38.7200 9840.0000 1.0000
38.7800 10135.0000 1.0000
38.8400 10090.0000 1.0000
38.9000 10067.0000 1.0000
38.9600 10061.0000 1.0000
39.0200 10024.0000 1.0000
39.0800 10085.0000 1.0000
39.1400 10124.0000 1.0000
39.2000 10111.0000 1.0000
39.2600 10285.0000 1.0000
39.3200 10302.0000 1.0000
39.3800 10572.0000 1.0000
39.4400 10808.0000 1.0000
39.5000 11473.0000 1.0000
39.5600 10804.0000 1.0000
39.6200 10507.0000 1.0000
39.6800 10072.0000 1.0000
39.7400 10246.0000 1.0000
39.8000 10012.0000 1.0000
39.8600 10111.0000 1.0000
39.9200 10068.0000 1.0000
39.9800 9996.0000 1.0000
40.0400 10067.0000 1.0000
40.1000 10080.0000 1.0000
40.1600 10190.0000 1.0000
40.2200 10332.0000 1.0000
40.2800 11178.0000 1.0000
40.3400 10776.0000 1.0000
40.4000 10764.0000 1.0000
40.4600 10295.0000 1.0000
40.5200 10375.0000 1.0000
40.5800 10170.0000 1.0000
40.6400 10150.0000 1.0000
40.7000 10302.0000 1.0000
40.7600 10767.0000 1.0000
40.8200 11337.0000 1.0000
40.8800 12772.0000 1.0000
40.9400 12105.0000 1.0000
41.0000 11785.0000 1.0000
41.0600 10855.0000 1.0000
41.1200 10242.0000 1.0000
41.1800 10284.0000 1.0000
41.2400 10064.0000 1.0000
41.3000 10074.0000 1.0000
41.3600 10022.0000 1.0000
41.4200 10162.0000 1.0000
41.4800 10135.0000 1.0000
41.5400 10075.0000 1.0000
41.6000 10074.0000 1.0000
41.6600 10005.0000 1.0000
41.7200 9939.0000 1.0000
41.7800 10120.0000 1.0000
41.8400 10042.0000 1.0000
41.9000 10115.0000 1.0000
41.9600 10015.0000 1.0000
42.0200 10034.0000 1.0000
42.0800 10139.0000 1.0000
42.1400 9998.0000 1.0000
42.2000 10210.0000 1.0000
42.2600 10122.0000 1.0000
42.3200 10172.0000 1.0000
42.3800 10373.0000 1.0000
42.4400 12016.0000 1.0000
42.5000 12706.0000 1.0000
42.5600 11489.0000 1.0000
42.6200 11065.0000 1.0000
42.6800 10346.0000 1.0000
42.7400 10092.0000 1.0000
42.8000 10114.0000 1.0000
42.8600 10186.0000 1.0000
42.9200 10350.0000 1.0000
42.9800 10365.0000 1.0000
43.0400 10386.0000 1.0000
43.1000 11468.0000 1.0000
43.1600 11905.0000 1.0000
43.2200 11722.0000 1.0000
43.2800 12084.0000 1.0000
43.3400 12318.0000 1.0000
43.4000 12488.0000 1.0000
43.4600 11662.0000 1.0000
43.5200 11453.0000 1.0000
43.5800 10593.0000 1.0000
43.6400 10273.0000 1.0000
43.7000 10203.0000 1.0000
43.7600 10217.0000 1.0000
43.8200 9953.0000 1.0000
43.8800 10065.0000 1.0000
43.9400 10022.0000 1.0000
44.0000 10046.0000 1.0000
44.0600 9950.0000 1.0000
44.1200 10131.0000 1.0000
44.1800 9910.0000 1.0000
44.2400 9949.0000 1.0000
44.3000 9998.0000 1.0000
44.3600 9851.0000 1.0000
44.4200 10071.0000 1.0000
44.4800 10078.0000 1.0000
44.5400 9916.0000 1.0000
44.6000 10074.0000 1.0000
44.6600 10030.0000 1.0000
44.7200 10023.0000 1.0000
44.7800 10051.0000 1.0000
44.8400 9990.0000 1.0000
44.9000 9744.0000 1.0000
44.9600 9870.0000 1.0000
45.0200 9780.0000 1.0000
45.0800 9988.0000 1.0000
45.1400 9970.0000 1.0000
45.2000 10049.0000 1.0000
45.2600 9941.0000 1.0000
45.3200 10002.0000 1.0000
45.3800 10099.0000 1.0000
45.4400 10067.0000 1.0000
45.5000 9963.0000 1.0000
45.5600 10007.0000 1.0000
45.6200 10102.0000 1.0000
45.6800 10075.0000 1.0000
45.7400 10308.0000 1.0000
45.8000 10678.0000 1.0000
45.8600 10255.0000 1.0000
45.9200 10543.0000 1.0000
45.9800 10239.0000 1.0000
46.0400 9848.0000 1.0000
46.1000 10038.0000 1.0000
46.1600 9950.0000 1.0000
46.2200 10011.0000 1.0000
46.2800 10062.0000 1.0000
46.3400 9995.0000 1.0000
46.4000 10028.0000 1.0000
46.4600 9984.0000 1.0000
46.5200 9983.0000 1.0000
46.5800 9937.0000 1.0000
46.6400 9949.0000 1.0000
46.7000 9973.0000 1.0000
46.7600 9992.0000 1.0000
46.8200 9884.0000 1.0000
46.8800 9934.0000 1.0000
46.9400 9826.0000 1.0000
47.0000 9830.0000 1.0000
47.0600 9755.0000 1.0000
47.1200 10076.0000 1.0000
47.1800 9739.0000 1.0000
47.2400 10231.0000 1.0000
47.3000 10018.0000 1.0000
47.3600 9960.0000 1.0000
47.4200 9949.0000 1.0000
47.4800 9881.0000 1.0000
47.5400 10004.0000 1.0000
47.6000 9880.0000 1.0000
47.6600 10132.0000 1.0000
47.7200 9950.0000 1.0000
47.7800 9988.0000 1.0000
47.8400 10017.0000 1.0000
47.9000 9898.0000 1.0000
47.9600 9973.0000 1.0000
48.0200 10016.0000 1.0000
48.0800 9930.0000 1.0000
48.1400 9793.0000 1.0000
48.2000 10033.0000 1.0000
48.2600 9906.0000 1.0000
48.3200 10050.0000 1.0000
48.3800 10124.0000 1.0000
48.4400 10077.0000 1.0000
48.5000 10059.0000 1.0000
48.5600 10017.0000 1.0000
48.6200 10017.0000 1.0000
48.6800 10001.0000 1.0000
48.7400 10155.0000 1.0000
48.8000 10001.0000 1.0000
48.8600 10064.0000 1.0000
48.9200 10046.0000 1.0000
48.9800 10034.0000 1.0000
49.0400 10073.0000 1.0000
49.1000 10021.0000 1.0000
49.1600 10178.0000 1.0000
49.2200 10369.0000 1.0000
49.2800 10412.0000 1.0000
49.3400 10917.0000 1.0000
49.4000 11517.0000 1.0000
49.4600 13804.0000 1.0000
49.5200 14181.0000 1.0000
49.5800 12657.0000 1.0000
49.6400 12578.0000 1.0000
49.7000 10921.0000 1.0000
49.7600 10597.0000 1.0000
49.8200 10396.0000 1.0000
49.8800 10278.0000 1.0000
49.9400 10338.0000 1.0000
50.0000 10314.0000 1.0000
50.0600 10664.0000 1.0000
50.1200 13110.0000 1.0000
50.1800 14144.0000 1.0000
50.2400 11450.0000 1.0000
50.3000 12936.0000 1.0000
50.3600 10554.0000 1.0000
50.4200 10098.0000 1.0000
50.4800 9900.0000 1.0000
50.5400 9827.0000 1.0000
50.6000 10123.0000 1.0000
50.6600 9942.0000 1.0000
50.7200 10072.0000 1.0000
50.7800 10148.0000 1.0000
50.8400 10089.0000 1.0000
50.9000 10014.0000 1.0000
50.9600 10124.0000 1.0000
51.0200 9952.0000 1.0000
51.0800 9873.0000 1.0000
51.1400 10186.0000 1.0000
51.2000 10011.0000 1.0000
51.2600 10042.0000 1.0000
51.3200 9971.0000 1.0000
51.3800 9955.0000 1.0000
51.4400 10003.0000 1.0000
51.5000 10045.0000 1.0000
51.5600 9934.0000 1.0000
51.6200 10078.0000 1.0000
51.6800 10064.0000 1.0000
51.7400 10159.0000 1.0000
51.8000 10178.0000 1.0000
51.8600 9988.0000 1.0000
51.9200 9945.0000 1.0000
51.9800 10076.0000 1.0000
52.0400 10088.0000 1.0000
52.1000 10125.0000 1.0000
52.1600 10265.0000 1.0000
52.2200 10064.0000 1.0000
52.2800 10010.0000 1.0000
52.3400 10013.0000 1.0000
52.4000 10142.0000 1.0000
52.4600 10392.0000 1.0000
52.5200 10848.0000 1.0000
52.5800 10840.0000 1.0000
52.6400 10537.0000 1.0000
52.7000 10573.0000 1.0000
52.7600 10274.0000 1.0000
52.8200 10293.0000 1.0000
52.8800 10097.0000 1.0000
52.9400 10099.0000 1.0000
53.0000 9961.0000 1.0000
53.0600 10037.0000 1.0000
53.1200 9948.0000 1.0000
53.1800 10004.0000 1.0000
53.2400 10088.0000 1.0000
53.3000 9933.0000 1.0000
53.3600 10208.0000 1.0000
53.4200 10245.0000 1.0000
53.4800 10582.0000 1.0000
53.5400 10721.0000 1.0000
53.6000 10696.0000 1.0000
53.6600 10664.0000 1.0000
53.7200 10543.0000 1.0000
53.7800 10503.0000 1.0000
53.8400 10696.0000 1.0000
53.9000 10665.0000 1.0000
53.9600 11201.0000 1.0000
54.0200 12310.0000 1.0000
54.0800 15123.0000 1.0000
54.1400 14338.0000 1.0000
54.2000 13084.0000 1.0000
54.2600 12797.0000 1.0000
54.3200 11141.0000 1.0000
54.3800 10794.0000 1.0000
54.4400 10285.0000 1.0000
54.5000 10126.0000 1.0000
54.5600 10111.0000 1.0000
54.6200 10124.0000 1.0000
54.6800 10172.0000 1.0000
54.7400 10349.0000 1.0000
54.8000 10370.0000 1.0000
54.8600 10926.0000 1.0000
54.9200 11076.0000 1.0000
54.9800 10362.0000 1.0000
55.0400 10951.0000 1.0000
55.1000 10403.0000 1.0000
55.1600 10128.0000 1.0000
55.2200 10223.0000 1.0000
55.2800 10125.0000 1.0000
55.3400 10433.0000 1.0000
55.4000 10074.0000 1.0000
55.4600 10248.0000 1.0000
55.5200 10129.0000 1.0000
55.5800 10031.0000 1.0000
55.6400 10008.0000 1.0000
55.7000 9844.0000 1.0000
55.7600 10003.0000 1.0000
55.8200 9999.0000 1.0000
55.8800 10107.0000 1.0000
55.9400 10199.0000 1.0000
56.0000 10028.0000 1.0000
56.0600 9985.0000 1.0000
56.1200 10039.0000 1.0000
56.1800 10173.0000 1.0000
56.2400 9877.0000 1.0000
56.3000 10089.0000 1.0000
56.3600 10191.0000 1.0000
56.4200 10175.0000 1.0000
56.4800 10006.0000 1.0000
56.5400 10204.0000 1.0000
56.6000 10128.0000 1.0000
56.6600 9967.0000 1.0000
56.7200 10295.0000 1.0000
56.7800 10111.0000 1.0000
56.8400 10341.0000 1.0000
56.9000 10537.0000 1.0000
56.9600 10769.0000 1.0000
57.0200 11727.0000 1.0000
57.0800 11995.0000 1.0000
57.1400 11496.0000 1.0000
57.2000 11843.0000 1.0000
57.2600 11522.0000 1.0000
57.3200 11063.0000 1.0000
57.3800 10961.0000 1.0000
57.4400 11532.0000 1.0000
57.5000 12698.0000 1.0000
57.5600 12313.0000 1.0000
57.6200 12346.0000 1.0000
57.6800 12048.0000 1.0000
57.7400 11320.0000 1.0000
57.8000 10921.0000 1.0000
57.8600 10502.0000 1.0000
57.9200 10231.0000 1.0000
57.9800 10414.0000 1.0000
58.0400 10042.0000 1.0000
58.1000 9975.0000 1.0000
58.1600 10135.0000 1.0000
58.2200 10079.0000 1.0000
58.2800 9984.0000 1.0000
58.3400 10080.0000 1.0000
58.4000 10036.0000 1.0000
58.4600 9978.0000 1.0000
58.5200 10042.0000 1.0000
58.5800 10157.0000 1.0000
58.6400 10064.0000 1.0000
58.7000 10057.0000 1.0000
58.7600 10087.0000 1.0000
58.8200 10092.0000 1.0000
58.8800 9910.0000 1.0000
58.9400 10238.0000 1.0000
59.0000 10164.0000 1.0000
59.0600 9928.0000 1.0000
59.1200 10244.0000 1.0000
59.1800 10063.0000 1.0000
59.2400 10137.0000 1.0000
59.3000 9977.0000 1.0000
59.3600 10104.0000 1.0000
59.4200 10025.0000 1.0000
59.4800 10185.0000 1.0000
59.5400 9902.0000 1.0000
59.6000 10086.0000 1.0000
59.6600 10063.0000 1.0000
59.7200 10107.0000 1.0000
59.7800 10196.0000 1.0000
59.8400 10173.0000 1.0000
59.9000 10698.0000 1.0000
59.9600 12807.0000 1.0000
60.0200 11862.0000 1.0000
60.0800 10724.0000 1.0000
60.1400 11945.0000 1.0000
60.2000 10515.0000 1.0000
60.2600 10431.0000 1.0000
60.3200 10162.0000 1.0000
60.3800 10009.0000 1.0000
60.4400 10117.0000 1.0000
60.5000 10178.0000 1.0000
60.5600 10302.0000 1.0000
60.6200 9975.0000 1.0000
60.6800 10223.0000 1.0000
60.7400 10105.0000 1.0000
60.8000 9899.0000 1.0000
60.8600 10153.0000 1.0000
60.9200 10087.0000 1.0000
60.9800 10047.0000 1.0000
61.0400 10231.0000 1.0000
61.1000 10135.0000 1.0000
61.1600 10253.0000 1.0000
61.2200 10219.0000 1.0000
61.2800 10191.0000 1.0000
61.3400 10281.0000 1.0000
61.4000 10187.0000 1.0000
61.4600 10151.0000 1.0000
61.5200 10162.0000 1.0000
61.5800 10068.0000 1.0000
61.6400 10102.0000 1.0000
61.7000 9928.0000 1.0000
61.7600 10056.0000 1.0000
61.8200 10164.0000 1.0000
61.8800 10079.0000 1.0000
61.9400 10137.0000 1.0000
62.0000 10168.0000 1.0000
62.0600 10236.0000 1.0000
62.1200 10165.0000 1.0000
62.1800 10467.0000 1.0000
62.2400 10314.0000 1.0000
62.3000 10801.0000 1.0000
62.3600 11445.0000 1.0000
62.4200 12988.0000 1.0000
62.4800 13756.0000 1.0000
62.5400 12848.0000 1.0000
62.6000 13806.0000 1.0000
62.6600 14472.0000 1.0000
62.7200 12991.0000 1.0000
62.7800 12407.0000 1.0000
62.8400 12128.0000 1.0000
62.9000 11341.0000 1.0000
62.9600 10812.0000 1.0000
63.0200 10495.0000 1.0000
63.0800 10342.0000 1.0000
63.1400 10356.0000 1.0000
63.2000 10375.0000 1.0000
63.2600 10392.0000 1.0000
63.3200 10230.0000 1.0000
63.3800 10121.0000 1.0000
63.4400 10058.0000 1.0000
63.5000 10065.0000 1.0000
63.5600 10056.0000 1.0000
63.6200 10383.0000 1.0000
63.6800 10312.0000 1.0000
63.7400 10234.0000 1.0000
63.8000 10475.0000 1.0000
63.8600 10761.0000 1.0000
63.9200 11091.0000 1.0000
63.9800 12494.0000 1.0000
64.0400 13803.0000 1.0000
64.1000 12284.0000 1.0000
64.1600 11944.0000 1.0000
64.2200 12380.0000 1.0000
64.2800 11000.0000 1.0000
64.3400 10528.0000 1.0000
64.4000 10313.0000 1.0000
64.4600 10266.0000 1.0000
64.5200 10136.0000 1.0000
64.5800 10102.0000 1.0000
64.6400 10111.0000 1.0000
64.7000 9955.0000 1.0000
64.7600 9903.0000 1.0000
64.8200 9914.0000 1.0000
64.8800 10029.0000 1.0000
64.9400 10066.0000 1.0000
65.0000 10074.0000 1.0000
65.0600 10016.0000 1.0000
65.1200 10110.0000 1.0000
65.1800 10065.0000 1.0000
65.2400 10035.0000 1.0000
65.3000 9960.0000 1.0000
65.3600 10208.0000 1.0000
65.4200 10094.0000 1.0000
65.4800 10086.0000 1.0000
65.5400 10122.0000 1.0000
65.6000 10269.0000 1.0000
65.6600 10199.0000 1.0000
65.7200 10265.0000 1.0000
65.7800 10429.0000 1.0000
65.8400 10356.0000 1.0000
65.9000 10305.0000 1.0000
65.9600 10217.0000 1.0000
66.0200 10513.0000 1.0000
66.0800 10389.0000 1.0000
66.1400 10365.0000 1.0000
66.2000 10234.0000 1.0000
66.2600 10173.0000 1.0000
66.3200 10367.0000 1.0000
66.3800 10204.0000 1.0000
66.4400 10660.0000 1.0000
66.5000 10780.0000 1.0000
66.5600 10783.0000 1.0000
66.6200 10453.0000 1.0000
66.6800 10389.0000 1.0000
66.7400 10656.0000 1.0000
66.8000 10284.0000 1.0000
66.8600 10170.0000 1.0000
66.9200 10138.0000 1.0000
66.9800 10130.0000 1.0000
67.0400 10079.0000 1.0000
67.1000 10282.0000 1.0000
67.1600 10300.0000 1.0000
67.2200 10294.0000 1.0000
67.2800 10313.0000 1.0000
67.3400 10163.0000 1.0000
67.4000 10185.0000 1.0000
67.4600 10202.0000 1.0000
67.5200 10200.0000 1.0000
67.5800 10306.0000 1.0000
67.6400 10287.0000 1.0000
67.7000 10968.0000 1.0000
67.7600 12754.0000 1.0000
67.8200 11098.0000 1.0000
67.8800 10723.0000 1.0000
67.9400 11569.0000 1.0000
68.0000 11050.0000 1.0000
68.0600 10791.0000 1.0000
68.1200 11781.0000 1.0000
68.1800 14221.0000 1.0000
68.2400 12135.0000 1.0000
68.3000 12257.0000 1.0000
68.3600 12944.0000 1.0000
68.4200 11594.0000 1.0000
68.4800 10791.0000 1.0000
68.5400 10965.0000 1.0000
68.6000 10557.0000 1.0000
68.6600 10154.0000 1.0000
68.7200 10303.0000 1.0000
68.7800 10253.0000 1.0000
68.8400 10279.0000 1.0000
68.9000 10271.0000 1.0000
68.9600 10268.0000 1.0000
69.0200 10329.0000 1.0000
69.0800 10126.0000 1.0000
69.1400 10158.0000 1.0000
69.2000 10117.0000 1.0000
69.2600 10176.0000 1.0000
69.3200 10160.0000 1.0000
69.3800 10196.0000 1.0000
69.4400 10296.0000 1.0000
69.5000 10210.0000 1.0000
69.5600 10225.0000 1.0000
69.6200 10336.0000 1.0000
69.6800 10418.0000 1.0000
69.7400 10283.0000 1.0000
69.8000 10362.0000 1.0000
69.8600 10147.0000 1.0000
69.9200 10098.0000 1.0000
69.9800 10221.0000 1.0000
70.0400 10136.0000 1.0000
70.1000 10291.0000 1.0000
70.1600 10164.0000 1.0000
70.2200 10168.0000 1.0000
70.2800 10303.0000 1.0000
70.3400 10191.0000 1.0000
70.4000 10136.0000 1.0000
70.4600 10231.0000 1.0000
70.5200 10046.0000 1.0000
70.5800 10163.0000 1.0000
70.6400 10030.0000 1.0000
70.7000 10274.0000 1.0000
70.7600 10130.0000 1.0000
70.8200 10157.0000 1.0000
70.8800 10025.0000 1.0000
70.9400 10305.0000 1.0000
71.0000 10355.0000 1.0000
71.0600 10331.0000 1.0000
71.1200 10397.0000 1.0000
71.1800 10345.0000 1.0000
71.2400 10260.0000 1.0000
71.3000 10205.0000 1.0000
71.3600 10294.0000 1.0000
71.4200 10218.0000 1.0000
71.4800 10277.0000 1.0000
71.5400 10345.0000 1.0000
71.6000 10247.0000 1.0000
71.6600 10112.0000 1.0000
71.7200 10308.0000 1.0000
71.7800 10435.0000 1.0000
71.8400 10472.0000 1.0000
71.9000 10713.0000 1.0000
71.9600 11031.0000 1.0000
72.0200 10943.0000 1.0000
72.0800 10791.0000 1.0000
72.1400 10744.0000 1.0000
72.2000 10834.0000 1.0000
72.2600 10614.0000 1.0000
72.3200 10380.0000 1.0000
72.3800 10452.0000 1.0000
72.4400 10483.0000 1.0000
72.5000 10274.0000 1.0000
72.5600 10338.0000 1.0000
72.6200 10262.0000 1.0000
72.6800 10278.0000 1.0000
72.7400 10227.0000 1.0000
72.8000 10281.0000 1.0000
72.8600 10254.0000 1.0000
72.9200 10170.0000 1.0000
72.9800 10314.0000 1.0000
73.0400 10136.0000 1.0000
73.1000 10398.0000 1.0000
73.1600 10150.0000 1.0000
73.2200 9971.0000 1.0000
73.2800 10178.0000 1.0000
73.3400 10296.0000 1.0000
73.4000 10333.0000 1.0000
73.4600 10568.0000 1.0000
73.5200 10448.0000 1.0000
73.5800 10429.0000 1.0000
73.6400 10342.0000 1.0000
73.7000 10506.0000 1.0000
73.7600 10129.0000 1.0000
73.8200 10313.0000 1.0000
73.8800 10182.0000 1.0000
73.9400 10316.0000 1.0000
74.0000 10428.0000 1.0000
74.0600 10593.0000 1.0000
74.1200 10621.0000 1.0000
74.1800 10508.0000 1.0000
74.2400 10505.0000 1.0000
74.3000 10387.0000 1.0000
74.3600 10527.0000 1.0000
74.4200 10218.0000 1.0000
74.4800 10379.0000 1.0000
74.5400 10317.0000 1.0000
74.6000 10228.0000 1.0000
74.6600 10043.0000 1.0000
74.7200 10223.0000 1.0000
74.7800 10189.0000 1.0000
74.8400 10207.0000 1.0000
74.9000 10314.0000 1.0000
74.9600 10195.0000 1.0000
75.0200 10110.0000 1.0000
75.0800 10342.0000 1.0000
75.1400 10286.0000 1.0000
75.2000 10339.0000 1.0000
75.2600 10419.0000 1.0000
75.3200 10527.0000 1.0000
75.3800 10452.0000 1.0000
75.4400 10870.0000 1.0000
75.5000 10795.0000 1.0000
75.5600 10591.0000 1.0000
75.6200 10737.0000 1.0000
75.6800 11278.0000 1.0000
75.7400 10670.0000 1.0000
75.8000 10339.0000 1.0000
75.8600 10659.0000 1.0000
75.9200 10547.0000 1.0000
75.9800 10259.0000 1.0000
76.0400 10237.0000 1.0000
76.1000 10409.0000 1.0000
76.1600 10313.0000 1.0000
76.2200 10206.0000 1.0000
76.2800 10269.0000 1.0000
76.3400 10013.0000 1.0000
76.4000 10475.0000 1.0000
76.4600 10241.0000 1.0000
76.5200 10254.0000 1.0000
76.5800 10187.0000 1.0000
76.6400 10138.0000 1.0000
76.7000 10182.0000 1.0000
76.7600 10317.0000 1.0000
76.8200 10544.0000 1.0000
76.8800 10646.0000 1.0000
76.9400 10510.0000 1.0000
77.0000 10414.0000 1.0000
77.0600 10361.0000 1.0000
77.1200 10605.0000 1.0000
77.1800 10409.0000 1.0000
77.2400 10560.0000 1.0000
77.3000 10329.0000 1.0000
77.3600 10315.0000 1.0000
77.4200 10326.0000 1.0000
77.4800 10487.0000 1.0000
77.5400 10364.0000 1.0000
77.6000 10293.0000 1.0000
77.6600 10760.0000 1.0000
77.7200 10568.0000 1.0000
77.7800 10417.0000 1.0000
77.8400 10449.0000 1.0000
77.9000 10595.0000 1.0000
77.9600 10547.0000 1.0000
78.0200 10183.0000 1.0000
78.0800 10422.0000 1.0000
78.1400 10264.0000 1.0000
78.2000 10168.0000 1.0000
78.2600 10353.0000 1.0000
78.3200 10160.0000 1.0000
78.3800 10331.0000 1.0000
78.4400 10161.0000 1.0000
78.5000 10249.0000 1.0000
78.5600 10087.0000 1.0000
78.6200 10013.0000 1.0000
78.6800 10222.0000 1.0000
78.7400 10370.0000 1.0000
78.8000 10357.0000 1.0000
78.8600 10139.0000 1.0000
78.9200 10329.0000 1.0000
78.9800 10442.0000 1.0000
79.0400 10351.0000 1.0000
79.1000 10387.0000 1.0000
79.1600 10111.0000 1.0000
79.2200 10395.0000 1.0000
79.2800 10343.0000 1.0000
79.3400 10396.0000 1.0000
79.4000 10290.0000 1.0000
79.4600 10260.0000 1.0000
79.5200 10254.0000 1.0000
79.5800 10263.0000 1.0000
79.6400 10229.0000 1.0000
79.7000 10397.0000 1.0000
79.7600 10296.0000 1.0000
79.8200 10520.0000 1.0000
79.8800 11480.0000 1.0000
79.9400 10921.0000 1.0000
80.0000 10572.0000 1.0000
80.0600 10865.0000 1.0000
80.1200 10982.0000 1.0000
80.1800 10458.0000 1.0000
80.2400 10287.0000 1.0000
80.3000 10420.0000 1.0000
80.3600 10256.0000 1.0000
80.4200 10340.0000 1.0000
80.4800 10393.0000 1.0000
80.5400 10515.0000 1.0000
80.6000 10584.0000 1.0000
80.6600 10635.0000 1.0000
80.7200 10827.0000 1.0000
80.7800 10906.0000 1.0000
80.8400 10518.0000 1.0000
80.9000 10638.0000 1.0000
80.9600 10618.0000 1.0000
81.0200 10527.0000 1.0000
81.0800 10418.0000 1.0000
81.1400 10471.0000 1.0000
81.2000 10883.0000 1.0000
81.2600 10647.0000 1.0000
81.3200 10720.0000 1.0000
81.3800 10387.0000 1.0000
81.4400 10832.0000 1.0000
81.5000 11306.0000 1.0000
81.5600 10620.0000 1.0000
81.6200 10436.0000 1.0000
81.6800 10267.0000 1.0000
81.7400 10817.0000 1.0000
81.8000 10669.0000 1.0000
81.8600 10405.0000 1.0000
81.9200 10233.0000 1.0000
81.9800 10298.0000 1.0000
82.0400 10382.0000 1.0000
82.1000 10148.0000 1.0000
82.1600 10049.0000 1.0000
82.2200 10194.0000 1.0000
82.2800 10228.0000 1.0000
82.3400 10324.0000 1.0000
82.4000 10286.0000 1.0000
82.4600 10352.0000 1.0000
82.5200 10180.0000 1.0000
82.5800 10157.0000 1.0000
82.6400 10201.0000 1.0000
82.7000 10351.0000 1.0000
82.7600 10380.0000 1.0000
82.8200 10528.0000 1.0000
82.8800 10478.0000 1.0000
82.9400 10650.0000 1.0000
83.0000 10694.0000 1.0000
83.0600 10584.0000 1.0000
83.1200 10465.0000 1.0000
83.1800 10499.0000 1.0000
83.2400 10537.0000 1.0000
83.3000 10536.0000 1.0000
83.3600 10299.0000 1.0000
83.4200 10485.0000 1.0000
83.4800 10497.0000 1.0000
83.5400 10226.0000 1.0000
83.6000 10384.0000 1.0000
83.6600 10400.0000 1.0000
83.7200 10466.0000 1.0000
83.7800 10421.0000 1.0000
83.8400 10865.0000 1.0000
83.9000 10540.0000 1.0000
83.9600 10543.0000 1.0000
84.0200 10559.0000 1.0000
84.0800 10416.0000 1.0000
84.1400 10474.0000 1.0000
84.2000 10451.0000 1.0000
84.2600 10327.0000 1.0000
84.3200 10428.0000 1.0000
84.3800 10531.0000 1.0000
84.4400 10314.0000 1.0000
84.5000 10313.0000 1.0000
84.5600 10356.0000 1.0000
84.6200 10472.0000 1.0000
84.6800 10427.0000 1.0000
84.7400 10367.0000 1.0000
84.8000 10617.0000 1.0000
84.8600 10370.0000 1.0000
84.9200 11050.0000 1.0000
84.9800 11048.0000 1.0000
85.0400 10759.0000 1.0000
85.1000 10755.0000 1.0000
85.1600 10458.0000 1.0000
85.2200 10551.0000 1.0000
85.2800 10515.0000 1.0000
85.3400 10360.0000 1.0000
85.4000 10512.0000 1.0000
85.4600 10309.0000 1.0000
85.5200 10283.0000 1.0000
85.5800 10362.0000 1.0000
85.6400 10089.0000 1.0000
85.7000 10287.0000 1.0000
85.7600 10331.0000 1.0000
85.8200 10278.0000 1.0000
85.8800 10201.0000 1.0000
85.9400 10387.0000 1.0000
86.0000 10407.0000 1.0000
86.0600 10417.0000 1.0000
86.1200 10287.0000 1.0000
86.1800 10377.0000 1.0000
86.2400 10283.0000 1.0000
86.3000 10363.0000 1.0000
86.3600 10414.0000 1.0000
86.4200 10281.0000 1.0000
86.4800 10188.0000 1.0000
86.5400 10416.0000 1.0000
86.6000 10289.0000 1.0000
86.6600 10405.0000 1.0000
86.7200 10515.0000 1.0000
86.7800 10530.0000 1.0000
86.8400 10431.0000 1.0000
86.9000 10458.0000 1.0000
86.9600 10310.0000 1.0000
87.0200 10630.0000 1.0000
87.0800 10347.0000 1.0000
87.1400 10601.0000 1.0000
87.2000 10433.0000 1.0000
87.2600 10541.0000 1.0000
87.3200 10538.0000 1.0000
87.3800 10246.0000 1.0000
87.4400 10367.0000 1.0000
87.5000 10266.0000 1.0000
87.5600 10435.0000 1.0000
87.6200 10346.0000 1.0000
87.6800 10281.0000 1.0000
87.7400 10337.0000 1.0000
87.8000 10340.0000 1.0000
87.8600 10432.0000 1.0000
87.9200 10274.0000 1.0000
87.9800 10395.0000 1.0000
88.0400 10407.0000 1.0000
88.1000 10521.0000 1.0000
88.1600 10405.0000 1.0000
88.2200 10477.0000 1.0000
88.2800 10321.0000 1.0000
88.3400 10433.0000 1.0000
88.4000 10505.0000 1.0000
88.4600 10479.0000 1.0000
88.5200 10985.0000 1.0000
88.5800 11019.0000 1.0000
88.6400 10699.0000 1.0000
88.7000 10716.0000 1.0000
88.7600 10644.0000 1.0000
88.8200 10797.0000 1.0000
88.8800 10803.0000 1.0000
88.9400 10735.0000 1.0000
89.0000 10586.0000 1.0000
89.0600 10471.0000 1.0000
89.1200 10545.0000 1.0000
89.1800 10352.0000 1.0000
89.2400 10316.0000 1.0000
89.3000 10426.0000 1.0000
89.3600 10496.0000 1.0000
89.4200 10327.0000 1.0000
89.4800 10372.0000 1.0000
89.5400 10469.0000 1.0000
89.6000 10608.0000 1.0000
89.6600 10650.0000 1.0000
89.7200 10820.0000 1.0000
89.7800 10900.0000 1.0000
89.8400 11032.0000 1.0000
89.9000 10749.0000 1.0000
89.9600 10730.0000 1.0000
90.0000 10770.0000 1.0000
*RAS_INT_END
*RAS_TEMPERATURE_START
*RAS_TEMPERATURE_END
*RAS_DATA_END