File: XRD/Data/20200910_mix_09.ras
*RAS_DATA_START
*RAS_HEADER_START
*DISP_FMT_X "%.2f"
*DISP_FMT_Y "%.0f"
*DISP_FULLSCALE "42549.0000000000"
*DISP_LINE_COLOR "255.0000000000"
*DISP_LINE_STYLE "0.0000000000"
*DISP_LINE_WIDTH "0.2500000000"
*DISP_NOTE "測定データ-3"
*DISP_OFFSET_Y "0.0000000000"
*DISP_PEAKSEARCH_UNIT_Y "cps"
*DISP_RANGE_BOTTOM "0.0000000000"
*DISP_RANGE_LEFT "20.0000000000"
*DISP_RANGE_LOGCUTOFF "0.0100000000"
*DISP_RANGE_RIGHT "90.0000000000"
*DISP_RANGE_TOP "42549.0000000000"
*DISP_SCALE_MODE_Y "0.0000000000"
*DISP_TAB_NAME "2θ/θ"
*DISP_TITLE_Y "強度"
*DISP_UNIT_Y "cps"
*DISP_WINDOW_NAME "MSG_MACROENGINE"
*FILE_COMMENT " "
*FILE_MD5 ""
*FILE_MEMO " "
*FILE_OPERATOR "Administrator"
*FILE_SAMPLE " "
*FILE_TYPE "RAS_RAW"
*FILE_USERGROUP "システムマネージャ"
*FILE_VERSION "1.0000000000"
*HW_ATTACHMENT_ID "ATT0025"
*HW_ATTACHMENT_NAME "標準|Standard"
*HW_COUNTER_ID-0 "CUT0025"
*HW_COUNTER_ID-1 "CUT0020"
*HW_COUNTER_ID-2 "CUT0020"
*HW_COUNTER_ID-3 "CSL0021"
*HW_COUNTER_ID-4 "CMC0021"
*HW_COUNTER_NAME-0 "D/teX Ultra|D/teX Ultra"
*HW_COUNTER_NAME-1 "None|None"
*HW_COUNTER_NAME-2 "None|None"
*HW_COUNTER_NAME-3 "BBM|BBM"
*HW_COUNTER_NAME-4 "検出器モノクロメータ|Detector monochromator"
*HW_COUNTER_SELECT_NAME "D/teX Ultra|D/teX Ultra"
*HW_GONIOMETER_ID "GON0023"
*HW_GONIOMETER_NAME "SmartLab|SmartLab"
*HW_GONIOMETER_RADIUS-0 "90.0"
*HW_GONIOMETER_RADIUS-1 "114.0"
*HW_GONIOMETER_RADIUS-2 "190.0"
*HW_GONIOMETER_RADIUS-3 "300.0"
*HW_GONIOMETER_RADIUS-4 "187.0"
*HW_GONIOMETER_RADIUS-5 "300.0"
*HW_GONIOMETER_RADIUS-6 "113.0"
*HW_GONIOMETER_RADIUS-7 "331.0"
*HW_I_OPT_ID-0 "CBO0021"
*HW_I_OPT_ID-1 "ICR0023"
*HW_I_OPT_ID-2 "ISL0021"
*HW_I_OPT_ID-3 "ISO0021"
*HW_I_OPT_ID-4 "IAD0021"
*HW_I_OPT_ID-5 "IPR0001"
*HW_I_OPT_NAME-0 "CBOユニット|CBO unit"
*HW_I_OPT_NAME-1 "標準入射光学ユニット|Standard incident optical unit"
*HW_I_OPT_NAME-2 "標準入射スリットボックス|Standard incident slit box"
*HW_I_OPT_NAME-3 "入射平行スリット|Incident parallel slit"
*HW_I_OPT_NAME-4 "長手制限スリット|Length limiting slit"
*HW_I_OPT_NAME-5 "None|None"
*HW_R_ATTENUATER_AUTOMODE "0"
*HW_R_OPT_ID-0 "RSS0021"
*HW_R_OPT_ID-1 "RCR0023"
*HW_R_OPT_ID-2 "RSO0021"
*HW_R_OPT_ID-3 "RRS0021"
*HW_R_OPT_ID-4 "ATN0021"
*HW_R_OPT_ID-5 "RFL0021"
*HW_R_OPT_ID-6 "RAD0021"
*HW_R_OPT_NAME-0 "標準受光スリットボックス1|Standard receiving slit box # 1"
*HW_R_OPT_NAME-1 "標準受光光学ユニット1|Standard receiving unit # 1"
*HW_R_OPT_NAME-2 "標準受光光学ユニット2|Standard receiving optical unit # 2"
*HW_R_OPT_NAME-3 "標準受光スリットボックス2|Standard receiving slit box # 2"
*HW_R_OPT_NAME-4 "標準アッテネータ|Standard Attenuator"
*HW_R_OPT_NAME-5 "Cu Kβ|Cu K-beta"
*HW_R_OPT_NAME-6 "調整用受光スリット|Alignment receiving slit"
*HW_SAMPLE_HOLDER_ID "SMP0023"
*HW_SAMPLE_HOLDER_NAME "標準Zステージ|Standard Z stage"
*HW_XG_CURRENT_MAX "50"
*HW_XG_CURRENT_MIN "2"
*HW_XG_CURRENT_RESOLUTION "2"
*HW_XG_CURRENT_UNIT "mA"
*HW_XG_FOCUS "1mm x 10mm"
*HW_XG_FOCUS_TYPE "Normal"
*HW_XG_ID ""
*HW_XG_NAME "3kW 封入管(ID:1200)|3kW Sealed tube(ID:1200)"
*HW_XG_TARGET_ATOMIC_NUMBER "29.0000000000"
*HW_XG_TARGET_NAME "Cu"
*HW_XG_TYPE "Hermetic"
*HW_XG_VOLTAGE_MAX "60"
*HW_XG_VOLTAGE_MIN "20"
*HW_XG_VOLTAGE_RESOLUTION "2"
*HW_XG_VOLTAGE_UNIT "kV"
*HW_XG_WATT_MAX "2"
*HW_XG_WATT_UNIT "kW"
*HW_XG_WAVE_LENGTH_ALPHA1 "1.540593"
*HW_XG_WAVE_LENGTH_ALPHA2 "1.544414"
*HW_XG_WAVE_LENGTH_BETA "1.392250"
*MEAS_COND_AXIS_NAME-0 "2θ/θ"
*MEAS_COND_AXIS_NAME-1 "2θ"
*MEAS_COND_AXIS_NAME-2 "ω"
*MEAS_COND_AXIS_NAME-3 "Z"
*MEAS_COND_AXIS_NAME-4 "2θ/ω"
*MEAS_COND_AXIS_NAME-5 "θs"
*MEAS_COND_AXIS_NAME-6 "θd"
*MEAS_COND_AXIS_NAME-7 "Ts"
*MEAS_COND_AXIS_NAME-8 "CBO選択スリット"
*MEAS_COND_AXIS_NAME-9 "M"
*MEAS_COND_AXIS_NAME-10 "入射平行スリット"
*MEAS_COND_AXIS_NAME-11 "入射スリット"
*MEAS_COND_AXIS_NAME-12 ""
*MEAS_COND_AXIS_NAME-13 "Zs"
*MEAS_COND_AXIS_NAME-14 "入射光学素子"
*MEAS_COND_AXIS_NAME-15 "長手制限スリット"
*MEAS_COND_AXIS_NAME-16 "センタースリット"
*MEAS_COND_AXIS_NAME-17 "フィルター"
*MEAS_COND_AXIS_NAME-18 "受光スリット1"
*MEAS_COND_AXIS_NAME-19 "受光スリット2"
*MEAS_COND_AXIS_NAME-20 "受光光学素子"
*MEAS_COND_AXIS_NAME-21 "受光平行スリット"
*MEAS_COND_AXIS_NAME-22 "調整用受光スリット"
*MEAS_COND_AXIS_NAME-23 ""
*MEAS_COND_AXIS_NAME-24 ""
*MEAS_COND_AXIS_NAME-25 "Zd"
*MEAS_COND_AXIS_NAME-26 "アッテネータ"
*MEAS_COND_AXIS_NAME-27 "検出器モノクロメータ"
*MEAS_COND_AXIS_NAME-28 "モノクロメータスリット"
*MEAS_COND_AXIS_NAME-29 "プライマリビーム"
*MEAS_COND_AXIS_NAME-30 "PHA"
*MEAS_COND_AXIS_NAME_INTERNAL-0 "TwoThetaTheta"
*MEAS_COND_AXIS_NAME_INTERNAL-1 "TwoTheta"
*MEAS_COND_AXIS_NAME_INTERNAL-2 "Omega"
*MEAS_COND_AXIS_NAME_INTERNAL-3 "Z"
*MEAS_COND_AXIS_NAME_INTERNAL-4 "TwoThetaOmega"
*MEAS_COND_AXIS_NAME_INTERNAL-5 "ThetaS"
*MEAS_COND_AXIS_NAME_INTERNAL-6 "ThetaD"
*MEAS_COND_AXIS_NAME_INTERNAL-7 "Ts"
*MEAS_COND_AXIS_NAME_INTERNAL-8 "CBO"
*MEAS_COND_AXIS_NAME_INTERNAL-9 "CBO-M"
*MEAS_COND_AXIS_NAME_INTERNAL-10 "IncidentSollerSlit"
*MEAS_COND_AXIS_NAME_INTERNAL-11 "IncidentSlitBox"
*MEAS_COND_AXIS_NAME_INTERNAL-12 "IncidentSlitBox-_Axis"
*MEAS_COND_AXIS_NAME_INTERNAL-13 "Zs"
*MEAS_COND_AXIS_NAME_INTERNAL-14 "IncidentMonochromator"
*MEAS_COND_AXIS_NAME_INTERNAL-15 "IncidentAxdSlit"
*MEAS_COND_AXIS_NAME_INTERNAL-16 "CenterSlit"
*MEAS_COND_AXIS_NAME_INTERNAL-17 "Filter"
*MEAS_COND_AXIS_NAME_INTERNAL-18 "ReceivingSlitBox1"
*MEAS_COND_AXIS_NAME_INTERNAL-19 "ReceivingSlitBox2"
*MEAS_COND_AXIS_NAME_INTERNAL-20 "ReceivingOptics"
*MEAS_COND_AXIS_NAME_INTERNAL-21 "ReceivingSollerSlit"
*MEAS_COND_AXIS_NAME_INTERNAL-22 "ReceivingAxdSlit"
*MEAS_COND_AXIS_NAME_INTERNAL-23 "ReceivingSlitBox1-_Axis"
*MEAS_COND_AXIS_NAME_INTERNAL-24 "ReceivingSlitBox2-_Axis"
*MEAS_COND_AXIS_NAME_INTERNAL-25 "ReceivingSlitBox2-Zd"
*MEAS_COND_AXIS_NAME_INTERNAL-26 "Attenuator"
*MEAS_COND_AXIS_NAME_INTERNAL-27 "CounterMonochromator"
*MEAS_COND_AXIS_NAME_INTERNAL-28 "CounterSlit"
*MEAS_COND_AXIS_NAME_INTERNAL-29 "IncidentPrimary"
*MEAS_COND_AXIS_NAME_INTERNAL-30 "PHA"
*MEAS_COND_AXIS_NAME_MAGICNO-0 "83951616.0000000000"
*MEAS_COND_AXIS_NAME_MAGICNO-1 "268632064.0000000000"
*MEAS_COND_AXIS_NAME_MAGICNO-2 "268500992.0000000000"
*MEAS_COND_AXIS_NAME_MAGICNO-3 "285278208.0000000000"
*MEAS_COND_AXIS_NAME_MAGICNO-4 "83951616.0000000000"
*MEAS_COND_AXIS_NAME_MAGICNO-5 "131072.0000000000"
*MEAS_COND_AXIS_NAME_MAGICNO-6 "131072.0000000000"
*MEAS_COND_AXIS_NAME_MAGICNO-7 "318898176.0000000000"
*MEAS_COND_AXIS_NAME_MAGICNO-8 "20971521.0000000000"
*MEAS_COND_AXIS_NAME_MAGICNO-9 "285343744.0000000000"
*MEAS_COND_AXIS_NAME_MAGICNO-10 "20971521.0000000000"
*MEAS_COND_AXIS_NAME_MAGICNO-11 "22020097.0000000000"
*MEAS_COND_AXIS_NAME_MAGICNO-12 "25165824.0000000000"
*MEAS_COND_AXIS_NAME_MAGICNO-13 "318898176.0000000000"
*MEAS_COND_AXIS_NAME_MAGICNO-14 "1.0000000000"
*MEAS_COND_AXIS_NAME_MAGICNO-15 "20971521.0000000000"
*MEAS_COND_AXIS_NAME_MAGICNO-16 "20971521.0000000000"
*MEAS_COND_AXIS_NAME_MAGICNO-17 "20971521.0000000000"
*MEAS_COND_AXIS_NAME_MAGICNO-18 "23068673.0000000000"
*MEAS_COND_AXIS_NAME_MAGICNO-19 "23068673.0000000000"
*MEAS_COND_AXIS_NAME_MAGICNO-20 "20971521.0000000000"
*MEAS_COND_AXIS_NAME_MAGICNO-21 "20971521.0000000000"
*MEAS_COND_AXIS_NAME_MAGICNO-22 "20971521.0000000000"
*MEAS_COND_AXIS_NAME_MAGICNO-23 "25165824.0000000000"
*MEAS_COND_AXIS_NAME_MAGICNO-24 "25165824.0000000000"
*MEAS_COND_AXIS_NAME_MAGICNO-25 "285343744.0000000000"
*MEAS_COND_AXIS_NAME_MAGICNO-26 "17301505.0000000000"
*MEAS_COND_AXIS_NAME_MAGICNO-27 "20971521.0000000000"
*MEAS_COND_AXIS_NAME_MAGICNO-28 "20971521.0000000000"
*MEAS_COND_AXIS_NAME_MAGICNO-29 "20971521.0000000000"
*MEAS_COND_AXIS_NAME_MAGICNO-30 "0.0000000000"
*MEAS_COND_AXIS_OFFSET-0 "-"
*MEAS_COND_AXIS_OFFSET-1 "-0.1081000000"
*MEAS_COND_AXIS_OFFSET-2 "0.3758000000"
*MEAS_COND_AXIS_OFFSET-3 "-"
*MEAS_COND_AXIS_OFFSET-4 "-"
*MEAS_COND_AXIS_OFFSET-5 "0.3758000000"
*MEAS_COND_AXIS_OFFSET-6 "-0.4839000000"
*MEAS_COND_AXIS_OFFSET-7 "-"
*MEAS_COND_AXIS_OFFSET-8 "-"
*MEAS_COND_AXIS_OFFSET-9 "-"
*MEAS_COND_AXIS_OFFSET-10 "-"
*MEAS_COND_AXIS_OFFSET-11 "-"
*MEAS_COND_AXIS_OFFSET-12 "-"
*MEAS_COND_AXIS_OFFSET-13 "-"
*MEAS_COND_AXIS_OFFSET-14 "-"
*MEAS_COND_AXIS_OFFSET-15 "-"
*MEAS_COND_AXIS_OFFSET-16 "-"
*MEAS_COND_AXIS_OFFSET-17 "-"
*MEAS_COND_AXIS_OFFSET-18 "-"
*MEAS_COND_AXIS_OFFSET-19 "-"
*MEAS_COND_AXIS_OFFSET-20 "-"
*MEAS_COND_AXIS_OFFSET-21 "-"
*MEAS_COND_AXIS_OFFSET-22 "-"
*MEAS_COND_AXIS_OFFSET-23 "-"
*MEAS_COND_AXIS_OFFSET-24 "-"
*MEAS_COND_AXIS_OFFSET-25 "-"
*MEAS_COND_AXIS_OFFSET-26 "-"
*MEAS_COND_AXIS_OFFSET-27 "-"
*MEAS_COND_AXIS_OFFSET-28 "-"
*MEAS_COND_AXIS_OFFSET-29 "-"
*MEAS_COND_AXIS_OFFSET-30 "-"
*MEAS_COND_AXIS_POSITION-0 "0.0000000000"
*MEAS_COND_AXIS_POSITION-1 "0.0000000000"
*MEAS_COND_AXIS_POSITION-2 "0.0000000000"
*MEAS_COND_AXIS_POSITION-3 "-0.5500000000"
*MEAS_COND_AXIS_POSITION-4 "0.0000000000"
*MEAS_COND_AXIS_POSITION-5 "0.0000000000"
*MEAS_COND_AXIS_POSITION-6 "0.0000000000"
*MEAS_COND_AXIS_POSITION-7 "-0.4278800000"
*MEAS_COND_AXIS_POSITION-8 "BB"
*MEAS_COND_AXIS_POSITION-9 "0.0000000000"
*MEAS_COND_AXIS_POSITION-10 "Soller_slit_5.0deg"
*MEAS_COND_AXIS_POSITION-11 "2/3deg"
*MEAS_COND_AXIS_POSITION-12 "2.2088000000"
*MEAS_COND_AXIS_POSITION-13 "-0.4140600000"
*MEAS_COND_AXIS_POSITION-14 "0.0000000000"
*MEAS_COND_AXIS_POSITION-15 "10.0mm"
*MEAS_COND_AXIS_POSITION-16 "None"
*MEAS_COND_AXIS_POSITION-17 "Cu_K-beta"
*MEAS_COND_AXIS_POSITION-18 "13.000mm"
*MEAS_COND_AXIS_POSITION-19 "13.000mm"
*MEAS_COND_AXIS_POSITION-20 "No_unit"
*MEAS_COND_AXIS_POSITION-21 "Soller_slit_5.0deg"
*MEAS_COND_AXIS_POSITION-22 "None"
*MEAS_COND_AXIS_POSITION-23 "13.0000000000"
*MEAS_COND_AXIS_POSITION-24 "13.0000000000"
*MEAS_COND_AXIS_POSITION-25 "0.0109400000"
*MEAS_COND_AXIS_POSITION-26 "Open"
*MEAS_COND_AXIS_POSITION-27 "None"
*MEAS_COND_AXIS_POSITION-28 "None"
*MEAS_COND_AXIS_POSITION-29 "None"
*MEAS_COND_AXIS_POSITION-30 "38.0000000000"
*MEAS_COND_AXIS_UNIT-0 "deg"
*MEAS_COND_AXIS_UNIT-1 "deg"
*MEAS_COND_AXIS_UNIT-2 "deg"
*MEAS_COND_AXIS_UNIT-3 "mm"
*MEAS_COND_AXIS_UNIT-4 "deg"
*MEAS_COND_AXIS_UNIT-5 "deg"
*MEAS_COND_AXIS_UNIT-6 "deg"
*MEAS_COND_AXIS_UNIT-7 "mm"
*MEAS_COND_AXIS_UNIT-8 ""
*MEAS_COND_AXIS_UNIT-9 "pulse"
*MEAS_COND_AXIS_UNIT-10 ""
*MEAS_COND_AXIS_UNIT-11 ""
*MEAS_COND_AXIS_UNIT-12 "mm"
*MEAS_COND_AXIS_UNIT-13 "mm"
*MEAS_COND_AXIS_UNIT-14 ""
*MEAS_COND_AXIS_UNIT-15 ""
*MEAS_COND_AXIS_UNIT-16 ""
*MEAS_COND_AXIS_UNIT-17 ""
*MEAS_COND_AXIS_UNIT-18 ""
*MEAS_COND_AXIS_UNIT-19 ""
*MEAS_COND_AXIS_UNIT-20 ""
*MEAS_COND_AXIS_UNIT-21 ""
*MEAS_COND_AXIS_UNIT-22 ""
*MEAS_COND_AXIS_UNIT-23 "mm"
*MEAS_COND_AXIS_UNIT-24 "mm"
*MEAS_COND_AXIS_UNIT-25 "mm"
*MEAS_COND_AXIS_UNIT-26 ""
*MEAS_COND_AXIS_UNIT-27 ""
*MEAS_COND_AXIS_UNIT-28 ""
*MEAS_COND_AXIS_UNIT-29 ""
*MEAS_COND_AXIS_UNIT-30 "div"
*MEAS_COND_COUNTER_CNTLOSS_CORR "0.0000000000"
*MEAS_COND_COUNTER_PHABASE "38.0000000000"
*MEAS_COND_COUNTER_PHAWINDOW "16.0000000000"
*MEAS_COND_COUNTER_PHA_UNIT "div"
*MEAS_COND_COUNTER_TAUDIFF "30.0000000000"
*MEAS_COND_COUNTER_TAUINT "0.0000000000"
*MEAS_COND_IRRADIATION_MODE "OFF"
*MEAS_COND_IRRADIATION_WIDTH ""
*MEAS_COND_OPT_ATTR "集中法"
*MEAS_COND_OPT_NAME "@集中法"
*MEAS_COND_UNSYMMETRIC_MODE "OFF"
*MEAS_COND_XG_CURRENT "30.0000000000"
*MEAS_COND_XG_VOLTAGE "40.0000000000"
*MEAS_COND_XG_WAVE_TYPE "Ka"
*MEAS_DATA_COUNT "3501.0000000000"
*MEAS_SCAN_AXIS_X "2θ/θ"
*MEAS_SCAN_AXIS_X_INTERNAL "TwoThetaTheta"
*MEAS_SCAN_END_TIME "09/10/20 17:03:54"
*MEAS_SCAN_MODE "CONTINUOUS"
*MEAS_SCAN_MONITOR "0"
*MEAS_SCAN_RESOLUTION_X "0.0002"
*MEAS_SCAN_SPEED "1.0"
*MEAS_SCAN_SPEED_UNIT "deg/min"
*MEAS_SCAN_START "20.0000000000"
*MEAS_SCAN_START_TIME "09/10/20 15:51:00"
*MEAS_SCAN_STEP "0.0200000000"
*MEAS_SCAN_STOP "90.0000000000"
*MEAS_SCAN_UNIT_X "deg"
*MEAS_SCAN_UNIT_Y "counts"
*RAS_HEADER_END
*RAS_INT_START
20.0000 11034.0000 1.0000
20.0600 10897.0000 1.0000
20.1200 10883.0000 1.0000
20.1800 10946.0000 1.0000
20.2400 10999.0000 1.0000
20.3000 10944.0000 1.0000
20.3600 10785.0000 1.0000
20.4200 10950.0000 1.0000
20.4800 10908.0000 1.0000
20.5400 11046.0000 1.0000
20.6000 11087.0000 1.0000
20.6600 11292.0000 1.0000
20.7200 11558.0000 1.0000
20.7800 12662.0000 1.0000
20.8400 16070.0000 1.0000
20.9000 16990.0000 1.0000
20.9600 13581.0000 1.0000
21.0200 11539.0000 1.0000
21.0800 11261.0000 1.0000
21.1400 11079.0000 1.0000
21.2000 11071.0000 1.0000
21.2600 10949.0000 1.0000
21.3200 10960.0000 1.0000
21.3800 10971.0000 1.0000
21.4400 10915.0000 1.0000
21.5000 10899.0000 1.0000
21.5600 11002.0000 1.0000
21.6200 10952.0000 1.0000
21.6800 10911.0000 1.0000
21.7400 10801.0000 1.0000
21.8000 11169.0000 1.0000
21.8600 11082.0000 1.0000
21.9200 11087.0000 1.0000
21.9800 10827.0000 1.0000
22.0400 10852.0000 1.0000
22.1000 10944.0000 1.0000
22.1600 10843.0000 1.0000
22.2200 10892.0000 1.0000
22.2800 10958.0000 1.0000
22.3400 10790.0000 1.0000
22.4000 10835.0000 1.0000
22.4600 10795.0000 1.0000
22.5200 10777.0000 1.0000
22.5800 10859.0000 1.0000
22.6400 10851.0000 1.0000
22.7000 11019.0000 1.0000
22.7600 10919.0000 1.0000
22.8200 10746.0000 1.0000
22.8800 11043.0000 1.0000
22.9400 10811.0000 1.0000
23.0000 10955.0000 1.0000
23.0600 10940.0000 1.0000
23.1200 11023.0000 1.0000
23.1800 10898.0000 1.0000
23.2400 10819.0000 1.0000
23.3000 10878.0000 1.0000
23.3600 10956.0000 1.0000
23.4200 10847.0000 1.0000
23.4800 10825.0000 1.0000
23.5400 10895.0000 1.0000
23.6000 11039.0000 1.0000
23.6600 10992.0000 1.0000
23.7200 11042.0000 1.0000
23.7800 10903.0000 1.0000
23.8400 11040.0000 1.0000
23.9000 11134.0000 1.0000
23.9600 11408.0000 1.0000
24.0200 11924.0000 1.0000
24.0800 13062.0000 1.0000
24.1400 14988.0000 1.0000
24.2000 15340.0000 1.0000
24.2600 13192.0000 1.0000
24.3200 11593.0000 1.0000
24.3800 11242.0000 1.0000
24.4400 11181.0000 1.0000
24.5000 11047.0000 1.0000
24.5600 10815.0000 1.0000
24.6200 10727.0000 1.0000
24.6800 10772.0000 1.0000
24.7400 10934.0000 1.0000
24.8000 10871.0000 1.0000
24.8600 10822.0000 1.0000
24.9200 10735.0000 1.0000
24.9800 10982.0000 1.0000
25.0400 10884.0000 1.0000
25.1000 10784.0000 1.0000
25.1600 10868.0000 1.0000
25.2200 10951.0000 1.0000
25.2800 10880.0000 1.0000
25.3400 10890.0000 1.0000
25.4000 11017.0000 1.0000
25.4600 11163.0000 1.0000
25.5200 11910.0000 1.0000
25.5800 12565.0000 1.0000
25.6400 12319.0000 1.0000
25.7000 11553.0000 1.0000
25.7600 10989.0000 1.0000
25.8200 11041.0000 1.0000
25.8800 10862.0000 1.0000
25.9400 10720.0000 1.0000
26.0000 11056.0000 1.0000
26.0600 11011.0000 1.0000
26.1200 10727.0000 1.0000
26.1800 11079.0000 1.0000
26.2400 10929.0000 1.0000
26.3000 11249.0000 1.0000
26.3600 11498.0000 1.0000
26.4200 12326.0000 1.0000
26.4800 13073.0000 1.0000
26.5400 16489.0000 1.0000
26.6000 25784.0000 1.0000
26.6600 42549.0000 1.0000
26.7200 33560.0000 1.0000
26.7800 18316.0000 1.0000
26.8400 12856.0000 1.0000
26.9000 11401.0000 1.0000
26.9600 10891.0000 1.0000
27.0200 11002.0000 1.0000
27.0800 10733.0000 1.0000
27.1400 10823.0000 1.0000
27.2000 10682.0000 1.0000
27.2600 10735.0000 1.0000
27.3200 10592.0000 1.0000
27.3800 10829.0000 1.0000
27.4400 10873.0000 1.0000
27.5000 10725.0000 1.0000
27.5600 10728.0000 1.0000
27.6200 10641.0000 1.0000
27.6800 10751.0000 1.0000
27.7400 10686.0000 1.0000
27.8000 10664.0000 1.0000
27.8600 10575.0000 1.0000
27.9200 10786.0000 1.0000
27.9800 10715.0000 1.0000
28.0400 10503.0000 1.0000
28.1000 10588.0000 1.0000
28.1600 10751.0000 1.0000
28.2200 10663.0000 1.0000
28.2800 10588.0000 1.0000
28.3400 10487.0000 1.0000
28.4000 10650.0000 1.0000
28.4600 10537.0000 1.0000
28.5200 10589.0000 1.0000
28.5800 10596.0000 1.0000
28.6400 10336.0000 1.0000
28.7000 10641.0000 1.0000
28.7600 10636.0000 1.0000
28.8200 10484.0000 1.0000
28.8800 10613.0000 1.0000
28.9400 10474.0000 1.0000
29.0000 10527.0000 1.0000
29.0600 10709.0000 1.0000
29.1200 10500.0000 1.0000
29.1800 10526.0000 1.0000
29.2400 10537.0000 1.0000
29.3000 10445.0000 1.0000
29.3600 10556.0000 1.0000
29.4200 10520.0000 1.0000
29.4800 10404.0000 1.0000
29.5400 10706.0000 1.0000
29.6000 10557.0000 1.0000
29.6600 10509.0000 1.0000
29.7200 10438.0000 1.0000
29.7800 10538.0000 1.0000
29.8400 10496.0000 1.0000
29.9000 10604.0000 1.0000
29.9600 10621.0000 1.0000
30.0200 10746.0000 1.0000
30.0800 10909.0000 1.0000
30.1400 11035.0000 1.0000
30.2000 10898.0000 1.0000
30.2600 10710.0000 1.0000
30.3200 10592.0000 1.0000
30.3800 10465.0000 1.0000
30.4400 10489.0000 1.0000
30.5000 10577.0000 1.0000
30.5600 10594.0000 1.0000
30.6200 10475.0000 1.0000
30.6800 10656.0000 1.0000
30.7400 10586.0000 1.0000
30.8000 10426.0000 1.0000
30.8600 10296.0000 1.0000
30.9200 10483.0000 1.0000
30.9800 10544.0000 1.0000
31.0400 10460.0000 1.0000
31.1000 10375.0000 1.0000
31.1600 10371.0000 1.0000
31.2200 10205.0000 1.0000
31.2800 10380.0000 1.0000
31.3400 10398.0000 1.0000
31.4000 10576.0000 1.0000
31.4600 10358.0000 1.0000
31.5200 10443.0000 1.0000
31.5800 10271.0000 1.0000
31.6400 10387.0000 1.0000
31.7000 10460.0000 1.0000
31.7600 10179.0000 1.0000
31.8200 10365.0000 1.0000
31.8800 10149.0000 1.0000
31.9400 10397.0000 1.0000
32.0000 10430.0000 1.0000
32.0600 10531.0000 1.0000
32.1200 10456.0000 1.0000
32.1800 10467.0000 1.0000
32.2400 10469.0000 1.0000
32.3000 10322.0000 1.0000
32.3600 10448.0000 1.0000
32.4200 10281.0000 1.0000
32.4800 10481.0000 1.0000
32.5400 10317.0000 1.0000
32.6000 10409.0000 1.0000
32.6600 10511.0000 1.0000
32.7200 10503.0000 1.0000
32.7800 10665.0000 1.0000
32.8400 10771.0000 1.0000
32.9000 11105.0000 1.0000
32.9600 11958.0000 1.0000
33.0200 13077.0000 1.0000
33.0800 15713.0000 1.0000
33.1400 22932.0000 1.0000
33.2000 26314.0000 1.0000
33.2600 21209.0000 1.0000
33.3200 15542.0000 1.0000
33.3800 12194.0000 1.0000
33.4400 11307.0000 1.0000
33.5000 10704.0000 1.0000
33.5600 10520.0000 1.0000
33.6200 10567.0000 1.0000
33.6800 10318.0000 1.0000
33.7400 10356.0000 1.0000
33.8000 10338.0000 1.0000
33.8600 10587.0000 1.0000
33.9200 10486.0000 1.0000
33.9800 10276.0000 1.0000
34.0400 10370.0000 1.0000
34.1000 10314.0000 1.0000
34.1600 10310.0000 1.0000
34.2200 10288.0000 1.0000
34.2800 10309.0000 1.0000
34.3400 10397.0000 1.0000
34.4000 10394.0000 1.0000
34.4600 10372.0000 1.0000
34.5200 10366.0000 1.0000
34.5800 10369.0000 1.0000
34.6400 10425.0000 1.0000
34.7000 10283.0000 1.0000
34.7600 10298.0000 1.0000
34.8200 10404.0000 1.0000
34.8800 10442.0000 1.0000
34.9400 10590.0000 1.0000
35.0000 10874.0000 1.0000
35.0600 11386.0000 1.0000
35.1200 12610.0000 1.0000
35.1800 13288.0000 1.0000
35.2400 12468.0000 1.0000
35.3000 11699.0000 1.0000
35.3600 11558.0000 1.0000
35.4200 12289.0000 1.0000
35.4800 13682.0000 1.0000
35.5400 15416.0000 1.0000
35.6000 19089.0000 1.0000
35.6600 23003.0000 1.0000
35.7200 18965.0000 1.0000
35.7800 15526.0000 1.0000
35.8400 12240.0000 1.0000
35.9000 11024.0000 1.0000
35.9600 10592.0000 1.0000
36.0200 10516.0000 1.0000
36.0800 10471.0000 1.0000
36.1400 10414.0000 1.0000
36.2000 10303.0000 1.0000
36.2600 10209.0000 1.0000
36.3200 10299.0000 1.0000
36.3800 10479.0000 1.0000
36.4400 10520.0000 1.0000
36.5000 11102.0000 1.0000
36.5600 12557.0000 1.0000
36.6200 11598.0000 1.0000
36.6800 11189.0000 1.0000
36.7400 10364.0000 1.0000
36.8000 10422.0000 1.0000
36.8600 10249.0000 1.0000
36.9200 10154.0000 1.0000
36.9800 10173.0000 1.0000
37.0400 10303.0000 1.0000
37.1000 10195.0000 1.0000
37.1600 10224.0000 1.0000
37.2200 10311.0000 1.0000
37.2800 10222.0000 1.0000
37.3400 10228.0000 1.0000
37.4000 10210.0000 1.0000
37.4600 10168.0000 1.0000
37.5200 10458.0000 1.0000
37.5800 10235.0000 1.0000
37.6400 10387.0000 1.0000
37.7000 10526.0000 1.0000
37.7600 11071.0000 1.0000
37.8200 11342.0000 1.0000
37.8800 10925.0000 1.0000
37.9400 10578.0000 1.0000
38.0000 10447.0000 1.0000
38.0600 10257.0000 1.0000
38.1200 10213.0000 1.0000
38.1800 10317.0000 1.0000
38.2400 10346.0000 1.0000
38.3000 10244.0000 1.0000
38.3600 10159.0000 1.0000
38.4200 10355.0000 1.0000
38.4800 10378.0000 1.0000
38.5400 10104.0000 1.0000
38.6000 9997.0000 1.0000
38.6600 10141.0000 1.0000
38.7200 10304.0000 1.0000
38.7800 10104.0000 1.0000
38.8400 10178.0000 1.0000
38.9000 10228.0000 1.0000
38.9600 10189.0000 1.0000
39.0200 10329.0000 1.0000
39.0800 10185.0000 1.0000
39.1400 10279.0000 1.0000
39.2000 10263.0000 1.0000
39.2600 10415.0000 1.0000
39.3200 10461.0000 1.0000
39.3800 10789.0000 1.0000
39.4400 11619.0000 1.0000
39.5000 12089.0000 1.0000
39.5600 11225.0000 1.0000
39.6200 10925.0000 1.0000
39.6800 10336.0000 1.0000
39.7400 10139.0000 1.0000
39.8000 10139.0000 1.0000
39.8600 10068.0000 1.0000
39.9200 9978.0000 1.0000
39.9800 10150.0000 1.0000
40.0400 10110.0000 1.0000
40.1000 10214.0000 1.0000
40.1600 10133.0000 1.0000
40.2200 10439.0000 1.0000
40.2800 10968.0000 1.0000
40.3400 11302.0000 1.0000
40.4000 10547.0000 1.0000
40.4600 10513.0000 1.0000
40.5200 10460.0000 1.0000
40.5800 10387.0000 1.0000
40.6400 10483.0000 1.0000
40.7000 10607.0000 1.0000
40.7600 11057.0000 1.0000
40.8200 12164.0000 1.0000
40.8800 13655.0000 1.0000
40.9400 12689.0000 1.0000
41.0000 12290.0000 1.0000
41.0600 11031.0000 1.0000
41.1200 10367.0000 1.0000
41.1800 10315.0000 1.0000
41.2400 10068.0000 1.0000
41.3000 10195.0000 1.0000
41.3600 10211.0000 1.0000
41.4200 10167.0000 1.0000
41.4800 10248.0000 1.0000
41.5400 10102.0000 1.0000
41.6000 10355.0000 1.0000
41.6600 10223.0000 1.0000
41.7200 10177.0000 1.0000
41.7800 10300.0000 1.0000
41.8400 10115.0000 1.0000
41.9000 10054.0000 1.0000
41.9600 10154.0000 1.0000
42.0200 10187.0000 1.0000
42.0800 10165.0000 1.0000
42.1400 10181.0000 1.0000
42.2000 10210.0000 1.0000
42.2600 10378.0000 1.0000
42.3200 10373.0000 1.0000
42.3800 10841.0000 1.0000
42.4400 12004.0000 1.0000
42.5000 12740.0000 1.0000
42.5600 11409.0000 1.0000
42.6200 11140.0000 1.0000
42.6800 10208.0000 1.0000
42.7400 10239.0000 1.0000
42.8000 10343.0000 1.0000
42.8600 10293.0000 1.0000
42.9200 10237.0000 1.0000
42.9800 10139.0000 1.0000
43.0400 10315.0000 1.0000
43.1000 10766.0000 1.0000
43.1600 11004.0000 1.0000
43.2200 11223.0000 1.0000
43.2800 11796.0000 1.0000
43.3400 13254.0000 1.0000
43.4000 12953.0000 1.0000
43.4600 12466.0000 1.0000
43.5200 11728.0000 1.0000
43.5800 10899.0000 1.0000
43.6400 10456.0000 1.0000
43.7000 10262.0000 1.0000
43.7600 10262.0000 1.0000
43.8200 10258.0000 1.0000
43.8800 10102.0000 1.0000
43.9400 10182.0000 1.0000
44.0000 10091.0000 1.0000
44.0600 10006.0000 1.0000
44.1200 10032.0000 1.0000
44.1800 10196.0000 1.0000
44.2400 10035.0000 1.0000
44.3000 9960.0000 1.0000
44.3600 10069.0000 1.0000
44.4200 10257.0000 1.0000
44.4800 10178.0000 1.0000
44.5400 10154.0000 1.0000
44.6000 10118.0000 1.0000
44.6600 9976.0000 1.0000
44.7200 10107.0000 1.0000
44.7800 10057.0000 1.0000
44.8400 10157.0000 1.0000
44.9000 9839.0000 1.0000
44.9600 9948.0000 1.0000
45.0200 10021.0000 1.0000
45.0800 10140.0000 1.0000
45.1400 10114.0000 1.0000
45.2000 10143.0000 1.0000
45.2600 10101.0000 1.0000
45.3200 9995.0000 1.0000
45.3800 10083.0000 1.0000
45.4400 10111.0000 1.0000
45.5000 10075.0000 1.0000
45.5600 10009.0000 1.0000
45.6200 10005.0000 1.0000
45.6800 10194.0000 1.0000
45.7400 10422.0000 1.0000
45.8000 11252.0000 1.0000
45.8600 10750.0000 1.0000
45.9200 10723.0000 1.0000
45.9800 10483.0000 1.0000
46.0400 10378.0000 1.0000
46.1000 10166.0000 1.0000
46.1600 10076.0000 1.0000
46.2200 9922.0000 1.0000
46.2800 10191.0000 1.0000
46.3400 10255.0000 1.0000
46.4000 9999.0000 1.0000
46.4600 9980.0000 1.0000
46.5200 10176.0000 1.0000
46.5800 10039.0000 1.0000
46.6400 9971.0000 1.0000
46.7000 10179.0000 1.0000
46.7600 9872.0000 1.0000
46.8200 9984.0000 1.0000
46.8800 10166.0000 1.0000
46.9400 10060.0000 1.0000
47.0000 10108.0000 1.0000
47.0600 9774.0000 1.0000
47.1200 10130.0000 1.0000
47.1800 10057.0000 1.0000
47.2400 10174.0000 1.0000
47.3000 10024.0000 1.0000
47.3600 10078.0000 1.0000
47.4200 9966.0000 1.0000
47.4800 9812.0000 1.0000
47.5400 9962.0000 1.0000
47.6000 9890.0000 1.0000
47.6600 10080.0000 1.0000
47.7200 9979.0000 1.0000
47.7800 9875.0000 1.0000
47.8400 10096.0000 1.0000
47.9000 10186.0000 1.0000
47.9600 10054.0000 1.0000
48.0200 10019.0000 1.0000
48.0800 10028.0000 1.0000
48.1400 9995.0000 1.0000
48.2000 9941.0000 1.0000
48.2600 10054.0000 1.0000
48.3200 10009.0000 1.0000
48.3800 10018.0000 1.0000
48.4400 9974.0000 1.0000
48.5000 10138.0000 1.0000
48.5600 9991.0000 1.0000
48.6200 10048.0000 1.0000
48.6800 9988.0000 1.0000
48.7400 10192.0000 1.0000
48.8000 10008.0000 1.0000
48.8600 9922.0000 1.0000
48.9200 10212.0000 1.0000
48.9800 10110.0000 1.0000
49.0400 10112.0000 1.0000
49.1000 10122.0000 1.0000
49.1600 10221.0000 1.0000
49.2200 10398.0000 1.0000
49.2800 10879.0000 1.0000
49.3400 11079.0000 1.0000
49.4000 12476.0000 1.0000
49.4600 15325.0000 1.0000
49.5200 14951.0000 1.0000
49.5800 13618.0000 1.0000
49.6400 12923.0000 1.0000
49.7000 11326.0000 1.0000
49.7600 10609.0000 1.0000
49.8200 10376.0000 1.0000
49.8800 10327.0000 1.0000
49.9400 10568.0000 1.0000
50.0000 10467.0000 1.0000
50.0600 11097.0000 1.0000
50.1200 16562.0000 1.0000
50.1800 14073.0000 1.0000
50.2400 12678.0000 1.0000
50.3000 12949.0000 1.0000
50.3600 10575.0000 1.0000
50.4200 10196.0000 1.0000
50.4800 9976.0000 1.0000
50.5400 10083.0000 1.0000
50.6000 10023.0000 1.0000
50.6600 10068.0000 1.0000
50.7200 9981.0000 1.0000
50.7800 10117.0000 1.0000
50.8400 10150.0000 1.0000
50.9000 10056.0000 1.0000
50.9600 9961.0000 1.0000
51.0200 9997.0000 1.0000
51.0800 9941.0000 1.0000
51.1400 10241.0000 1.0000
51.2000 10016.0000 1.0000
51.2600 9831.0000 1.0000
51.3200 10041.0000 1.0000
51.3800 10003.0000 1.0000
51.4400 9888.0000 1.0000
51.5000 10079.0000 1.0000
51.5600 9955.0000 1.0000
51.6200 9786.0000 1.0000
51.6800 9960.0000 1.0000
51.7400 9999.0000 1.0000
51.8000 10060.0000 1.0000
51.8600 9941.0000 1.0000
51.9200 9954.0000 1.0000
51.9800 10060.0000 1.0000
52.0400 10041.0000 1.0000
52.1000 10186.0000 1.0000
52.1600 10197.0000 1.0000
52.2200 9947.0000 1.0000
52.2800 10177.0000 1.0000
52.3400 10257.0000 1.0000
52.4000 10487.0000 1.0000
52.4600 10498.0000 1.0000
52.5200 11239.0000 1.0000
52.5800 11418.0000 1.0000
52.6400 10919.0000 1.0000
52.7000 10947.0000 1.0000
52.7600 10609.0000 1.0000
52.8200 10153.0000 1.0000
52.8800 9969.0000 1.0000
52.9400 10185.0000 1.0000
53.0000 10089.0000 1.0000
53.0600 10101.0000 1.0000
53.1200 9925.0000 1.0000
53.1800 9838.0000 1.0000
53.2400 10070.0000 1.0000
53.3000 10021.0000 1.0000
53.3600 9883.0000 1.0000
53.4200 10274.0000 1.0000
53.4800 10167.0000 1.0000
53.5400 10149.0000 1.0000
53.6000 10298.0000 1.0000
53.6600 10441.0000 1.0000
53.7200 10474.0000 1.0000
53.7800 10399.0000 1.0000
53.8400 10636.0000 1.0000
53.9000 10925.0000 1.0000
53.9600 11671.0000 1.0000
54.0200 13739.0000 1.0000
54.0800 17026.0000 1.0000
54.1400 15131.0000 1.0000
54.2000 14125.0000 1.0000
54.2600 13481.0000 1.0000
54.3200 11521.0000 1.0000
54.3800 10695.0000 1.0000
54.4400 10379.0000 1.0000
54.5000 10256.0000 1.0000
54.5600 10132.0000 1.0000
54.6200 10178.0000 1.0000
54.6800 10053.0000 1.0000
54.7400 10077.0000 1.0000
54.8000 10288.0000 1.0000
54.8600 10961.0000 1.0000
54.9200 11066.0000 1.0000
54.9800 10550.0000 1.0000
55.0400 10870.0000 1.0000
55.1000 10413.0000 1.0000
55.1600 10128.0000 1.0000
55.2200 9994.0000 1.0000
55.2800 10125.0000 1.0000
55.3400 10665.0000 1.0000
55.4000 10303.0000 1.0000
55.4600 10266.0000 1.0000
55.5200 10299.0000 1.0000
55.5800 10057.0000 1.0000
55.6400 10190.0000 1.0000
55.7000 10163.0000 1.0000
55.7600 9927.0000 1.0000
55.8200 10280.0000 1.0000
55.8800 10001.0000 1.0000
55.9400 10103.0000 1.0000
56.0000 10062.0000 1.0000
56.0600 10074.0000 1.0000
56.1200 10170.0000 1.0000
56.1800 10026.0000 1.0000
56.2400 9977.0000 1.0000
56.3000 10104.0000 1.0000
56.3600 10170.0000 1.0000
56.4200 10130.0000 1.0000
56.4800 10013.0000 1.0000
56.5400 10002.0000 1.0000
56.6000 9994.0000 1.0000
56.6600 10101.0000 1.0000
56.7200 10049.0000 1.0000
56.7800 9968.0000 1.0000
56.8400 10022.0000 1.0000
56.9000 10076.0000 1.0000
56.9600 10426.0000 1.0000
57.0200 10583.0000 1.0000
57.0800 10730.0000 1.0000
57.1400 10666.0000 1.0000
57.2000 10717.0000 1.0000
57.2600 10846.0000 1.0000
57.3200 10918.0000 1.0000
57.3800 11379.0000 1.0000
57.4400 12353.0000 1.0000
57.5000 13560.0000 1.0000
57.5600 13085.0000 1.0000
57.6200 13165.0000 1.0000
57.6800 12571.0000 1.0000
57.7400 11436.0000 1.0000
57.8000 11054.0000 1.0000
57.8600 10602.0000 1.0000
57.9200 10334.0000 1.0000
57.9800 10053.0000 1.0000
58.0400 10161.0000 1.0000
58.1000 10042.0000 1.0000
58.1600 9933.0000 1.0000
58.2200 9839.0000 1.0000
58.2800 10020.0000 1.0000
58.3400 9974.0000 1.0000
58.4000 9904.0000 1.0000
58.4600 9991.0000 1.0000
58.5200 10002.0000 1.0000
58.5800 10018.0000 1.0000
58.6400 10079.0000 1.0000
58.7000 9892.0000 1.0000
58.7600 9986.0000 1.0000
58.8200 9852.0000 1.0000
58.8800 10153.0000 1.0000
58.9400 9930.0000 1.0000
59.0000 9829.0000 1.0000
59.0600 9876.0000 1.0000
59.1200 10069.0000 1.0000
59.1800 9869.0000 1.0000
59.2400 10066.0000 1.0000
59.3000 10171.0000 1.0000
59.3600 9937.0000 1.0000
59.4200 9857.0000 1.0000
59.4800 9890.0000 1.0000
59.5400 10060.0000 1.0000
59.6000 10013.0000 1.0000
59.6600 10188.0000 1.0000
59.7200 10363.0000 1.0000
59.7800 10129.0000 1.0000
59.8400 10333.0000 1.0000
59.9000 10892.0000 1.0000
59.9600 13609.0000 1.0000
60.0200 11516.0000 1.0000
60.0800 11031.0000 1.0000
60.1400 11851.0000 1.0000
60.2000 10550.0000 1.0000
60.2600 10209.0000 1.0000
60.3200 9949.0000 1.0000
60.3800 10067.0000 1.0000
60.4400 9958.0000 1.0000
60.5000 10078.0000 1.0000
60.5600 10084.0000 1.0000
60.6200 10080.0000 1.0000
60.6800 10079.0000 1.0000
60.7400 10113.0000 1.0000
60.8000 10054.0000 1.0000
60.8600 9938.0000 1.0000
60.9200 10040.0000 1.0000
60.9800 9949.0000 1.0000
61.0400 10168.0000 1.0000
61.1000 10181.0000 1.0000
61.1600 10077.0000 1.0000
61.2200 10161.0000 1.0000
61.2800 10272.0000 1.0000
61.3400 10293.0000 1.0000
61.4000 10201.0000 1.0000
61.4600 10015.0000 1.0000
61.5200 10294.0000 1.0000
61.5800 10199.0000 1.0000
61.6400 9971.0000 1.0000
61.7000 10230.0000 1.0000
61.7600 9875.0000 1.0000
61.8200 9991.0000 1.0000
61.8800 10142.0000 1.0000
61.9400 10262.0000 1.0000
62.0000 10229.0000 1.0000
62.0600 10189.0000 1.0000
62.1200 10409.0000 1.0000
62.1800 10298.0000 1.0000
62.2400 10598.0000 1.0000
62.3000 10723.0000 1.0000
62.3600 11789.0000 1.0000
62.4200 14092.0000 1.0000
62.4800 14236.0000 1.0000
62.5400 12729.0000 1.0000
62.6000 13158.0000 1.0000
62.6600 12767.0000 1.0000
62.7200 11489.0000 1.0000
62.7800 10883.0000 1.0000
62.8400 10784.0000 1.0000
62.9000 10323.0000 1.0000
62.9600 10156.0000 1.0000
63.0200 10274.0000 1.0000
63.0800 10199.0000 1.0000
63.1400 10138.0000 1.0000
63.2000 10100.0000 1.0000
63.2600 10201.0000 1.0000
63.3200 10089.0000 1.0000
63.3800 9837.0000 1.0000
63.4400 10008.0000 1.0000
63.5000 10076.0000 1.0000
63.5600 10201.0000 1.0000
63.6200 10314.0000 1.0000
63.6800 10258.0000 1.0000
63.7400 10409.0000 1.0000
63.8000 10561.0000 1.0000
63.8600 10804.0000 1.0000
63.9200 11798.0000 1.0000
63.9800 13880.0000 1.0000
64.0400 14529.0000 1.0000
64.1000 12479.0000 1.0000
64.1600 12693.0000 1.0000
64.2200 12401.0000 1.0000
64.2800 10985.0000 1.0000
64.3400 10606.0000 1.0000
64.4000 10286.0000 1.0000
64.4600 10066.0000 1.0000
64.5200 10045.0000 1.0000
64.5800 10071.0000 1.0000
64.6400 10073.0000 1.0000
64.7000 10082.0000 1.0000
64.7600 9946.0000 1.0000
64.8200 10007.0000 1.0000
64.8800 9902.0000 1.0000
64.9400 10090.0000 1.0000
65.0000 9906.0000 1.0000
65.0600 9902.0000 1.0000
65.1200 9995.0000 1.0000
65.1800 9969.0000 1.0000
65.2400 9946.0000 1.0000
65.3000 10020.0000 1.0000
65.3600 9899.0000 1.0000
65.4200 9898.0000 1.0000
65.4800 9983.0000 1.0000
65.5400 10077.0000 1.0000
65.6000 9980.0000 1.0000
65.6600 10133.0000 1.0000
65.7200 10289.0000 1.0000
65.7800 10247.0000 1.0000
65.8400 10326.0000 1.0000
65.9000 10180.0000 1.0000
65.9600 10127.0000 1.0000
66.0200 10242.0000 1.0000
66.0800 10162.0000 1.0000
66.1400 10003.0000 1.0000
66.2000 10036.0000 1.0000
66.2600 10214.0000 1.0000
66.3200 10342.0000 1.0000
66.3800 10353.0000 1.0000
66.4400 10522.0000 1.0000
66.5000 11001.0000 1.0000
66.5600 10922.0000 1.0000
66.6200 10419.0000 1.0000
66.6800 10603.0000 1.0000
66.7400 10419.0000 1.0000
66.8000 10077.0000 1.0000
66.8600 10125.0000 1.0000
66.9200 9932.0000 1.0000
66.9800 10110.0000 1.0000
67.0400 10018.0000 1.0000
67.1000 10152.0000 1.0000
67.1600 10193.0000 1.0000
67.2200 10057.0000 1.0000
67.2800 10162.0000 1.0000
67.3400 9862.0000 1.0000
67.4000 10239.0000 1.0000
67.4600 10086.0000 1.0000
67.5200 10154.0000 1.0000
67.5800 10260.0000 1.0000
67.6400 10393.0000 1.0000
67.7000 11090.0000 1.0000
67.7600 11522.0000 1.0000
67.8200 10610.0000 1.0000
67.8800 10720.0000 1.0000
67.9400 11074.0000 1.0000
68.0000 10912.0000 1.0000
68.0600 11226.0000 1.0000
68.1200 13528.0000 1.0000
68.1800 14067.0000 1.0000
68.2400 12610.0000 1.0000
68.3000 13475.0000 1.0000
68.3600 13172.0000 1.0000
68.4200 11302.0000 1.0000
68.4800 11224.0000 1.0000
68.5400 10670.0000 1.0000
68.6000 10336.0000 1.0000
68.6600 10231.0000 1.0000
68.7200 10086.0000 1.0000
68.7800 9886.0000 1.0000
68.8400 10055.0000 1.0000
68.9000 10013.0000 1.0000
68.9600 10073.0000 1.0000
69.0200 10212.0000 1.0000
69.0800 10105.0000 1.0000
69.1400 9882.0000 1.0000
69.2000 10017.0000 1.0000
69.2600 10145.0000 1.0000
69.3200 10008.0000 1.0000
69.3800 10180.0000 1.0000
69.4400 10078.0000 1.0000
69.5000 10178.0000 1.0000
69.5600 10295.0000 1.0000
69.6200 10331.0000 1.0000
69.6800 10321.0000 1.0000
69.7400 10152.0000 1.0000
69.8000 10397.0000 1.0000
69.8600 10128.0000 1.0000
69.9200 10012.0000 1.0000
69.9800 9999.0000 1.0000
70.0400 10180.0000 1.0000
70.1000 9930.0000 1.0000
70.1600 10148.0000 1.0000
70.2200 10002.0000 1.0000
70.2800 9930.0000 1.0000
70.3400 9993.0000 1.0000
70.4000 10010.0000 1.0000
70.4600 10098.0000 1.0000
70.5200 9974.0000 1.0000
70.5800 10011.0000 1.0000
70.6400 9949.0000 1.0000
70.7000 10061.0000 1.0000
70.7600 10190.0000 1.0000
70.8200 9922.0000 1.0000
70.8800 9994.0000 1.0000
70.9400 9919.0000 1.0000
71.0000 10083.0000 1.0000
71.0600 10026.0000 1.0000
71.1200 10047.0000 1.0000
71.1800 10171.0000 1.0000
71.2400 10088.0000 1.0000
71.3000 9932.0000 1.0000
71.3600 10050.0000 1.0000
71.4200 10033.0000 1.0000
71.4800 10103.0000 1.0000
71.5400 10019.0000 1.0000
71.6000 10184.0000 1.0000
71.6600 9814.0000 1.0000
71.7200 10182.0000 1.0000
71.7800 10283.0000 1.0000
71.8400 10314.0000 1.0000
71.9000 10939.0000 1.0000
71.9600 11651.0000 1.0000
72.0200 11196.0000 1.0000
72.0800 10536.0000 1.0000
72.1400 10739.0000 1.0000
72.2000 10611.0000 1.0000
72.2600 10452.0000 1.0000
72.3200 10346.0000 1.0000
72.3800 10235.0000 1.0000
72.4400 10170.0000 1.0000
72.5000 10197.0000 1.0000
72.5600 10125.0000 1.0000
72.6200 10103.0000 1.0000
72.6800 10145.0000 1.0000
72.7400 10016.0000 1.0000
72.8000 10023.0000 1.0000
72.8600 9990.0000 1.0000
72.9200 9848.0000 1.0000
72.9800 9854.0000 1.0000
73.0400 9905.0000 1.0000
73.1000 9956.0000 1.0000
73.1600 9901.0000 1.0000
73.2200 9906.0000 1.0000
73.2800 9802.0000 1.0000
73.3400 9974.0000 1.0000
73.4000 10099.0000 1.0000
73.4600 10647.0000 1.0000
73.5200 10372.0000 1.0000
73.5800 10048.0000 1.0000
73.6400 10025.0000 1.0000
73.7000 10335.0000 1.0000
73.7600 10044.0000 1.0000
73.8200 10095.0000 1.0000
73.8800 10145.0000 1.0000
73.9400 9825.0000 1.0000
74.0000 10023.0000 1.0000
74.0600 10146.0000 1.0000
74.1200 9996.0000 1.0000
74.1800 10150.0000 1.0000
74.2400 10119.0000 1.0000
74.3000 10139.0000 1.0000
74.3600 10022.0000 1.0000
74.4200 10036.0000 1.0000
74.4800 10018.0000 1.0000
74.5400 10108.0000 1.0000
74.6000 9954.0000 1.0000
74.6600 10083.0000 1.0000
74.7200 9934.0000 1.0000
74.7800 9966.0000 1.0000
74.8400 10079.0000 1.0000
74.9000 10032.0000 1.0000
74.9600 10008.0000 1.0000
75.0200 10136.0000 1.0000
75.0800 9877.0000 1.0000
75.1400 10110.0000 1.0000
75.2000 10133.0000 1.0000
75.2600 10047.0000 1.0000
75.3200 10130.0000 1.0000
75.3800 10483.0000 1.0000
75.4400 10886.0000 1.0000
75.5000 10833.0000 1.0000
75.5600 10528.0000 1.0000
75.6200 11038.0000 1.0000
75.6800 11343.0000 1.0000
75.7400 10703.0000 1.0000
75.8000 10247.0000 1.0000
75.8600 10360.0000 1.0000
75.9200 10367.0000 1.0000
75.9800 9960.0000 1.0000
76.0400 10163.0000 1.0000
76.1000 10078.0000 1.0000
76.1600 9970.0000 1.0000
76.2200 10110.0000 1.0000
76.2800 9933.0000 1.0000
76.3400 9952.0000 1.0000
76.4000 9956.0000 1.0000
76.4600 9996.0000 1.0000
76.5200 9897.0000 1.0000
76.5800 9868.0000 1.0000
76.6400 9964.0000 1.0000
76.7000 10068.0000 1.0000
76.7600 10140.0000 1.0000
76.8200 10301.0000 1.0000
76.8800 10295.0000 1.0000
76.9400 10315.0000 1.0000
77.0000 10183.0000 1.0000
77.0600 10321.0000 1.0000
77.1200 10306.0000 1.0000
77.1800 10060.0000 1.0000
77.2400 10016.0000 1.0000
77.3000 10002.0000 1.0000
77.3600 10147.0000 1.0000
77.4200 10179.0000 1.0000
77.4800 10218.0000 1.0000
77.5400 10062.0000 1.0000
77.6000 10207.0000 1.0000
77.6600 11426.0000 1.0000
77.7200 11141.0000 1.0000
77.7800 10546.0000 1.0000
77.8400 10241.0000 1.0000
77.9000 10844.0000 1.0000
77.9600 10473.0000 1.0000
78.0200 10180.0000 1.0000
78.0800 10001.0000 1.0000
78.1400 10092.0000 1.0000
78.2000 9919.0000 1.0000
78.2600 9774.0000 1.0000
78.3200 9959.0000 1.0000
78.3800 9967.0000 1.0000
78.4400 9860.0000 1.0000
78.5000 10044.0000 1.0000
78.5600 9902.0000 1.0000
78.6200 9931.0000 1.0000
78.6800 9954.0000 1.0000
78.7400 9854.0000 1.0000
78.8000 9964.0000 1.0000
78.8600 10153.0000 1.0000
78.9200 10092.0000 1.0000
78.9800 9899.0000 1.0000
79.0400 10127.0000 1.0000
79.1000 9804.0000 1.0000
79.1600 9858.0000 1.0000
79.2200 9998.0000 1.0000
79.2800 10104.0000 1.0000
79.3400 9929.0000 1.0000
79.4000 9995.0000 1.0000
79.4600 9818.0000 1.0000
79.5200 10003.0000 1.0000
79.5800 10018.0000 1.0000
79.6400 9961.0000 1.0000
79.7000 9996.0000 1.0000
79.7600 9901.0000 1.0000
79.8200 10168.0000 1.0000
79.8800 10820.0000 1.0000
79.9400 10290.0000 1.0000
80.0000 10180.0000 1.0000
80.0600 10497.0000 1.0000
80.1200 10424.0000 1.0000
80.1800 10326.0000 1.0000
80.2400 10116.0000 1.0000
80.3000 10200.0000 1.0000
80.3600 9987.0000 1.0000
80.4200 10236.0000 1.0000
80.4800 10155.0000 1.0000
80.5400 10446.0000 1.0000
80.6000 10247.0000 1.0000
80.6600 10605.0000 1.0000
80.7200 10619.0000 1.0000
80.7800 10439.0000 1.0000
80.8400 10462.0000 1.0000
80.9000 10412.0000 1.0000
80.9600 10303.0000 1.0000
81.0200 10203.0000 1.0000
81.0800 10189.0000 1.0000
81.1400 10391.0000 1.0000
81.2000 10501.0000 1.0000
81.2600 10259.0000 1.0000
81.3200 10162.0000 1.0000
81.3800 10243.0000 1.0000
81.4400 10488.0000 1.0000
81.5000 10695.0000 1.0000
81.5600 10137.0000 1.0000
81.6200 10092.0000 1.0000
81.6800 9994.0000 1.0000
81.7400 10315.0000 1.0000
81.8000 9967.0000 1.0000
81.8600 10051.0000 1.0000
81.9200 9876.0000 1.0000
81.9800 9896.0000 1.0000
82.0400 10120.0000 1.0000
82.1000 9808.0000 1.0000
82.1600 9778.0000 1.0000
82.2200 9883.0000 1.0000
82.2800 9942.0000 1.0000
82.3400 9964.0000 1.0000
82.4000 9718.0000 1.0000
82.4600 9990.0000 1.0000
82.5200 9931.0000 1.0000
82.5800 9848.0000 1.0000
82.6400 9985.0000 1.0000
82.7000 9866.0000 1.0000
82.7600 10044.0000 1.0000
82.8200 10083.0000 1.0000
82.8800 10149.0000 1.0000
82.9400 10460.0000 1.0000
83.0000 10353.0000 1.0000
83.0600 10180.0000 1.0000
83.1200 10099.0000 1.0000
83.1800 10127.0000 1.0000
83.2400 10258.0000 1.0000
83.3000 10085.0000 1.0000
83.3600 10061.0000 1.0000
83.4200 10129.0000 1.0000
83.4800 9898.0000 1.0000
83.5400 9775.0000 1.0000
83.6000 9743.0000 1.0000
83.6600 9831.0000 1.0000
83.7200 9960.0000 1.0000
83.7800 10113.0000 1.0000
83.8400 10380.0000 1.0000
83.9000 10107.0000 1.0000
83.9600 9807.0000 1.0000
84.0200 10057.0000 1.0000
84.0800 10184.0000 1.0000
84.1400 10083.0000 1.0000
84.2000 10030.0000 1.0000
84.2600 10058.0000 1.0000
84.3200 10089.0000 1.0000
84.3800 10196.0000 1.0000
84.4400 9892.0000 1.0000
84.5000 9963.0000 1.0000
84.5600 9942.0000 1.0000
84.6200 9941.0000 1.0000
84.6800 9980.0000 1.0000
84.7400 10043.0000 1.0000
84.8000 10362.0000 1.0000
84.8600 10437.0000 1.0000
84.9200 10829.0000 1.0000
84.9800 10959.0000 1.0000
85.0400 10479.0000 1.0000
85.1000 10306.0000 1.0000
85.1600 10572.0000 1.0000
85.2200 10536.0000 1.0000
85.2800 10113.0000 1.0000
85.3400 9942.0000 1.0000
85.4000 10034.0000 1.0000
85.4600 9997.0000 1.0000
85.5200 9798.0000 1.0000
85.5800 9925.0000 1.0000
85.6400 9929.0000 1.0000
85.7000 9893.0000 1.0000
85.7600 9813.0000 1.0000
85.8200 9879.0000 1.0000
85.8800 9800.0000 1.0000
85.9400 9809.0000 1.0000
86.0000 9944.0000 1.0000
86.0600 9935.0000 1.0000
86.1200 9850.0000 1.0000
86.1800 9905.0000 1.0000
86.2400 9872.0000 1.0000
86.3000 9916.0000 1.0000
86.3600 10012.0000 1.0000
86.4200 10085.0000 1.0000
86.4800 9939.0000 1.0000
86.5400 9827.0000 1.0000
86.6000 9889.0000 1.0000
86.6600 10080.0000 1.0000
86.7200 9772.0000 1.0000
86.7800 9894.0000 1.0000
86.8400 9871.0000 1.0000
86.9000 9851.0000 1.0000
86.9600 9866.0000 1.0000
87.0200 9762.0000 1.0000
87.0800 9840.0000 1.0000
87.1400 9761.0000 1.0000
87.2000 9766.0000 1.0000
87.2600 9747.0000 1.0000
87.3200 9797.0000 1.0000
87.3800 9709.0000 1.0000
87.4400 9812.0000 1.0000
87.5000 10094.0000 1.0000
87.5600 9859.0000 1.0000
87.6200 9758.0000 1.0000
87.6800 9904.0000 1.0000
87.7400 9686.0000 1.0000
87.8000 9604.0000 1.0000
87.8600 9958.0000 1.0000
87.9200 9842.0000 1.0000
87.9800 9818.0000 1.0000
88.0400 9710.0000 1.0000
88.1000 9825.0000 1.0000
88.1600 9935.0000 1.0000
88.2200 9831.0000 1.0000
88.2800 9867.0000 1.0000
88.3400 10002.0000 1.0000
88.4000 10099.0000 1.0000
88.4600 10320.0000 1.0000
88.5200 10641.0000 1.0000
88.5800 10909.0000 1.0000
88.6400 10432.0000 1.0000
88.7000 10151.0000 1.0000
88.7600 10269.0000 1.0000
88.8200 10409.0000 1.0000
88.8800 10313.0000 1.0000
88.9400 10180.0000 1.0000
89.0000 10088.0000 1.0000
89.0600 10036.0000 1.0000
89.1200 9937.0000 1.0000
89.1800 9870.0000 1.0000
89.2400 9886.0000 1.0000
89.3000 9858.0000 1.0000
89.3600 9764.0000 1.0000
89.4200 9899.0000 1.0000
89.4800 9979.0000 1.0000
89.5400 9756.0000 1.0000
89.6000 9918.0000 1.0000
89.6600 9976.0000 1.0000
89.7200 9967.0000 1.0000
89.7800 9925.0000 1.0000
89.8400 9995.0000 1.0000
89.9000 10057.0000 1.0000
89.9600 10071.0000 1.0000
90.0000 9954.0000 1.0000
*RAS_INT_END
*RAS_TEMPERATURE_START
*RAS_TEMPERATURE_END
*RAS_DATA_END