File: XRD/Data/20200819_mix_02.ras
*RAS_DATA_START
*RAS_HEADER_START
*DISP_FMT_X "%.2f"
*DISP_FMT_Y "%.0f"
*DISP_FULLSCALE "60749.0000000000"
*DISP_LINE_COLOR "255.0000000000"
*DISP_LINE_STYLE "0.0000000000"
*DISP_LINE_WIDTH "0.2500000000"
*DISP_NOTE "測定データ-3"
*DISP_OFFSET_Y "0.0000000000"
*DISP_PEAKSEARCH_UNIT_Y "cps"
*DISP_RANGE_BOTTOM "0.0000000000"
*DISP_RANGE_LEFT "20.0000000000"
*DISP_RANGE_LOGCUTOFF "0.0100000000"
*DISP_RANGE_RIGHT "90.0000000000"
*DISP_RANGE_TOP "60749.0000000000"
*DISP_SCALE_MODE_Y "0.0000000000"
*DISP_TAB_NAME "2θ/θ"
*DISP_TITLE_Y "強度"
*DISP_UNIT_Y "cps"
*DISP_WINDOW_NAME "MSG_MACROENGINE"
*FILE_COMMENT " "
*FILE_MD5 ""
*FILE_MEMO " "
*FILE_OPERATOR "Administrator"
*FILE_SAMPLE " "
*FILE_TYPE "RAS_RAW"
*FILE_USERGROUP "システムマネージャ"
*FILE_VERSION "1.0000000000"
*HW_ATTACHMENT_ID "ATT0025"
*HW_ATTACHMENT_NAME "標準|Standard"
*HW_COUNTER_ID-0 "CUT0025"
*HW_COUNTER_ID-1 "CUT0020"
*HW_COUNTER_ID-2 "CUT0020"
*HW_COUNTER_ID-3 "CSL0021"
*HW_COUNTER_ID-4 "CMC0021"
*HW_COUNTER_NAME-0 "D/teX Ultra|D/teX Ultra"
*HW_COUNTER_NAME-1 "None|None"
*HW_COUNTER_NAME-2 "None|None"
*HW_COUNTER_NAME-3 "BBM|BBM"
*HW_COUNTER_NAME-4 "検出器モノクロメータ|Detector monochromator"
*HW_COUNTER_SELECT_NAME "D/teX Ultra|D/teX Ultra"
*HW_GONIOMETER_ID "GON0023"
*HW_GONIOMETER_NAME "SmartLab|SmartLab"
*HW_GONIOMETER_RADIUS-0 "90.0"
*HW_GONIOMETER_RADIUS-1 "114.0"
*HW_GONIOMETER_RADIUS-2 "190.0"
*HW_GONIOMETER_RADIUS-3 "300.0"
*HW_GONIOMETER_RADIUS-4 "187.0"
*HW_GONIOMETER_RADIUS-5 "300.0"
*HW_GONIOMETER_RADIUS-6 "113.0"
*HW_GONIOMETER_RADIUS-7 "331.0"
*HW_I_OPT_ID-0 "CBO0021"
*HW_I_OPT_ID-1 "ICR0023"
*HW_I_OPT_ID-2 "ISL0021"
*HW_I_OPT_ID-3 "ISO0021"
*HW_I_OPT_ID-4 "IAD0021"
*HW_I_OPT_ID-5 "IPR0001"
*HW_I_OPT_NAME-0 "CBOユニット|CBO unit"
*HW_I_OPT_NAME-1 "標準入射光学ユニット|Standard incident optical unit"
*HW_I_OPT_NAME-2 "標準入射スリットボックス|Standard incident slit box"
*HW_I_OPT_NAME-3 "入射平行スリット|Incident parallel slit"
*HW_I_OPT_NAME-4 "長手制限スリット|Length limiting slit"
*HW_I_OPT_NAME-5 "None|None"
*HW_R_ATTENUATER_AUTOMODE "0"
*HW_R_OPT_ID-0 "RSS0021"
*HW_R_OPT_ID-1 "RCR0023"
*HW_R_OPT_ID-2 "RSO0021"
*HW_R_OPT_ID-3 "RRS0021"
*HW_R_OPT_ID-4 "ATN0021"
*HW_R_OPT_ID-5 "RFL0021"
*HW_R_OPT_ID-6 "RAD0021"
*HW_R_OPT_NAME-0 "標準受光スリットボックス1|Standard receiving slit box # 1"
*HW_R_OPT_NAME-1 "標準受光光学ユニット1|Standard receiving unit # 1"
*HW_R_OPT_NAME-2 "標準受光光学ユニット2|Standard receiving optical unit # 2"
*HW_R_OPT_NAME-3 "標準受光スリットボックス2|Standard receiving slit box # 2"
*HW_R_OPT_NAME-4 "標準アッテネータ|Standard Attenuator"
*HW_R_OPT_NAME-5 "Cu Kβ|Cu K-beta"
*HW_R_OPT_NAME-6 "調整用受光スリット|Alignment receiving slit"
*HW_SAMPLE_HOLDER_ID "SMP0023"
*HW_SAMPLE_HOLDER_NAME "標準Zステージ|Standard Z stage"
*HW_XG_CURRENT_MAX "50"
*HW_XG_CURRENT_MIN "2"
*HW_XG_CURRENT_RESOLUTION "2"
*HW_XG_CURRENT_UNIT "mA"
*HW_XG_FOCUS "1mm x 10mm"
*HW_XG_FOCUS_TYPE "Normal"
*HW_XG_ID ""
*HW_XG_NAME "3kW 封入管(ID:1200)|3kW Sealed tube(ID:1200)"
*HW_XG_TARGET_ATOMIC_NUMBER "29.0000000000"
*HW_XG_TARGET_NAME "Cu"
*HW_XG_TYPE "Hermetic"
*HW_XG_VOLTAGE_MAX "60"
*HW_XG_VOLTAGE_MIN "20"
*HW_XG_VOLTAGE_RESOLUTION "2"
*HW_XG_VOLTAGE_UNIT "kV"
*HW_XG_WATT_MAX "2"
*HW_XG_WATT_UNIT "kW"
*HW_XG_WAVE_LENGTH_ALPHA1 "1.540593"
*HW_XG_WAVE_LENGTH_ALPHA2 "1.544414"
*HW_XG_WAVE_LENGTH_BETA "1.392250"
*MEAS_COND_AXIS_NAME-0 "2θ/θ"
*MEAS_COND_AXIS_NAME-1 "2θ"
*MEAS_COND_AXIS_NAME-2 "ω"
*MEAS_COND_AXIS_NAME-3 "Z"
*MEAS_COND_AXIS_NAME-4 "2θ/ω"
*MEAS_COND_AXIS_NAME-5 "θs"
*MEAS_COND_AXIS_NAME-6 "θd"
*MEAS_COND_AXIS_NAME-7 "Ts"
*MEAS_COND_AXIS_NAME-8 "CBO選択スリット"
*MEAS_COND_AXIS_NAME-9 "M"
*MEAS_COND_AXIS_NAME-10 "入射平行スリット"
*MEAS_COND_AXIS_NAME-11 "入射スリット"
*MEAS_COND_AXIS_NAME-12 ""
*MEAS_COND_AXIS_NAME-13 "Zs"
*MEAS_COND_AXIS_NAME-14 "入射光学素子"
*MEAS_COND_AXIS_NAME-15 "長手制限スリット"
*MEAS_COND_AXIS_NAME-16 "センタースリット"
*MEAS_COND_AXIS_NAME-17 "フィルター"
*MEAS_COND_AXIS_NAME-18 "受光スリット1"
*MEAS_COND_AXIS_NAME-19 "受光スリット2"
*MEAS_COND_AXIS_NAME-20 "受光光学素子"
*MEAS_COND_AXIS_NAME-21 "受光平行スリット"
*MEAS_COND_AXIS_NAME-22 "調整用受光スリット"
*MEAS_COND_AXIS_NAME-23 ""
*MEAS_COND_AXIS_NAME-24 ""
*MEAS_COND_AXIS_NAME-25 "Zd"
*MEAS_COND_AXIS_NAME-26 "アッテネータ"
*MEAS_COND_AXIS_NAME-27 "検出器モノクロメータ"
*MEAS_COND_AXIS_NAME-28 "モノクロメータスリット"
*MEAS_COND_AXIS_NAME-29 "プライマリビーム"
*MEAS_COND_AXIS_NAME-30 "PHA"
*MEAS_COND_AXIS_NAME_INTERNAL-0 "TwoThetaTheta"
*MEAS_COND_AXIS_NAME_INTERNAL-1 "TwoTheta"
*MEAS_COND_AXIS_NAME_INTERNAL-2 "Omega"
*MEAS_COND_AXIS_NAME_INTERNAL-3 "Z"
*MEAS_COND_AXIS_NAME_INTERNAL-4 "TwoThetaOmega"
*MEAS_COND_AXIS_NAME_INTERNAL-5 "ThetaS"
*MEAS_COND_AXIS_NAME_INTERNAL-6 "ThetaD"
*MEAS_COND_AXIS_NAME_INTERNAL-7 "Ts"
*MEAS_COND_AXIS_NAME_INTERNAL-8 "CBO"
*MEAS_COND_AXIS_NAME_INTERNAL-9 "CBO-M"
*MEAS_COND_AXIS_NAME_INTERNAL-10 "IncidentSollerSlit"
*MEAS_COND_AXIS_NAME_INTERNAL-11 "IncidentSlitBox"
*MEAS_COND_AXIS_NAME_INTERNAL-12 "IncidentSlitBox-_Axis"
*MEAS_COND_AXIS_NAME_INTERNAL-13 "Zs"
*MEAS_COND_AXIS_NAME_INTERNAL-14 "IncidentMonochromator"
*MEAS_COND_AXIS_NAME_INTERNAL-15 "IncidentAxdSlit"
*MEAS_COND_AXIS_NAME_INTERNAL-16 "CenterSlit"
*MEAS_COND_AXIS_NAME_INTERNAL-17 "Filter"
*MEAS_COND_AXIS_NAME_INTERNAL-18 "ReceivingSlitBox1"
*MEAS_COND_AXIS_NAME_INTERNAL-19 "ReceivingSlitBox2"
*MEAS_COND_AXIS_NAME_INTERNAL-20 "ReceivingOptics"
*MEAS_COND_AXIS_NAME_INTERNAL-21 "ReceivingSollerSlit"
*MEAS_COND_AXIS_NAME_INTERNAL-22 "ReceivingAxdSlit"
*MEAS_COND_AXIS_NAME_INTERNAL-23 "ReceivingSlitBox1-_Axis"
*MEAS_COND_AXIS_NAME_INTERNAL-24 "ReceivingSlitBox2-_Axis"
*MEAS_COND_AXIS_NAME_INTERNAL-25 "ReceivingSlitBox2-Zd"
*MEAS_COND_AXIS_NAME_INTERNAL-26 "Attenuator"
*MEAS_COND_AXIS_NAME_INTERNAL-27 "CounterMonochromator"
*MEAS_COND_AXIS_NAME_INTERNAL-28 "CounterSlit"
*MEAS_COND_AXIS_NAME_INTERNAL-29 "IncidentPrimary"
*MEAS_COND_AXIS_NAME_INTERNAL-30 "PHA"
*MEAS_COND_AXIS_NAME_MAGICNO-0 "83951616.0000000000"
*MEAS_COND_AXIS_NAME_MAGICNO-1 "268632064.0000000000"
*MEAS_COND_AXIS_NAME_MAGICNO-2 "268500992.0000000000"
*MEAS_COND_AXIS_NAME_MAGICNO-3 "285278208.0000000000"
*MEAS_COND_AXIS_NAME_MAGICNO-4 "83951616.0000000000"
*MEAS_COND_AXIS_NAME_MAGICNO-5 "131072.0000000000"
*MEAS_COND_AXIS_NAME_MAGICNO-6 "131072.0000000000"
*MEAS_COND_AXIS_NAME_MAGICNO-7 "318898176.0000000000"
*MEAS_COND_AXIS_NAME_MAGICNO-8 "20971521.0000000000"
*MEAS_COND_AXIS_NAME_MAGICNO-9 "285343744.0000000000"
*MEAS_COND_AXIS_NAME_MAGICNO-10 "20971521.0000000000"
*MEAS_COND_AXIS_NAME_MAGICNO-11 "22020097.0000000000"
*MEAS_COND_AXIS_NAME_MAGICNO-12 "25165824.0000000000"
*MEAS_COND_AXIS_NAME_MAGICNO-13 "318898176.0000000000"
*MEAS_COND_AXIS_NAME_MAGICNO-14 "1.0000000000"
*MEAS_COND_AXIS_NAME_MAGICNO-15 "20971521.0000000000"
*MEAS_COND_AXIS_NAME_MAGICNO-16 "20971521.0000000000"
*MEAS_COND_AXIS_NAME_MAGICNO-17 "20971521.0000000000"
*MEAS_COND_AXIS_NAME_MAGICNO-18 "23068673.0000000000"
*MEAS_COND_AXIS_NAME_MAGICNO-19 "23068673.0000000000"
*MEAS_COND_AXIS_NAME_MAGICNO-20 "20971521.0000000000"
*MEAS_COND_AXIS_NAME_MAGICNO-21 "20971521.0000000000"
*MEAS_COND_AXIS_NAME_MAGICNO-22 "20971521.0000000000"
*MEAS_COND_AXIS_NAME_MAGICNO-23 "25165824.0000000000"
*MEAS_COND_AXIS_NAME_MAGICNO-24 "25165824.0000000000"
*MEAS_COND_AXIS_NAME_MAGICNO-25 "285343744.0000000000"
*MEAS_COND_AXIS_NAME_MAGICNO-26 "17301505.0000000000"
*MEAS_COND_AXIS_NAME_MAGICNO-27 "20971521.0000000000"
*MEAS_COND_AXIS_NAME_MAGICNO-28 "20971521.0000000000"
*MEAS_COND_AXIS_NAME_MAGICNO-29 "20971521.0000000000"
*MEAS_COND_AXIS_NAME_MAGICNO-30 "0.0000000000"
*MEAS_COND_AXIS_OFFSET-0 "-"
*MEAS_COND_AXIS_OFFSET-1 "-0.1081000000"
*MEAS_COND_AXIS_OFFSET-2 "0.3758000000"
*MEAS_COND_AXIS_OFFSET-3 "-"
*MEAS_COND_AXIS_OFFSET-4 "-"
*MEAS_COND_AXIS_OFFSET-5 "0.3758000000"
*MEAS_COND_AXIS_OFFSET-6 "-0.4839000000"
*MEAS_COND_AXIS_OFFSET-7 "-"
*MEAS_COND_AXIS_OFFSET-8 "-"
*MEAS_COND_AXIS_OFFSET-9 "-"
*MEAS_COND_AXIS_OFFSET-10 "-"
*MEAS_COND_AXIS_OFFSET-11 "-"
*MEAS_COND_AXIS_OFFSET-12 "-"
*MEAS_COND_AXIS_OFFSET-13 "-"
*MEAS_COND_AXIS_OFFSET-14 "-"
*MEAS_COND_AXIS_OFFSET-15 "-"
*MEAS_COND_AXIS_OFFSET-16 "-"
*MEAS_COND_AXIS_OFFSET-17 "-"
*MEAS_COND_AXIS_OFFSET-18 "-"
*MEAS_COND_AXIS_OFFSET-19 "-"
*MEAS_COND_AXIS_OFFSET-20 "-"
*MEAS_COND_AXIS_OFFSET-21 "-"
*MEAS_COND_AXIS_OFFSET-22 "-"
*MEAS_COND_AXIS_OFFSET-23 "-"
*MEAS_COND_AXIS_OFFSET-24 "-"
*MEAS_COND_AXIS_OFFSET-25 "-"
*MEAS_COND_AXIS_OFFSET-26 "-"
*MEAS_COND_AXIS_OFFSET-27 "-"
*MEAS_COND_AXIS_OFFSET-28 "-"
*MEAS_COND_AXIS_OFFSET-29 "-"
*MEAS_COND_AXIS_OFFSET-30 "-"
*MEAS_COND_AXIS_POSITION-0 "0.0000000000"
*MEAS_COND_AXIS_POSITION-1 "0.0000000000"
*MEAS_COND_AXIS_POSITION-2 "0.0000000000"
*MEAS_COND_AXIS_POSITION-3 "-0.5500000000"
*MEAS_COND_AXIS_POSITION-4 "0.0000000000"
*MEAS_COND_AXIS_POSITION-5 "0.0000000000"
*MEAS_COND_AXIS_POSITION-6 "0.0000000000"
*MEAS_COND_AXIS_POSITION-7 "-0.4278800000"
*MEAS_COND_AXIS_POSITION-8 "BB"
*MEAS_COND_AXIS_POSITION-9 "0.0000000000"
*MEAS_COND_AXIS_POSITION-10 "Soller_slit_5.0deg"
*MEAS_COND_AXIS_POSITION-11 "2/3deg"
*MEAS_COND_AXIS_POSITION-12 "2.2088000000"
*MEAS_COND_AXIS_POSITION-13 "-0.4140600000"
*MEAS_COND_AXIS_POSITION-14 "0.0000000000"
*MEAS_COND_AXIS_POSITION-15 "10.0mm"
*MEAS_COND_AXIS_POSITION-16 "None"
*MEAS_COND_AXIS_POSITION-17 "Cu_K-beta"
*MEAS_COND_AXIS_POSITION-18 "13.000mm"
*MEAS_COND_AXIS_POSITION-19 "13.000mm"
*MEAS_COND_AXIS_POSITION-20 "No_unit"
*MEAS_COND_AXIS_POSITION-21 "Soller_slit_5.0deg"
*MEAS_COND_AXIS_POSITION-22 "None"
*MEAS_COND_AXIS_POSITION-23 "13.0000000000"
*MEAS_COND_AXIS_POSITION-24 "13.0000000000"
*MEAS_COND_AXIS_POSITION-25 "0.0109400000"
*MEAS_COND_AXIS_POSITION-26 "Open"
*MEAS_COND_AXIS_POSITION-27 "None"
*MEAS_COND_AXIS_POSITION-28 "None"
*MEAS_COND_AXIS_POSITION-29 "None"
*MEAS_COND_AXIS_POSITION-30 "38.0000000000"
*MEAS_COND_AXIS_UNIT-0 "deg"
*MEAS_COND_AXIS_UNIT-1 "deg"
*MEAS_COND_AXIS_UNIT-2 "deg"
*MEAS_COND_AXIS_UNIT-3 "mm"
*MEAS_COND_AXIS_UNIT-4 "deg"
*MEAS_COND_AXIS_UNIT-5 "deg"
*MEAS_COND_AXIS_UNIT-6 "deg"
*MEAS_COND_AXIS_UNIT-7 "mm"
*MEAS_COND_AXIS_UNIT-8 ""
*MEAS_COND_AXIS_UNIT-9 "pulse"
*MEAS_COND_AXIS_UNIT-10 ""
*MEAS_COND_AXIS_UNIT-11 ""
*MEAS_COND_AXIS_UNIT-12 "mm"
*MEAS_COND_AXIS_UNIT-13 "mm"
*MEAS_COND_AXIS_UNIT-14 ""
*MEAS_COND_AXIS_UNIT-15 ""
*MEAS_COND_AXIS_UNIT-16 ""
*MEAS_COND_AXIS_UNIT-17 ""
*MEAS_COND_AXIS_UNIT-18 ""
*MEAS_COND_AXIS_UNIT-19 ""
*MEAS_COND_AXIS_UNIT-20 ""
*MEAS_COND_AXIS_UNIT-21 ""
*MEAS_COND_AXIS_UNIT-22 ""
*MEAS_COND_AXIS_UNIT-23 "mm"
*MEAS_COND_AXIS_UNIT-24 "mm"
*MEAS_COND_AXIS_UNIT-25 "mm"
*MEAS_COND_AXIS_UNIT-26 ""
*MEAS_COND_AXIS_UNIT-27 ""
*MEAS_COND_AXIS_UNIT-28 ""
*MEAS_COND_AXIS_UNIT-29 ""
*MEAS_COND_AXIS_UNIT-30 "div"
*MEAS_COND_COUNTER_CNTLOSS_CORR "0.0000000000"
*MEAS_COND_COUNTER_PHABASE "38.0000000000"
*MEAS_COND_COUNTER_PHAWINDOW "16.0000000000"
*MEAS_COND_COUNTER_PHA_UNIT "div"
*MEAS_COND_COUNTER_TAUDIFF "30.0000000000"
*MEAS_COND_COUNTER_TAUINT "0.0000000000"
*MEAS_COND_IRRADIATION_MODE "OFF"
*MEAS_COND_IRRADIATION_WIDTH ""
*MEAS_COND_OPT_ATTR "集中法"
*MEAS_COND_OPT_NAME "@集中法"
*MEAS_COND_UNSYMMETRIC_MODE "OFF"
*MEAS_COND_XG_CURRENT "30.0000000000"
*MEAS_COND_XG_VOLTAGE "40.0000000000"
*MEAS_COND_XG_WAVE_TYPE "Ka"
*MEAS_DATA_COUNT "3501.0000000000"
*MEAS_SCAN_AXIS_X "2θ/θ"
*MEAS_SCAN_AXIS_X_INTERNAL "TwoThetaTheta"
*MEAS_SCAN_END_TIME "08/19/20 16:56:25"
*MEAS_SCAN_MODE "CONTINUOUS"
*MEAS_SCAN_MONITOR "0"
*MEAS_SCAN_RESOLUTION_X "0.0002"
*MEAS_SCAN_SPEED "1.0"
*MEAS_SCAN_SPEED_UNIT "deg/min"
*MEAS_SCAN_START "20.0000000000"
*MEAS_SCAN_START_TIME "08/19/20 15:43:30"
*MEAS_SCAN_STEP "0.0200000000"
*MEAS_SCAN_STOP "90.0000000000"
*MEAS_SCAN_UNIT_X "deg"
*MEAS_SCAN_UNIT_Y "counts"
*RAS_HEADER_END
*RAS_INT_START
20.0000 11024.0000 1.0000
20.0600 11172.0000 1.0000
20.1200 11079.0000 1.0000
20.1800 11175.0000 1.0000
20.2400 11160.0000 1.0000
20.3000 11173.0000 1.0000
20.3600 11311.0000 1.0000
20.4200 11456.0000 1.0000
20.4800 11095.0000 1.0000
20.5400 11349.0000 1.0000
20.6000 11505.0000 1.0000
20.6600 12053.0000 1.0000
20.7200 13178.0000 1.0000
20.7800 14673.0000 1.0000
20.8400 19007.0000 1.0000
20.9000 16313.0000 1.0000
20.9600 12059.0000 1.0000
21.0200 11563.0000 1.0000
21.0800 11225.0000 1.0000
21.1400 11327.0000 1.0000
21.2000 11227.0000 1.0000
21.2600 11197.0000 1.0000
21.3200 11295.0000 1.0000
21.3800 11218.0000 1.0000
21.4400 11286.0000 1.0000
21.5000 11110.0000 1.0000
21.5600 11219.0000 1.0000
21.6200 11359.0000 1.0000
21.6800 11349.0000 1.0000
21.7400 11158.0000 1.0000
21.8000 11194.0000 1.0000
21.8600 11252.0000 1.0000
21.9200 11271.0000 1.0000
21.9800 11115.0000 1.0000
22.0400 11157.0000 1.0000
22.1000 11132.0000 1.0000
22.1600 11255.0000 1.0000
22.2200 11076.0000 1.0000
22.2800 11152.0000 1.0000
22.3400 11190.0000 1.0000
22.4000 11336.0000 1.0000
22.4600 11314.0000 1.0000
22.5200 11134.0000 1.0000
22.5800 11188.0000 1.0000
22.6400 10922.0000 1.0000
22.7000 11407.0000 1.0000
22.7600 11144.0000 1.0000
22.8200 11375.0000 1.0000
22.8800 11251.0000 1.0000
22.9400 11232.0000 1.0000
23.0000 11155.0000 1.0000
23.0600 11238.0000 1.0000
23.1200 11384.0000 1.0000
23.1800 11024.0000 1.0000
23.2400 11136.0000 1.0000
23.3000 11184.0000 1.0000
23.3600 11222.0000 1.0000
23.4200 11275.0000 1.0000
23.4800 11175.0000 1.0000
23.5400 11198.0000 1.0000
23.6000 11137.0000 1.0000
23.6600 11295.0000 1.0000
23.7200 11287.0000 1.0000
23.7800 11325.0000 1.0000
23.8400 11420.0000 1.0000
23.9000 11642.0000 1.0000
23.9600 12004.0000 1.0000
24.0200 12660.0000 1.0000
24.0800 13545.0000 1.0000
24.1400 15217.0000 1.0000
24.2000 14099.0000 1.0000
24.2600 12128.0000 1.0000
24.3200 11559.0000 1.0000
24.3800 11511.0000 1.0000
24.4400 11328.0000 1.0000
24.5000 11239.0000 1.0000
24.5600 11357.0000 1.0000
24.6200 11155.0000 1.0000
24.6800 11164.0000 1.0000
24.7400 11299.0000 1.0000
24.8000 11178.0000 1.0000
24.8600 10952.0000 1.0000
24.9200 11118.0000 1.0000
24.9800 11193.0000 1.0000
25.0400 11080.0000 1.0000
25.1000 11145.0000 1.0000
25.1600 11246.0000 1.0000
25.2200 11270.0000 1.0000
25.2800 11280.0000 1.0000
25.3400 11290.0000 1.0000
25.4000 11268.0000 1.0000
25.4600 11604.0000 1.0000
25.5200 11850.0000 1.0000
25.5800 12136.0000 1.0000
25.6400 11483.0000 1.0000
25.7000 11390.0000 1.0000
25.7600 11331.0000 1.0000
25.8200 11327.0000 1.0000
25.8800 11212.0000 1.0000
25.9400 11191.0000 1.0000
26.0000 11313.0000 1.0000
26.0600 11307.0000 1.0000
26.1200 11552.0000 1.0000
26.1800 11360.0000 1.0000
26.2400 11576.0000 1.0000
26.3000 11833.0000 1.0000
26.3600 12518.0000 1.0000
26.4200 13713.0000 1.0000
26.4800 15835.0000 1.0000
26.5400 22826.0000 1.0000
26.6000 40692.0000 1.0000
26.6600 48698.0000 1.0000
26.7200 29987.0000 1.0000
26.7800 14009.0000 1.0000
26.8400 12382.0000 1.0000
26.9000 11531.0000 1.0000
26.9600 11187.0000 1.0000
27.0200 11321.0000 1.0000
27.0800 11199.0000 1.0000
27.1400 11124.0000 1.0000
27.2000 11018.0000 1.0000
27.2600 11208.0000 1.0000
27.3200 10973.0000 1.0000
27.3800 10983.0000 1.0000
27.4400 11102.0000 1.0000
27.5000 11133.0000 1.0000
27.5600 11154.0000 1.0000
27.6200 11010.0000 1.0000
27.6800 11105.0000 1.0000
27.7400 10988.0000 1.0000
27.8000 11166.0000 1.0000
27.8600 10826.0000 1.0000
27.9200 10989.0000 1.0000
27.9800 11068.0000 1.0000
28.0400 10953.0000 1.0000
28.1000 10936.0000 1.0000
28.1600 11034.0000 1.0000
28.2200 10905.0000 1.0000
28.2800 10860.0000 1.0000
28.3400 10935.0000 1.0000
28.4000 11156.0000 1.0000
28.4600 10988.0000 1.0000
28.5200 11194.0000 1.0000
28.5800 10896.0000 1.0000
28.6400 11078.0000 1.0000
28.7000 10984.0000 1.0000
28.7600 10983.0000 1.0000
28.8200 11154.0000 1.0000
28.8800 11059.0000 1.0000
28.9400 11116.0000 1.0000
29.0000 11057.0000 1.0000
29.0600 11068.0000 1.0000
29.1200 10937.0000 1.0000
29.1800 10963.0000 1.0000
29.2400 10862.0000 1.0000
29.3000 10712.0000 1.0000
29.3600 10829.0000 1.0000
29.4200 11022.0000 1.0000
29.4800 11072.0000 1.0000
29.5400 10768.0000 1.0000
29.6000 10840.0000 1.0000
29.6600 10921.0000 1.0000
29.7200 11060.0000 1.0000
29.7800 11124.0000 1.0000
29.8400 11090.0000 1.0000
29.9000 11126.0000 1.0000
29.9600 11452.0000 1.0000
30.0200 11837.0000 1.0000
30.0800 13156.0000 1.0000
30.1400 13443.0000 1.0000
30.2000 12770.0000 1.0000
30.2600 11734.0000 1.0000
30.3200 11191.0000 1.0000
30.3800 11192.0000 1.0000
30.4400 10962.0000 1.0000
30.5000 10968.0000 1.0000
30.5600 10976.0000 1.0000
30.6200 10962.0000 1.0000
30.6800 11108.0000 1.0000
30.7400 10996.0000 1.0000
30.8000 10883.0000 1.0000
30.8600 11044.0000 1.0000
30.9200 10803.0000 1.0000
30.9800 10802.0000 1.0000
31.0400 10599.0000 1.0000
31.1000 10682.0000 1.0000
31.1600 11056.0000 1.0000
31.2200 10973.0000 1.0000
31.2800 10764.0000 1.0000
31.3400 10874.0000 1.0000
31.4000 10694.0000 1.0000
31.4600 10668.0000 1.0000
31.5200 10792.0000 1.0000
31.5800 10871.0000 1.0000
31.6400 10759.0000 1.0000
31.7000 10743.0000 1.0000
31.7600 10976.0000 1.0000
31.8200 10973.0000 1.0000
31.8800 10901.0000 1.0000
31.9400 11070.0000 1.0000
32.0000 10918.0000 1.0000
32.0600 10997.0000 1.0000
32.1200 11146.0000 1.0000
32.1800 11058.0000 1.0000
32.2400 10717.0000 1.0000
32.3000 10967.0000 1.0000
32.3600 10918.0000 1.0000
32.4200 10946.0000 1.0000
32.4800 10945.0000 1.0000
32.5400 10814.0000 1.0000
32.6000 11072.0000 1.0000
32.6600 10994.0000 1.0000
32.7200 10872.0000 1.0000
32.7800 11091.0000 1.0000
32.8400 11393.0000 1.0000
32.9000 11788.0000 1.0000
32.9600 12567.0000 1.0000
33.0200 14000.0000 1.0000
33.0800 17975.0000 1.0000
33.1400 25010.0000 1.0000
33.2000 21536.0000 1.0000
33.2600 17129.0000 1.0000
33.3200 12867.0000 1.0000
33.3800 11748.0000 1.0000
33.4400 11249.0000 1.0000
33.5000 11120.0000 1.0000
33.5600 11044.0000 1.0000
33.6200 11102.0000 1.0000
33.6800 10904.0000 1.0000
33.7400 10750.0000 1.0000
33.8000 10927.0000 1.0000
33.8600 10814.0000 1.0000
33.9200 11009.0000 1.0000
33.9800 10869.0000 1.0000
34.0400 10907.0000 1.0000
34.1000 10734.0000 1.0000
34.1600 10792.0000 1.0000
34.2200 10810.0000 1.0000
34.2800 10786.0000 1.0000
34.3400 10910.0000 1.0000
34.4000 10830.0000 1.0000
34.4600 10985.0000 1.0000
34.5200 10946.0000 1.0000
34.5800 11008.0000 1.0000
34.6400 10907.0000 1.0000
34.7000 11014.0000 1.0000
34.7600 11066.0000 1.0000
34.8200 11068.0000 1.0000
34.8800 10909.0000 1.0000
34.9400 11061.0000 1.0000
35.0000 11282.0000 1.0000
35.0600 11747.0000 1.0000
35.1200 12493.0000 1.0000
35.1800 12519.0000 1.0000
35.2400 12562.0000 1.0000
35.3000 12666.0000 1.0000
35.3600 14074.0000 1.0000
35.4200 17804.0000 1.0000
35.4800 21573.0000 1.0000
35.5400 21880.0000 1.0000
35.6000 24543.0000 1.0000
35.6600 20881.0000 1.0000
35.7200 17740.0000 1.0000
35.7800 13414.0000 1.0000
35.8400 11942.0000 1.0000
35.9000 11395.0000 1.0000
35.9600 11052.0000 1.0000
36.0200 11154.0000 1.0000
36.0800 10780.0000 1.0000
36.1400 10832.0000 1.0000
36.2000 10924.0000 1.0000
36.2600 10732.0000 1.0000
36.3200 10947.0000 1.0000
36.3800 10927.0000 1.0000
36.4400 11273.0000 1.0000
36.5000 13402.0000 1.0000
36.5600 13445.0000 1.0000
36.6200 12900.0000 1.0000
36.6800 11223.0000 1.0000
36.7400 10813.0000 1.0000
36.8000 10882.0000 1.0000
36.8600 10821.0000 1.0000
36.9200 10780.0000 1.0000
36.9800 10747.0000 1.0000
37.0400 10865.0000 1.0000
37.1000 11066.0000 1.0000
37.1600 11035.0000 1.0000
37.2200 10937.0000 1.0000
37.2800 10860.0000 1.0000
37.3400 10568.0000 1.0000
37.4000 10633.0000 1.0000
37.4600 10679.0000 1.0000
37.5200 10751.0000 1.0000
37.5800 10709.0000 1.0000
37.6400 10796.0000 1.0000
37.7000 10838.0000 1.0000
37.7600 11289.0000 1.0000
37.8200 11026.0000 1.0000
37.8800 10953.0000 1.0000
37.9400 10822.0000 1.0000
38.0000 10810.0000 1.0000
38.0600 10658.0000 1.0000
38.1200 10588.0000 1.0000
38.1800 10499.0000 1.0000
38.2400 10702.0000 1.0000
38.3000 10465.0000 1.0000
38.3600 10579.0000 1.0000
38.4200 10493.0000 1.0000
38.4800 10657.0000 1.0000
38.5400 10577.0000 1.0000
38.6000 10512.0000 1.0000
38.6600 10699.0000 1.0000
38.7200 10507.0000 1.0000
38.7800 10602.0000 1.0000
38.8400 10367.0000 1.0000
38.9000 10491.0000 1.0000
38.9600 10623.0000 1.0000
39.0200 10520.0000 1.0000
39.0800 10591.0000 1.0000
39.1400 10697.0000 1.0000
39.2000 10788.0000 1.0000
39.2600 10871.0000 1.0000
39.3200 11030.0000 1.0000
39.3800 11263.0000 1.0000
39.4400 14978.0000 1.0000
39.5000 12307.0000 1.0000
39.5600 13250.0000 1.0000
39.6200 11003.0000 1.0000
39.6800 10777.0000 1.0000
39.7400 10620.0000 1.0000
39.8000 10492.0000 1.0000
39.8600 10520.0000 1.0000
39.9200 10503.0000 1.0000
39.9800 10442.0000 1.0000
40.0400 10535.0000 1.0000
40.1000 10561.0000 1.0000
40.1600 10600.0000 1.0000
40.2200 10940.0000 1.0000
40.2800 11864.0000 1.0000
40.3400 11236.0000 1.0000
40.4000 10979.0000 1.0000
40.4600 10519.0000 1.0000
40.5200 10513.0000 1.0000
40.5800 10840.0000 1.0000
40.6400 10922.0000 1.0000
40.7000 10890.0000 1.0000
40.7600 11522.0000 1.0000
40.8200 12978.0000 1.0000
40.8800 13122.0000 1.0000
40.9400 12327.0000 1.0000
41.0000 11683.0000 1.0000
41.0600 10878.0000 1.0000
41.1200 10774.0000 1.0000
41.1800 10573.0000 1.0000
41.2400 10526.0000 1.0000
41.3000 10638.0000 1.0000
41.3600 10732.0000 1.0000
41.4200 10387.0000 1.0000
41.4800 10508.0000 1.0000
41.5400 10365.0000 1.0000
41.6000 10495.0000 1.0000
41.6600 10641.0000 1.0000
41.7200 10318.0000 1.0000
41.7800 10557.0000 1.0000
41.8400 10497.0000 1.0000
41.9000 10475.0000 1.0000
41.9600 10395.0000 1.0000
42.0200 10322.0000 1.0000
42.0800 10405.0000 1.0000
42.1400 10436.0000 1.0000
42.2000 10402.0000 1.0000
42.2600 10607.0000 1.0000
42.3200 10686.0000 1.0000
42.3800 11467.0000 1.0000
42.4400 13393.0000 1.0000
42.5000 11292.0000 1.0000
42.5600 11412.0000 1.0000
42.6200 10683.0000 1.0000
42.6800 10418.0000 1.0000
42.7400 10494.0000 1.0000
42.8000 10474.0000 1.0000
42.8600 10409.0000 1.0000
42.9200 10602.0000 1.0000
42.9800 10733.0000 1.0000
43.0400 11563.0000 1.0000
43.1000 12316.0000 1.0000
43.1600 12192.0000 1.0000
43.2200 12030.0000 1.0000
43.2800 11871.0000 1.0000
43.3400 12306.0000 1.0000
43.4000 11662.0000 1.0000
43.4600 11600.0000 1.0000
43.5200 10921.0000 1.0000
43.5800 10709.0000 1.0000
43.6400 10560.0000 1.0000
43.7000 10386.0000 1.0000
43.7600 10295.0000 1.0000
43.8200 10296.0000 1.0000
43.8800 10420.0000 1.0000
43.9400 10253.0000 1.0000
44.0000 10486.0000 1.0000
44.0600 10129.0000 1.0000
44.1200 10324.0000 1.0000
44.1800 10437.0000 1.0000
44.2400 10284.0000 1.0000
44.3000 10412.0000 1.0000
44.3600 10383.0000 1.0000
44.4200 10172.0000 1.0000
44.4800 10236.0000 1.0000
44.5400 10344.0000 1.0000
44.6000 10240.0000 1.0000
44.6600 10263.0000 1.0000
44.7200 10418.0000 1.0000
44.7800 10455.0000 1.0000
44.8400 10302.0000 1.0000
44.9000 10332.0000 1.0000
44.9600 10302.0000 1.0000
45.0200 10172.0000 1.0000
45.0800 10271.0000 1.0000
45.1400 10410.0000 1.0000
45.2000 10346.0000 1.0000
45.2600 10337.0000 1.0000
45.3200 10270.0000 1.0000
45.3800 10356.0000 1.0000
45.4400 10173.0000 1.0000
45.5000 10124.0000 1.0000
45.5600 10496.0000 1.0000
45.6200 10415.0000 1.0000
45.6800 10513.0000 1.0000
45.7400 11191.0000 1.0000
45.8000 13198.0000 1.0000
45.8600 11029.0000 1.0000
45.9200 11774.0000 1.0000
45.9800 10445.0000 1.0000
46.0400 10400.0000 1.0000
46.1000 10225.0000 1.0000
46.1600 10307.0000 1.0000
46.2200 10191.0000 1.0000
46.2800 10139.0000 1.0000
46.3400 10208.0000 1.0000
46.4000 10268.0000 1.0000
46.4600 10346.0000 1.0000
46.5200 10300.0000 1.0000
46.5800 10228.0000 1.0000
46.6400 10265.0000 1.0000
46.7000 10142.0000 1.0000
46.7600 10111.0000 1.0000
46.8200 10315.0000 1.0000
46.8800 10338.0000 1.0000
46.9400 10208.0000 1.0000
47.0000 10190.0000 1.0000
47.0600 10059.0000 1.0000
47.1200 10090.0000 1.0000
47.1800 10241.0000 1.0000
47.2400 10263.0000 1.0000
47.3000 10322.0000 1.0000
47.3600 10353.0000 1.0000
47.4200 10257.0000 1.0000
47.4800 10169.0000 1.0000
47.5400 10399.0000 1.0000
47.6000 10166.0000 1.0000
47.6600 10383.0000 1.0000
47.7200 10188.0000 1.0000
47.7800 10166.0000 1.0000
47.8400 10336.0000 1.0000
47.9000 10426.0000 1.0000
47.9600 10212.0000 1.0000
48.0200 10159.0000 1.0000
48.0800 10212.0000 1.0000
48.1400 10268.0000 1.0000
48.2000 10182.0000 1.0000
48.2600 10311.0000 1.0000
48.3200 10461.0000 1.0000
48.3800 10284.0000 1.0000
48.4400 10450.0000 1.0000
48.5000 10415.0000 1.0000
48.5600 10304.0000 1.0000
48.6200 10157.0000 1.0000
48.6800 10146.0000 1.0000
48.7400 10415.0000 1.0000
48.8000 10383.0000 1.0000
48.8600 10242.0000 1.0000
48.9200 10264.0000 1.0000
48.9800 10404.0000 1.0000
49.0400 10409.0000 1.0000
49.1000 10189.0000 1.0000
49.1600 10648.0000 1.0000
49.2200 10617.0000 1.0000
49.2800 10859.0000 1.0000
49.3400 11661.0000 1.0000
49.4000 13190.0000 1.0000
49.4600 14821.0000 1.0000
49.5200 13214.0000 1.0000
49.5800 13150.0000 1.0000
49.6400 11700.0000 1.0000
49.7000 10819.0000 1.0000
49.7600 10580.0000 1.0000
49.8200 10441.0000 1.0000
49.8800 10552.0000 1.0000
49.9400 10417.0000 1.0000
50.0000 10687.0000 1.0000
50.0600 11381.0000 1.0000
50.1200 14256.0000 1.0000
50.1800 11718.0000 1.0000
50.2400 12239.0000 1.0000
50.3000 11156.0000 1.0000
50.3600 10503.0000 1.0000
50.4200 10305.0000 1.0000
50.4800 10340.0000 1.0000
50.5400 10340.0000 1.0000
50.6000 10376.0000 1.0000
50.6600 10175.0000 1.0000
50.7200 10375.0000 1.0000
50.7800 10448.0000 1.0000
50.8400 10220.0000 1.0000
50.9000 10268.0000 1.0000
50.9600 10148.0000 1.0000
51.0200 10098.0000 1.0000
51.0800 10282.0000 1.0000
51.1400 10099.0000 1.0000
51.2000 10327.0000 1.0000
51.2600 10157.0000 1.0000
51.3200 10236.0000 1.0000
51.3800 10135.0000 1.0000
51.4400 10289.0000 1.0000
51.5000 10108.0000 1.0000
51.5600 10302.0000 1.0000
51.6200 10244.0000 1.0000
51.6800 10381.0000 1.0000
51.7400 10253.0000 1.0000
51.8000 10275.0000 1.0000
51.8600 10466.0000 1.0000
51.9200 10254.0000 1.0000
51.9800 10092.0000 1.0000
52.0400 10249.0000 1.0000
52.1000 10293.0000 1.0000
52.1600 10054.0000 1.0000
52.2200 10317.0000 1.0000
52.2800 10291.0000 1.0000
52.3400 10396.0000 1.0000
52.4000 10424.0000 1.0000
52.4600 10558.0000 1.0000
52.5200 10856.0000 1.0000
52.5800 10675.0000 1.0000
52.6400 10583.0000 1.0000
52.7000 10468.0000 1.0000
52.7600 10461.0000 1.0000
52.8200 10392.0000 1.0000
52.8800 10456.0000 1.0000
52.9400 10289.0000 1.0000
53.0000 10272.0000 1.0000
53.0600 10191.0000 1.0000
53.1200 10317.0000 1.0000
53.1800 10297.0000 1.0000
53.2400 10122.0000 1.0000
53.3000 10426.0000 1.0000
53.3600 10585.0000 1.0000
53.4200 10646.0000 1.0000
53.4800 11094.0000 1.0000
53.5400 11032.0000 1.0000
53.6000 10981.0000 1.0000
53.6600 10701.0000 1.0000
53.7200 10719.0000 1.0000
53.7800 10608.0000 1.0000
53.8400 10816.0000 1.0000
53.9000 11042.0000 1.0000
53.9600 11889.0000 1.0000
54.0200 14662.0000 1.0000
54.0800 15525.0000 1.0000
54.1400 13294.0000 1.0000
54.2000 13703.0000 1.0000
54.2600 12127.0000 1.0000
54.3200 10901.0000 1.0000
54.3800 10617.0000 1.0000
54.4400 10421.0000 1.0000
54.5000 10384.0000 1.0000
54.5600 10392.0000 1.0000
54.6200 10440.0000 1.0000
54.6800 10391.0000 1.0000
54.7400 10512.0000 1.0000
54.8000 10870.0000 1.0000
54.8600 12412.0000 1.0000
54.9200 10910.0000 1.0000
54.9800 10978.0000 1.0000
55.0400 10937.0000 1.0000
55.1000 10375.0000 1.0000
55.1600 10289.0000 1.0000
55.2200 10358.0000 1.0000
55.2800 10361.0000 1.0000
55.3400 10678.0000 1.0000
55.4000 10332.0000 1.0000
55.4600 10422.0000 1.0000
55.5200 10138.0000 1.0000
55.5800 10137.0000 1.0000
55.6400 10399.0000 1.0000
55.7000 10373.0000 1.0000
55.7600 10399.0000 1.0000
55.8200 10399.0000 1.0000
55.8800 10183.0000 1.0000
55.9400 10392.0000 1.0000
56.0000 10319.0000 1.0000
56.0600 10325.0000 1.0000
56.1200 10248.0000 1.0000
56.1800 10198.0000 1.0000
56.2400 10265.0000 1.0000
56.3000 10193.0000 1.0000
56.3600 10274.0000 1.0000
56.4200 10348.0000 1.0000
56.4800 10214.0000 1.0000
56.5400 10136.0000 1.0000
56.6000 10152.0000 1.0000
56.6600 10307.0000 1.0000
56.7200 10347.0000 1.0000
56.7800 10381.0000 1.0000
56.8400 10647.0000 1.0000
56.9000 10849.0000 1.0000
56.9600 11777.0000 1.0000
57.0200 12582.0000 1.0000
57.0800 11962.0000 1.0000
57.1400 12152.0000 1.0000
57.2000 11950.0000 1.0000
57.2600 11195.0000 1.0000
57.3200 11106.0000 1.0000
57.3800 11483.0000 1.0000
57.4400 11937.0000 1.0000
57.5000 12147.0000 1.0000
57.5600 12002.0000 1.0000
57.6200 11803.0000 1.0000
57.6800 11284.0000 1.0000
57.7400 11115.0000 1.0000
57.8000 10819.0000 1.0000
57.8600 10725.0000 1.0000
57.9200 10460.0000 1.0000
57.9800 10462.0000 1.0000
58.0400 10379.0000 1.0000
58.1000 10331.0000 1.0000
58.1600 10229.0000 1.0000
58.2200 10157.0000 1.0000
58.2800 10271.0000 1.0000
58.3400 10206.0000 1.0000
58.4000 10213.0000 1.0000
58.4600 10397.0000 1.0000
58.5200 10234.0000 1.0000
58.5800 10224.0000 1.0000
58.6400 10362.0000 1.0000
58.7000 10326.0000 1.0000
58.7600 10275.0000 1.0000
58.8200 10315.0000 1.0000
58.8800 10274.0000 1.0000
58.9400 10318.0000 1.0000
59.0000 10287.0000 1.0000
59.0600 10202.0000 1.0000
59.1200 10361.0000 1.0000
59.1800 10362.0000 1.0000
59.2400 10235.0000 1.0000
59.3000 10339.0000 1.0000
59.3600 10333.0000 1.0000
59.4200 10393.0000 1.0000
59.4800 10399.0000 1.0000
59.5400 10131.0000 1.0000
59.6000 10239.0000 1.0000
59.6600 10435.0000 1.0000
59.7200 10419.0000 1.0000
59.7800 10501.0000 1.0000
59.8400 10813.0000 1.0000
59.9000 12360.0000 1.0000
59.9600 13517.0000 1.0000
60.0200 11029.0000 1.0000
60.0800 11856.0000 1.0000
60.1400 11458.0000 1.0000
60.2000 10458.0000 1.0000
60.2600 10586.0000 1.0000
60.3200 10274.0000 1.0000
60.3800 10330.0000 1.0000
60.4400 10379.0000 1.0000
60.5000 10432.0000 1.0000
60.5600 10475.0000 1.0000
60.6200 10247.0000 1.0000
60.6800 10453.0000 1.0000
60.7400 10355.0000 1.0000
60.8000 10212.0000 1.0000
60.8600 10250.0000 1.0000
60.9200 10381.0000 1.0000
60.9800 10368.0000 1.0000
61.0400 10488.0000 1.0000
61.1000 10267.0000 1.0000
61.1600 10254.0000 1.0000
61.2200 10511.0000 1.0000
61.2800 10466.0000 1.0000
61.3400 10273.0000 1.0000
61.4000 10201.0000 1.0000
61.4600 10358.0000 1.0000
61.5200 10301.0000 1.0000
61.5800 10233.0000 1.0000
61.6400 10306.0000 1.0000
61.7000 10261.0000 1.0000
61.7600 10285.0000 1.0000
61.8200 10478.0000 1.0000
61.8800 10287.0000 1.0000
61.9400 10422.0000 1.0000
62.0000 10332.0000 1.0000
62.0600 10265.0000 1.0000
62.1200 10542.0000 1.0000
62.1800 10597.0000 1.0000
62.2400 10908.0000 1.0000
62.3000 11320.0000 1.0000
62.3600 12516.0000 1.0000
62.4200 14140.0000 1.0000
62.4800 13235.0000 1.0000
62.5400 13746.0000 1.0000
62.6000 14938.0000 1.0000
62.6600 13731.0000 1.0000
62.7200 12759.0000 1.0000
62.7800 12700.0000 1.0000
62.8400 11702.0000 1.0000
62.9000 10951.0000 1.0000
62.9600 10795.0000 1.0000
63.0200 10578.0000 1.0000
63.0800 10458.0000 1.0000
63.1400 10496.0000 1.0000
63.2000 10440.0000 1.0000
63.2600 10331.0000 1.0000
63.3200 10412.0000 1.0000
63.3800 10258.0000 1.0000
63.4400 10355.0000 1.0000
63.5000 10241.0000 1.0000
63.5600 10455.0000 1.0000
63.6200 10271.0000 1.0000
63.6800 10563.0000 1.0000
63.7400 10659.0000 1.0000
63.8000 10758.0000 1.0000
63.8600 11186.0000 1.0000
63.9200 12363.0000 1.0000
63.9800 14133.0000 1.0000
64.0400 12996.0000 1.0000
64.1000 11850.0000 1.0000
64.1600 12513.0000 1.0000
64.2200 11546.0000 1.0000
64.2800 10683.0000 1.0000
64.3400 10540.0000 1.0000
64.4000 10331.0000 1.0000
64.4600 10526.0000 1.0000
64.5200 10461.0000 1.0000
64.5800 10400.0000 1.0000
64.6400 10319.0000 1.0000
64.7000 10407.0000 1.0000
64.7600 10336.0000 1.0000
64.8200 10364.0000 1.0000
64.8800 10185.0000 1.0000
64.9400 10267.0000 1.0000
65.0000 10346.0000 1.0000
65.0600 10350.0000 1.0000
65.1200 10168.0000 1.0000
65.1800 10294.0000 1.0000
65.2400 10250.0000 1.0000
65.3000 10254.0000 1.0000
65.3600 10177.0000 1.0000
65.4200 10340.0000 1.0000
65.4800 10191.0000 1.0000
65.5400 10046.0000 1.0000
65.6000 10060.0000 1.0000
65.6600 10420.0000 1.0000
65.7200 10318.0000 1.0000
65.7800 10576.0000 1.0000
65.8400 10423.0000 1.0000
65.9000 10242.0000 1.0000
65.9600 10402.0000 1.0000
66.0200 10462.0000 1.0000
66.0800 10351.0000 1.0000
66.1400 10428.0000 1.0000
66.2000 10215.0000 1.0000
66.2600 10190.0000 1.0000
66.3200 10420.0000 1.0000
66.3800 10407.0000 1.0000
66.4400 10752.0000 1.0000
66.5000 10779.0000 1.0000
66.5600 10685.0000 1.0000
66.6200 10498.0000 1.0000
66.6800 10758.0000 1.0000
66.7400 10330.0000 1.0000
66.8000 10383.0000 1.0000
66.8600 10099.0000 1.0000
66.9200 10356.0000 1.0000
66.9800 10456.0000 1.0000
67.0400 10374.0000 1.0000
67.1000 10274.0000 1.0000
67.1600 10207.0000 1.0000
67.2200 10453.0000 1.0000
67.2800 10409.0000 1.0000
67.3400 10365.0000 1.0000
67.4000 10386.0000 1.0000
67.4600 10307.0000 1.0000
67.5200 10340.0000 1.0000
67.5800 10786.0000 1.0000
67.6400 10809.0000 1.0000
67.7000 12095.0000 1.0000
67.7600 11612.0000 1.0000
67.8200 10648.0000 1.0000
67.8800 11240.0000 1.0000
67.9400 11486.0000 1.0000
68.0000 10770.0000 1.0000
68.0600 11245.0000 1.0000
68.1200 13432.0000 1.0000
68.1800 11927.0000 1.0000
68.2400 12224.0000 1.0000
68.3000 13931.0000 1.0000
68.3600 11842.0000 1.0000
68.4200 11560.0000 1.0000
68.4800 11491.0000 1.0000
68.5400 10704.0000 1.0000
68.6000 10253.0000 1.0000
68.6600 10413.0000 1.0000
68.7200 10345.0000 1.0000
68.7800 10222.0000 1.0000
68.8400 10386.0000 1.0000
68.9000 10372.0000 1.0000
68.9600 10208.0000 1.0000
69.0200 10327.0000 1.0000
69.0800 10448.0000 1.0000
69.1400 10436.0000 1.0000
69.2000 10352.0000 1.0000
69.2600 10182.0000 1.0000
69.3200 10251.0000 1.0000
69.3800 10387.0000 1.0000
69.4400 10190.0000 1.0000
69.5000 10395.0000 1.0000
69.5600 10695.0000 1.0000
69.6200 10587.0000 1.0000
69.6800 10418.0000 1.0000
69.7400 10620.0000 1.0000
69.8000 10570.0000 1.0000
69.8600 10289.0000 1.0000
69.9200 10317.0000 1.0000
69.9800 10275.0000 1.0000
70.0400 10234.0000 1.0000
70.1000 10390.0000 1.0000
70.1600 10428.0000 1.0000
70.2200 10411.0000 1.0000
70.2800 10305.0000 1.0000
70.3400 10313.0000 1.0000
70.4000 10337.0000 1.0000
70.4600 10314.0000 1.0000
70.5200 10120.0000 1.0000
70.5800 10341.0000 1.0000
70.6400 10378.0000 1.0000
70.7000 10443.0000 1.0000
70.7600 10113.0000 1.0000
70.8200 10204.0000 1.0000
70.8800 10304.0000 1.0000
70.9400 10260.0000 1.0000
71.0000 10500.0000 1.0000
71.0600 10529.0000 1.0000
71.1200 10606.0000 1.0000
71.1800 10462.0000 1.0000
71.2400 10621.0000 1.0000
71.3000 10409.0000 1.0000
71.3600 10528.0000 1.0000
71.4200 10440.0000 1.0000
71.4800 10364.0000 1.0000
71.5400 10340.0000 1.0000
71.6000 10557.0000 1.0000
71.6600 10453.0000 1.0000
71.7200 10379.0000 1.0000
71.7800 10647.0000 1.0000
71.8400 10716.0000 1.0000
71.9000 11164.0000 1.0000
71.9600 11320.0000 1.0000
72.0200 10583.0000 1.0000
72.0800 10805.0000 1.0000
72.1400 10926.0000 1.0000
72.2000 10576.0000 1.0000
72.2600 10594.0000 1.0000
72.3200 10696.0000 1.0000
72.3800 10449.0000 1.0000
72.4400 10208.0000 1.0000
72.5000 10505.0000 1.0000
72.5600 10301.0000 1.0000
72.6200 10424.0000 1.0000
72.6800 10300.0000 1.0000
72.7400 10455.0000 1.0000
72.8000 10310.0000 1.0000
72.8600 10251.0000 1.0000
72.9200 10273.0000 1.0000
72.9800 10235.0000 1.0000
73.0400 10228.0000 1.0000
73.1000 10423.0000 1.0000
73.1600 10241.0000 1.0000
73.2200 10267.0000 1.0000
73.2800 10443.0000 1.0000
73.3400 10307.0000 1.0000
73.4000 10645.0000 1.0000
73.4600 10714.0000 1.0000
73.5200 10584.0000 1.0000
73.5800 10661.0000 1.0000
73.6400 10571.0000 1.0000
73.7000 10306.0000 1.0000
73.7600 10277.0000 1.0000
73.8200 10435.0000 1.0000
73.8800 10562.0000 1.0000
73.9400 10497.0000 1.0000
74.0000 10612.0000 1.0000
74.0600 10759.0000 1.0000
74.1200 10652.0000 1.0000
74.1800 10572.0000 1.0000
74.2400 10665.0000 1.0000
74.3000 10752.0000 1.0000
74.3600 10532.0000 1.0000
74.4200 10447.0000 1.0000
74.4800 10533.0000 1.0000
74.5400 10499.0000 1.0000
74.6000 10367.0000 1.0000
74.6600 10348.0000 1.0000
74.7200 10339.0000 1.0000
74.7800 10528.0000 1.0000
74.8400 10352.0000 1.0000
74.9000 10362.0000 1.0000
74.9600 10383.0000 1.0000
75.0200 10364.0000 1.0000
75.0800 10479.0000 1.0000
75.1400 10499.0000 1.0000
75.2000 10603.0000 1.0000
75.2600 10628.0000 1.0000
75.3200 10677.0000 1.0000
75.3800 10763.0000 1.0000
75.4400 11410.0000 1.0000
75.5000 10968.0000 1.0000
75.5600 10988.0000 1.0000
75.6200 11667.0000 1.0000
75.6800 11264.0000 1.0000
75.7400 10876.0000 1.0000
75.8000 10729.0000 1.0000
75.8600 10919.0000 1.0000
75.9200 10599.0000 1.0000
75.9800 10518.0000 1.0000
76.0400 10361.0000 1.0000
76.1000 10463.0000 1.0000
76.1600 10413.0000 1.0000
76.2200 10499.0000 1.0000
76.2800 10533.0000 1.0000
76.3400 10266.0000 1.0000
76.4000 10208.0000 1.0000
76.4600 10478.0000 1.0000
76.5200 10489.0000 1.0000
76.5800 10372.0000 1.0000
76.6400 10412.0000 1.0000
76.7000 10569.0000 1.0000
76.7600 10611.0000 1.0000
76.8200 10657.0000 1.0000
76.8800 10641.0000 1.0000
76.9400 10547.0000 1.0000
77.0000 10387.0000 1.0000
77.0600 10627.0000 1.0000
77.1200 10562.0000 1.0000
77.1800 10592.0000 1.0000
77.2400 10587.0000 1.0000
77.3000 10498.0000 1.0000
77.3600 10542.0000 1.0000
77.4200 10680.0000 1.0000
77.4800 10567.0000 1.0000
77.5400 10538.0000 1.0000
77.6000 10795.0000 1.0000
77.6600 10969.0000 1.0000
77.7200 10699.0000 1.0000
77.7800 10670.0000 1.0000
77.8400 10681.0000 1.0000
77.9000 10680.0000 1.0000
77.9600 10486.0000 1.0000
78.0200 10514.0000 1.0000
78.0800 10320.0000 1.0000
78.1400 10446.0000 1.0000
78.2000 10389.0000 1.0000
78.2600 10386.0000 1.0000
78.3200 10350.0000 1.0000
78.3800 10455.0000 1.0000
78.4400 10440.0000 1.0000
78.5000 10402.0000 1.0000
78.5600 10217.0000 1.0000
78.6200 10453.0000 1.0000
78.6800 10455.0000 1.0000
78.7400 10429.0000 1.0000
78.8000 10941.0000 1.0000
78.8600 10428.0000 1.0000
78.9200 10445.0000 1.0000
78.9800 10438.0000 1.0000
79.0400 10591.0000 1.0000
79.1000 10692.0000 1.0000
79.1600 10544.0000 1.0000
79.2200 10445.0000 1.0000
79.2800 10640.0000 1.0000
79.3400 10492.0000 1.0000
79.4000 10436.0000 1.0000
79.4600 10477.0000 1.0000
79.5200 10556.0000 1.0000
79.5800 10432.0000 1.0000
79.6400 10476.0000 1.0000
79.7000 10619.0000 1.0000
79.7600 10551.0000 1.0000
79.8200 10912.0000 1.0000
79.8800 11273.0000 1.0000
79.9400 10634.0000 1.0000
80.0000 10764.0000 1.0000
80.0600 10810.0000 1.0000
80.1200 10953.0000 1.0000
80.1800 10526.0000 1.0000
80.2400 10538.0000 1.0000
80.3000 10590.0000 1.0000
80.3600 10497.0000 1.0000
80.4200 10316.0000 1.0000
80.4800 10596.0000 1.0000
80.5400 10748.0000 1.0000
80.6000 10951.0000 1.0000
80.6600 11060.0000 1.0000
80.7200 10990.0000 1.0000
80.7800 10719.0000 1.0000
80.8400 10780.0000 1.0000
80.9000 10708.0000 1.0000
80.9600 10831.0000 1.0000
81.0200 10789.0000 1.0000
81.0800 10636.0000 1.0000
81.1400 11179.0000 1.0000
81.2000 10740.0000 1.0000
81.2600 10496.0000 1.0000
81.3200 10673.0000 1.0000
81.3800 10846.0000 1.0000
81.4400 11239.0000 1.0000
81.5000 10880.0000 1.0000
81.5600 10583.0000 1.0000
81.6200 10524.0000 1.0000
81.6800 10761.0000 1.0000
81.7400 10669.0000 1.0000
81.8000 10532.0000 1.0000
81.8600 10545.0000 1.0000
81.9200 10489.0000 1.0000
81.9800 10574.0000 1.0000
82.0400 10511.0000 1.0000
82.1000 10487.0000 1.0000
82.1600 10446.0000 1.0000
82.2200 10492.0000 1.0000
82.2800 10318.0000 1.0000
82.3400 10508.0000 1.0000
82.4000 10637.0000 1.0000
82.4600 10416.0000 1.0000
82.5200 10395.0000 1.0000
82.5800 10344.0000 1.0000
82.6400 10419.0000 1.0000
82.7000 10289.0000 1.0000
82.7600 10509.0000 1.0000
82.8200 10650.0000 1.0000
82.8800 10629.0000 1.0000
82.9400 11005.0000 1.0000
83.0000 10830.0000 1.0000
83.0600 10583.0000 1.0000
83.1200 10423.0000 1.0000
83.1800 10392.0000 1.0000
83.2400 10705.0000 1.0000
83.3000 10500.0000 1.0000
83.3600 10291.0000 1.0000
83.4200 10438.0000 1.0000
83.4800 10334.0000 1.0000
83.5400 10180.0000 1.0000
83.6000 10472.0000 1.0000
83.6600 10392.0000 1.0000
83.7200 10534.0000 1.0000
83.7800 10931.0000 1.0000
83.8400 11058.0000 1.0000
83.9000 10581.0000 1.0000
83.9600 10274.0000 1.0000
84.0200 10571.0000 1.0000
84.0800 10736.0000 1.0000
84.1400 10504.0000 1.0000
84.2000 10396.0000 1.0000
84.2600 10243.0000 1.0000
84.3200 10369.0000 1.0000
84.3800 10408.0000 1.0000
84.4400 10537.0000 1.0000
84.5000 10264.0000 1.0000
84.5600 10374.0000 1.0000
84.6200 10430.0000 1.0000
84.6800 10475.0000 1.0000
84.7400 10518.0000 1.0000
84.8000 10518.0000 1.0000
84.8600 10793.0000 1.0000
84.9200 11274.0000 1.0000
84.9800 10827.0000 1.0000
85.0400 10554.0000 1.0000
85.1000 10774.0000 1.0000
85.1600 10810.0000 1.0000
85.2200 10632.0000 1.0000
85.2800 10553.0000 1.0000
85.3400 10340.0000 1.0000
85.4000 10445.0000 1.0000
85.4600 10222.0000 1.0000
85.5200 10435.0000 1.0000
85.5800 10349.0000 1.0000
85.6400 10238.0000 1.0000
85.7000 10404.0000 1.0000
85.7600 10299.0000 1.0000
85.8200 10310.0000 1.0000
85.8800 10396.0000 1.0000
85.9400 10321.0000 1.0000
86.0000 10277.0000 1.0000
86.0600 10444.0000 1.0000
86.1200 10424.0000 1.0000
86.1800 10316.0000 1.0000
86.2400 10405.0000 1.0000
86.3000 10403.0000 1.0000
86.3600 10382.0000 1.0000
86.4200 10337.0000 1.0000
86.4800 10444.0000 1.0000
86.5400 10308.0000 1.0000
86.6000 10343.0000 1.0000
86.6600 10532.0000 1.0000
86.7200 10480.0000 1.0000
86.7800 10426.0000 1.0000
86.8400 10600.0000 1.0000
86.9000 10673.0000 1.0000
86.9600 10285.0000 1.0000
87.0200 10466.0000 1.0000
87.0800 10433.0000 1.0000
87.1400 10351.0000 1.0000
87.2000 10398.0000 1.0000
87.2600 10326.0000 1.0000
87.3200 10338.0000 1.0000
87.3800 10443.0000 1.0000
87.4400 10433.0000 1.0000
87.5000 10201.0000 1.0000
87.5600 10295.0000 1.0000
87.6200 10447.0000 1.0000
87.6800 10381.0000 1.0000
87.7400 10141.0000 1.0000
87.8000 10402.0000 1.0000
87.8600 10524.0000 1.0000
87.9200 10324.0000 1.0000
87.9800 10235.0000 1.0000
88.0400 10310.0000 1.0000
88.1000 10343.0000 1.0000
88.1600 10552.0000 1.0000
88.2200 10493.0000 1.0000
88.2800 10384.0000 1.0000
88.3400 10483.0000 1.0000
88.4000 10377.0000 1.0000
88.4600 10539.0000 1.0000
88.5200 11070.0000 1.0000
88.5800 11077.0000 1.0000
88.6400 10866.0000 1.0000
88.7000 10678.0000 1.0000
88.7600 10741.0000 1.0000
88.8200 10674.0000 1.0000
88.8800 10609.0000 1.0000
88.9400 10591.0000 1.0000
89.0000 10595.0000 1.0000
89.0600 10480.0000 1.0000
89.1200 10390.0000 1.0000
89.1800 10156.0000 1.0000
89.2400 10525.0000 1.0000
89.3000 10287.0000 1.0000
89.3600 10486.0000 1.0000
89.4200 10469.0000 1.0000
89.4800 10516.0000 1.0000
89.5400 10555.0000 1.0000
89.6000 10796.0000 1.0000
89.6600 10745.0000 1.0000
89.7200 10954.0000 1.0000
89.7800 10879.0000 1.0000
89.8400 10838.0000 1.0000
89.9000 10861.0000 1.0000
89.9600 10737.0000 1.0000
90.0000 10871.0000 1.0000
*RAS_INT_END
*RAS_TEMPERATURE_START
*RAS_TEMPERATURE_END
*RAS_DATA_END