File: XRD/Data/20200819_mix_03.ras
*RAS_DATA_START
*RAS_HEADER_START
*DISP_FMT_X "%.2f"
*DISP_FMT_Y "%.0f"
*DISP_FULLSCALE "99759.0000000000"
*DISP_LINE_COLOR "255.0000000000"
*DISP_LINE_STYLE "0.0000000000"
*DISP_LINE_WIDTH "0.2500000000"
*DISP_NOTE "測定データ-4"
*DISP_OFFSET_Y "0.0000000000"
*DISP_PEAKSEARCH_UNIT_Y "cps"
*DISP_RANGE_BOTTOM "0.0000000000"
*DISP_RANGE_LEFT "20.0000000000"
*DISP_RANGE_LOGCUTOFF "0.0100000000"
*DISP_RANGE_RIGHT "90.0000000000"
*DISP_RANGE_TOP "99759.0000000000"
*DISP_SCALE_MODE_Y "0.0000000000"
*DISP_TAB_NAME "2θ/θ"
*DISP_TITLE_Y "強度"
*DISP_UNIT_Y "cps"
*DISP_WINDOW_NAME "MSG_MACROENGINE"
*FILE_COMMENT " "
*FILE_MD5 ""
*FILE_MEMO " "
*FILE_OPERATOR "Administrator"
*FILE_SAMPLE " "
*FILE_TYPE "RAS_RAW"
*FILE_USERGROUP "システムマネージャ"
*FILE_VERSION "1.0000000000"
*HW_ATTACHMENT_ID "ATT0025"
*HW_ATTACHMENT_NAME "標準|Standard"
*HW_COUNTER_ID-0 "CUT0025"
*HW_COUNTER_ID-1 "CUT0020"
*HW_COUNTER_ID-2 "CUT0020"
*HW_COUNTER_ID-3 "CSL0021"
*HW_COUNTER_ID-4 "CMC0021"
*HW_COUNTER_NAME-0 "D/teX Ultra|D/teX Ultra"
*HW_COUNTER_NAME-1 "None|None"
*HW_COUNTER_NAME-2 "None|None"
*HW_COUNTER_NAME-3 "BBM|BBM"
*HW_COUNTER_NAME-4 "検出器モノクロメータ|Detector monochromator"
*HW_COUNTER_SELECT_NAME "D/teX Ultra|D/teX Ultra"
*HW_GONIOMETER_ID "GON0023"
*HW_GONIOMETER_NAME "SmartLab|SmartLab"
*HW_GONIOMETER_RADIUS-0 "90.0"
*HW_GONIOMETER_RADIUS-1 "114.0"
*HW_GONIOMETER_RADIUS-2 "190.0"
*HW_GONIOMETER_RADIUS-3 "300.0"
*HW_GONIOMETER_RADIUS-4 "187.0"
*HW_GONIOMETER_RADIUS-5 "300.0"
*HW_GONIOMETER_RADIUS-6 "113.0"
*HW_GONIOMETER_RADIUS-7 "331.0"
*HW_I_OPT_ID-0 "CBO0021"
*HW_I_OPT_ID-1 "ICR0023"
*HW_I_OPT_ID-2 "ISL0021"
*HW_I_OPT_ID-3 "ISO0021"
*HW_I_OPT_ID-4 "IAD0021"
*HW_I_OPT_ID-5 "IPR0001"
*HW_I_OPT_NAME-0 "CBOユニット|CBO unit"
*HW_I_OPT_NAME-1 "標準入射光学ユニット|Standard incident optical unit"
*HW_I_OPT_NAME-2 "標準入射スリットボックス|Standard incident slit box"
*HW_I_OPT_NAME-3 "入射平行スリット|Incident parallel slit"
*HW_I_OPT_NAME-4 "長手制限スリット|Length limiting slit"
*HW_I_OPT_NAME-5 "None|None"
*HW_R_ATTENUATER_AUTOMODE "0"
*HW_R_OPT_ID-0 "RSS0021"
*HW_R_OPT_ID-1 "RCR0023"
*HW_R_OPT_ID-2 "RSO0021"
*HW_R_OPT_ID-3 "RRS0021"
*HW_R_OPT_ID-4 "ATN0021"
*HW_R_OPT_ID-5 "RFL0021"
*HW_R_OPT_ID-6 "RAD0021"
*HW_R_OPT_NAME-0 "標準受光スリットボックス1|Standard receiving slit box # 1"
*HW_R_OPT_NAME-1 "標準受光光学ユニット1|Standard receiving unit # 1"
*HW_R_OPT_NAME-2 "標準受光光学ユニット2|Standard receiving optical unit # 2"
*HW_R_OPT_NAME-3 "標準受光スリットボックス2|Standard receiving slit box # 2"
*HW_R_OPT_NAME-4 "標準アッテネータ|Standard Attenuator"
*HW_R_OPT_NAME-5 "Cu Kβ|Cu K-beta"
*HW_R_OPT_NAME-6 "調整用受光スリット|Alignment receiving slit"
*HW_SAMPLE_HOLDER_ID "SMP0023"
*HW_SAMPLE_HOLDER_NAME "標準Zステージ|Standard Z stage"
*HW_XG_CURRENT_MAX "50"
*HW_XG_CURRENT_MIN "2"
*HW_XG_CURRENT_RESOLUTION "2"
*HW_XG_CURRENT_UNIT "mA"
*HW_XG_FOCUS "1mm x 10mm"
*HW_XG_FOCUS_TYPE "Normal"
*HW_XG_ID ""
*HW_XG_NAME "3kW 封入管(ID:1200)|3kW Sealed tube(ID:1200)"
*HW_XG_TARGET_ATOMIC_NUMBER "29.0000000000"
*HW_XG_TARGET_NAME "Cu"
*HW_XG_TYPE "Hermetic"
*HW_XG_VOLTAGE_MAX "60"
*HW_XG_VOLTAGE_MIN "20"
*HW_XG_VOLTAGE_RESOLUTION "2"
*HW_XG_VOLTAGE_UNIT "kV"
*HW_XG_WATT_MAX "2"
*HW_XG_WATT_UNIT "kW"
*HW_XG_WAVE_LENGTH_ALPHA1 "1.540593"
*HW_XG_WAVE_LENGTH_ALPHA2 "1.544414"
*HW_XG_WAVE_LENGTH_BETA "1.392250"
*MEAS_COND_AXIS_NAME-0 "2θ/θ"
*MEAS_COND_AXIS_NAME-1 "2θ"
*MEAS_COND_AXIS_NAME-2 "ω"
*MEAS_COND_AXIS_NAME-3 "Z"
*MEAS_COND_AXIS_NAME-4 "2θ/ω"
*MEAS_COND_AXIS_NAME-5 "θs"
*MEAS_COND_AXIS_NAME-6 "θd"
*MEAS_COND_AXIS_NAME-7 "Ts"
*MEAS_COND_AXIS_NAME-8 "CBO選択スリット"
*MEAS_COND_AXIS_NAME-9 "M"
*MEAS_COND_AXIS_NAME-10 "入射平行スリット"
*MEAS_COND_AXIS_NAME-11 "入射スリット"
*MEAS_COND_AXIS_NAME-12 ""
*MEAS_COND_AXIS_NAME-13 "Zs"
*MEAS_COND_AXIS_NAME-14 "入射光学素子"
*MEAS_COND_AXIS_NAME-15 "長手制限スリット"
*MEAS_COND_AXIS_NAME-16 "センタースリット"
*MEAS_COND_AXIS_NAME-17 "フィルター"
*MEAS_COND_AXIS_NAME-18 "受光スリット1"
*MEAS_COND_AXIS_NAME-19 "受光スリット2"
*MEAS_COND_AXIS_NAME-20 "受光光学素子"
*MEAS_COND_AXIS_NAME-21 "受光平行スリット"
*MEAS_COND_AXIS_NAME-22 "調整用受光スリット"
*MEAS_COND_AXIS_NAME-23 ""
*MEAS_COND_AXIS_NAME-24 ""
*MEAS_COND_AXIS_NAME-25 "Zd"
*MEAS_COND_AXIS_NAME-26 "アッテネータ"
*MEAS_COND_AXIS_NAME-27 "検出器モノクロメータ"
*MEAS_COND_AXIS_NAME-28 "モノクロメータスリット"
*MEAS_COND_AXIS_NAME-29 "プライマリビーム"
*MEAS_COND_AXIS_NAME-30 "PHA"
*MEAS_COND_AXIS_NAME_INTERNAL-0 "TwoThetaTheta"
*MEAS_COND_AXIS_NAME_INTERNAL-1 "TwoTheta"
*MEAS_COND_AXIS_NAME_INTERNAL-2 "Omega"
*MEAS_COND_AXIS_NAME_INTERNAL-3 "Z"
*MEAS_COND_AXIS_NAME_INTERNAL-4 "TwoThetaOmega"
*MEAS_COND_AXIS_NAME_INTERNAL-5 "ThetaS"
*MEAS_COND_AXIS_NAME_INTERNAL-6 "ThetaD"
*MEAS_COND_AXIS_NAME_INTERNAL-7 "Ts"
*MEAS_COND_AXIS_NAME_INTERNAL-8 "CBO"
*MEAS_COND_AXIS_NAME_INTERNAL-9 "CBO-M"
*MEAS_COND_AXIS_NAME_INTERNAL-10 "IncidentSollerSlit"
*MEAS_COND_AXIS_NAME_INTERNAL-11 "IncidentSlitBox"
*MEAS_COND_AXIS_NAME_INTERNAL-12 "IncidentSlitBox-_Axis"
*MEAS_COND_AXIS_NAME_INTERNAL-13 "Zs"
*MEAS_COND_AXIS_NAME_INTERNAL-14 "IncidentMonochromator"
*MEAS_COND_AXIS_NAME_INTERNAL-15 "IncidentAxdSlit"
*MEAS_COND_AXIS_NAME_INTERNAL-16 "CenterSlit"
*MEAS_COND_AXIS_NAME_INTERNAL-17 "Filter"
*MEAS_COND_AXIS_NAME_INTERNAL-18 "ReceivingSlitBox1"
*MEAS_COND_AXIS_NAME_INTERNAL-19 "ReceivingSlitBox2"
*MEAS_COND_AXIS_NAME_INTERNAL-20 "ReceivingOptics"
*MEAS_COND_AXIS_NAME_INTERNAL-21 "ReceivingSollerSlit"
*MEAS_COND_AXIS_NAME_INTERNAL-22 "ReceivingAxdSlit"
*MEAS_COND_AXIS_NAME_INTERNAL-23 "ReceivingSlitBox1-_Axis"
*MEAS_COND_AXIS_NAME_INTERNAL-24 "ReceivingSlitBox2-_Axis"
*MEAS_COND_AXIS_NAME_INTERNAL-25 "ReceivingSlitBox2-Zd"
*MEAS_COND_AXIS_NAME_INTERNAL-26 "Attenuator"
*MEAS_COND_AXIS_NAME_INTERNAL-27 "CounterMonochromator"
*MEAS_COND_AXIS_NAME_INTERNAL-28 "CounterSlit"
*MEAS_COND_AXIS_NAME_INTERNAL-29 "IncidentPrimary"
*MEAS_COND_AXIS_NAME_INTERNAL-30 "PHA"
*MEAS_COND_AXIS_NAME_MAGICNO-0 "83951616.0000000000"
*MEAS_COND_AXIS_NAME_MAGICNO-1 "268632064.0000000000"
*MEAS_COND_AXIS_NAME_MAGICNO-2 "268500992.0000000000"
*MEAS_COND_AXIS_NAME_MAGICNO-3 "285278208.0000000000"
*MEAS_COND_AXIS_NAME_MAGICNO-4 "83951616.0000000000"
*MEAS_COND_AXIS_NAME_MAGICNO-5 "131072.0000000000"
*MEAS_COND_AXIS_NAME_MAGICNO-6 "131072.0000000000"
*MEAS_COND_AXIS_NAME_MAGICNO-7 "318898176.0000000000"
*MEAS_COND_AXIS_NAME_MAGICNO-8 "20971521.0000000000"
*MEAS_COND_AXIS_NAME_MAGICNO-9 "285343744.0000000000"
*MEAS_COND_AXIS_NAME_MAGICNO-10 "20971521.0000000000"
*MEAS_COND_AXIS_NAME_MAGICNO-11 "22020097.0000000000"
*MEAS_COND_AXIS_NAME_MAGICNO-12 "25165824.0000000000"
*MEAS_COND_AXIS_NAME_MAGICNO-13 "318898176.0000000000"
*MEAS_COND_AXIS_NAME_MAGICNO-14 "1.0000000000"
*MEAS_COND_AXIS_NAME_MAGICNO-15 "20971521.0000000000"
*MEAS_COND_AXIS_NAME_MAGICNO-16 "20971521.0000000000"
*MEAS_COND_AXIS_NAME_MAGICNO-17 "20971521.0000000000"
*MEAS_COND_AXIS_NAME_MAGICNO-18 "23068673.0000000000"
*MEAS_COND_AXIS_NAME_MAGICNO-19 "23068673.0000000000"
*MEAS_COND_AXIS_NAME_MAGICNO-20 "20971521.0000000000"
*MEAS_COND_AXIS_NAME_MAGICNO-21 "20971521.0000000000"
*MEAS_COND_AXIS_NAME_MAGICNO-22 "20971521.0000000000"
*MEAS_COND_AXIS_NAME_MAGICNO-23 "25165824.0000000000"
*MEAS_COND_AXIS_NAME_MAGICNO-24 "25165824.0000000000"
*MEAS_COND_AXIS_NAME_MAGICNO-25 "285343744.0000000000"
*MEAS_COND_AXIS_NAME_MAGICNO-26 "17301505.0000000000"
*MEAS_COND_AXIS_NAME_MAGICNO-27 "20971521.0000000000"
*MEAS_COND_AXIS_NAME_MAGICNO-28 "20971521.0000000000"
*MEAS_COND_AXIS_NAME_MAGICNO-29 "20971521.0000000000"
*MEAS_COND_AXIS_NAME_MAGICNO-30 "0.0000000000"
*MEAS_COND_AXIS_OFFSET-0 "-"
*MEAS_COND_AXIS_OFFSET-1 "-0.1081000000"
*MEAS_COND_AXIS_OFFSET-2 "0.3758000000"
*MEAS_COND_AXIS_OFFSET-3 "-"
*MEAS_COND_AXIS_OFFSET-4 "-"
*MEAS_COND_AXIS_OFFSET-5 "0.3758000000"
*MEAS_COND_AXIS_OFFSET-6 "-0.4839000000"
*MEAS_COND_AXIS_OFFSET-7 "-"
*MEAS_COND_AXIS_OFFSET-8 "-"
*MEAS_COND_AXIS_OFFSET-9 "-"
*MEAS_COND_AXIS_OFFSET-10 "-"
*MEAS_COND_AXIS_OFFSET-11 "-"
*MEAS_COND_AXIS_OFFSET-12 "-"
*MEAS_COND_AXIS_OFFSET-13 "-"
*MEAS_COND_AXIS_OFFSET-14 "-"
*MEAS_COND_AXIS_OFFSET-15 "-"
*MEAS_COND_AXIS_OFFSET-16 "-"
*MEAS_COND_AXIS_OFFSET-17 "-"
*MEAS_COND_AXIS_OFFSET-18 "-"
*MEAS_COND_AXIS_OFFSET-19 "-"
*MEAS_COND_AXIS_OFFSET-20 "-"
*MEAS_COND_AXIS_OFFSET-21 "-"
*MEAS_COND_AXIS_OFFSET-22 "-"
*MEAS_COND_AXIS_OFFSET-23 "-"
*MEAS_COND_AXIS_OFFSET-24 "-"
*MEAS_COND_AXIS_OFFSET-25 "-"
*MEAS_COND_AXIS_OFFSET-26 "-"
*MEAS_COND_AXIS_OFFSET-27 "-"
*MEAS_COND_AXIS_OFFSET-28 "-"
*MEAS_COND_AXIS_OFFSET-29 "-"
*MEAS_COND_AXIS_OFFSET-30 "-"
*MEAS_COND_AXIS_POSITION-0 "0.0000000000"
*MEAS_COND_AXIS_POSITION-1 "0.0000000000"
*MEAS_COND_AXIS_POSITION-2 "0.0000000000"
*MEAS_COND_AXIS_POSITION-3 "-0.5500000000"
*MEAS_COND_AXIS_POSITION-4 "0.0000000000"
*MEAS_COND_AXIS_POSITION-5 "0.0000000000"
*MEAS_COND_AXIS_POSITION-6 "0.0000000000"
*MEAS_COND_AXIS_POSITION-7 "-0.4278800000"
*MEAS_COND_AXIS_POSITION-8 "BB"
*MEAS_COND_AXIS_POSITION-9 "0.0000000000"
*MEAS_COND_AXIS_POSITION-10 "Soller_slit_5.0deg"
*MEAS_COND_AXIS_POSITION-11 "2/3deg"
*MEAS_COND_AXIS_POSITION-12 "2.2088000000"
*MEAS_COND_AXIS_POSITION-13 "-0.4140600000"
*MEAS_COND_AXIS_POSITION-14 "0.0000000000"
*MEAS_COND_AXIS_POSITION-15 "10.0mm"
*MEAS_COND_AXIS_POSITION-16 "None"
*MEAS_COND_AXIS_POSITION-17 "Cu_K-beta"
*MEAS_COND_AXIS_POSITION-18 "13.000mm"
*MEAS_COND_AXIS_POSITION-19 "13.000mm"
*MEAS_COND_AXIS_POSITION-20 "No_unit"
*MEAS_COND_AXIS_POSITION-21 "Soller_slit_5.0deg"
*MEAS_COND_AXIS_POSITION-22 "None"
*MEAS_COND_AXIS_POSITION-23 "13.0000000000"
*MEAS_COND_AXIS_POSITION-24 "13.0000000000"
*MEAS_COND_AXIS_POSITION-25 "0.0109400000"
*MEAS_COND_AXIS_POSITION-26 "Open"
*MEAS_COND_AXIS_POSITION-27 "None"
*MEAS_COND_AXIS_POSITION-28 "None"
*MEAS_COND_AXIS_POSITION-29 "None"
*MEAS_COND_AXIS_POSITION-30 "38.0000000000"
*MEAS_COND_AXIS_UNIT-0 "deg"
*MEAS_COND_AXIS_UNIT-1 "deg"
*MEAS_COND_AXIS_UNIT-2 "deg"
*MEAS_COND_AXIS_UNIT-3 "mm"
*MEAS_COND_AXIS_UNIT-4 "deg"
*MEAS_COND_AXIS_UNIT-5 "deg"
*MEAS_COND_AXIS_UNIT-6 "deg"
*MEAS_COND_AXIS_UNIT-7 "mm"
*MEAS_COND_AXIS_UNIT-8 ""
*MEAS_COND_AXIS_UNIT-9 "pulse"
*MEAS_COND_AXIS_UNIT-10 ""
*MEAS_COND_AXIS_UNIT-11 ""
*MEAS_COND_AXIS_UNIT-12 "mm"
*MEAS_COND_AXIS_UNIT-13 "mm"
*MEAS_COND_AXIS_UNIT-14 ""
*MEAS_COND_AXIS_UNIT-15 ""
*MEAS_COND_AXIS_UNIT-16 ""
*MEAS_COND_AXIS_UNIT-17 ""
*MEAS_COND_AXIS_UNIT-18 ""
*MEAS_COND_AXIS_UNIT-19 ""
*MEAS_COND_AXIS_UNIT-20 ""
*MEAS_COND_AXIS_UNIT-21 ""
*MEAS_COND_AXIS_UNIT-22 ""
*MEAS_COND_AXIS_UNIT-23 "mm"
*MEAS_COND_AXIS_UNIT-24 "mm"
*MEAS_COND_AXIS_UNIT-25 "mm"
*MEAS_COND_AXIS_UNIT-26 ""
*MEAS_COND_AXIS_UNIT-27 ""
*MEAS_COND_AXIS_UNIT-28 ""
*MEAS_COND_AXIS_UNIT-29 ""
*MEAS_COND_AXIS_UNIT-30 "div"
*MEAS_COND_COUNTER_CNTLOSS_CORR "0.0000000000"
*MEAS_COND_COUNTER_PHABASE "38.0000000000"
*MEAS_COND_COUNTER_PHAWINDOW "16.0000000000"
*MEAS_COND_COUNTER_PHA_UNIT "div"
*MEAS_COND_COUNTER_TAUDIFF "30.0000000000"
*MEAS_COND_COUNTER_TAUINT "0.0000000000"
*MEAS_COND_IRRADIATION_MODE "OFF"
*MEAS_COND_IRRADIATION_WIDTH ""
*MEAS_COND_OPT_ATTR "集中法"
*MEAS_COND_OPT_NAME "@集中法"
*MEAS_COND_UNSYMMETRIC_MODE "OFF"
*MEAS_COND_XG_CURRENT "30.0000000000"
*MEAS_COND_XG_VOLTAGE "40.0000000000"
*MEAS_COND_XG_WAVE_TYPE "Ka"
*MEAS_DATA_COUNT "3501.0000000000"
*MEAS_SCAN_AXIS_X "2θ/θ"
*MEAS_SCAN_AXIS_X_INTERNAL "TwoThetaTheta"
*MEAS_SCAN_END_TIME "08/19/20 18:22:25"
*MEAS_SCAN_MODE "CONTINUOUS"
*MEAS_SCAN_MONITOR "0"
*MEAS_SCAN_RESOLUTION_X "0.0002"
*MEAS_SCAN_SPEED "1.0"
*MEAS_SCAN_SPEED_UNIT "deg/min"
*MEAS_SCAN_START "20.0000000000"
*MEAS_SCAN_START_TIME "08/19/20 17:09:32"
*MEAS_SCAN_STEP "0.0200000000"
*MEAS_SCAN_STOP "90.0000000000"
*MEAS_SCAN_UNIT_X "deg"
*MEAS_SCAN_UNIT_Y "counts"
*RAS_HEADER_END
*RAS_INT_START
20.0000 9345.0000 1.0000
20.0600 9243.0000 1.0000
20.1200 9334.0000 1.0000
20.1800 9103.0000 1.0000
20.2400 9185.0000 1.0000
20.3000 9173.0000 1.0000
20.3600 9360.0000 1.0000
20.4200 9209.0000 1.0000
20.4800 9479.0000 1.0000
20.5400 9580.0000 1.0000
20.6000 9802.0000 1.0000
20.6600 10567.0000 1.0000
20.7200 11406.0000 1.0000
20.7800 13133.0000 1.0000
20.8400 22845.0000 1.0000
20.9000 24317.0000 1.0000
20.9600 13757.0000 1.0000
21.0200 9939.0000 1.0000
21.0800 9441.0000 1.0000
21.1400 9181.0000 1.0000
21.2000 9434.0000 1.0000
21.2600 9303.0000 1.0000
21.3200 9347.0000 1.0000
21.3800 9326.0000 1.0000
21.4400 9301.0000 1.0000
21.5000 9381.0000 1.0000
21.5600 9232.0000 1.0000
21.6200 9243.0000 1.0000
21.6800 9154.0000 1.0000
21.7400 9447.0000 1.0000
21.8000 9149.0000 1.0000
21.8600 9116.0000 1.0000
21.9200 9368.0000 1.0000
21.9800 9268.0000 1.0000
22.0400 9073.0000 1.0000
22.1000 9362.0000 1.0000
22.1600 8963.0000 1.0000
22.2200 9221.0000 1.0000
22.2800 9047.0000 1.0000
22.3400 9162.0000 1.0000
22.4000 9161.0000 1.0000
22.4600 9103.0000 1.0000
22.5200 9220.0000 1.0000
22.5800 9151.0000 1.0000
22.6400 9099.0000 1.0000
22.7000 9097.0000 1.0000
22.7600 8996.0000 1.0000
22.8200 9086.0000 1.0000
22.8800 9053.0000 1.0000
22.9400 8869.0000 1.0000
23.0000 9039.0000 1.0000
23.0600 9089.0000 1.0000
23.1200 8898.0000 1.0000
23.1800 9099.0000 1.0000
23.2400 9021.0000 1.0000
23.3000 8887.0000 1.0000
23.3600 8963.0000 1.0000
23.4200 9028.0000 1.0000
23.4800 9005.0000 1.0000
23.5400 9035.0000 1.0000
23.6000 8975.0000 1.0000
23.6600 9007.0000 1.0000
23.7200 9017.0000 1.0000
23.7800 8882.0000 1.0000
23.8400 9169.0000 1.0000
23.9000 9447.0000 1.0000
23.9600 9902.0000 1.0000
24.0200 10464.0000 1.0000
24.0800 11325.0000 1.0000
24.1400 13406.0000 1.0000
24.2000 12599.0000 1.0000
24.2600 10607.0000 1.0000
24.3200 9253.0000 1.0000
24.3800 9172.0000 1.0000
24.4400 8997.0000 1.0000
24.5000 8931.0000 1.0000
24.5600 8885.0000 1.0000
24.6200 8898.0000 1.0000
24.6800 8753.0000 1.0000
24.7400 9091.0000 1.0000
24.8000 8731.0000 1.0000
24.8600 8861.0000 1.0000
24.9200 8571.0000 1.0000
24.9800 8608.0000 1.0000
25.0400 8824.0000 1.0000
25.1000 8685.0000 1.0000
25.1600 8644.0000 1.0000
25.2200 8867.0000 1.0000
25.2800 8921.0000 1.0000
25.3400 8967.0000 1.0000
25.4000 8994.0000 1.0000
25.4600 9211.0000 1.0000
25.5200 9653.0000 1.0000
25.5800 10285.0000 1.0000
25.6400 9802.0000 1.0000
25.7000 9435.0000 1.0000
25.7600 9187.0000 1.0000
25.8200 9258.0000 1.0000
25.8800 9190.0000 1.0000
25.9400 8954.0000 1.0000
26.0000 8907.0000 1.0000
26.0600 9011.0000 1.0000
26.1200 9012.0000 1.0000
26.1800 9160.0000 1.0000
26.2400 9295.0000 1.0000
26.3000 9793.0000 1.0000
26.3600 10804.0000 1.0000
26.4200 13161.0000 1.0000
26.4800 17937.0000 1.0000
26.5400 30863.0000 1.0000
26.6000 58964.0000 1.0000
26.6600 99759.0000 1.0000
26.7200 56456.0000 1.0000
26.7800 17792.0000 1.0000
26.8400 12156.0000 1.0000
26.9000 10029.0000 1.0000
26.9600 9205.0000 1.0000
27.0200 9189.0000 1.0000
27.0800 8992.0000 1.0000
27.1400 8869.0000 1.0000
27.2000 8719.0000 1.0000
27.2600 8851.0000 1.0000
27.3200 8697.0000 1.0000
27.3800 8648.0000 1.0000
27.4400 8669.0000 1.0000
27.5000 8713.0000 1.0000
27.5600 8724.0000 1.0000
27.6200 8613.0000 1.0000
27.6800 8508.0000 1.0000
27.7400 8724.0000 1.0000
27.8000 8672.0000 1.0000
27.8600 8580.0000 1.0000
27.9200 8712.0000 1.0000
27.9800 8567.0000 1.0000
28.0400 8498.0000 1.0000
28.1000 8417.0000 1.0000
28.1600 8673.0000 1.0000
28.2200 8594.0000 1.0000
28.2800 8513.0000 1.0000
28.3400 8419.0000 1.0000
28.4000 8442.0000 1.0000
28.4600 8451.0000 1.0000
28.5200 8481.0000 1.0000
28.5800 8452.0000 1.0000
28.6400 8326.0000 1.0000
28.7000 8378.0000 1.0000
28.7600 8469.0000 1.0000
28.8200 8387.0000 1.0000
28.8800 8480.0000 1.0000
28.9400 8309.0000 1.0000
29.0000 8201.0000 1.0000
29.0600 8368.0000 1.0000
29.1200 8383.0000 1.0000
29.1800 8226.0000 1.0000
29.2400 8404.0000 1.0000
29.3000 8225.0000 1.0000
29.3600 8301.0000 1.0000
29.4200 8185.0000 1.0000
29.4800 8213.0000 1.0000
29.5400 8130.0000 1.0000
29.6000 8129.0000 1.0000
29.6600 8370.0000 1.0000
29.7200 8295.0000 1.0000
29.7800 8257.0000 1.0000
29.8400 8421.0000 1.0000
29.9000 8320.0000 1.0000
29.9600 8235.0000 1.0000
30.0200 8558.0000 1.0000
30.0800 8854.0000 1.0000
30.1400 9226.0000 1.0000
30.2000 8971.0000 1.0000
30.2600 8640.0000 1.0000
30.3200 8420.0000 1.0000
30.3800 8452.0000 1.0000
30.4400 8270.0000 1.0000
30.5000 8118.0000 1.0000
30.5600 8233.0000 1.0000
30.6200 8294.0000 1.0000
30.6800 8027.0000 1.0000
30.7400 8090.0000 1.0000
30.8000 8248.0000 1.0000
30.8600 8132.0000 1.0000
30.9200 8088.0000 1.0000
30.9800 8275.0000 1.0000
31.0400 8292.0000 1.0000
31.1000 8080.0000 1.0000
31.1600 8258.0000 1.0000
31.2200 8112.0000 1.0000
31.2800 8146.0000 1.0000
31.3400 8131.0000 1.0000
31.4000 8031.0000 1.0000
31.4600 8012.0000 1.0000
31.5200 8133.0000 1.0000
31.5800 8018.0000 1.0000
31.6400 8067.0000 1.0000
31.7000 8199.0000 1.0000
31.7600 8151.0000 1.0000
31.8200 7898.0000 1.0000
31.8800 8075.0000 1.0000
31.9400 8090.0000 1.0000
32.0000 8292.0000 1.0000
32.0600 8138.0000 1.0000
32.1200 8215.0000 1.0000
32.1800 8237.0000 1.0000
32.2400 8077.0000 1.0000
32.3000 8259.0000 1.0000
32.3600 8031.0000 1.0000
32.4200 7991.0000 1.0000
32.4800 8018.0000 1.0000
32.5400 8148.0000 1.0000
32.6000 7994.0000 1.0000
32.6600 8046.0000 1.0000
32.7200 8162.0000 1.0000
32.7800 8302.0000 1.0000
32.8400 8504.0000 1.0000
32.9000 8834.0000 1.0000
32.9600 9486.0000 1.0000
33.0200 10637.0000 1.0000
33.0800 13649.0000 1.0000
33.1400 20565.0000 1.0000
33.2000 21466.0000 1.0000
33.2600 16814.0000 1.0000
33.3200 11436.0000 1.0000
33.3800 9316.0000 1.0000
33.4400 8676.0000 1.0000
33.5000 8350.0000 1.0000
33.5600 8358.0000 1.0000
33.6200 8102.0000 1.0000
33.6800 7950.0000 1.0000
33.7400 8121.0000 1.0000
33.8000 8040.0000 1.0000
33.8600 7905.0000 1.0000
33.9200 7878.0000 1.0000
33.9800 8044.0000 1.0000
34.0400 7945.0000 1.0000
34.1000 7948.0000 1.0000
34.1600 7991.0000 1.0000
34.2200 8145.0000 1.0000
34.2800 8016.0000 1.0000
34.3400 8066.0000 1.0000
34.4000 7890.0000 1.0000
34.4600 8016.0000 1.0000
34.5200 7937.0000 1.0000
34.5800 7923.0000 1.0000
34.6400 7934.0000 1.0000
34.7000 8114.0000 1.0000
34.7600 7956.0000 1.0000
34.8200 7955.0000 1.0000
34.8800 8093.0000 1.0000
34.9400 8177.0000 1.0000
35.0000 8443.0000 1.0000
35.0600 8909.0000 1.0000
35.1200 9734.0000 1.0000
35.1800 10279.0000 1.0000
35.2400 9575.0000 1.0000
35.3000 9071.0000 1.0000
35.3600 9282.0000 1.0000
35.4200 10386.0000 1.0000
35.4800 12582.0000 1.0000
35.5400 13785.0000 1.0000
35.6000 17451.0000 1.0000
35.6600 19168.0000 1.0000
35.7200 15261.0000 1.0000
35.7800 11503.0000 1.0000
35.8400 9067.0000 1.0000
35.9000 8477.0000 1.0000
35.9600 8336.0000 1.0000
36.0200 8013.0000 1.0000
36.0800 8087.0000 1.0000
36.1400 7914.0000 1.0000
36.2000 7945.0000 1.0000
36.2600 8156.0000 1.0000
36.3200 8078.0000 1.0000
36.3800 8181.0000 1.0000
36.4400 8495.0000 1.0000
36.5000 10397.0000 1.0000
36.5600 16070.0000 1.0000
36.6200 11602.0000 1.0000
36.6800 9971.0000 1.0000
36.7400 8105.0000 1.0000
36.8000 8037.0000 1.0000
36.8600 7858.0000 1.0000
36.9200 7831.0000 1.0000
36.9800 7900.0000 1.0000
37.0400 7814.0000 1.0000
37.1000 7851.0000 1.0000
37.1600 8012.0000 1.0000
37.2200 7822.0000 1.0000
37.2800 7812.0000 1.0000
37.3400 7842.0000 1.0000
37.4000 7727.0000 1.0000
37.4600 7731.0000 1.0000
37.5200 7708.0000 1.0000
37.5800 7758.0000 1.0000
37.6400 7946.0000 1.0000
37.7000 8177.0000 1.0000
37.7600 8686.0000 1.0000
37.8200 8402.0000 1.0000
37.8800 8264.0000 1.0000
37.9400 7884.0000 1.0000
38.0000 7856.0000 1.0000
38.0600 7649.0000 1.0000
38.1200 7699.0000 1.0000
38.1800 7733.0000 1.0000
38.2400 7730.0000 1.0000
38.3000 7797.0000 1.0000
38.3600 7782.0000 1.0000
38.4200 7775.0000 1.0000
38.4800 7564.0000 1.0000
38.5400 7752.0000 1.0000
38.6000 7760.0000 1.0000
38.6600 7789.0000 1.0000
38.7200 7801.0000 1.0000
38.7800 7571.0000 1.0000
38.8400 7743.0000 1.0000
38.9000 7733.0000 1.0000
38.9600 7592.0000 1.0000
39.0200 7782.0000 1.0000
39.0800 7776.0000 1.0000
39.1400 7538.0000 1.0000
39.2000 7948.0000 1.0000
39.2600 8300.0000 1.0000
39.3200 8235.0000 1.0000
39.3800 8737.0000 1.0000
39.4400 10863.0000 1.0000
39.5000 13101.0000 1.0000
39.5600 10115.0000 1.0000
39.6200 9147.0000 1.0000
39.6800 8094.0000 1.0000
39.7400 7775.0000 1.0000
39.8000 7736.0000 1.0000
39.8600 7763.0000 1.0000
39.9200 7645.0000 1.0000
39.9800 7725.0000 1.0000
40.0400 7820.0000 1.0000
40.1000 7754.0000 1.0000
40.1600 8001.0000 1.0000
40.2200 8433.0000 1.0000
40.2800 11824.0000 1.0000
40.3400 9606.0000 1.0000
40.4000 10303.0000 1.0000
40.4600 8259.0000 1.0000
40.5200 7864.0000 1.0000
40.5800 7939.0000 1.0000
40.6400 8012.0000 1.0000
40.7000 8053.0000 1.0000
40.7600 8424.0000 1.0000
40.8200 9620.0000 1.0000
40.8800 11008.0000 1.0000
40.9400 9679.0000 1.0000
41.0000 9352.0000 1.0000
41.0600 8098.0000 1.0000
41.1200 7819.0000 1.0000
41.1800 7781.0000 1.0000
41.2400 7767.0000 1.0000
41.3000 7607.0000 1.0000
41.3600 7813.0000 1.0000
41.4200 7477.0000 1.0000
41.4800 7630.0000 1.0000
41.5400 7562.0000 1.0000
41.6000 7696.0000 1.0000
41.6600 7596.0000 1.0000
41.7200 7588.0000 1.0000
41.7800 7542.0000 1.0000
41.8400 7668.0000 1.0000
41.9000 7825.0000 1.0000
41.9600 7746.0000 1.0000
42.0200 7648.0000 1.0000
42.0800 7732.0000 1.0000
42.1400 7675.0000 1.0000
42.2000 7673.0000 1.0000
42.2600 7889.0000 1.0000
42.3200 7975.0000 1.0000
42.3800 8618.0000 1.0000
42.4400 12266.0000 1.0000
42.5000 11706.0000 1.0000
42.5600 10746.0000 1.0000
42.6200 9055.0000 1.0000
42.6800 7841.0000 1.0000
42.7400 7839.0000 1.0000
42.8000 7586.0000 1.0000
42.8600 7591.0000 1.0000
42.9200 7842.0000 1.0000
42.9800 7559.0000 1.0000
43.0400 8037.0000 1.0000
43.1000 8249.0000 1.0000
43.1600 8492.0000 1.0000
43.2200 8395.0000 1.0000
43.2800 9069.0000 1.0000
43.3400 10239.0000 1.0000
43.4000 9572.0000 1.0000
43.4600 9248.0000 1.0000
43.5200 8552.0000 1.0000
43.5800 8006.0000 1.0000
43.6400 7969.0000 1.0000
43.7000 7689.0000 1.0000
43.7600 7626.0000 1.0000
43.8200 7726.0000 1.0000
43.8800 7451.0000 1.0000
43.9400 7656.0000 1.0000
44.0000 7378.0000 1.0000
44.0600 7581.0000 1.0000
44.1200 7591.0000 1.0000
44.1800 7725.0000 1.0000
44.2400 7565.0000 1.0000
44.3000 7553.0000 1.0000
44.3600 7674.0000 1.0000
44.4200 7622.0000 1.0000
44.4800 7596.0000 1.0000
44.5400 7607.0000 1.0000
44.6000 7454.0000 1.0000
44.6600 7547.0000 1.0000
44.7200 7656.0000 1.0000
44.7800 7490.0000 1.0000
44.8400 7537.0000 1.0000
44.9000 7392.0000 1.0000
44.9600 7611.0000 1.0000
45.0200 7598.0000 1.0000
45.0800 7524.0000 1.0000
45.1400 7770.0000 1.0000
45.2000 7412.0000 1.0000
45.2600 7619.0000 1.0000
45.3200 7589.0000 1.0000
45.3800 7495.0000 1.0000
45.4400 7615.0000 1.0000
45.5000 7464.0000 1.0000
45.5600 7619.0000 1.0000
45.6200 7627.0000 1.0000
45.6800 7643.0000 1.0000
45.7400 8359.0000 1.0000
45.8000 12150.0000 1.0000
45.8600 8739.0000 1.0000
45.9200 9914.0000 1.0000
45.9800 8004.0000 1.0000
46.0400 7653.0000 1.0000
46.1000 7630.0000 1.0000
46.1600 7678.0000 1.0000
46.2200 7697.0000 1.0000
46.2800 7397.0000 1.0000
46.3400 7712.0000 1.0000
46.4000 7475.0000 1.0000
46.4600 7493.0000 1.0000
46.5200 7418.0000 1.0000
46.5800 7469.0000 1.0000
46.6400 7446.0000 1.0000
46.7000 7492.0000 1.0000
46.7600 7582.0000 1.0000
46.8200 7466.0000 1.0000
46.8800 7668.0000 1.0000
46.9400 7388.0000 1.0000
47.0000 7574.0000 1.0000
47.0600 7578.0000 1.0000
47.1200 7526.0000 1.0000
47.1800 7502.0000 1.0000
47.2400 7425.0000 1.0000
47.3000 7515.0000 1.0000
47.3600 7627.0000 1.0000
47.4200 7434.0000 1.0000
47.4800 7438.0000 1.0000
47.5400 7628.0000 1.0000
47.6000 7483.0000 1.0000
47.6600 7607.0000 1.0000
47.7200 7332.0000 1.0000
47.7800 7588.0000 1.0000
47.8400 7485.0000 1.0000
47.9000 7518.0000 1.0000
47.9600 7580.0000 1.0000
48.0200 7631.0000 1.0000
48.0800 7562.0000 1.0000
48.1400 7459.0000 1.0000
48.2000 7579.0000 1.0000
48.2600 7562.0000 1.0000
48.3200 7538.0000 1.0000
48.3800 7399.0000 1.0000
48.4400 7553.0000 1.0000
48.5000 7627.0000 1.0000
48.5600 7511.0000 1.0000
48.6200 7566.0000 1.0000
48.6800 7568.0000 1.0000
48.7400 7649.0000 1.0000
48.8000 7495.0000 1.0000
48.8600 7708.0000 1.0000
48.9200 7459.0000 1.0000
48.9800 7596.0000 1.0000
49.0400 7550.0000 1.0000
49.1000 7579.0000 1.0000
49.1600 7890.0000 1.0000
49.2200 7950.0000 1.0000
49.2800 8013.0000 1.0000
49.3400 8663.0000 1.0000
49.4000 9943.0000 1.0000
49.4600 12592.0000 1.0000
49.5200 11186.0000 1.0000
49.5800 10468.0000 1.0000
49.6400 9855.0000 1.0000
49.7000 8439.0000 1.0000
49.7600 7917.0000 1.0000
49.8200 7960.0000 1.0000
49.8800 7894.0000 1.0000
49.9400 8129.0000 1.0000
50.0000 8485.0000 1.0000
50.0600 9664.0000 1.0000
50.1200 15585.0000 1.0000
50.1800 15219.0000 1.0000
50.2400 11457.0000 1.0000
50.3000 13011.0000 1.0000
50.3600 8513.0000 1.0000
50.4200 8052.0000 1.0000
50.4800 7776.0000 1.0000
50.5400 7770.0000 1.0000
50.6000 7823.0000 1.0000
50.6600 7660.0000 1.0000
50.7200 7553.0000 1.0000
50.7800 7666.0000 1.0000
50.8400 7636.0000 1.0000
50.9000 7560.0000 1.0000
50.9600 7537.0000 1.0000
51.0200 7578.0000 1.0000
51.0800 7558.0000 1.0000
51.1400 7579.0000 1.0000
51.2000 7482.0000 1.0000
51.2600 7465.0000 1.0000
51.3200 7487.0000 1.0000
51.3800 7509.0000 1.0000
51.4400 7425.0000 1.0000
51.5000 7494.0000 1.0000
51.5600 7605.0000 1.0000
51.6200 7518.0000 1.0000
51.6800 7611.0000 1.0000
51.7400 7573.0000 1.0000
51.8000 7506.0000 1.0000
51.8600 7524.0000 1.0000
51.9200 7618.0000 1.0000
51.9800 7429.0000 1.0000
52.0400 7610.0000 1.0000
52.1000 7573.0000 1.0000
52.1600 7609.0000 1.0000
52.2200 7595.0000 1.0000
52.2800 7596.0000 1.0000
52.3400 7794.0000 1.0000
52.4000 7827.0000 1.0000
52.4600 8101.0000 1.0000
52.5200 8393.0000 1.0000
52.5800 8407.0000 1.0000
52.6400 8166.0000 1.0000
52.7000 8251.0000 1.0000
52.7600 7729.0000 1.0000
52.8200 7538.0000 1.0000
52.8800 7625.0000 1.0000
52.9400 7644.0000 1.0000
53.0000 7665.0000 1.0000
53.0600 7545.0000 1.0000
53.1200 7628.0000 1.0000
53.1800 7610.0000 1.0000
53.2400 7582.0000 1.0000
53.3000 7628.0000 1.0000
53.3600 7580.0000 1.0000
53.4200 7862.0000 1.0000
53.4800 7791.0000 1.0000
53.5400 7829.0000 1.0000
53.6000 7799.0000 1.0000
53.6600 8067.0000 1.0000
53.7200 7824.0000 1.0000
53.7800 7973.0000 1.0000
53.8400 7954.0000 1.0000
53.9000 8384.0000 1.0000
53.9600 9056.0000 1.0000
54.0200 11363.0000 1.0000
54.0800 13816.0000 1.0000
54.1400 11231.0000 1.0000
54.2000 11040.0000 1.0000
54.2600 10105.0000 1.0000
54.3200 8577.0000 1.0000
54.3800 8034.0000 1.0000
54.4400 7748.0000 1.0000
54.5000 7778.0000 1.0000
54.5600 7665.0000 1.0000
54.6200 7645.0000 1.0000
54.6800 7640.0000 1.0000
54.7400 7778.0000 1.0000
54.8000 8321.0000 1.0000
54.8600 10701.0000 1.0000
54.9200 9381.0000 1.0000
54.9800 8566.0000 1.0000
55.0400 9443.0000 1.0000
55.1000 8105.0000 1.0000
55.1600 7782.0000 1.0000
55.2200 7804.0000 1.0000
55.2800 8149.0000 1.0000
55.3400 9063.0000 1.0000
55.4000 7978.0000 1.0000
55.4600 8237.0000 1.0000
55.5200 8034.0000 1.0000
55.5800 7490.0000 1.0000
55.6400 7527.0000 1.0000
55.7000 7596.0000 1.0000
55.7600 7399.0000 1.0000
55.8200 7678.0000 1.0000
55.8800 7478.0000 1.0000
55.9400 7745.0000 1.0000
56.0000 7579.0000 1.0000
56.0600 7553.0000 1.0000
56.1200 7523.0000 1.0000
56.1800 7712.0000 1.0000
56.2400 7450.0000 1.0000
56.3000 7520.0000 1.0000
56.3600 7496.0000 1.0000
56.4200 7426.0000 1.0000
56.4800 7480.0000 1.0000
56.5400 7493.0000 1.0000
56.6000 7539.0000 1.0000
56.6600 7570.0000 1.0000
56.7200 7717.0000 1.0000
56.7800 7771.0000 1.0000
56.8400 7740.0000 1.0000
56.9000 7792.0000 1.0000
56.9600 8026.0000 1.0000
57.0200 8481.0000 1.0000
57.0800 8290.0000 1.0000
57.1400 8390.0000 1.0000
57.2000 8581.0000 1.0000
57.2600 8346.0000 1.0000
57.3200 8465.0000 1.0000
57.3800 8744.0000 1.0000
57.4400 9488.0000 1.0000
57.5000 10407.0000 1.0000
57.5600 10055.0000 1.0000
57.6200 10122.0000 1.0000
57.6800 9348.0000 1.0000
57.7400 8769.0000 1.0000
57.8000 8321.0000 1.0000
57.8600 7899.0000 1.0000
57.9200 7848.0000 1.0000
57.9800 7751.0000 1.0000
58.0400 7585.0000 1.0000
58.1000 7660.0000 1.0000
58.1600 7693.0000 1.0000
58.2200 7438.0000 1.0000
58.2800 7677.0000 1.0000
58.3400 7585.0000 1.0000
58.4000 7490.0000 1.0000
58.4600 7639.0000 1.0000
58.5200 7562.0000 1.0000
58.5800 7508.0000 1.0000
58.6400 7517.0000 1.0000
58.7000 7478.0000 1.0000
58.7600 7437.0000 1.0000
58.8200 7505.0000 1.0000
58.8800 7610.0000 1.0000
58.9400 7657.0000 1.0000
59.0000 7526.0000 1.0000
59.0600 7466.0000 1.0000
59.1200 7613.0000 1.0000
59.1800 7586.0000 1.0000
59.2400 7507.0000 1.0000
59.3000 7510.0000 1.0000
59.3600 7537.0000 1.0000
59.4200 7577.0000 1.0000
59.4800 7628.0000 1.0000
59.5400 7602.0000 1.0000
59.6000 7647.0000 1.0000
59.6600 7710.0000 1.0000
59.7200 7714.0000 1.0000
59.7800 7996.0000 1.0000
59.8400 8324.0000 1.0000
59.9000 10260.0000 1.0000
59.9600 16980.0000 1.0000
60.0200 10474.0000 1.0000
60.0800 10276.0000 1.0000
60.1400 11883.0000 1.0000
60.2000 8396.0000 1.0000
60.2600 7968.0000 1.0000
60.3200 7730.0000 1.0000
60.3800 7501.0000 1.0000
60.4400 7713.0000 1.0000
60.5000 7489.0000 1.0000
60.5600 7524.0000 1.0000
60.6200 7628.0000 1.0000
60.6800 7387.0000 1.0000
60.7400 7554.0000 1.0000
60.8000 7668.0000 1.0000
60.8600 7712.0000 1.0000
60.9200 7654.0000 1.0000
60.9800 7600.0000 1.0000
61.0400 7589.0000 1.0000
61.1000 7775.0000 1.0000
61.1600 7708.0000 1.0000
61.2200 7577.0000 1.0000
61.2800 7740.0000 1.0000
61.3400 7789.0000 1.0000
61.4000 7677.0000 1.0000
61.4600 7719.0000 1.0000
61.5200 7581.0000 1.0000
61.5800 7541.0000 1.0000
61.6400 7597.0000 1.0000
61.7000 7689.0000 1.0000
61.7600 7535.0000 1.0000
61.8200 7588.0000 1.0000
61.8800 7425.0000 1.0000
61.9400 7576.0000 1.0000
62.0000 7564.0000 1.0000
62.0600 7809.0000 1.0000
62.1200 7806.0000 1.0000
62.1800 7845.0000 1.0000
62.2400 8151.0000 1.0000
62.3000 8264.0000 1.0000
62.3600 9368.0000 1.0000
62.4200 11422.0000 1.0000
62.4800 10860.0000 1.0000
62.5400 9865.0000 1.0000
62.6000 10785.0000 1.0000
62.6600 9780.0000 1.0000
62.7200 8962.0000 1.0000
62.7800 8656.0000 1.0000
62.8400 8301.0000 1.0000
62.9000 8224.0000 1.0000
62.9600 8051.0000 1.0000
63.0200 7849.0000 1.0000
63.0800 7714.0000 1.0000
63.1400 7739.0000 1.0000
63.2000 7705.0000 1.0000
63.2600 7749.0000 1.0000
63.3200 7754.0000 1.0000
63.3800 7712.0000 1.0000
63.4400 7612.0000 1.0000
63.5000 7670.0000 1.0000
63.5600 7693.0000 1.0000
63.6200 7749.0000 1.0000
63.6800 7869.0000 1.0000
63.7400 7884.0000 1.0000
63.8000 8073.0000 1.0000
63.8600 8500.0000 1.0000
63.9200 9277.0000 1.0000
63.9800 11972.0000 1.0000
64.0400 12844.0000 1.0000
64.1000 9931.0000 1.0000
64.1600 10297.0000 1.0000
64.2200 10108.0000 1.0000
64.2800 8488.0000 1.0000
64.3400 7986.0000 1.0000
64.4000 7857.0000 1.0000
64.4600 7635.0000 1.0000
64.5200 7690.0000 1.0000
64.5800 7522.0000 1.0000
64.6400 7544.0000 1.0000
64.7000 7630.0000 1.0000
64.7600 7531.0000 1.0000
64.8200 7461.0000 1.0000
64.8800 7449.0000 1.0000
64.9400 7510.0000 1.0000
65.0000 7500.0000 1.0000
65.0600 7617.0000 1.0000
65.1200 7493.0000 1.0000
65.1800 7608.0000 1.0000
65.2400 7490.0000 1.0000
65.3000 7530.0000 1.0000
65.3600 7573.0000 1.0000
65.4200 7513.0000 1.0000
65.4800 7592.0000 1.0000
65.5400 7615.0000 1.0000
65.6000 7735.0000 1.0000
65.6600 7546.0000 1.0000
65.7200 7808.0000 1.0000
65.7800 8230.0000 1.0000
65.8400 7987.0000 1.0000
65.9000 7779.0000 1.0000
65.9600 7868.0000 1.0000
66.0200 7701.0000 1.0000
66.0800 7740.0000 1.0000
66.1400 7610.0000 1.0000
66.2000 7522.0000 1.0000
66.2600 7576.0000 1.0000
66.3200 7634.0000 1.0000
66.3800 7846.0000 1.0000
66.4400 8082.0000 1.0000
66.5000 8216.0000 1.0000
66.5600 8170.0000 1.0000
66.6200 7944.0000 1.0000
66.6800 8086.0000 1.0000
66.7400 7917.0000 1.0000
66.8000 7737.0000 1.0000
66.8600 7658.0000 1.0000
66.9200 7717.0000 1.0000
66.9800 7541.0000 1.0000
67.0400 7600.0000 1.0000
67.1000 7682.0000 1.0000
67.1600 7551.0000 1.0000
67.2200 7651.0000 1.0000
67.2800 7649.0000 1.0000
67.3400 7837.0000 1.0000
67.4000 7793.0000 1.0000
67.4600 7615.0000 1.0000
67.5200 7757.0000 1.0000
67.5800 7892.0000 1.0000
67.6400 8151.0000 1.0000
67.7000 10219.0000 1.0000
67.7600 11454.0000 1.0000
67.8200 8625.0000 1.0000
67.8800 9103.0000 1.0000
67.9400 10182.0000 1.0000
68.0000 8678.0000 1.0000
68.0600 9049.0000 1.0000
68.1200 13047.0000 1.0000
68.1800 12104.0000 1.0000
68.2400 10237.0000 1.0000
68.3000 12772.0000 1.0000
68.3600 11346.0000 1.0000
68.4200 8990.0000 1.0000
68.4800 9336.0000 1.0000
68.5400 8775.0000 1.0000
68.6000 7897.0000 1.0000
68.6600 7838.0000 1.0000
68.7200 7675.0000 1.0000
68.7800 7642.0000 1.0000
68.8400 7575.0000 1.0000
68.9000 7542.0000 1.0000
68.9600 7557.0000 1.0000
69.0200 7786.0000 1.0000
69.0800 7749.0000 1.0000
69.1400 7516.0000 1.0000
69.2000 7489.0000 1.0000
69.2600 7712.0000 1.0000
69.3200 7649.0000 1.0000
69.3800 7775.0000 1.0000
69.4400 7604.0000 1.0000
69.5000 7601.0000 1.0000
69.5600 7838.0000 1.0000
69.6200 7840.0000 1.0000
69.6800 7780.0000 1.0000
69.7400 7915.0000 1.0000
69.8000 7810.0000 1.0000
69.8600 7779.0000 1.0000
69.9200 7625.0000 1.0000
69.9800 7613.0000 1.0000
70.0400 7587.0000 1.0000
70.1000 7570.0000 1.0000
70.1600 7654.0000 1.0000
70.2200 7712.0000 1.0000
70.2800 7472.0000 1.0000
70.3400 7491.0000 1.0000
70.4000 7661.0000 1.0000
70.4600 7670.0000 1.0000
70.5200 7732.0000 1.0000
70.5800 7607.0000 1.0000
70.6400 7566.0000 1.0000
70.7000 7480.0000 1.0000
70.7600 7642.0000 1.0000
70.8200 7611.0000 1.0000
70.8800 7583.0000 1.0000
70.9400 7582.0000 1.0000
71.0000 7721.0000 1.0000
71.0600 7635.0000 1.0000
71.1200 7505.0000 1.0000
71.1800 7705.0000 1.0000
71.2400 7643.0000 1.0000
71.3000 7673.0000 1.0000
71.3600 7636.0000 1.0000
71.4200 7520.0000 1.0000
71.4800 7739.0000 1.0000
71.5400 7635.0000 1.0000
71.6000 7557.0000 1.0000
71.6600 7641.0000 1.0000
71.7200 7731.0000 1.0000
71.7800 8007.0000 1.0000
71.8400 7988.0000 1.0000
71.9000 8544.0000 1.0000
71.9600 8881.0000 1.0000
72.0200 8364.0000 1.0000
72.0800 8034.0000 1.0000
72.1400 8236.0000 1.0000
72.2000 8122.0000 1.0000
72.2600 7981.0000 1.0000
72.3200 7851.0000 1.0000
72.3800 7752.0000 1.0000
72.4400 7676.0000 1.0000
72.5000 7704.0000 1.0000
72.5600 7685.0000 1.0000
72.6200 7502.0000 1.0000
72.6800 7727.0000 1.0000
72.7400 7587.0000 1.0000
72.8000 7589.0000 1.0000
72.8600 7545.0000 1.0000
72.9200 7641.0000 1.0000
72.9800 7604.0000 1.0000
73.0400 7603.0000 1.0000
73.1000 7670.0000 1.0000
73.1600 7710.0000 1.0000
73.2200 7663.0000 1.0000
73.2800 7715.0000 1.0000
73.3400 7599.0000 1.0000
73.4000 7969.0000 1.0000
73.4600 8983.0000 1.0000
73.5200 8072.0000 1.0000
73.5800 7778.0000 1.0000
73.6400 8047.0000 1.0000
73.7000 8279.0000 1.0000
73.7600 7685.0000 1.0000
73.8200 7823.0000 1.0000
73.8800 7562.0000 1.0000
73.9400 7758.0000 1.0000
74.0000 7637.0000 1.0000
74.0600 7783.0000 1.0000
74.1200 7625.0000 1.0000
74.1800 7732.0000 1.0000
74.2400 7791.0000 1.0000
74.3000 7609.0000 1.0000
74.3600 7706.0000 1.0000
74.4200 7608.0000 1.0000
74.4800 7517.0000 1.0000
74.5400 7677.0000 1.0000
74.6000 7645.0000 1.0000
74.6600 7513.0000 1.0000
74.7200 7750.0000 1.0000
74.7800 7543.0000 1.0000
74.8400 7648.0000 1.0000
74.9000 7572.0000 1.0000
74.9600 7697.0000 1.0000
75.0200 7545.0000 1.0000
75.0800 7569.0000 1.0000
75.1400 7679.0000 1.0000
75.2000 7716.0000 1.0000
75.2600 7741.0000 1.0000
75.3200 7836.0000 1.0000
75.3800 8022.0000 1.0000
75.4400 8604.0000 1.0000
75.5000 8304.0000 1.0000
75.5600 8268.0000 1.0000
75.6200 9762.0000 1.0000
75.6800 10679.0000 1.0000
75.7400 8310.0000 1.0000
75.8000 8282.0000 1.0000
75.8600 9028.0000 1.0000
75.9200 8394.0000 1.0000
75.9800 7728.0000 1.0000
76.0400 7757.0000 1.0000
76.1000 7605.0000 1.0000
76.1600 7551.0000 1.0000
76.2200 7601.0000 1.0000
76.2800 7561.0000 1.0000
76.3400 7527.0000 1.0000
76.4000 7635.0000 1.0000
76.4600 7494.0000 1.0000
76.5200 7500.0000 1.0000
76.5800 7639.0000 1.0000
76.6400 7638.0000 1.0000
76.7000 7699.0000 1.0000
76.7600 7707.0000 1.0000
76.8200 7823.0000 1.0000
76.8800 7895.0000 1.0000
76.9400 7863.0000 1.0000
77.0000 7791.0000 1.0000
77.0600 7776.0000 1.0000
77.1200 7751.0000 1.0000
77.1800 7833.0000 1.0000
77.2400 7787.0000 1.0000
77.3000 7775.0000 1.0000
77.3600 7713.0000 1.0000
77.4200 7784.0000 1.0000
77.4800 7962.0000 1.0000
77.5400 7812.0000 1.0000
77.6000 8348.0000 1.0000
77.6600 10105.0000 1.0000
77.7200 8642.0000 1.0000
77.7800 8209.0000 1.0000
77.8400 8309.0000 1.0000
77.9000 8753.0000 1.0000
77.9600 8072.0000 1.0000
78.0200 7922.0000 1.0000
78.0800 7826.0000 1.0000
78.1400 7727.0000 1.0000
78.2000 7650.0000 1.0000
78.2600 7829.0000 1.0000
78.3200 7463.0000 1.0000
78.3800 7582.0000 1.0000
78.4400 7449.0000 1.0000
78.5000 7648.0000 1.0000
78.5600 7492.0000 1.0000
78.6200 7555.0000 1.0000
78.6800 7837.0000 1.0000
78.7400 7735.0000 1.0000
78.8000 7666.0000 1.0000
78.8600 7618.0000 1.0000
78.9200 7415.0000 1.0000
78.9800 7653.0000 1.0000
79.0400 7570.0000 1.0000
79.1000 7700.0000 1.0000
79.1600 7720.0000 1.0000
79.2200 7612.0000 1.0000
79.2800 7564.0000 1.0000
79.3400 7696.0000 1.0000
79.4000 7656.0000 1.0000
79.4600 7555.0000 1.0000
79.5200 7651.0000 1.0000
79.5800 7673.0000 1.0000
79.6400 7750.0000 1.0000
79.7000 7727.0000 1.0000
79.7600 7795.0000 1.0000
79.8200 8553.0000 1.0000
79.8800 10051.0000 1.0000
79.9400 8463.0000 1.0000
80.0000 8472.0000 1.0000
80.0600 8832.0000 1.0000
80.1200 8921.0000 1.0000
80.1800 8079.0000 1.0000
80.2400 8001.0000 1.0000
80.3000 8055.0000 1.0000
80.3600 7756.0000 1.0000
80.4200 7796.0000 1.0000
80.4800 7757.0000 1.0000
80.5400 8144.0000 1.0000
80.6000 8021.0000 1.0000
80.6600 8102.0000 1.0000
80.7200 8417.0000 1.0000
80.7800 8036.0000 1.0000
80.8400 7832.0000 1.0000
80.9000 8032.0000 1.0000
80.9600 8096.0000 1.0000
81.0200 7966.0000 1.0000
81.0800 8049.0000 1.0000
81.1400 9056.0000 1.0000
81.2000 8825.0000 1.0000
81.2600 8045.0000 1.0000
81.3200 8219.0000 1.0000
81.3800 8578.0000 1.0000
81.4400 9790.0000 1.0000
81.5000 9783.0000 1.0000
81.5600 8304.0000 1.0000
81.6200 7962.0000 1.0000
81.6800 8148.0000 1.0000
81.7400 8710.0000 1.0000
81.8000 8023.0000 1.0000
81.8600 7622.0000 1.0000
81.9200 7806.0000 1.0000
81.9800 7597.0000 1.0000
82.0400 7637.0000 1.0000
82.1000 7543.0000 1.0000
82.1600 7635.0000 1.0000
82.2200 7550.0000 1.0000
82.2800 7509.0000 1.0000
82.3400 7630.0000 1.0000
82.4000 7767.0000 1.0000
82.4600 7730.0000 1.0000
82.5200 7618.0000 1.0000
82.5800 7459.0000 1.0000
82.6400 7737.0000 1.0000
82.7000 7582.0000 1.0000
82.7600 7848.0000 1.0000
82.8200 7845.0000 1.0000
82.8800 7913.0000 1.0000
82.9400 8188.0000 1.0000
83.0000 8161.0000 1.0000
83.0600 7789.0000 1.0000
83.1200 7895.0000 1.0000
83.1800 7871.0000 1.0000
83.2400 7941.0000 1.0000
83.3000 7752.0000 1.0000
83.3600 7701.0000 1.0000
83.4200 7708.0000 1.0000
83.4800 7597.0000 1.0000
83.5400 7693.0000 1.0000
83.6000 7623.0000 1.0000
83.6600 7642.0000 1.0000
83.7200 7712.0000 1.0000
83.7800 8394.0000 1.0000
83.8400 8683.0000 1.0000
83.9000 7843.0000 1.0000
83.9600 7859.0000 1.0000
84.0200 7687.0000 1.0000
84.0800 8275.0000 1.0000
84.1400 7906.0000 1.0000
84.2000 7780.0000 1.0000
84.2600 7596.0000 1.0000
84.3200 7705.0000 1.0000
84.3800 7692.0000 1.0000
84.4400 7591.0000 1.0000
84.5000 7763.0000 1.0000
84.5600 7683.0000 1.0000
84.6200 7768.0000 1.0000
84.6800 7751.0000 1.0000
84.7400 7915.0000 1.0000
84.8000 7842.0000 1.0000
84.8600 8100.0000 1.0000
84.9200 8661.0000 1.0000
84.9800 8331.0000 1.0000
85.0400 8060.0000 1.0000
85.1000 7826.0000 1.0000
85.1600 8061.0000 1.0000
85.2200 8047.0000 1.0000
85.2800 8021.0000 1.0000
85.3400 7772.0000 1.0000
85.4000 7732.0000 1.0000
85.4600 7662.0000 1.0000
85.5200 7618.0000 1.0000
85.5800 7819.0000 1.0000
85.6400 7641.0000 1.0000
85.7000 7550.0000 1.0000
85.7600 7469.0000 1.0000
85.8200 7519.0000 1.0000
85.8800 7746.0000 1.0000
85.9400 7546.0000 1.0000
86.0000 7531.0000 1.0000
86.0600 7711.0000 1.0000
86.1200 7629.0000 1.0000
86.1800 7658.0000 1.0000
86.2400 7590.0000 1.0000
86.3000 7664.0000 1.0000
86.3600 7735.0000 1.0000
86.4200 7730.0000 1.0000
86.4800 7755.0000 1.0000
86.5400 7741.0000 1.0000
86.6000 7582.0000 1.0000
86.6600 7645.0000 1.0000
86.7200 7699.0000 1.0000
86.7800 7610.0000 1.0000
86.8400 7524.0000 1.0000
86.9000 7689.0000 1.0000
86.9600 7592.0000 1.0000
87.0200 7681.0000 1.0000
87.0800 7769.0000 1.0000
87.1400 7796.0000 1.0000
87.2000 7789.0000 1.0000
87.2600 7584.0000 1.0000
87.3200 7733.0000 1.0000
87.3800 7570.0000 1.0000
87.4400 7867.0000 1.0000
87.5000 7709.0000 1.0000
87.5600 7666.0000 1.0000
87.6200 7763.0000 1.0000
87.6800 7784.0000 1.0000
87.7400 7769.0000 1.0000
87.8000 7701.0000 1.0000
87.8600 7465.0000 1.0000
87.9200 7723.0000 1.0000
87.9800 7588.0000 1.0000
88.0400 7403.0000 1.0000
88.1000 7673.0000 1.0000
88.1600 7537.0000 1.0000
88.2200 7653.0000 1.0000
88.2800 7636.0000 1.0000
88.3400 7749.0000 1.0000
88.4000 7737.0000 1.0000
88.4600 8005.0000 1.0000
88.5200 8304.0000 1.0000
88.5800 8343.0000 1.0000
88.6400 8069.0000 1.0000
88.7000 7960.0000 1.0000
88.7600 7980.0000 1.0000
88.8200 8115.0000 1.0000
88.8800 8044.0000 1.0000
88.9400 7965.0000 1.0000
89.0000 7762.0000 1.0000
89.0600 7662.0000 1.0000
89.1200 7714.0000 1.0000
89.1800 7720.0000 1.0000
89.2400 7830.0000 1.0000
89.3000 7802.0000 1.0000
89.3600 7794.0000 1.0000
89.4200 7703.0000 1.0000
89.4800 7665.0000 1.0000
89.5400 7648.0000 1.0000
89.6000 7820.0000 1.0000
89.6600 7839.0000 1.0000
89.7200 7855.0000 1.0000
89.7800 7940.0000 1.0000
89.8400 7846.0000 1.0000
89.9000 7778.0000 1.0000
89.9600 7808.0000 1.0000
90.0000 7858.0000 1.0000
*RAS_INT_END
*RAS_TEMPERATURE_START
*RAS_TEMPERATURE_END
*RAS_DATA_END