File: XRD/Data/20200910_mix_08.ras
*RAS_DATA_START
*RAS_HEADER_START
*DISP_FMT_X "%.2f"
*DISP_FMT_Y "%.0f"
*DISP_FULLSCALE "26084.0000000000"
*DISP_LINE_COLOR "255.0000000000"
*DISP_LINE_STYLE "0.0000000000"
*DISP_LINE_WIDTH "0.2500000000"
*DISP_NOTE "測定データ-2"
*DISP_OFFSET_Y "0.0000000000"
*DISP_PEAKSEARCH_UNIT_Y "cps"
*DISP_RANGE_BOTTOM "0.0000000000"
*DISP_RANGE_LEFT "20.0000000000"
*DISP_RANGE_LOGCUTOFF "0.0100000000"
*DISP_RANGE_RIGHT "90.0000000000"
*DISP_RANGE_TOP "26084.0000000000"
*DISP_SCALE_MODE_Y "0.0000000000"
*DISP_TAB_NAME "2θ/θ"
*DISP_TITLE_Y "強度"
*DISP_UNIT_Y "cps"
*DISP_WINDOW_NAME "MSG_MACROENGINE"
*FILE_COMMENT " "
*FILE_MD5 ""
*FILE_MEMO " "
*FILE_OPERATOR "Administrator"
*FILE_SAMPLE " "
*FILE_TYPE "RAS_RAW"
*FILE_USERGROUP "システムマネージャ"
*FILE_VERSION "1.0000000000"
*HW_ATTACHMENT_ID "ATT0025"
*HW_ATTACHMENT_NAME "標準|Standard"
*HW_COUNTER_ID-0 "CUT0025"
*HW_COUNTER_ID-1 "CUT0020"
*HW_COUNTER_ID-2 "CUT0020"
*HW_COUNTER_ID-3 "CSL0021"
*HW_COUNTER_ID-4 "CMC0021"
*HW_COUNTER_NAME-0 "D/teX Ultra|D/teX Ultra"
*HW_COUNTER_NAME-1 "None|None"
*HW_COUNTER_NAME-2 "None|None"
*HW_COUNTER_NAME-3 "BBM|BBM"
*HW_COUNTER_NAME-4 "検出器モノクロメータ|Detector monochromator"
*HW_COUNTER_SELECT_NAME "D/teX Ultra|D/teX Ultra"
*HW_GONIOMETER_ID "GON0023"
*HW_GONIOMETER_NAME "SmartLab|SmartLab"
*HW_GONIOMETER_RADIUS-0 "90.0"
*HW_GONIOMETER_RADIUS-1 "114.0"
*HW_GONIOMETER_RADIUS-2 "190.0"
*HW_GONIOMETER_RADIUS-3 "300.0"
*HW_GONIOMETER_RADIUS-4 "187.0"
*HW_GONIOMETER_RADIUS-5 "300.0"
*HW_GONIOMETER_RADIUS-6 "113.0"
*HW_GONIOMETER_RADIUS-7 "331.0"
*HW_I_OPT_ID-0 "CBO0021"
*HW_I_OPT_ID-1 "ICR0023"
*HW_I_OPT_ID-2 "ISL0021"
*HW_I_OPT_ID-3 "ISO0021"
*HW_I_OPT_ID-4 "IAD0021"
*HW_I_OPT_ID-5 "IPR0001"
*HW_I_OPT_NAME-0 "CBOユニット|CBO unit"
*HW_I_OPT_NAME-1 "標準入射光学ユニット|Standard incident optical unit"
*HW_I_OPT_NAME-2 "標準入射スリットボックス|Standard incident slit box"
*HW_I_OPT_NAME-3 "入射平行スリット|Incident parallel slit"
*HW_I_OPT_NAME-4 "長手制限スリット|Length limiting slit"
*HW_I_OPT_NAME-5 "None|None"
*HW_R_ATTENUATER_AUTOMODE "0"
*HW_R_OPT_ID-0 "RSS0021"
*HW_R_OPT_ID-1 "RCR0023"
*HW_R_OPT_ID-2 "RSO0021"
*HW_R_OPT_ID-3 "RRS0021"
*HW_R_OPT_ID-4 "ATN0021"
*HW_R_OPT_ID-5 "RFL0021"
*HW_R_OPT_ID-6 "RAD0021"
*HW_R_OPT_NAME-0 "標準受光スリットボックス1|Standard receiving slit box # 1"
*HW_R_OPT_NAME-1 "標準受光光学ユニット1|Standard receiving unit # 1"
*HW_R_OPT_NAME-2 "標準受光光学ユニット2|Standard receiving optical unit # 2"
*HW_R_OPT_NAME-3 "標準受光スリットボックス2|Standard receiving slit box # 2"
*HW_R_OPT_NAME-4 "標準アッテネータ|Standard Attenuator"
*HW_R_OPT_NAME-5 "Cu Kβ|Cu K-beta"
*HW_R_OPT_NAME-6 "調整用受光スリット|Alignment receiving slit"
*HW_SAMPLE_HOLDER_ID "SMP0023"
*HW_SAMPLE_HOLDER_NAME "標準Zステージ|Standard Z stage"
*HW_XG_CURRENT_MAX "50"
*HW_XG_CURRENT_MIN "2"
*HW_XG_CURRENT_RESOLUTION "2"
*HW_XG_CURRENT_UNIT "mA"
*HW_XG_FOCUS "1mm x 10mm"
*HW_XG_FOCUS_TYPE "Normal"
*HW_XG_ID ""
*HW_XG_NAME "3kW 封入管(ID:1200)|3kW Sealed tube(ID:1200)"
*HW_XG_TARGET_ATOMIC_NUMBER "29.0000000000"
*HW_XG_TARGET_NAME "Cu"
*HW_XG_TYPE "Hermetic"
*HW_XG_VOLTAGE_MAX "60"
*HW_XG_VOLTAGE_MIN "20"
*HW_XG_VOLTAGE_RESOLUTION "2"
*HW_XG_VOLTAGE_UNIT "kV"
*HW_XG_WATT_MAX "2"
*HW_XG_WATT_UNIT "kW"
*HW_XG_WAVE_LENGTH_ALPHA1 "1.540593"
*HW_XG_WAVE_LENGTH_ALPHA2 "1.544414"
*HW_XG_WAVE_LENGTH_BETA "1.392250"
*MEAS_COND_AXIS_NAME-0 "2θ/θ"
*MEAS_COND_AXIS_NAME-1 "2θ"
*MEAS_COND_AXIS_NAME-2 "ω"
*MEAS_COND_AXIS_NAME-3 "Z"
*MEAS_COND_AXIS_NAME-4 "2θ/ω"
*MEAS_COND_AXIS_NAME-5 "θs"
*MEAS_COND_AXIS_NAME-6 "θd"
*MEAS_COND_AXIS_NAME-7 "Ts"
*MEAS_COND_AXIS_NAME-8 "CBO選択スリット"
*MEAS_COND_AXIS_NAME-9 "M"
*MEAS_COND_AXIS_NAME-10 "入射平行スリット"
*MEAS_COND_AXIS_NAME-11 "入射スリット"
*MEAS_COND_AXIS_NAME-12 ""
*MEAS_COND_AXIS_NAME-13 "Zs"
*MEAS_COND_AXIS_NAME-14 "入射光学素子"
*MEAS_COND_AXIS_NAME-15 "長手制限スリット"
*MEAS_COND_AXIS_NAME-16 "センタースリット"
*MEAS_COND_AXIS_NAME-17 "フィルター"
*MEAS_COND_AXIS_NAME-18 "受光スリット1"
*MEAS_COND_AXIS_NAME-19 "受光スリット2"
*MEAS_COND_AXIS_NAME-20 "受光光学素子"
*MEAS_COND_AXIS_NAME-21 "受光平行スリット"
*MEAS_COND_AXIS_NAME-22 "調整用受光スリット"
*MEAS_COND_AXIS_NAME-23 ""
*MEAS_COND_AXIS_NAME-24 ""
*MEAS_COND_AXIS_NAME-25 "Zd"
*MEAS_COND_AXIS_NAME-26 "アッテネータ"
*MEAS_COND_AXIS_NAME-27 "検出器モノクロメータ"
*MEAS_COND_AXIS_NAME-28 "モノクロメータスリット"
*MEAS_COND_AXIS_NAME-29 "プライマリビーム"
*MEAS_COND_AXIS_NAME-30 "PHA"
*MEAS_COND_AXIS_NAME_INTERNAL-0 "TwoThetaTheta"
*MEAS_COND_AXIS_NAME_INTERNAL-1 "TwoTheta"
*MEAS_COND_AXIS_NAME_INTERNAL-2 "Omega"
*MEAS_COND_AXIS_NAME_INTERNAL-3 "Z"
*MEAS_COND_AXIS_NAME_INTERNAL-4 "TwoThetaOmega"
*MEAS_COND_AXIS_NAME_INTERNAL-5 "ThetaS"
*MEAS_COND_AXIS_NAME_INTERNAL-6 "ThetaD"
*MEAS_COND_AXIS_NAME_INTERNAL-7 "Ts"
*MEAS_COND_AXIS_NAME_INTERNAL-8 "CBO"
*MEAS_COND_AXIS_NAME_INTERNAL-9 "CBO-M"
*MEAS_COND_AXIS_NAME_INTERNAL-10 "IncidentSollerSlit"
*MEAS_COND_AXIS_NAME_INTERNAL-11 "IncidentSlitBox"
*MEAS_COND_AXIS_NAME_INTERNAL-12 "IncidentSlitBox-_Axis"
*MEAS_COND_AXIS_NAME_INTERNAL-13 "Zs"
*MEAS_COND_AXIS_NAME_INTERNAL-14 "IncidentMonochromator"
*MEAS_COND_AXIS_NAME_INTERNAL-15 "IncidentAxdSlit"
*MEAS_COND_AXIS_NAME_INTERNAL-16 "CenterSlit"
*MEAS_COND_AXIS_NAME_INTERNAL-17 "Filter"
*MEAS_COND_AXIS_NAME_INTERNAL-18 "ReceivingSlitBox1"
*MEAS_COND_AXIS_NAME_INTERNAL-19 "ReceivingSlitBox2"
*MEAS_COND_AXIS_NAME_INTERNAL-20 "ReceivingOptics"
*MEAS_COND_AXIS_NAME_INTERNAL-21 "ReceivingSollerSlit"
*MEAS_COND_AXIS_NAME_INTERNAL-22 "ReceivingAxdSlit"
*MEAS_COND_AXIS_NAME_INTERNAL-23 "ReceivingSlitBox1-_Axis"
*MEAS_COND_AXIS_NAME_INTERNAL-24 "ReceivingSlitBox2-_Axis"
*MEAS_COND_AXIS_NAME_INTERNAL-25 "ReceivingSlitBox2-Zd"
*MEAS_COND_AXIS_NAME_INTERNAL-26 "Attenuator"
*MEAS_COND_AXIS_NAME_INTERNAL-27 "CounterMonochromator"
*MEAS_COND_AXIS_NAME_INTERNAL-28 "CounterSlit"
*MEAS_COND_AXIS_NAME_INTERNAL-29 "IncidentPrimary"
*MEAS_COND_AXIS_NAME_INTERNAL-30 "PHA"
*MEAS_COND_AXIS_NAME_MAGICNO-0 "83951616.0000000000"
*MEAS_COND_AXIS_NAME_MAGICNO-1 "268632064.0000000000"
*MEAS_COND_AXIS_NAME_MAGICNO-2 "268500992.0000000000"
*MEAS_COND_AXIS_NAME_MAGICNO-3 "285278208.0000000000"
*MEAS_COND_AXIS_NAME_MAGICNO-4 "83951616.0000000000"
*MEAS_COND_AXIS_NAME_MAGICNO-5 "131072.0000000000"
*MEAS_COND_AXIS_NAME_MAGICNO-6 "131072.0000000000"
*MEAS_COND_AXIS_NAME_MAGICNO-7 "318898176.0000000000"
*MEAS_COND_AXIS_NAME_MAGICNO-8 "20971521.0000000000"
*MEAS_COND_AXIS_NAME_MAGICNO-9 "285343744.0000000000"
*MEAS_COND_AXIS_NAME_MAGICNO-10 "20971521.0000000000"
*MEAS_COND_AXIS_NAME_MAGICNO-11 "22020097.0000000000"
*MEAS_COND_AXIS_NAME_MAGICNO-12 "25165824.0000000000"
*MEAS_COND_AXIS_NAME_MAGICNO-13 "318898176.0000000000"
*MEAS_COND_AXIS_NAME_MAGICNO-14 "1.0000000000"
*MEAS_COND_AXIS_NAME_MAGICNO-15 "20971521.0000000000"
*MEAS_COND_AXIS_NAME_MAGICNO-16 "20971521.0000000000"
*MEAS_COND_AXIS_NAME_MAGICNO-17 "20971521.0000000000"
*MEAS_COND_AXIS_NAME_MAGICNO-18 "23068673.0000000000"
*MEAS_COND_AXIS_NAME_MAGICNO-19 "23068673.0000000000"
*MEAS_COND_AXIS_NAME_MAGICNO-20 "20971521.0000000000"
*MEAS_COND_AXIS_NAME_MAGICNO-21 "20971521.0000000000"
*MEAS_COND_AXIS_NAME_MAGICNO-22 "20971521.0000000000"
*MEAS_COND_AXIS_NAME_MAGICNO-23 "25165824.0000000000"
*MEAS_COND_AXIS_NAME_MAGICNO-24 "25165824.0000000000"
*MEAS_COND_AXIS_NAME_MAGICNO-25 "285343744.0000000000"
*MEAS_COND_AXIS_NAME_MAGICNO-26 "17301505.0000000000"
*MEAS_COND_AXIS_NAME_MAGICNO-27 "20971521.0000000000"
*MEAS_COND_AXIS_NAME_MAGICNO-28 "20971521.0000000000"
*MEAS_COND_AXIS_NAME_MAGICNO-29 "20971521.0000000000"
*MEAS_COND_AXIS_NAME_MAGICNO-30 "0.0000000000"
*MEAS_COND_AXIS_OFFSET-0 "-"
*MEAS_COND_AXIS_OFFSET-1 "-0.1081000000"
*MEAS_COND_AXIS_OFFSET-2 "0.3758000000"
*MEAS_COND_AXIS_OFFSET-3 "-"
*MEAS_COND_AXIS_OFFSET-4 "-"
*MEAS_COND_AXIS_OFFSET-5 "0.3758000000"
*MEAS_COND_AXIS_OFFSET-6 "-0.4839000000"
*MEAS_COND_AXIS_OFFSET-7 "-"
*MEAS_COND_AXIS_OFFSET-8 "-"
*MEAS_COND_AXIS_OFFSET-9 "-"
*MEAS_COND_AXIS_OFFSET-10 "-"
*MEAS_COND_AXIS_OFFSET-11 "-"
*MEAS_COND_AXIS_OFFSET-12 "-"
*MEAS_COND_AXIS_OFFSET-13 "-"
*MEAS_COND_AXIS_OFFSET-14 "-"
*MEAS_COND_AXIS_OFFSET-15 "-"
*MEAS_COND_AXIS_OFFSET-16 "-"
*MEAS_COND_AXIS_OFFSET-17 "-"
*MEAS_COND_AXIS_OFFSET-18 "-"
*MEAS_COND_AXIS_OFFSET-19 "-"
*MEAS_COND_AXIS_OFFSET-20 "-"
*MEAS_COND_AXIS_OFFSET-21 "-"
*MEAS_COND_AXIS_OFFSET-22 "-"
*MEAS_COND_AXIS_OFFSET-23 "-"
*MEAS_COND_AXIS_OFFSET-24 "-"
*MEAS_COND_AXIS_OFFSET-25 "-"
*MEAS_COND_AXIS_OFFSET-26 "-"
*MEAS_COND_AXIS_OFFSET-27 "-"
*MEAS_COND_AXIS_OFFSET-28 "-"
*MEAS_COND_AXIS_OFFSET-29 "-"
*MEAS_COND_AXIS_OFFSET-30 "-"
*MEAS_COND_AXIS_POSITION-0 "0.0000000000"
*MEAS_COND_AXIS_POSITION-1 "0.0000000000"
*MEAS_COND_AXIS_POSITION-2 "0.0000000000"
*MEAS_COND_AXIS_POSITION-3 "-0.5500000000"
*MEAS_COND_AXIS_POSITION-4 "0.0000000000"
*MEAS_COND_AXIS_POSITION-5 "0.0000000000"
*MEAS_COND_AXIS_POSITION-6 "0.0000000000"
*MEAS_COND_AXIS_POSITION-7 "-0.4278800000"
*MEAS_COND_AXIS_POSITION-8 "BB"
*MEAS_COND_AXIS_POSITION-9 "0.0000000000"
*MEAS_COND_AXIS_POSITION-10 "Soller_slit_5.0deg"
*MEAS_COND_AXIS_POSITION-11 "2/3deg"
*MEAS_COND_AXIS_POSITION-12 "2.2088000000"
*MEAS_COND_AXIS_POSITION-13 "-0.4140600000"
*MEAS_COND_AXIS_POSITION-14 "0.0000000000"
*MEAS_COND_AXIS_POSITION-15 "10.0mm"
*MEAS_COND_AXIS_POSITION-16 "None"
*MEAS_COND_AXIS_POSITION-17 "Cu_K-beta"
*MEAS_COND_AXIS_POSITION-18 "13.000mm"
*MEAS_COND_AXIS_POSITION-19 "13.000mm"
*MEAS_COND_AXIS_POSITION-20 "No_unit"
*MEAS_COND_AXIS_POSITION-21 "Soller_slit_5.0deg"
*MEAS_COND_AXIS_POSITION-22 "None"
*MEAS_COND_AXIS_POSITION-23 "13.0000000000"
*MEAS_COND_AXIS_POSITION-24 "13.0000000000"
*MEAS_COND_AXIS_POSITION-25 "0.0109400000"
*MEAS_COND_AXIS_POSITION-26 "Open"
*MEAS_COND_AXIS_POSITION-27 "None"
*MEAS_COND_AXIS_POSITION-28 "None"
*MEAS_COND_AXIS_POSITION-29 "None"
*MEAS_COND_AXIS_POSITION-30 "38.0000000000"
*MEAS_COND_AXIS_UNIT-0 "deg"
*MEAS_COND_AXIS_UNIT-1 "deg"
*MEAS_COND_AXIS_UNIT-2 "deg"
*MEAS_COND_AXIS_UNIT-3 "mm"
*MEAS_COND_AXIS_UNIT-4 "deg"
*MEAS_COND_AXIS_UNIT-5 "deg"
*MEAS_COND_AXIS_UNIT-6 "deg"
*MEAS_COND_AXIS_UNIT-7 "mm"
*MEAS_COND_AXIS_UNIT-8 ""
*MEAS_COND_AXIS_UNIT-9 "pulse"
*MEAS_COND_AXIS_UNIT-10 ""
*MEAS_COND_AXIS_UNIT-11 ""
*MEAS_COND_AXIS_UNIT-12 "mm"
*MEAS_COND_AXIS_UNIT-13 "mm"
*MEAS_COND_AXIS_UNIT-14 ""
*MEAS_COND_AXIS_UNIT-15 ""
*MEAS_COND_AXIS_UNIT-16 ""
*MEAS_COND_AXIS_UNIT-17 ""
*MEAS_COND_AXIS_UNIT-18 ""
*MEAS_COND_AXIS_UNIT-19 ""
*MEAS_COND_AXIS_UNIT-20 ""
*MEAS_COND_AXIS_UNIT-21 ""
*MEAS_COND_AXIS_UNIT-22 ""
*MEAS_COND_AXIS_UNIT-23 "mm"
*MEAS_COND_AXIS_UNIT-24 "mm"
*MEAS_COND_AXIS_UNIT-25 "mm"
*MEAS_COND_AXIS_UNIT-26 ""
*MEAS_COND_AXIS_UNIT-27 ""
*MEAS_COND_AXIS_UNIT-28 ""
*MEAS_COND_AXIS_UNIT-29 ""
*MEAS_COND_AXIS_UNIT-30 "div"
*MEAS_COND_COUNTER_CNTLOSS_CORR "0.0000000000"
*MEAS_COND_COUNTER_PHABASE "38.0000000000"
*MEAS_COND_COUNTER_PHAWINDOW "16.0000000000"
*MEAS_COND_COUNTER_PHA_UNIT "div"
*MEAS_COND_COUNTER_TAUDIFF "30.0000000000"
*MEAS_COND_COUNTER_TAUINT "0.0000000000"
*MEAS_COND_IRRADIATION_MODE "OFF"
*MEAS_COND_IRRADIATION_WIDTH ""
*MEAS_COND_OPT_ATTR "集中法"
*MEAS_COND_OPT_NAME "@集中法"
*MEAS_COND_UNSYMMETRIC_MODE "OFF"
*MEAS_COND_XG_CURRENT "30.0000000000"
*MEAS_COND_XG_VOLTAGE "40.0000000000"
*MEAS_COND_XG_WAVE_TYPE "Ka"
*MEAS_DATA_COUNT "3501.0000000000"
*MEAS_SCAN_AXIS_X "2θ/θ"
*MEAS_SCAN_AXIS_X_INTERNAL "TwoThetaTheta"
*MEAS_SCAN_END_TIME "09/10/20 15:37:49"
*MEAS_SCAN_MODE "CONTINUOUS"
*MEAS_SCAN_MONITOR "0"
*MEAS_SCAN_RESOLUTION_X "0.0002"
*MEAS_SCAN_SPEED "1.0"
*MEAS_SCAN_SPEED_UNIT "deg/min"
*MEAS_SCAN_START "20.0000000000"
*MEAS_SCAN_START_TIME "09/10/20 14:24:54"
*MEAS_SCAN_STEP "0.0200000000"
*MEAS_SCAN_STOP "90.0000000000"
*MEAS_SCAN_UNIT_X "deg"
*MEAS_SCAN_UNIT_Y "counts"
*RAS_HEADER_END
*RAS_INT_START
20.0000 9605.0000 1.0000
20.0600 9891.0000 1.0000
20.1200 9595.0000 1.0000
20.1800 9778.0000 1.0000
20.2400 9914.0000 1.0000
20.3000 9689.0000 1.0000
20.3600 9760.0000 1.0000
20.4200 9825.0000 1.0000
20.4800 9814.0000 1.0000
20.5400 9695.0000 1.0000
20.6000 9777.0000 1.0000
20.6600 9787.0000 1.0000
20.7200 9834.0000 1.0000
20.7800 10359.0000 1.0000
20.8400 10776.0000 1.0000
20.9000 12059.0000 1.0000
20.9600 10804.0000 1.0000
21.0200 10113.0000 1.0000
21.0800 9744.0000 1.0000
21.1400 9949.0000 1.0000
21.2000 9716.0000 1.0000
21.2600 9833.0000 1.0000
21.3200 9883.0000 1.0000
21.3800 9912.0000 1.0000
21.4400 9723.0000 1.0000
21.5000 9768.0000 1.0000
21.5600 9738.0000 1.0000
21.6200 9946.0000 1.0000
21.6800 9691.0000 1.0000
21.7400 9913.0000 1.0000
21.8000 9837.0000 1.0000
21.8600 9855.0000 1.0000
21.9200 9959.0000 1.0000
21.9800 9738.0000 1.0000
22.0400 9865.0000 1.0000
22.1000 9746.0000 1.0000
22.1600 9753.0000 1.0000
22.2200 9809.0000 1.0000
22.2800 9686.0000 1.0000
22.3400 9718.0000 1.0000
22.4000 9780.0000 1.0000
22.4600 9865.0000 1.0000
22.5200 9888.0000 1.0000
22.5800 9820.0000 1.0000
22.6400 9784.0000 1.0000
22.7000 9804.0000 1.0000
22.7600 9710.0000 1.0000
22.8200 9737.0000 1.0000
22.8800 9756.0000 1.0000
22.9400 9908.0000 1.0000
23.0000 9675.0000 1.0000
23.0600 9725.0000 1.0000
23.1200 9789.0000 1.0000
23.1800 9901.0000 1.0000
23.2400 9796.0000 1.0000
23.3000 9733.0000 1.0000
23.3600 9746.0000 1.0000
23.4200 9766.0000 1.0000
23.4800 9801.0000 1.0000
23.5400 10020.0000 1.0000
23.6000 9861.0000 1.0000
23.6600 9733.0000 1.0000
23.7200 9958.0000 1.0000
23.7800 9859.0000 1.0000
23.8400 9961.0000 1.0000
23.9000 9949.0000 1.0000
23.9600 9924.0000 1.0000
24.0200 9911.0000 1.0000
24.0800 10218.0000 1.0000
24.1400 10491.0000 1.0000
24.2000 10575.0000 1.0000
24.2600 10375.0000 1.0000
24.3200 10096.0000 1.0000
24.3800 9894.0000 1.0000
24.4400 9857.0000 1.0000
24.5000 9856.0000 1.0000
24.5600 9685.0000 1.0000
24.6200 9817.0000 1.0000
24.6800 9825.0000 1.0000
24.7400 9737.0000 1.0000
24.8000 9813.0000 1.0000
24.8600 9818.0000 1.0000
24.9200 9816.0000 1.0000
24.9800 9803.0000 1.0000
25.0400 9974.0000 1.0000
25.1000 9963.0000 1.0000
25.1600 9788.0000 1.0000
25.2200 9850.0000 1.0000
25.2800 9969.0000 1.0000
25.3400 10137.0000 1.0000
25.4000 10160.0000 1.0000
25.4600 10477.0000 1.0000
25.5200 11256.0000 1.0000
25.5800 12229.0000 1.0000
25.6400 12385.0000 1.0000
25.7000 11141.0000 1.0000
25.7600 10531.0000 1.0000
25.8200 10292.0000 1.0000
25.8800 10167.0000 1.0000
25.9400 10171.0000 1.0000
26.0000 9879.0000 1.0000
26.0600 9781.0000 1.0000
26.1200 10033.0000 1.0000
26.1800 9893.0000 1.0000
26.2400 9873.0000 1.0000
26.3000 10092.0000 1.0000
26.3600 10010.0000 1.0000
26.4200 10358.0000 1.0000
26.4800 10448.0000 1.0000
26.5400 11002.0000 1.0000
26.6000 13319.0000 1.0000
26.6600 19308.0000 1.0000
26.7200 17259.0000 1.0000
26.7800 13139.0000 1.0000
26.8400 10487.0000 1.0000
26.9000 10275.0000 1.0000
26.9600 10012.0000 1.0000
27.0200 9870.0000 1.0000
27.0800 10031.0000 1.0000
27.1400 9764.0000 1.0000
27.2000 10063.0000 1.0000
27.2600 10040.0000 1.0000
27.3200 9769.0000 1.0000
27.3800 9792.0000 1.0000
27.4400 9776.0000 1.0000
27.5000 9893.0000 1.0000
27.5600 9927.0000 1.0000
27.6200 9875.0000 1.0000
27.6800 9867.0000 1.0000
27.7400 9792.0000 1.0000
27.8000 9881.0000 1.0000
27.8600 9874.0000 1.0000
27.9200 9782.0000 1.0000
27.9800 9770.0000 1.0000
28.0400 9829.0000 1.0000
28.1000 9730.0000 1.0000
28.1600 9764.0000 1.0000
28.2200 9901.0000 1.0000
28.2800 9751.0000 1.0000
28.3400 9741.0000 1.0000
28.4000 9719.0000 1.0000
28.4600 9805.0000 1.0000
28.5200 9734.0000 1.0000
28.5800 9804.0000 1.0000
28.6400 9700.0000 1.0000
28.7000 9773.0000 1.0000
28.7600 9636.0000 1.0000
28.8200 9631.0000 1.0000
28.8800 9870.0000 1.0000
28.9400 9820.0000 1.0000
29.0000 9683.0000 1.0000
29.0600 9846.0000 1.0000
29.1200 9776.0000 1.0000
29.1800 9827.0000 1.0000
29.2400 9723.0000 1.0000
29.3000 9843.0000 1.0000
29.3600 10007.0000 1.0000
29.4200 9765.0000 1.0000
29.4800 9688.0000 1.0000
29.5400 9681.0000 1.0000
29.6000 9792.0000 1.0000
29.6600 9689.0000 1.0000
29.7200 9751.0000 1.0000
29.7800 9883.0000 1.0000
29.8400 9781.0000 1.0000
29.9000 10036.0000 1.0000
29.9600 10287.0000 1.0000
30.0200 10735.0000 1.0000
30.0800 11896.0000 1.0000
30.1400 14085.0000 1.0000
30.2000 14317.0000 1.0000
30.2600 12816.0000 1.0000
30.3200 11246.0000 1.0000
30.3800 10460.0000 1.0000
30.4400 10020.0000 1.0000
30.5000 9861.0000 1.0000
30.5600 10008.0000 1.0000
30.6200 9881.0000 1.0000
30.6800 9931.0000 1.0000
30.7400 9678.0000 1.0000
30.8000 9734.0000 1.0000
30.8600 9767.0000 1.0000
30.9200 9775.0000 1.0000
30.9800 9773.0000 1.0000
31.0400 9748.0000 1.0000
31.1000 9800.0000 1.0000
31.1600 9609.0000 1.0000
31.2200 9630.0000 1.0000
31.2800 9673.0000 1.0000
31.3400 9683.0000 1.0000
31.4000 9855.0000 1.0000
31.4600 9881.0000 1.0000
31.5200 9823.0000 1.0000
31.5800 9690.0000 1.0000
31.6400 9735.0000 1.0000
31.7000 9649.0000 1.0000
31.7600 9554.0000 1.0000
31.8200 9667.0000 1.0000
31.8800 9639.0000 1.0000
31.9400 9809.0000 1.0000
32.0000 9824.0000 1.0000
32.0600 9729.0000 1.0000
32.1200 9842.0000 1.0000
32.1800 9761.0000 1.0000
32.2400 9616.0000 1.0000
32.3000 9581.0000 1.0000
32.3600 9596.0000 1.0000
32.4200 9731.0000 1.0000
32.4800 9814.0000 1.0000
32.5400 9672.0000 1.0000
32.6000 9681.0000 1.0000
32.6600 9718.0000 1.0000
32.7200 9565.0000 1.0000
32.7800 9735.0000 1.0000
32.8400 9740.0000 1.0000
32.9000 9881.0000 1.0000
32.9600 9801.0000 1.0000
33.0200 9916.0000 1.0000
33.0800 10273.0000 1.0000
33.1400 11141.0000 1.0000
33.2000 12137.0000 1.0000
33.2600 11530.0000 1.0000
33.3200 10762.0000 1.0000
33.3800 9900.0000 1.0000
33.4400 9793.0000 1.0000
33.5000 9668.0000 1.0000
33.5600 9671.0000 1.0000
33.6200 9475.0000 1.0000
33.6800 9641.0000 1.0000
33.7400 9551.0000 1.0000
33.8000 9660.0000 1.0000
33.8600 9633.0000 1.0000
33.9200 9500.0000 1.0000
33.9800 9650.0000 1.0000
34.0400 9796.0000 1.0000
34.1000 9495.0000 1.0000
34.1600 9503.0000 1.0000
34.2200 9701.0000 1.0000
34.2800 9884.0000 1.0000
34.3400 9668.0000 1.0000
34.4000 9659.0000 1.0000
34.4600 9658.0000 1.0000
34.5200 9797.0000 1.0000
34.5800 9786.0000 1.0000
34.6400 9774.0000 1.0000
34.7000 9875.0000 1.0000
34.7600 9837.0000 1.0000
34.8200 9718.0000 1.0000
34.8800 10110.0000 1.0000
34.9400 10093.0000 1.0000
35.0000 10460.0000 1.0000
35.0600 11219.0000 1.0000
35.1200 12610.0000 1.0000
35.1800 14593.0000 1.0000
35.2400 13822.0000 1.0000
35.3000 13273.0000 1.0000
35.3600 12952.0000 1.0000
35.4200 15612.0000 1.0000
35.4800 22681.0000 1.0000
35.5400 26084.0000 1.0000
35.6000 23010.0000 1.0000
35.6600 18773.0000 1.0000
35.7200 14806.0000 1.0000
35.7800 12385.0000 1.0000
35.8400 10801.0000 1.0000
35.9000 10533.0000 1.0000
35.9600 10120.0000 1.0000
36.0200 9939.0000 1.0000
36.0800 9672.0000 1.0000
36.1400 9544.0000 1.0000
36.2000 9655.0000 1.0000
36.2600 9563.0000 1.0000
36.3200 9713.0000 1.0000
36.3800 9777.0000 1.0000
36.4400 9870.0000 1.0000
36.5000 9921.0000 1.0000
36.5600 12055.0000 1.0000
36.6200 11344.0000 1.0000
36.6800 10924.0000 1.0000
36.7400 9958.0000 1.0000
36.8000 9714.0000 1.0000
36.8600 9650.0000 1.0000
36.9200 9504.0000 1.0000
36.9800 9576.0000 1.0000
37.0400 9822.0000 1.0000
37.1000 10241.0000 1.0000
37.1600 10371.0000 1.0000
37.2200 10400.0000 1.0000
37.2800 10002.0000 1.0000
37.3400 9737.0000 1.0000
37.4000 9710.0000 1.0000
37.4600 9527.0000 1.0000
37.5200 9634.0000 1.0000
37.5800 9639.0000 1.0000
37.6400 9761.0000 1.0000
37.7000 9951.0000 1.0000
37.7600 10859.0000 1.0000
37.8200 11315.0000 1.0000
37.8800 10840.0000 1.0000
37.9400 10358.0000 1.0000
38.0000 9783.0000 1.0000
38.0600 9770.0000 1.0000
38.1200 9602.0000 1.0000
38.1800 9440.0000 1.0000
38.2400 9585.0000 1.0000
38.3000 9488.0000 1.0000
38.3600 9461.0000 1.0000
38.4200 9520.0000 1.0000
38.4800 9340.0000 1.0000
38.5400 9541.0000 1.0000
38.6000 9552.0000 1.0000
38.6600 9356.0000 1.0000
38.7200 9440.0000 1.0000
38.7800 9397.0000 1.0000
38.8400 9527.0000 1.0000
38.9000 9596.0000 1.0000
38.9600 9460.0000 1.0000
39.0200 9395.0000 1.0000
39.0800 9653.0000 1.0000
39.1400 9365.0000 1.0000
39.2000 9535.0000 1.0000
39.2600 9612.0000 1.0000
39.3200 9374.0000 1.0000
39.3800 9418.0000 1.0000
39.4400 9742.0000 1.0000
39.5000 10109.0000 1.0000
39.5600 9719.0000 1.0000
39.6200 9824.0000 1.0000
39.6800 9596.0000 1.0000
39.7400 9419.0000 1.0000
39.8000 9330.0000 1.0000
39.8600 9573.0000 1.0000
39.9200 9362.0000 1.0000
39.9800 9539.0000 1.0000
40.0400 9486.0000 1.0000
40.1000 9429.0000 1.0000
40.1600 9420.0000 1.0000
40.2200 9430.0000 1.0000
40.2800 9632.0000 1.0000
40.3400 9871.0000 1.0000
40.4000 9649.0000 1.0000
40.4600 9560.0000 1.0000
40.5200 9483.0000 1.0000
40.5800 9599.0000 1.0000
40.6400 9280.0000 1.0000
40.7000 9421.0000 1.0000
40.7600 9525.0000 1.0000
40.8200 9713.0000 1.0000
40.8800 10007.0000 1.0000
40.9400 9949.0000 1.0000
41.0000 9830.0000 1.0000
41.0600 9448.0000 1.0000
41.1200 9658.0000 1.0000
41.1800 9380.0000 1.0000
41.2400 9347.0000 1.0000
41.3000 9489.0000 1.0000
41.3600 9383.0000 1.0000
41.4200 9536.0000 1.0000
41.4800 9485.0000 1.0000
41.5400 9462.0000 1.0000
41.6000 9515.0000 1.0000
41.6600 9474.0000 1.0000
41.7200 9496.0000 1.0000
41.7800 9479.0000 1.0000
41.8400 9413.0000 1.0000
41.9000 9524.0000 1.0000
41.9600 9457.0000 1.0000
42.0200 9543.0000 1.0000
42.0800 9526.0000 1.0000
42.1400 9492.0000 1.0000
42.2000 9422.0000 1.0000
42.2600 9440.0000 1.0000
42.3200 9543.0000 1.0000
42.3800 9505.0000 1.0000
42.4400 9595.0000 1.0000
42.5000 9945.0000 1.0000
42.5600 9621.0000 1.0000
42.6200 9797.0000 1.0000
42.6800 9625.0000 1.0000
42.7400 9550.0000 1.0000
42.8000 9616.0000 1.0000
42.8600 9572.0000 1.0000
42.9200 9906.0000 1.0000
42.9800 9973.0000 1.0000
43.0400 10580.0000 1.0000
43.1000 11847.0000 1.0000
43.1600 13315.0000 1.0000
43.2200 13070.0000 1.0000
43.2800 13362.0000 1.0000
43.3400 14259.0000 1.0000
43.4000 14707.0000 1.0000
43.4600 13208.0000 1.0000
43.5200 12262.0000 1.0000
43.5800 10614.0000 1.0000
43.6400 10082.0000 1.0000
43.7000 9874.0000 1.0000
43.7600 9690.0000 1.0000
43.8200 9796.0000 1.0000
43.8800 9649.0000 1.0000
43.9400 9531.0000 1.0000
44.0000 9512.0000 1.0000
44.0600 9662.0000 1.0000
44.1200 9474.0000 1.0000
44.1800 9488.0000 1.0000
44.2400 9472.0000 1.0000
44.3000 9298.0000 1.0000
44.3600 9417.0000 1.0000
44.4200 9508.0000 1.0000
44.4800 9674.0000 1.0000
44.5400 9408.0000 1.0000
44.6000 9494.0000 1.0000
44.6600 9505.0000 1.0000
44.7200 9527.0000 1.0000
44.7800 9572.0000 1.0000
44.8400 9622.0000 1.0000
44.9000 9482.0000 1.0000
44.9600 9482.0000 1.0000
45.0200 9422.0000 1.0000
45.0800 9459.0000 1.0000
45.1400 9332.0000 1.0000
45.2000 9620.0000 1.0000
45.2600 9467.0000 1.0000
45.3200 9440.0000 1.0000
45.3800 9513.0000 1.0000
45.4400 9347.0000 1.0000
45.5000 9402.0000 1.0000
45.5600 9558.0000 1.0000
45.6200 9677.0000 1.0000
45.6800 9342.0000 1.0000
45.7400 9471.0000 1.0000
45.8000 9786.0000 1.0000
45.8600 9781.0000 1.0000
45.9200 9642.0000 1.0000
45.9800 9770.0000 1.0000
46.0400 9531.0000 1.0000
46.1000 9440.0000 1.0000
46.1600 9344.0000 1.0000
46.2200 9613.0000 1.0000
46.2800 9479.0000 1.0000
46.3400 9570.0000 1.0000
46.4000 9417.0000 1.0000
46.4600 9343.0000 1.0000
46.5200 9493.0000 1.0000
46.5800 9419.0000 1.0000
46.6400 9509.0000 1.0000
46.7000 9446.0000 1.0000
46.7600 9584.0000 1.0000
46.8200 9511.0000 1.0000
46.8800 9398.0000 1.0000
46.9400 9567.0000 1.0000
47.0000 9725.0000 1.0000
47.0600 9476.0000 1.0000
47.1200 9504.0000 1.0000
47.1800 9534.0000 1.0000
47.2400 9555.0000 1.0000
47.3000 9578.0000 1.0000
47.3600 9474.0000 1.0000
47.4200 9621.0000 1.0000
47.4800 9352.0000 1.0000
47.5400 9580.0000 1.0000
47.6000 9416.0000 1.0000
47.6600 9552.0000 1.0000
47.7200 9556.0000 1.0000
47.7800 9563.0000 1.0000
47.8400 9328.0000 1.0000
47.9000 9366.0000 1.0000
47.9600 9451.0000 1.0000
48.0200 9776.0000 1.0000
48.0800 9462.0000 1.0000
48.1400 9714.0000 1.0000
48.2000 9530.0000 1.0000
48.2600 9396.0000 1.0000
48.3200 9414.0000 1.0000
48.3800 9429.0000 1.0000
48.4400 9586.0000 1.0000
48.5000 9566.0000 1.0000
48.5600 9313.0000 1.0000
48.6200 9533.0000 1.0000
48.6800 9443.0000 1.0000
48.7400 9532.0000 1.0000
48.8000 9587.0000 1.0000
48.8600 9359.0000 1.0000
48.9200 9565.0000 1.0000
48.9800 9676.0000 1.0000
49.0400 9525.0000 1.0000
49.1000 9525.0000 1.0000
49.1600 9516.0000 1.0000
49.2200 9746.0000 1.0000
49.2800 9600.0000 1.0000
49.3400 9750.0000 1.0000
49.4000 9847.0000 1.0000
49.4600 10156.0000 1.0000
49.5200 10218.0000 1.0000
49.5800 10167.0000 1.0000
49.6400 10162.0000 1.0000
49.7000 9768.0000 1.0000
49.7600 9605.0000 1.0000
49.8200 9615.0000 1.0000
49.8800 9753.0000 1.0000
49.9400 9540.0000 1.0000
50.0000 9633.0000 1.0000
50.0600 9839.0000 1.0000
50.1200 9994.0000 1.0000
50.1800 10596.0000 1.0000
50.2400 9867.0000 1.0000
50.3000 10021.0000 1.0000
50.3600 9612.0000 1.0000
50.4200 9473.0000 1.0000
50.4800 9662.0000 1.0000
50.5400 9525.0000 1.0000
50.6000 9402.0000 1.0000
50.6600 9597.0000 1.0000
50.7200 9577.0000 1.0000
50.7800 9361.0000 1.0000
50.8400 9474.0000 1.0000
50.9000 9724.0000 1.0000
50.9600 9531.0000 1.0000
51.0200 9484.0000 1.0000
51.0800 9565.0000 1.0000
51.1400 9496.0000 1.0000
51.2000 9475.0000 1.0000
51.2600 9531.0000 1.0000
51.3200 9583.0000 1.0000
51.3800 9586.0000 1.0000
51.4400 9368.0000 1.0000
51.5000 9640.0000 1.0000
51.5600 9687.0000 1.0000
51.6200 9629.0000 1.0000
51.6800 9583.0000 1.0000
51.7400 9430.0000 1.0000
51.8000 9510.0000 1.0000
51.8600 9497.0000 1.0000
51.9200 9614.0000 1.0000
51.9800 9666.0000 1.0000
52.0400 9684.0000 1.0000
52.1000 9567.0000 1.0000
52.1600 9735.0000 1.0000
52.2200 9697.0000 1.0000
52.2800 9758.0000 1.0000
52.3400 9847.0000 1.0000
52.4000 10032.0000 1.0000
52.4600 10204.0000 1.0000
52.5200 10863.0000 1.0000
52.5800 11828.0000 1.0000
52.6400 11048.0000 1.0000
52.7000 10967.0000 1.0000
52.7600 10438.0000 1.0000
52.8200 10026.0000 1.0000
52.8800 9676.0000 1.0000
52.9400 9777.0000 1.0000
53.0000 9632.0000 1.0000
53.0600 9563.0000 1.0000
53.1200 9754.0000 1.0000
53.1800 9801.0000 1.0000
53.2400 9695.0000 1.0000
53.3000 9731.0000 1.0000
53.3600 9859.0000 1.0000
53.4200 9990.0000 1.0000
53.4800 10736.0000 1.0000
53.5400 11080.0000 1.0000
53.6000 10694.0000 1.0000
53.6600 10716.0000 1.0000
53.7200 10528.0000 1.0000
53.7800 9990.0000 1.0000
53.8400 9928.0000 1.0000
53.9000 9743.0000 1.0000
53.9600 10018.0000 1.0000
54.0200 10254.0000 1.0000
54.0800 10727.0000 1.0000
54.1400 10442.0000 1.0000
54.2000 10234.0000 1.0000
54.2600 10216.0000 1.0000
54.3200 9896.0000 1.0000
54.3800 9718.0000 1.0000
54.4400 9700.0000 1.0000
54.5000 9682.0000 1.0000
54.5600 9563.0000 1.0000
54.6200 9684.0000 1.0000
54.6800 9731.0000 1.0000
54.7400 9686.0000 1.0000
54.8000 9775.0000 1.0000
54.8600 9851.0000 1.0000
54.9200 10305.0000 1.0000
54.9800 9816.0000 1.0000
55.0400 9985.0000 1.0000
55.1000 9753.0000 1.0000
55.1600 9717.0000 1.0000
55.2200 9732.0000 1.0000
55.2800 9720.0000 1.0000
55.3400 9830.0000 1.0000
55.4000 9747.0000 1.0000
55.4600 9859.0000 1.0000
55.5200 9772.0000 1.0000
55.5800 9594.0000 1.0000
55.6400 9796.0000 1.0000
55.7000 9831.0000 1.0000
55.7600 9806.0000 1.0000
55.8200 9700.0000 1.0000
55.8800 9723.0000 1.0000
55.9400 9754.0000 1.0000
56.0000 9821.0000 1.0000
56.0600 9847.0000 1.0000
56.1200 9735.0000 1.0000
56.1800 9806.0000 1.0000
56.2400 9582.0000 1.0000
56.3000 9757.0000 1.0000
56.3600 9679.0000 1.0000
56.4200 9719.0000 1.0000
56.4800 9905.0000 1.0000
56.5400 9827.0000 1.0000
56.6000 9825.0000 1.0000
56.6600 9795.0000 1.0000
56.7200 9723.0000 1.0000
56.7800 9885.0000 1.0000
56.8400 10188.0000 1.0000
56.9000 10438.0000 1.0000
56.9600 11398.0000 1.0000
57.0200 13310.0000 1.0000
57.0800 13668.0000 1.0000
57.1400 13156.0000 1.0000
57.2000 13242.0000 1.0000
57.2600 12453.0000 1.0000
57.3200 11863.0000 1.0000
57.3800 11555.0000 1.0000
57.4400 12439.0000 1.0000
57.5000 14095.0000 1.0000
57.5600 13821.0000 1.0000
57.6200 12477.0000 1.0000
57.6800 12532.0000 1.0000
57.7400 11597.0000 1.0000
57.8000 10611.0000 1.0000
57.8600 10184.0000 1.0000
57.9200 10002.0000 1.0000
57.9800 10013.0000 1.0000
58.0400 9669.0000 1.0000
58.1000 9958.0000 1.0000
58.1600 9799.0000 1.0000
58.2200 9922.0000 1.0000
58.2800 9822.0000 1.0000
58.3400 9915.0000 1.0000
58.4000 9746.0000 1.0000
58.4600 9643.0000 1.0000
58.5200 9739.0000 1.0000
58.5800 9807.0000 1.0000
58.6400 9602.0000 1.0000
58.7000 9667.0000 1.0000
58.7600 9616.0000 1.0000
58.8200 9756.0000 1.0000
58.8800 9837.0000 1.0000
58.9400 9656.0000 1.0000
59.0000 9799.0000 1.0000
59.0600 9806.0000 1.0000
59.1200 9664.0000 1.0000
59.1800 9700.0000 1.0000
59.2400 9702.0000 1.0000
59.3000 9788.0000 1.0000
59.3600 9866.0000 1.0000
59.4200 9812.0000 1.0000
59.4800 9575.0000 1.0000
59.5400 9771.0000 1.0000
59.6000 9902.0000 1.0000
59.6600 9803.0000 1.0000
59.7200 9921.0000 1.0000
59.7800 10060.0000 1.0000
59.8400 9944.0000 1.0000
59.9000 10149.0000 1.0000
59.9600 10804.0000 1.0000
60.0200 10627.0000 1.0000
60.0800 10224.0000 1.0000
60.1400 10646.0000 1.0000
60.2000 9995.0000 1.0000
60.2600 9952.0000 1.0000
60.3200 9607.0000 1.0000
60.3800 9851.0000 1.0000
60.4400 9911.0000 1.0000
60.5000 9892.0000 1.0000
60.5600 9944.0000 1.0000
60.6200 9903.0000 1.0000
60.6800 9709.0000 1.0000
60.7400 9966.0000 1.0000
60.8000 9728.0000 1.0000
60.8600 9822.0000 1.0000
60.9200 9982.0000 1.0000
60.9800 9948.0000 1.0000
61.0400 9857.0000 1.0000
61.1000 10085.0000 1.0000
61.1600 10103.0000 1.0000
61.2200 10118.0000 1.0000
61.2800 10154.0000 1.0000
61.3400 10331.0000 1.0000
61.4000 10061.0000 1.0000
61.4600 10120.0000 1.0000
61.5200 10070.0000 1.0000
61.5800 9959.0000 1.0000
61.6400 10065.0000 1.0000
61.7000 9806.0000 1.0000
61.7600 9927.0000 1.0000
61.8200 9726.0000 1.0000
61.8800 9837.0000 1.0000
61.9400 9888.0000 1.0000
62.0000 9804.0000 1.0000
62.0600 10180.0000 1.0000
62.1200 9997.0000 1.0000
62.1800 10024.0000 1.0000
62.2400 10111.0000 1.0000
62.3000 10180.0000 1.0000
62.3600 10322.0000 1.0000
62.4200 10965.0000 1.0000
62.4800 11385.0000 1.0000
62.5400 12096.0000 1.0000
62.6000 14482.0000 1.0000
62.6600 16123.0000 1.0000
62.7200 14800.0000 1.0000
62.7800 13904.0000 1.0000
62.8400 13727.0000 1.0000
62.9000 12566.0000 1.0000
62.9600 11259.0000 1.0000
63.0200 10903.0000 1.0000
63.0800 10561.0000 1.0000
63.1400 10480.0000 1.0000
63.2000 10248.0000 1.0000
63.2600 10160.0000 1.0000
63.3200 9977.0000 1.0000
63.3800 10047.0000 1.0000
63.4400 9975.0000 1.0000
63.5000 9895.0000 1.0000
63.5600 10102.0000 1.0000
63.6200 10036.0000 1.0000
63.6800 9875.0000 1.0000
63.7400 10005.0000 1.0000
63.8000 10163.0000 1.0000
63.8600 10081.0000 1.0000
63.9200 10048.0000 1.0000
63.9800 10699.0000 1.0000
64.0400 10949.0000 1.0000
64.1000 10418.0000 1.0000
64.1600 10285.0000 1.0000
64.2200 10447.0000 1.0000
64.2800 10124.0000 1.0000
64.3400 10015.0000 1.0000
64.4000 9999.0000 1.0000
64.4600 10005.0000 1.0000
64.5200 9989.0000 1.0000
64.5800 9827.0000 1.0000
64.6400 9911.0000 1.0000
64.7000 9976.0000 1.0000
64.7600 9858.0000 1.0000
64.8200 9963.0000 1.0000
64.8800 10147.0000 1.0000
64.9400 10016.0000 1.0000
65.0000 9941.0000 1.0000
65.0600 9987.0000 1.0000
65.1200 9973.0000 1.0000
65.1800 9856.0000 1.0000
65.2400 10129.0000 1.0000
65.3000 9841.0000 1.0000
65.3600 9874.0000 1.0000
65.4200 9944.0000 1.0000
65.4800 10109.0000 1.0000
65.5400 10085.0000 1.0000
65.6000 10134.0000 1.0000
65.6600 9861.0000 1.0000
65.7200 10117.0000 1.0000
65.7800 10094.0000 1.0000
65.8400 10227.0000 1.0000
65.9000 10143.0000 1.0000
65.9600 10201.0000 1.0000
66.0200 10245.0000 1.0000
66.0800 10194.0000 1.0000
66.1400 10177.0000 1.0000
66.2000 10007.0000 1.0000
66.2600 10154.0000 1.0000
66.3200 10163.0000 1.0000
66.3800 10388.0000 1.0000
66.4400 10550.0000 1.0000
66.5000 11355.0000 1.0000
66.5600 11638.0000 1.0000
66.6200 10834.0000 1.0000
66.6800 10835.0000 1.0000
66.7400 10995.0000 1.0000
66.8000 10550.0000 1.0000
66.8600 10317.0000 1.0000
66.9200 10029.0000 1.0000
66.9800 10114.0000 1.0000
67.0400 10043.0000 1.0000
67.1000 10028.0000 1.0000
67.1600 10094.0000 1.0000
67.2200 10213.0000 1.0000
67.2800 10034.0000 1.0000
67.3400 10097.0000 1.0000
67.4000 10140.0000 1.0000
67.4600 10315.0000 1.0000
67.5200 10162.0000 1.0000
67.5800 10102.0000 1.0000
67.6400 10144.0000 1.0000
67.7000 10165.0000 1.0000
67.7600 10718.0000 1.0000
67.8200 10433.0000 1.0000
67.8800 10403.0000 1.0000
67.9400 10592.0000 1.0000
68.0000 10500.0000 1.0000
68.0600 10823.0000 1.0000
68.1200 11817.0000 1.0000
68.1800 12789.0000 1.0000
68.2400 12947.0000 1.0000
68.3000 12215.0000 1.0000
68.3600 12119.0000 1.0000
68.4200 11703.0000 1.0000
68.4800 11066.0000 1.0000
68.5400 10651.0000 1.0000
68.6000 10455.0000 1.0000
68.6600 10234.0000 1.0000
68.7200 9970.0000 1.0000
68.7800 10268.0000 1.0000
68.8400 10191.0000 1.0000
68.9000 10197.0000 1.0000
68.9600 10018.0000 1.0000
69.0200 10216.0000 1.0000
69.0800 10111.0000 1.0000
69.1400 10049.0000 1.0000
69.2000 10233.0000 1.0000
69.2600 10101.0000 1.0000
69.3200 10165.0000 1.0000
69.3800 10177.0000 1.0000
69.4400 10227.0000 1.0000
69.5000 10066.0000 1.0000
69.5600 10246.0000 1.0000
69.6200 10192.0000 1.0000
69.6800 10121.0000 1.0000
69.7400 10073.0000 1.0000
69.8000 10127.0000 1.0000
69.8600 10170.0000 1.0000
69.9200 10049.0000 1.0000
69.9800 10039.0000 1.0000
70.0400 10212.0000 1.0000
70.1000 10170.0000 1.0000
70.1600 10096.0000 1.0000
70.2200 10284.0000 1.0000
70.2800 10207.0000 1.0000
70.3400 10100.0000 1.0000
70.4000 10085.0000 1.0000
70.4600 10182.0000 1.0000
70.5200 10034.0000 1.0000
70.5800 10210.0000 1.0000
70.6400 10242.0000 1.0000
70.7000 10143.0000 1.0000
70.7600 10232.0000 1.0000
70.8200 10221.0000 1.0000
70.8800 10095.0000 1.0000
70.9400 10258.0000 1.0000
71.0000 10501.0000 1.0000
71.0600 10505.0000 1.0000
71.1200 10569.0000 1.0000
71.1800 10412.0000 1.0000
71.2400 10413.0000 1.0000
71.3000 10492.0000 1.0000
71.3600 10375.0000 1.0000
71.4200 10311.0000 1.0000
71.4800 10143.0000 1.0000
71.5400 10247.0000 1.0000
71.6000 10327.0000 1.0000
71.6600 10492.0000 1.0000
71.7200 10169.0000 1.0000
71.7800 10306.0000 1.0000
71.8400 10291.0000 1.0000
71.9000 10338.0000 1.0000
71.9600 10433.0000 1.0000
72.0200 10462.0000 1.0000
72.0800 10517.0000 1.0000
72.1400 10372.0000 1.0000
72.2000 10269.0000 1.0000
72.2600 10322.0000 1.0000
72.3200 10094.0000 1.0000
72.3800 10184.0000 1.0000
72.4400 10172.0000 1.0000
72.5000 10293.0000 1.0000
72.5600 10244.0000 1.0000
72.6200 9947.0000 1.0000
72.6800 10201.0000 1.0000
72.7400 10140.0000 1.0000
72.8000 10173.0000 1.0000
72.8600 10203.0000 1.0000
72.9200 10248.0000 1.0000
72.9800 10039.0000 1.0000
73.0400 10003.0000 1.0000
73.1000 10118.0000 1.0000
73.1600 10119.0000 1.0000
73.2200 10281.0000 1.0000
73.2800 10123.0000 1.0000
73.3400 10232.0000 1.0000
73.4000 10157.0000 1.0000
73.4600 10375.0000 1.0000
73.5200 10335.0000 1.0000
73.5800 10070.0000 1.0000
73.6400 10429.0000 1.0000
73.7000 10419.0000 1.0000
73.7600 10201.0000 1.0000
73.8200 10400.0000 1.0000
73.8800 10333.0000 1.0000
73.9400 10436.0000 1.0000
74.0000 10660.0000 1.0000
74.0600 10913.0000 1.0000
74.1200 11281.0000 1.0000
74.1800 11001.0000 1.0000
74.2400 10942.0000 1.0000
74.3000 11107.0000 1.0000
74.3600 10854.0000 1.0000
74.4200 10601.0000 1.0000
74.4800 10476.0000 1.0000
74.5400 10493.0000 1.0000
74.6000 10355.0000 1.0000
74.6600 10240.0000 1.0000
74.7200 10178.0000 1.0000
74.7800 10517.0000 1.0000
74.8400 10217.0000 1.0000
74.9000 10342.0000 1.0000
74.9600 10432.0000 1.0000
75.0200 10323.0000 1.0000
75.0800 10608.0000 1.0000
75.1400 10662.0000 1.0000
75.2000 10576.0000 1.0000
75.2600 10663.0000 1.0000
75.3200 10501.0000 1.0000
75.3800 10604.0000 1.0000
75.4400 10533.0000 1.0000
75.5000 10709.0000 1.0000
75.5600 10407.0000 1.0000
75.6200 10653.0000 1.0000
75.6800 10561.0000 1.0000
75.7400 10595.0000 1.0000
75.8000 10214.0000 1.0000
75.8600 10329.0000 1.0000
75.9200 10467.0000 1.0000
75.9800 10301.0000 1.0000
76.0400 10060.0000 1.0000
76.1000 10273.0000 1.0000
76.1600 10326.0000 1.0000
76.2200 10270.0000 1.0000
76.2800 10373.0000 1.0000
76.3400 10347.0000 1.0000
76.4000 10292.0000 1.0000
76.4600 10249.0000 1.0000
76.5200 10312.0000 1.0000
76.5800 10339.0000 1.0000
76.6400 10365.0000 1.0000
76.7000 10600.0000 1.0000
76.7600 10476.0000 1.0000
76.8200 10604.0000 1.0000
76.8800 10893.0000 1.0000
76.9400 10642.0000 1.0000
77.0000 10766.0000 1.0000
77.0600 10534.0000 1.0000
77.1200 10645.0000 1.0000
77.1800 10746.0000 1.0000
77.2400 10745.0000 1.0000
77.3000 10690.0000 1.0000
77.3600 10432.0000 1.0000
77.4200 10476.0000 1.0000
77.4800 10534.0000 1.0000
77.5400 10560.0000 1.0000
77.6000 10489.0000 1.0000
77.6600 10512.0000 1.0000
77.7200 10647.0000 1.0000
77.7800 10367.0000 1.0000
77.8400 10340.0000 1.0000
77.9000 10377.0000 1.0000
77.9600 10645.0000 1.0000
78.0200 10300.0000 1.0000
78.0800 10316.0000 1.0000
78.1400 10337.0000 1.0000
78.2000 10340.0000 1.0000
78.2600 10242.0000 1.0000
78.3200 10252.0000 1.0000
78.3800 10477.0000 1.0000
78.4400 10330.0000 1.0000
78.5000 10363.0000 1.0000
78.5600 10270.0000 1.0000
78.6200 10574.0000 1.0000
78.6800 10364.0000 1.0000
78.7400 10382.0000 1.0000
78.8000 10667.0000 1.0000
78.8600 10409.0000 1.0000
78.9200 10400.0000 1.0000
78.9800 10508.0000 1.0000
79.0400 10365.0000 1.0000
79.1000 10655.0000 1.0000
79.1600 10537.0000 1.0000
79.2200 10422.0000 1.0000
79.2800 10758.0000 1.0000
79.3400 10513.0000 1.0000
79.4000 10402.0000 1.0000
79.4600 10463.0000 1.0000
79.5200 10417.0000 1.0000
79.5800 10459.0000 1.0000
79.6400 10282.0000 1.0000
79.7000 10201.0000 1.0000
79.7600 10391.0000 1.0000
79.8200 10430.0000 1.0000
79.8800 10786.0000 1.0000
79.9400 10500.0000 1.0000
80.0000 10509.0000 1.0000
80.0600 10656.0000 1.0000
80.1200 10566.0000 1.0000
80.1800 10619.0000 1.0000
80.2400 10424.0000 1.0000
80.3000 10516.0000 1.0000
80.3600 10513.0000 1.0000
80.4200 10448.0000 1.0000
80.4800 10352.0000 1.0000
80.5400 10654.0000 1.0000
80.6000 10675.0000 1.0000
80.6600 10744.0000 1.0000
80.7200 10677.0000 1.0000
80.7800 10687.0000 1.0000
80.8400 10572.0000 1.0000
80.9000 10458.0000 1.0000
80.9600 10564.0000 1.0000
81.0200 10440.0000 1.0000
81.0800 10376.0000 1.0000
81.1400 10523.0000 1.0000
81.2000 10686.0000 1.0000
81.2600 10396.0000 1.0000
81.3200 10509.0000 1.0000
81.3800 10330.0000 1.0000
81.4400 10851.0000 1.0000
81.5000 10720.0000 1.0000
81.5600 10691.0000 1.0000
81.6200 10419.0000 1.0000
81.6800 10572.0000 1.0000
81.7400 10419.0000 1.0000
81.8000 10385.0000 1.0000
81.8600 10333.0000 1.0000
81.9200 10402.0000 1.0000
81.9800 10507.0000 1.0000
82.0400 10289.0000 1.0000
82.1000 10511.0000 1.0000
82.1600 10438.0000 1.0000
82.2200 10501.0000 1.0000
82.2800 10434.0000 1.0000
82.3400 10491.0000 1.0000
82.4000 10323.0000 1.0000
82.4600 10361.0000 1.0000
82.5200 10395.0000 1.0000
82.5800 10434.0000 1.0000
82.6400 10476.0000 1.0000
82.7000 10608.0000 1.0000
82.7600 10401.0000 1.0000
82.8200 10441.0000 1.0000
82.8800 10655.0000 1.0000
82.9400 10336.0000 1.0000
83.0000 10691.0000 1.0000
83.0600 10577.0000 1.0000
83.1200 10427.0000 1.0000
83.1800 10388.0000 1.0000
83.2400 10622.0000 1.0000
83.3000 10388.0000 1.0000
83.3600 10439.0000 1.0000
83.4200 10469.0000 1.0000
83.4800 10336.0000 1.0000
83.5400 10405.0000 1.0000
83.6000 10566.0000 1.0000
83.6600 10426.0000 1.0000
83.7200 10587.0000 1.0000
83.7800 10484.0000 1.0000
83.8400 10649.0000 1.0000
83.9000 10595.0000 1.0000
83.9600 10501.0000 1.0000
84.0200 10527.0000 1.0000
84.0800 10536.0000 1.0000
84.1400 10571.0000 1.0000
84.2000 10521.0000 1.0000
84.2600 10433.0000 1.0000
84.3200 10643.0000 1.0000
84.3800 10640.0000 1.0000
84.4400 10344.0000 1.0000
84.5000 10590.0000 1.0000
84.5600 10384.0000 1.0000
84.6200 10603.0000 1.0000
84.6800 10503.0000 1.0000
84.7400 10521.0000 1.0000
84.8000 10487.0000 1.0000
84.8600 10622.0000 1.0000
84.9200 10449.0000 1.0000
84.9800 10734.0000 1.0000
85.0400 10494.0000 1.0000
85.1000 10543.0000 1.0000
85.1600 10556.0000 1.0000
85.2200 10575.0000 1.0000
85.2800 10630.0000 1.0000
85.3400 10665.0000 1.0000
85.4000 10655.0000 1.0000
85.4600 10586.0000 1.0000
85.5200 10659.0000 1.0000
85.5800 10633.0000 1.0000
85.6400 10581.0000 1.0000
85.7000 10415.0000 1.0000
85.7600 10556.0000 1.0000
85.8200 10405.0000 1.0000
85.8800 10349.0000 1.0000
85.9400 10567.0000 1.0000
86.0000 10405.0000 1.0000
86.0600 10548.0000 1.0000
86.1200 10427.0000 1.0000
86.1800 10519.0000 1.0000
86.2400 10515.0000 1.0000
86.3000 10660.0000 1.0000
86.3600 10645.0000 1.0000
86.4200 10556.0000 1.0000
86.4800 10624.0000 1.0000
86.5400 10591.0000 1.0000
86.6000 10668.0000 1.0000
86.6600 10599.0000 1.0000
86.7200 10707.0000 1.0000
86.7800 10818.0000 1.0000
86.8400 11094.0000 1.0000
86.9000 10979.0000 1.0000
86.9600 10946.0000 1.0000
87.0200 10791.0000 1.0000
87.0800 10654.0000 1.0000
87.1400 10689.0000 1.0000
87.2000 10544.0000 1.0000
87.2600 10720.0000 1.0000
87.3200 10524.0000 1.0000
87.3800 10753.0000 1.0000
87.4400 10677.0000 1.0000
87.5000 10649.0000 1.0000
87.5600 10566.0000 1.0000
87.6200 10539.0000 1.0000
87.6800 10540.0000 1.0000
87.7400 10586.0000 1.0000
87.8000 10667.0000 1.0000
87.8600 10392.0000 1.0000
87.9200 10712.0000 1.0000
87.9800 10525.0000 1.0000
88.0400 10455.0000 1.0000
88.1000 10458.0000 1.0000
88.1600 10569.0000 1.0000
88.2200 10689.0000 1.0000
88.2800 10593.0000 1.0000
88.3400 10577.0000 1.0000
88.4000 10550.0000 1.0000
88.4600 10698.0000 1.0000
88.5200 10744.0000 1.0000
88.5800 10819.0000 1.0000
88.6400 10741.0000 1.0000
88.7000 10799.0000 1.0000
88.7600 10650.0000 1.0000
88.8200 10837.0000 1.0000
88.8800 10702.0000 1.0000
88.9400 10717.0000 1.0000
89.0000 10830.0000 1.0000
89.0600 10746.0000 1.0000
89.1200 10801.0000 1.0000
89.1800 10527.0000 1.0000
89.2400 10595.0000 1.0000
89.3000 10856.0000 1.0000
89.3600 10563.0000 1.0000
89.4200 10776.0000 1.0000
89.4800 10668.0000 1.0000
89.5400 10749.0000 1.0000
89.6000 10873.0000 1.0000
89.6600 11258.0000 1.0000
89.7200 11571.0000 1.0000
89.7800 11641.0000 1.0000
89.8400 11757.0000 1.0000
89.9000 11513.0000 1.0000
89.9600 11323.0000 1.0000
90.0000 11376.0000 1.0000
*RAS_INT_END
*RAS_TEMPERATURE_START
*RAS_TEMPERATURE_END
*RAS_DATA_END