File: XRD/Data/20200826_mix_06.ras
*RAS_DATA_START
*RAS_HEADER_START
*DISP_FMT_X "%.2f"
*DISP_FMT_Y "%.0f"
*DISP_FULLSCALE "25153.0000000000"
*DISP_LINE_COLOR "255.0000000000"
*DISP_LINE_STYLE "0.0000000000"
*DISP_LINE_WIDTH "0.2500000000"
*DISP_NOTE "測定データ-5"
*DISP_OFFSET_Y "0.0000000000"
*DISP_PEAKSEARCH_UNIT_Y "cps"
*DISP_RANGE_BOTTOM "0.0000000000"
*DISP_RANGE_LEFT "20.0000000000"
*DISP_RANGE_LOGCUTOFF "0.0100000000"
*DISP_RANGE_RIGHT "90.0000000000"
*DISP_RANGE_TOP "25153.0000000000"
*DISP_SCALE_MODE_Y "0.0000000000"
*DISP_TAB_NAME "2θ/θ"
*DISP_TITLE_Y "強度"
*DISP_UNIT_Y "cps"
*DISP_WINDOW_NAME "MSG_MACROENGINE"
*FILE_COMMENT " "
*FILE_MD5 ""
*FILE_MEMO " "
*FILE_OPERATOR "Administrator"
*FILE_SAMPLE " "
*FILE_TYPE "RAS_RAW"
*FILE_USERGROUP "システムマネージャ"
*FILE_VERSION "1.0000000000"
*HW_ATTACHMENT_ID "ATT0025"
*HW_ATTACHMENT_NAME "標準|Standard"
*HW_COUNTER_ID-0 "CUT0025"
*HW_COUNTER_ID-1 "CUT0020"
*HW_COUNTER_ID-2 "CUT0020"
*HW_COUNTER_ID-3 "CSL0021"
*HW_COUNTER_ID-4 "CMC0021"
*HW_COUNTER_NAME-0 "D/teX Ultra|D/teX Ultra"
*HW_COUNTER_NAME-1 "None|None"
*HW_COUNTER_NAME-2 "None|None"
*HW_COUNTER_NAME-3 "BBM|BBM"
*HW_COUNTER_NAME-4 "検出器モノクロメータ|Detector monochromator"
*HW_COUNTER_SELECT_NAME "D/teX Ultra|D/teX Ultra"
*HW_GONIOMETER_ID "GON0023"
*HW_GONIOMETER_NAME "SmartLab|SmartLab"
*HW_GONIOMETER_RADIUS-0 "90.0"
*HW_GONIOMETER_RADIUS-1 "114.0"
*HW_GONIOMETER_RADIUS-2 "190.0"
*HW_GONIOMETER_RADIUS-3 "300.0"
*HW_GONIOMETER_RADIUS-4 "187.0"
*HW_GONIOMETER_RADIUS-5 "300.0"
*HW_GONIOMETER_RADIUS-6 "113.0"
*HW_GONIOMETER_RADIUS-7 "331.0"
*HW_I_OPT_ID-0 "CBO0021"
*HW_I_OPT_ID-1 "ICR0023"
*HW_I_OPT_ID-2 "ISL0021"
*HW_I_OPT_ID-3 "ISO0021"
*HW_I_OPT_ID-4 "IAD0021"
*HW_I_OPT_ID-5 "IPR0001"
*HW_I_OPT_NAME-0 "CBOユニット|CBO unit"
*HW_I_OPT_NAME-1 "標準入射光学ユニット|Standard incident optical unit"
*HW_I_OPT_NAME-2 "標準入射スリットボックス|Standard incident slit box"
*HW_I_OPT_NAME-3 "入射平行スリット|Incident parallel slit"
*HW_I_OPT_NAME-4 "長手制限スリット|Length limiting slit"
*HW_I_OPT_NAME-5 "None|None"
*HW_R_ATTENUATER_AUTOMODE "0"
*HW_R_OPT_ID-0 "RSS0021"
*HW_R_OPT_ID-1 "RCR0023"
*HW_R_OPT_ID-2 "RSO0021"
*HW_R_OPT_ID-3 "RRS0021"
*HW_R_OPT_ID-4 "ATN0021"
*HW_R_OPT_ID-5 "RFL0021"
*HW_R_OPT_ID-6 "RAD0021"
*HW_R_OPT_NAME-0 "標準受光スリットボックス1|Standard receiving slit box # 1"
*HW_R_OPT_NAME-1 "標準受光光学ユニット1|Standard receiving unit # 1"
*HW_R_OPT_NAME-2 "標準受光光学ユニット2|Standard receiving optical unit # 2"
*HW_R_OPT_NAME-3 "標準受光スリットボックス2|Standard receiving slit box # 2"
*HW_R_OPT_NAME-4 "標準アッテネータ|Standard Attenuator"
*HW_R_OPT_NAME-5 "Cu Kβ|Cu K-beta"
*HW_R_OPT_NAME-6 "調整用受光スリット|Alignment receiving slit"
*HW_SAMPLE_HOLDER_ID "SMP0023"
*HW_SAMPLE_HOLDER_NAME "標準Zステージ|Standard Z stage"
*HW_XG_CURRENT_MAX "50"
*HW_XG_CURRENT_MIN "2"
*HW_XG_CURRENT_RESOLUTION "2"
*HW_XG_CURRENT_UNIT "mA"
*HW_XG_FOCUS "1mm x 10mm"
*HW_XG_FOCUS_TYPE "Normal"
*HW_XG_ID ""
*HW_XG_NAME "3kW 封入管(ID:1200)|3kW Sealed tube(ID:1200)"
*HW_XG_TARGET_ATOMIC_NUMBER "29.0000000000"
*HW_XG_TARGET_NAME "Cu"
*HW_XG_TYPE "Hermetic"
*HW_XG_VOLTAGE_MAX "60"
*HW_XG_VOLTAGE_MIN "20"
*HW_XG_VOLTAGE_RESOLUTION "2"
*HW_XG_VOLTAGE_UNIT "kV"
*HW_XG_WATT_MAX "2"
*HW_XG_WATT_UNIT "kW"
*HW_XG_WAVE_LENGTH_ALPHA1 "1.540593"
*HW_XG_WAVE_LENGTH_ALPHA2 "1.544414"
*HW_XG_WAVE_LENGTH_BETA "1.392250"
*MEAS_COND_AXIS_NAME-0 "2θ/θ"
*MEAS_COND_AXIS_NAME-1 "2θ"
*MEAS_COND_AXIS_NAME-2 "ω"
*MEAS_COND_AXIS_NAME-3 "Z"
*MEAS_COND_AXIS_NAME-4 "2θ/ω"
*MEAS_COND_AXIS_NAME-5 "θs"
*MEAS_COND_AXIS_NAME-6 "θd"
*MEAS_COND_AXIS_NAME-7 "Ts"
*MEAS_COND_AXIS_NAME-8 "CBO選択スリット"
*MEAS_COND_AXIS_NAME-9 "M"
*MEAS_COND_AXIS_NAME-10 "入射平行スリット"
*MEAS_COND_AXIS_NAME-11 "入射スリット"
*MEAS_COND_AXIS_NAME-12 ""
*MEAS_COND_AXIS_NAME-13 "Zs"
*MEAS_COND_AXIS_NAME-14 "入射光学素子"
*MEAS_COND_AXIS_NAME-15 "長手制限スリット"
*MEAS_COND_AXIS_NAME-16 "センタースリット"
*MEAS_COND_AXIS_NAME-17 "フィルター"
*MEAS_COND_AXIS_NAME-18 "受光スリット1"
*MEAS_COND_AXIS_NAME-19 "受光スリット2"
*MEAS_COND_AXIS_NAME-20 "受光光学素子"
*MEAS_COND_AXIS_NAME-21 "受光平行スリット"
*MEAS_COND_AXIS_NAME-22 "調整用受光スリット"
*MEAS_COND_AXIS_NAME-23 ""
*MEAS_COND_AXIS_NAME-24 ""
*MEAS_COND_AXIS_NAME-25 "Zd"
*MEAS_COND_AXIS_NAME-26 "アッテネータ"
*MEAS_COND_AXIS_NAME-27 "検出器モノクロメータ"
*MEAS_COND_AXIS_NAME-28 "モノクロメータスリット"
*MEAS_COND_AXIS_NAME-29 "プライマリビーム"
*MEAS_COND_AXIS_NAME-30 "PHA"
*MEAS_COND_AXIS_NAME_INTERNAL-0 "TwoThetaTheta"
*MEAS_COND_AXIS_NAME_INTERNAL-1 "TwoTheta"
*MEAS_COND_AXIS_NAME_INTERNAL-2 "Omega"
*MEAS_COND_AXIS_NAME_INTERNAL-3 "Z"
*MEAS_COND_AXIS_NAME_INTERNAL-4 "TwoThetaOmega"
*MEAS_COND_AXIS_NAME_INTERNAL-5 "ThetaS"
*MEAS_COND_AXIS_NAME_INTERNAL-6 "ThetaD"
*MEAS_COND_AXIS_NAME_INTERNAL-7 "Ts"
*MEAS_COND_AXIS_NAME_INTERNAL-8 "CBO"
*MEAS_COND_AXIS_NAME_INTERNAL-9 "CBO-M"
*MEAS_COND_AXIS_NAME_INTERNAL-10 "IncidentSollerSlit"
*MEAS_COND_AXIS_NAME_INTERNAL-11 "IncidentSlitBox"
*MEAS_COND_AXIS_NAME_INTERNAL-12 "IncidentSlitBox-_Axis"
*MEAS_COND_AXIS_NAME_INTERNAL-13 "Zs"
*MEAS_COND_AXIS_NAME_INTERNAL-14 "IncidentMonochromator"
*MEAS_COND_AXIS_NAME_INTERNAL-15 "IncidentAxdSlit"
*MEAS_COND_AXIS_NAME_INTERNAL-16 "CenterSlit"
*MEAS_COND_AXIS_NAME_INTERNAL-17 "Filter"
*MEAS_COND_AXIS_NAME_INTERNAL-18 "ReceivingSlitBox1"
*MEAS_COND_AXIS_NAME_INTERNAL-19 "ReceivingSlitBox2"
*MEAS_COND_AXIS_NAME_INTERNAL-20 "ReceivingOptics"
*MEAS_COND_AXIS_NAME_INTERNAL-21 "ReceivingSollerSlit"
*MEAS_COND_AXIS_NAME_INTERNAL-22 "ReceivingAxdSlit"
*MEAS_COND_AXIS_NAME_INTERNAL-23 "ReceivingSlitBox1-_Axis"
*MEAS_COND_AXIS_NAME_INTERNAL-24 "ReceivingSlitBox2-_Axis"
*MEAS_COND_AXIS_NAME_INTERNAL-25 "ReceivingSlitBox2-Zd"
*MEAS_COND_AXIS_NAME_INTERNAL-26 "Attenuator"
*MEAS_COND_AXIS_NAME_INTERNAL-27 "CounterMonochromator"
*MEAS_COND_AXIS_NAME_INTERNAL-28 "CounterSlit"
*MEAS_COND_AXIS_NAME_INTERNAL-29 "IncidentPrimary"
*MEAS_COND_AXIS_NAME_INTERNAL-30 "PHA"
*MEAS_COND_AXIS_NAME_MAGICNO-0 "83951616.0000000000"
*MEAS_COND_AXIS_NAME_MAGICNO-1 "268632064.0000000000"
*MEAS_COND_AXIS_NAME_MAGICNO-2 "268500992.0000000000"
*MEAS_COND_AXIS_NAME_MAGICNO-3 "285278208.0000000000"
*MEAS_COND_AXIS_NAME_MAGICNO-4 "83951616.0000000000"
*MEAS_COND_AXIS_NAME_MAGICNO-5 "131072.0000000000"
*MEAS_COND_AXIS_NAME_MAGICNO-6 "131072.0000000000"
*MEAS_COND_AXIS_NAME_MAGICNO-7 "318898176.0000000000"
*MEAS_COND_AXIS_NAME_MAGICNO-8 "20971521.0000000000"
*MEAS_COND_AXIS_NAME_MAGICNO-9 "285343744.0000000000"
*MEAS_COND_AXIS_NAME_MAGICNO-10 "20971521.0000000000"
*MEAS_COND_AXIS_NAME_MAGICNO-11 "22020097.0000000000"
*MEAS_COND_AXIS_NAME_MAGICNO-12 "25165824.0000000000"
*MEAS_COND_AXIS_NAME_MAGICNO-13 "318898176.0000000000"
*MEAS_COND_AXIS_NAME_MAGICNO-14 "1.0000000000"
*MEAS_COND_AXIS_NAME_MAGICNO-15 "20971521.0000000000"
*MEAS_COND_AXIS_NAME_MAGICNO-16 "20971521.0000000000"
*MEAS_COND_AXIS_NAME_MAGICNO-17 "20971521.0000000000"
*MEAS_COND_AXIS_NAME_MAGICNO-18 "23068673.0000000000"
*MEAS_COND_AXIS_NAME_MAGICNO-19 "23068673.0000000000"
*MEAS_COND_AXIS_NAME_MAGICNO-20 "20971521.0000000000"
*MEAS_COND_AXIS_NAME_MAGICNO-21 "20971521.0000000000"
*MEAS_COND_AXIS_NAME_MAGICNO-22 "20971521.0000000000"
*MEAS_COND_AXIS_NAME_MAGICNO-23 "25165824.0000000000"
*MEAS_COND_AXIS_NAME_MAGICNO-24 "25165824.0000000000"
*MEAS_COND_AXIS_NAME_MAGICNO-25 "285343744.0000000000"
*MEAS_COND_AXIS_NAME_MAGICNO-26 "17301505.0000000000"
*MEAS_COND_AXIS_NAME_MAGICNO-27 "20971521.0000000000"
*MEAS_COND_AXIS_NAME_MAGICNO-28 "20971521.0000000000"
*MEAS_COND_AXIS_NAME_MAGICNO-29 "20971521.0000000000"
*MEAS_COND_AXIS_NAME_MAGICNO-30 "0.0000000000"
*MEAS_COND_AXIS_OFFSET-0 "-"
*MEAS_COND_AXIS_OFFSET-1 "-0.1081000000"
*MEAS_COND_AXIS_OFFSET-2 "0.3758000000"
*MEAS_COND_AXIS_OFFSET-3 "-"
*MEAS_COND_AXIS_OFFSET-4 "-"
*MEAS_COND_AXIS_OFFSET-5 "0.3758000000"
*MEAS_COND_AXIS_OFFSET-6 "-0.4839000000"
*MEAS_COND_AXIS_OFFSET-7 "-"
*MEAS_COND_AXIS_OFFSET-8 "-"
*MEAS_COND_AXIS_OFFSET-9 "-"
*MEAS_COND_AXIS_OFFSET-10 "-"
*MEAS_COND_AXIS_OFFSET-11 "-"
*MEAS_COND_AXIS_OFFSET-12 "-"
*MEAS_COND_AXIS_OFFSET-13 "-"
*MEAS_COND_AXIS_OFFSET-14 "-"
*MEAS_COND_AXIS_OFFSET-15 "-"
*MEAS_COND_AXIS_OFFSET-16 "-"
*MEAS_COND_AXIS_OFFSET-17 "-"
*MEAS_COND_AXIS_OFFSET-18 "-"
*MEAS_COND_AXIS_OFFSET-19 "-"
*MEAS_COND_AXIS_OFFSET-20 "-"
*MEAS_COND_AXIS_OFFSET-21 "-"
*MEAS_COND_AXIS_OFFSET-22 "-"
*MEAS_COND_AXIS_OFFSET-23 "-"
*MEAS_COND_AXIS_OFFSET-24 "-"
*MEAS_COND_AXIS_OFFSET-25 "-"
*MEAS_COND_AXIS_OFFSET-26 "-"
*MEAS_COND_AXIS_OFFSET-27 "-"
*MEAS_COND_AXIS_OFFSET-28 "-"
*MEAS_COND_AXIS_OFFSET-29 "-"
*MEAS_COND_AXIS_OFFSET-30 "-"
*MEAS_COND_AXIS_POSITION-0 "0.0000000000"
*MEAS_COND_AXIS_POSITION-1 "0.0000000000"
*MEAS_COND_AXIS_POSITION-2 "0.0000000000"
*MEAS_COND_AXIS_POSITION-3 "-0.5500000000"
*MEAS_COND_AXIS_POSITION-4 "0.0000000000"
*MEAS_COND_AXIS_POSITION-5 "0.0000000000"
*MEAS_COND_AXIS_POSITION-6 "0.0000000000"
*MEAS_COND_AXIS_POSITION-7 "-0.4278800000"
*MEAS_COND_AXIS_POSITION-8 "BB"
*MEAS_COND_AXIS_POSITION-9 "0.0000000000"
*MEAS_COND_AXIS_POSITION-10 "Soller_slit_5.0deg"
*MEAS_COND_AXIS_POSITION-11 "2/3deg"
*MEAS_COND_AXIS_POSITION-12 "2.2088000000"
*MEAS_COND_AXIS_POSITION-13 "-0.4140600000"
*MEAS_COND_AXIS_POSITION-14 "0.0000000000"
*MEAS_COND_AXIS_POSITION-15 "10.0mm"
*MEAS_COND_AXIS_POSITION-16 "None"
*MEAS_COND_AXIS_POSITION-17 "Cu_K-beta"
*MEAS_COND_AXIS_POSITION-18 "13.000mm"
*MEAS_COND_AXIS_POSITION-19 "13.000mm"
*MEAS_COND_AXIS_POSITION-20 "No_unit"
*MEAS_COND_AXIS_POSITION-21 "Soller_slit_5.0deg"
*MEAS_COND_AXIS_POSITION-22 "None"
*MEAS_COND_AXIS_POSITION-23 "13.0000000000"
*MEAS_COND_AXIS_POSITION-24 "13.0000000000"
*MEAS_COND_AXIS_POSITION-25 "0.0109400000"
*MEAS_COND_AXIS_POSITION-26 "Open"
*MEAS_COND_AXIS_POSITION-27 "None"
*MEAS_COND_AXIS_POSITION-28 "None"
*MEAS_COND_AXIS_POSITION-29 "None"
*MEAS_COND_AXIS_POSITION-30 "38.0000000000"
*MEAS_COND_AXIS_UNIT-0 "deg"
*MEAS_COND_AXIS_UNIT-1 "deg"
*MEAS_COND_AXIS_UNIT-2 "deg"
*MEAS_COND_AXIS_UNIT-3 "mm"
*MEAS_COND_AXIS_UNIT-4 "deg"
*MEAS_COND_AXIS_UNIT-5 "deg"
*MEAS_COND_AXIS_UNIT-6 "deg"
*MEAS_COND_AXIS_UNIT-7 "mm"
*MEAS_COND_AXIS_UNIT-8 ""
*MEAS_COND_AXIS_UNIT-9 "pulse"
*MEAS_COND_AXIS_UNIT-10 ""
*MEAS_COND_AXIS_UNIT-11 ""
*MEAS_COND_AXIS_UNIT-12 "mm"
*MEAS_COND_AXIS_UNIT-13 "mm"
*MEAS_COND_AXIS_UNIT-14 ""
*MEAS_COND_AXIS_UNIT-15 ""
*MEAS_COND_AXIS_UNIT-16 ""
*MEAS_COND_AXIS_UNIT-17 ""
*MEAS_COND_AXIS_UNIT-18 ""
*MEAS_COND_AXIS_UNIT-19 ""
*MEAS_COND_AXIS_UNIT-20 ""
*MEAS_COND_AXIS_UNIT-21 ""
*MEAS_COND_AXIS_UNIT-22 ""
*MEAS_COND_AXIS_UNIT-23 "mm"
*MEAS_COND_AXIS_UNIT-24 "mm"
*MEAS_COND_AXIS_UNIT-25 "mm"
*MEAS_COND_AXIS_UNIT-26 ""
*MEAS_COND_AXIS_UNIT-27 ""
*MEAS_COND_AXIS_UNIT-28 ""
*MEAS_COND_AXIS_UNIT-29 ""
*MEAS_COND_AXIS_UNIT-30 "div"
*MEAS_COND_COUNTER_CNTLOSS_CORR "0.0000000000"
*MEAS_COND_COUNTER_PHABASE "38.0000000000"
*MEAS_COND_COUNTER_PHAWINDOW "16.0000000000"
*MEAS_COND_COUNTER_PHA_UNIT "div"
*MEAS_COND_COUNTER_TAUDIFF "30.0000000000"
*MEAS_COND_COUNTER_TAUINT "0.0000000000"
*MEAS_COND_IRRADIATION_MODE "OFF"
*MEAS_COND_IRRADIATION_WIDTH ""
*MEAS_COND_OPT_ATTR "集中法"
*MEAS_COND_OPT_NAME "@集中法"
*MEAS_COND_UNSYMMETRIC_MODE "OFF"
*MEAS_COND_XG_CURRENT "30.0000000000"
*MEAS_COND_XG_VOLTAGE "40.0000000000"
*MEAS_COND_XG_WAVE_TYPE "Ka"
*MEAS_DATA_COUNT "3501.0000000000"
*MEAS_SCAN_AXIS_X "2θ/θ"
*MEAS_SCAN_AXIS_X_INTERNAL "TwoThetaTheta"
*MEAS_SCAN_END_TIME "08/26/20 18:23:47"
*MEAS_SCAN_MODE "CONTINUOUS"
*MEAS_SCAN_MONITOR "0"
*MEAS_SCAN_RESOLUTION_X "0.0002"
*MEAS_SCAN_SPEED "1.0"
*MEAS_SCAN_SPEED_UNIT "deg/min"
*MEAS_SCAN_START "20.0000000000"
*MEAS_SCAN_START_TIME "08/26/20 17:10:52"
*MEAS_SCAN_STEP "0.0200000000"
*MEAS_SCAN_STOP "90.0000000000"
*MEAS_SCAN_UNIT_X "deg"
*MEAS_SCAN_UNIT_Y "counts"
*RAS_HEADER_END
*RAS_INT_START
20.0000 12286.0000 1.0000
20.0600 12357.0000 1.0000
20.1200 12427.0000 1.0000
20.1800 12578.0000 1.0000
20.2400 12390.0000 1.0000
20.3000 12457.0000 1.0000
20.3600 12163.0000 1.0000
20.4200 12475.0000 1.0000
20.4800 12427.0000 1.0000
20.5400 12392.0000 1.0000
20.6000 12374.0000 1.0000
20.6600 12277.0000 1.0000
20.7200 12516.0000 1.0000
20.7800 12587.0000 1.0000
20.8400 13462.0000 1.0000
20.9000 13779.0000 1.0000
20.9600 12825.0000 1.0000
21.0200 12433.0000 1.0000
21.0800 12373.0000 1.0000
21.1400 12379.0000 1.0000
21.2000 12275.0000 1.0000
21.2600 12233.0000 1.0000
21.3200 12133.0000 1.0000
21.3800 12246.0000 1.0000
21.4400 12142.0000 1.0000
21.5000 12244.0000 1.0000
21.5600 12298.0000 1.0000
21.6200 12341.0000 1.0000
21.6800 12373.0000 1.0000
21.7400 12376.0000 1.0000
21.8000 12102.0000 1.0000
21.8600 12185.0000 1.0000
21.9200 12260.0000 1.0000
21.9800 12234.0000 1.0000
22.0400 12366.0000 1.0000
22.1000 12138.0000 1.0000
22.1600 12261.0000 1.0000
22.2200 12265.0000 1.0000
22.2800 12280.0000 1.0000
22.3400 12243.0000 1.0000
22.4000 12239.0000 1.0000
22.4600 12008.0000 1.0000
22.5200 12078.0000 1.0000
22.5800 11944.0000 1.0000
22.6400 12061.0000 1.0000
22.7000 12077.0000 1.0000
22.7600 12197.0000 1.0000
22.8200 12172.0000 1.0000
22.8800 12222.0000 1.0000
22.9400 12112.0000 1.0000
23.0000 12095.0000 1.0000
23.0600 11802.0000 1.0000
23.1200 12131.0000 1.0000
23.1800 11967.0000 1.0000
23.2400 11999.0000 1.0000
23.3000 12112.0000 1.0000
23.3600 12132.0000 1.0000
23.4200 12184.0000 1.0000
23.4800 12317.0000 1.0000
23.5400 11855.0000 1.0000
23.6000 12032.0000 1.0000
23.6600 12032.0000 1.0000
23.7200 12055.0000 1.0000
23.7800 12073.0000 1.0000
23.8400 12114.0000 1.0000
23.9000 12253.0000 1.0000
23.9600 12644.0000 1.0000
24.0200 12985.0000 1.0000
24.0800 13959.0000 1.0000
24.1400 15590.0000 1.0000
24.2000 14743.0000 1.0000
24.2600 13027.0000 1.0000
24.3200 12359.0000 1.0000
24.3800 11930.0000 1.0000
24.4400 11926.0000 1.0000
24.5000 12073.0000 1.0000
24.5600 12143.0000 1.0000
24.6200 12000.0000 1.0000
24.6800 11855.0000 1.0000
24.7400 12024.0000 1.0000
24.8000 12302.0000 1.0000
24.8600 11855.0000 1.0000
24.9200 11846.0000 1.0000
24.9800 11822.0000 1.0000
25.0400 12034.0000 1.0000
25.1000 11980.0000 1.0000
25.1600 11986.0000 1.0000
25.2200 11927.0000 1.0000
25.2800 12032.0000 1.0000
25.3400 12138.0000 1.0000
25.4000 12505.0000 1.0000
25.4600 12945.0000 1.0000
25.5200 14548.0000 1.0000
25.5800 15659.0000 1.0000
25.6400 14296.0000 1.0000
25.7000 12664.0000 1.0000
25.7600 12276.0000 1.0000
25.8200 12115.0000 1.0000
25.8800 11837.0000 1.0000
25.9400 11854.0000 1.0000
26.0000 11920.0000 1.0000
26.0600 11902.0000 1.0000
26.1200 11811.0000 1.0000
26.1800 11869.0000 1.0000
26.2400 11828.0000 1.0000
26.3000 11919.0000 1.0000
26.3600 12124.0000 1.0000
26.4200 12085.0000 1.0000
26.4800 12180.0000 1.0000
26.5400 13878.0000 1.0000
26.6000 17046.0000 1.0000
26.6600 19004.0000 1.0000
26.7200 15552.0000 1.0000
26.7800 12413.0000 1.0000
26.8400 11937.0000 1.0000
26.9000 11971.0000 1.0000
26.9600 11802.0000 1.0000
27.0200 11698.0000 1.0000
27.0800 11489.0000 1.0000
27.1400 11616.0000 1.0000
27.2000 11780.0000 1.0000
27.2600 11823.0000 1.0000
27.3200 11505.0000 1.0000
27.3800 11721.0000 1.0000
27.4400 11636.0000 1.0000
27.5000 11626.0000 1.0000
27.5600 11618.0000 1.0000
27.6200 11517.0000 1.0000
27.6800 11555.0000 1.0000
27.7400 11547.0000 1.0000
27.8000 11639.0000 1.0000
27.8600 11718.0000 1.0000
27.9200 11704.0000 1.0000
27.9800 11636.0000 1.0000
28.0400 11618.0000 1.0000
28.1000 11634.0000 1.0000
28.1600 11659.0000 1.0000
28.2200 11499.0000 1.0000
28.2800 11630.0000 1.0000
28.3400 11609.0000 1.0000
28.4000 11580.0000 1.0000
28.4600 11500.0000 1.0000
28.5200 11636.0000 1.0000
28.5800 11491.0000 1.0000
28.6400 11589.0000 1.0000
28.7000 11452.0000 1.0000
28.7600 11633.0000 1.0000
28.8200 11549.0000 1.0000
28.8800 11630.0000 1.0000
28.9400 11616.0000 1.0000
29.0000 11555.0000 1.0000
29.0600 11453.0000 1.0000
29.1200 11530.0000 1.0000
29.1800 11367.0000 1.0000
29.2400 11633.0000 1.0000
29.3000 11540.0000 1.0000
29.3600 11518.0000 1.0000
29.4200 11452.0000 1.0000
29.4800 11622.0000 1.0000
29.5400 11606.0000 1.0000
29.6000 11875.0000 1.0000
29.6600 11738.0000 1.0000
29.7200 11640.0000 1.0000
29.7800 11510.0000 1.0000
29.8400 11685.0000 1.0000
29.9000 11966.0000 1.0000
29.9600 12178.0000 1.0000
30.0200 12421.0000 1.0000
30.0800 13829.0000 1.0000
30.1400 14748.0000 1.0000
30.2000 13842.0000 1.0000
30.2600 12709.0000 1.0000
30.3200 12116.0000 1.0000
30.3800 11656.0000 1.0000
30.4400 11760.0000 1.0000
30.5000 11621.0000 1.0000
30.5600 11445.0000 1.0000
30.6200 11364.0000 1.0000
30.6800 11728.0000 1.0000
30.7400 11452.0000 1.0000
30.8000 11485.0000 1.0000
30.8600 11593.0000 1.0000
30.9200 11301.0000 1.0000
30.9800 11638.0000 1.0000
31.0400 11757.0000 1.0000
31.1000 11663.0000 1.0000
31.1600 11459.0000 1.0000
31.2200 11507.0000 1.0000
31.2800 11340.0000 1.0000
31.3400 11433.0000 1.0000
31.4000 11488.0000 1.0000
31.4600 11447.0000 1.0000
31.5200 11546.0000 1.0000
31.5800 11433.0000 1.0000
31.6400 11586.0000 1.0000
31.7000 11591.0000 1.0000
31.7600 11382.0000 1.0000
31.8200 11604.0000 1.0000
31.8800 11541.0000 1.0000
31.9400 11706.0000 1.0000
32.0000 11604.0000 1.0000
32.0600 11629.0000 1.0000
32.1200 11647.0000 1.0000
32.1800 11640.0000 1.0000
32.2400 11531.0000 1.0000
32.3000 11440.0000 1.0000
32.3600 11357.0000 1.0000
32.4200 11698.0000 1.0000
32.4800 11504.0000 1.0000
32.5400 11637.0000 1.0000
32.6000 11655.0000 1.0000
32.6600 11700.0000 1.0000
32.7200 11650.0000 1.0000
32.7800 11813.0000 1.0000
32.8400 11812.0000 1.0000
32.9000 12372.0000 1.0000
32.9600 12855.0000 1.0000
33.0200 14059.0000 1.0000
33.0800 16894.0000 1.0000
33.1400 23394.0000 1.0000
33.2000 22624.0000 1.0000
33.2600 18817.0000 1.0000
33.3200 14026.0000 1.0000
33.3800 12554.0000 1.0000
33.4400 12185.0000 1.0000
33.5000 11655.0000 1.0000
33.5600 11602.0000 1.0000
33.6200 11565.0000 1.0000
33.6800 11564.0000 1.0000
33.7400 11659.0000 1.0000
33.8000 11672.0000 1.0000
33.8600 11737.0000 1.0000
33.9200 11543.0000 1.0000
33.9800 11577.0000 1.0000
34.0400 11590.0000 1.0000
34.1000 11340.0000 1.0000
34.1600 11694.0000 1.0000
34.2200 11403.0000 1.0000
34.2800 11582.0000 1.0000
34.3400 11684.0000 1.0000
34.4000 11427.0000 1.0000
34.4600 11659.0000 1.0000
34.5200 11818.0000 1.0000
34.5800 11715.0000 1.0000
34.6400 11597.0000 1.0000
34.7000 11667.0000 1.0000
34.7600 11922.0000 1.0000
34.8200 11824.0000 1.0000
34.8800 12167.0000 1.0000
34.9400 12628.0000 1.0000
35.0000 12731.0000 1.0000
35.0600 14099.0000 1.0000
35.1200 16866.0000 1.0000
35.1800 17490.0000 1.0000
35.2400 15843.0000 1.0000
35.3000 14542.0000 1.0000
35.3600 15081.0000 1.0000
35.4200 18292.0000 1.0000
35.4800 23419.0000 1.0000
35.5400 23066.0000 1.0000
35.6000 24855.0000 1.0000
35.6600 22737.0000 1.0000
35.7200 18838.0000 1.0000
35.7800 14910.0000 1.0000
35.8400 12788.0000 1.0000
35.9000 11983.0000 1.0000
35.9600 11713.0000 1.0000
36.0200 11658.0000 1.0000
36.0800 11600.0000 1.0000
36.1400 11290.0000 1.0000
36.2000 11658.0000 1.0000
36.2600 11437.0000 1.0000
36.3200 11553.0000 1.0000
36.3800 11481.0000 1.0000
36.4400 11577.0000 1.0000
36.5000 11542.0000 1.0000
36.5600 11792.0000 1.0000
36.6200 11784.0000 1.0000
36.6800 11730.0000 1.0000
36.7400 11532.0000 1.0000
36.8000 11624.0000 1.0000
36.8600 11394.0000 1.0000
36.9200 11437.0000 1.0000
36.9800 11693.0000 1.0000
37.0400 11867.0000 1.0000
37.1000 11823.0000 1.0000
37.1600 12126.0000 1.0000
37.2200 11737.0000 1.0000
37.2800 11682.0000 1.0000
37.3400 11491.0000 1.0000
37.4000 11428.0000 1.0000
37.4600 11677.0000 1.0000
37.5200 11651.0000 1.0000
37.5800 11681.0000 1.0000
37.6400 11965.0000 1.0000
37.7000 12582.0000 1.0000
37.7600 14097.0000 1.0000
37.8200 13336.0000 1.0000
37.8800 12938.0000 1.0000
37.9400 11970.0000 1.0000
38.0000 11643.0000 1.0000
38.0600 11638.0000 1.0000
38.1200 11479.0000 1.0000
38.1800 11439.0000 1.0000
38.2400 11470.0000 1.0000
38.3000 11522.0000 1.0000
38.3600 11287.0000 1.0000
38.4200 11512.0000 1.0000
38.4800 11415.0000 1.0000
38.5400 11179.0000 1.0000
38.6000 11463.0000 1.0000
38.6600 11284.0000 1.0000
38.7200 11236.0000 1.0000
38.7800 11334.0000 1.0000
38.8400 11399.0000 1.0000
38.9000 11384.0000 1.0000
38.9600 11489.0000 1.0000
39.0200 11198.0000 1.0000
39.0800 11390.0000 1.0000
39.1400 11212.0000 1.0000
39.2000 11499.0000 1.0000
39.2600 11607.0000 1.0000
39.3200 11492.0000 1.0000
39.3800 11564.0000 1.0000
39.4400 11686.0000 1.0000
39.5000 11670.0000 1.0000
39.5600 11556.0000 1.0000
39.6200 11308.0000 1.0000
39.6800 11537.0000 1.0000
39.7400 11298.0000 1.0000
39.8000 11460.0000 1.0000
39.8600 11378.0000 1.0000
39.9200 11411.0000 1.0000
39.9800 11393.0000 1.0000
40.0400 11316.0000 1.0000
40.1000 11542.0000 1.0000
40.1600 11242.0000 1.0000
40.2200 11370.0000 1.0000
40.2800 11764.0000 1.0000
40.3400 11458.0000 1.0000
40.4000 11652.0000 1.0000
40.4600 11282.0000 1.0000
40.5200 11498.0000 1.0000
40.5800 11527.0000 1.0000
40.6400 11469.0000 1.0000
40.7000 11820.0000 1.0000
40.7600 12123.0000 1.0000
40.8200 13385.0000 1.0000
40.8800 13985.0000 1.0000
40.9400 13085.0000 1.0000
41.0000 12574.0000 1.0000
41.0600 11761.0000 1.0000
41.1200 11520.0000 1.0000
41.1800 11377.0000 1.0000
41.2400 11525.0000 1.0000
41.3000 11497.0000 1.0000
41.3600 11482.0000 1.0000
41.4200 11327.0000 1.0000
41.4800 11322.0000 1.0000
41.5400 11183.0000 1.0000
41.6000 11579.0000 1.0000
41.6600 11304.0000 1.0000
41.7200 11240.0000 1.0000
41.7800 11520.0000 1.0000
41.8400 11415.0000 1.0000
41.9000 11520.0000 1.0000
41.9600 11381.0000 1.0000
42.0200 11508.0000 1.0000
42.0800 11214.0000 1.0000
42.1400 11200.0000 1.0000
42.2000 11335.0000 1.0000
42.2600 11397.0000 1.0000
42.3200 11364.0000 1.0000
42.3800 11757.0000 1.0000
42.4400 11839.0000 1.0000
42.5000 11559.0000 1.0000
42.5600 11826.0000 1.0000
42.6200 11402.0000 1.0000
42.6800 11302.0000 1.0000
42.7400 11451.0000 1.0000
42.8000 11510.0000 1.0000
42.8600 11684.0000 1.0000
42.9200 11817.0000 1.0000
42.9800 11806.0000 1.0000
43.0400 12557.0000 1.0000
43.1000 13815.0000 1.0000
43.1600 14242.0000 1.0000
43.2200 14763.0000 1.0000
43.2800 15812.0000 1.0000
43.3400 18586.0000 1.0000
43.4000 16715.0000 1.0000
43.4600 15903.0000 1.0000
43.5200 13560.0000 1.0000
43.5800 12403.0000 1.0000
43.6400 12021.0000 1.0000
43.7000 11504.0000 1.0000
43.7600 11342.0000 1.0000
43.8200 11472.0000 1.0000
43.8800 11457.0000 1.0000
43.9400 11407.0000 1.0000
44.0000 11420.0000 1.0000
44.0600 11276.0000 1.0000
44.1200 11291.0000 1.0000
44.1800 11334.0000 1.0000
44.2400 11336.0000 1.0000
44.3000 11289.0000 1.0000
44.3600 11110.0000 1.0000
44.4200 11482.0000 1.0000
44.4800 11327.0000 1.0000
44.5400 11423.0000 1.0000
44.6000 11398.0000 1.0000
44.6600 11180.0000 1.0000
44.7200 11232.0000 1.0000
44.7800 11253.0000 1.0000
44.8400 11022.0000 1.0000
44.9000 11179.0000 1.0000
44.9600 11183.0000 1.0000
45.0200 11221.0000 1.0000
45.0800 11165.0000 1.0000
45.1400 11452.0000 1.0000
45.2000 11087.0000 1.0000
45.2600 11200.0000 1.0000
45.3200 11137.0000 1.0000
45.3800 11119.0000 1.0000
45.4400 11385.0000 1.0000
45.5000 11374.0000 1.0000
45.5600 11212.0000 1.0000
45.6200 11432.0000 1.0000
45.6800 11337.0000 1.0000
45.7400 11376.0000 1.0000
45.8000 11663.0000 1.0000
45.8600 11443.0000 1.0000
45.9200 11344.0000 1.0000
45.9800 11498.0000 1.0000
46.0400 11164.0000 1.0000
46.1000 11467.0000 1.0000
46.1600 11353.0000 1.0000
46.2200 11132.0000 1.0000
46.2800 11114.0000 1.0000
46.3400 11518.0000 1.0000
46.4000 11201.0000 1.0000
46.4600 11335.0000 1.0000
46.5200 11172.0000 1.0000
46.5800 11318.0000 1.0000
46.6400 11226.0000 1.0000
46.7000 11295.0000 1.0000
46.7600 11090.0000 1.0000
46.8200 11311.0000 1.0000
46.8800 11221.0000 1.0000
46.9400 11161.0000 1.0000
47.0000 11213.0000 1.0000
47.0600 11299.0000 1.0000
47.1200 11292.0000 1.0000
47.1800 11347.0000 1.0000
47.2400 11491.0000 1.0000
47.3000 11460.0000 1.0000
47.3600 11392.0000 1.0000
47.4200 11230.0000 1.0000
47.4800 11320.0000 1.0000
47.5400 11167.0000 1.0000
47.6000 11166.0000 1.0000
47.6600 11252.0000 1.0000
47.7200 11322.0000 1.0000
47.7800 11060.0000 1.0000
47.8400 11420.0000 1.0000
47.9000 11028.0000 1.0000
47.9600 11181.0000 1.0000
48.0200 11005.0000 1.0000
48.0800 11319.0000 1.0000
48.1400 11257.0000 1.0000
48.2000 11350.0000 1.0000
48.2600 11161.0000 1.0000
48.3200 11273.0000 1.0000
48.3800 11268.0000 1.0000
48.4400 11371.0000 1.0000
48.5000 11247.0000 1.0000
48.5600 11416.0000 1.0000
48.6200 11262.0000 1.0000
48.6800 11324.0000 1.0000
48.7400 11097.0000 1.0000
48.8000 11489.0000 1.0000
48.8600 11277.0000 1.0000
48.9200 11242.0000 1.0000
48.9800 11094.0000 1.0000
49.0400 11314.0000 1.0000
49.1000 11236.0000 1.0000
49.1600 11397.0000 1.0000
49.2200 11849.0000 1.0000
49.2800 11833.0000 1.0000
49.3400 12174.0000 1.0000
49.4000 13709.0000 1.0000
49.4600 16155.0000 1.0000
49.5200 14134.0000 1.0000
49.5800 13963.0000 1.0000
49.6400 12876.0000 1.0000
49.7000 11992.0000 1.0000
49.7600 11575.0000 1.0000
49.8200 11286.0000 1.0000
49.8800 11458.0000 1.0000
49.9400 11275.0000 1.0000
50.0000 11432.0000 1.0000
50.0600 11553.0000 1.0000
50.1200 12721.0000 1.0000
50.1800 11958.0000 1.0000
50.2400 11929.0000 1.0000
50.3000 11754.0000 1.0000
50.3600 11153.0000 1.0000
50.4200 11389.0000 1.0000
50.4800 11415.0000 1.0000
50.5400 11109.0000 1.0000
50.6000 11368.0000 1.0000
50.6600 11149.0000 1.0000
50.7200 11449.0000 1.0000
50.7800 11258.0000 1.0000
50.8400 11417.0000 1.0000
50.9000 11219.0000 1.0000
50.9600 11406.0000 1.0000
51.0200 11364.0000 1.0000
51.0800 11290.0000 1.0000
51.1400 11162.0000 1.0000
51.2000 11210.0000 1.0000
51.2600 11203.0000 1.0000
51.3200 11236.0000 1.0000
51.3800 11091.0000 1.0000
51.4400 11309.0000 1.0000
51.5000 11375.0000 1.0000
51.5600 11235.0000 1.0000
51.6200 11233.0000 1.0000
51.6800 11299.0000 1.0000
51.7400 11109.0000 1.0000
51.8000 11113.0000 1.0000
51.8600 11192.0000 1.0000
51.9200 11348.0000 1.0000
51.9800 11363.0000 1.0000
52.0400 11158.0000 1.0000
52.1000 11442.0000 1.0000
52.1600 11315.0000 1.0000
52.2200 11533.0000 1.0000
52.2800 11569.0000 1.0000
52.3400 11698.0000 1.0000
52.4000 11976.0000 1.0000
52.4600 12582.0000 1.0000
52.5200 13659.0000 1.0000
52.5800 13845.0000 1.0000
52.6400 12984.0000 1.0000
52.7000 13008.0000 1.0000
52.7600 12243.0000 1.0000
52.8200 11721.0000 1.0000
52.8800 11365.0000 1.0000
52.9400 11420.0000 1.0000
53.0000 11294.0000 1.0000
53.0600 11459.0000 1.0000
53.1200 11366.0000 1.0000
53.1800 11368.0000 1.0000
53.2400 11295.0000 1.0000
53.3000 11397.0000 1.0000
53.3600 11458.0000 1.0000
53.4200 11708.0000 1.0000
53.4800 12016.0000 1.0000
53.5400 12119.0000 1.0000
53.6000 12005.0000 1.0000
53.6600 11874.0000 1.0000
53.7200 11942.0000 1.0000
53.7800 11663.0000 1.0000
53.8400 11920.0000 1.0000
53.9000 12017.0000 1.0000
53.9600 12706.0000 1.0000
54.0200 14782.0000 1.0000
54.0800 16571.0000 1.0000
54.1400 14418.0000 1.0000
54.2000 14468.0000 1.0000
54.2600 13366.0000 1.0000
54.3200 12229.0000 1.0000
54.3800 11755.0000 1.0000
54.4400 11236.0000 1.0000
54.5000 11555.0000 1.0000
54.5600 11384.0000 1.0000
54.6200 11280.0000 1.0000
54.6800 11110.0000 1.0000
54.7400 11103.0000 1.0000
54.8000 11294.0000 1.0000
54.8600 11627.0000 1.0000
54.9200 11165.0000 1.0000
54.9800 11380.0000 1.0000
55.0400 11263.0000 1.0000
55.1000 11153.0000 1.0000
55.1600 11242.0000 1.0000
55.2200 11248.0000 1.0000
55.2800 11453.0000 1.0000
55.3400 11349.0000 1.0000
55.4000 11260.0000 1.0000
55.4600 11268.0000 1.0000
55.5200 11208.0000 1.0000
55.5800 11130.0000 1.0000
55.6400 11416.0000 1.0000
55.7000 11260.0000 1.0000
55.7600 11326.0000 1.0000
55.8200 11477.0000 1.0000
55.8800 11423.0000 1.0000
55.9400 11382.0000 1.0000
56.0000 11197.0000 1.0000
56.0600 10995.0000 1.0000
56.1200 11343.0000 1.0000
56.1800 11304.0000 1.0000
56.2400 11391.0000 1.0000
56.3000 11201.0000 1.0000
56.3600 11353.0000 1.0000
56.4200 11372.0000 1.0000
56.4800 11460.0000 1.0000
56.5400 11346.0000 1.0000
56.6000 11360.0000 1.0000
56.6600 11501.0000 1.0000
56.7200 11398.0000 1.0000
56.7800 11491.0000 1.0000
56.8400 11810.0000 1.0000
56.9000 11975.0000 1.0000
56.9600 12866.0000 1.0000
57.0200 14014.0000 1.0000
57.0800 13597.0000 1.0000
57.1400 13600.0000 1.0000
57.2000 13429.0000 1.0000
57.2600 13177.0000 1.0000
57.3200 13192.0000 1.0000
57.3800 13594.0000 1.0000
57.4400 15526.0000 1.0000
57.5000 17811.0000 1.0000
57.5600 15612.0000 1.0000
57.6200 15574.0000 1.0000
57.6800 14564.0000 1.0000
57.7400 13024.0000 1.0000
57.8000 12546.0000 1.0000
57.8600 11843.0000 1.0000
57.9200 11585.0000 1.0000
57.9800 11674.0000 1.0000
58.0400 11331.0000 1.0000
58.1000 11445.0000 1.0000
58.1600 11427.0000 1.0000
58.2200 11471.0000 1.0000
58.2800 11393.0000 1.0000
58.3400 11348.0000 1.0000
58.4000 11423.0000 1.0000
58.4600 11348.0000 1.0000
58.5200 11240.0000 1.0000
58.5800 11188.0000 1.0000
58.6400 11391.0000 1.0000
58.7000 11320.0000 1.0000
58.7600 11205.0000 1.0000
58.8200 11400.0000 1.0000
58.8800 11139.0000 1.0000
58.9400 11225.0000 1.0000
59.0000 11230.0000 1.0000
59.0600 11209.0000 1.0000
59.1200 11273.0000 1.0000
59.1800 11426.0000 1.0000
59.2400 11311.0000 1.0000
59.3000 11198.0000 1.0000
59.3600 11294.0000 1.0000
59.4200 11378.0000 1.0000
59.4800 11168.0000 1.0000
59.5400 11155.0000 1.0000
59.6000 11314.0000 1.0000
59.6600 11286.0000 1.0000
59.7200 11444.0000 1.0000
59.7800 11398.0000 1.0000
59.8400 11402.0000 1.0000
59.9000 11690.0000 1.0000
59.9600 12020.0000 1.0000
60.0200 11439.0000 1.0000
60.0800 11608.0000 1.0000
60.1400 11623.0000 1.0000
60.2000 11257.0000 1.0000
60.2600 11318.0000 1.0000
60.3200 11340.0000 1.0000
60.3800 11212.0000 1.0000
60.4400 11216.0000 1.0000
60.5000 11132.0000 1.0000
60.5600 11237.0000 1.0000
60.6200 11268.0000 1.0000
60.6800 11347.0000 1.0000
60.7400 11469.0000 1.0000
60.8000 11153.0000 1.0000
60.8600 11301.0000 1.0000
60.9200 11271.0000 1.0000
60.9800 11482.0000 1.0000
61.0400 11255.0000 1.0000
61.1000 11441.0000 1.0000
61.1600 11668.0000 1.0000
61.2200 11589.0000 1.0000
61.2800 11896.0000 1.0000
61.3400 11518.0000 1.0000
61.4000 11560.0000 1.0000
61.4600 11576.0000 1.0000
61.5200 11370.0000 1.0000
61.5800 11485.0000 1.0000
61.6400 11471.0000 1.0000
61.7000 11340.0000 1.0000
61.7600 11228.0000 1.0000
61.8200 11348.0000 1.0000
61.8800 11203.0000 1.0000
61.9400 11334.0000 1.0000
62.0000 11354.0000 1.0000
62.0600 11478.0000 1.0000
62.1200 11290.0000 1.0000
62.1800 11517.0000 1.0000
62.2400 11700.0000 1.0000
62.3000 12068.0000 1.0000
62.3600 13126.0000 1.0000
62.4200 15009.0000 1.0000
62.4800 14495.0000 1.0000
62.5400 14728.0000 1.0000
62.6000 16361.0000 1.0000
62.6600 15770.0000 1.0000
62.7200 14222.0000 1.0000
62.7800 14136.0000 1.0000
62.8400 13467.0000 1.0000
62.9000 12441.0000 1.0000
62.9600 11828.0000 1.0000
63.0200 11663.0000 1.0000
63.0800 11506.0000 1.0000
63.1400 11280.0000 1.0000
63.2000 11507.0000 1.0000
63.2600 11513.0000 1.0000
63.3200 11352.0000 1.0000
63.3800 11439.0000 1.0000
63.4400 11428.0000 1.0000
63.5000 11466.0000 1.0000
63.5600 11370.0000 1.0000
63.6200 11404.0000 1.0000
63.6800 11462.0000 1.0000
63.7400 11404.0000 1.0000
63.8000 11840.0000 1.0000
63.8600 11856.0000 1.0000
63.9200 12760.0000 1.0000
63.9800 14638.0000 1.0000
64.0400 14163.0000 1.0000
64.1000 12952.0000 1.0000
64.1600 13166.0000 1.0000
64.2200 12591.0000 1.0000
64.2800 12059.0000 1.0000
64.3400 11645.0000 1.0000
64.4000 11632.0000 1.0000
64.4600 11393.0000 1.0000
64.5200 11295.0000 1.0000
64.5800 11343.0000 1.0000
64.6400 11197.0000 1.0000
64.7000 11131.0000 1.0000
64.7600 11416.0000 1.0000
64.8200 11249.0000 1.0000
64.8800 11200.0000 1.0000
64.9400 11273.0000 1.0000
65.0000 11273.0000 1.0000
65.0600 11228.0000 1.0000
65.1200 11233.0000 1.0000
65.1800 11310.0000 1.0000
65.2400 11218.0000 1.0000
65.3000 11231.0000 1.0000
65.3600 11081.0000 1.0000
65.4200 11344.0000 1.0000
65.4800 11268.0000 1.0000
65.5400 11195.0000 1.0000
65.6000 11298.0000 1.0000
65.6600 11370.0000 1.0000
65.7200 11412.0000 1.0000
65.7800 11574.0000 1.0000
65.8400 11478.0000 1.0000
65.9000 11539.0000 1.0000
65.9600 11356.0000 1.0000
66.0200 11589.0000 1.0000
66.0800 11334.0000 1.0000
66.1400 11426.0000 1.0000
66.2000 11499.0000 1.0000
66.2600 11747.0000 1.0000
66.3200 11799.0000 1.0000
66.3800 11977.0000 1.0000
66.4400 12304.0000 1.0000
66.5000 13376.0000 1.0000
66.5600 12776.0000 1.0000
66.6200 12167.0000 1.0000
66.6800 12513.0000 1.0000
66.7400 12030.0000 1.0000
66.8000 11831.0000 1.0000
66.8600 11359.0000 1.0000
66.9200 11608.0000 1.0000
66.9800 11566.0000 1.0000
67.0400 11228.0000 1.0000
67.1000 11397.0000 1.0000
67.1600 11324.0000 1.0000
67.2200 11330.0000 1.0000
67.2800 11436.0000 1.0000
67.3400 11403.0000 1.0000
67.4000 11345.0000 1.0000
67.4600 11307.0000 1.0000
67.5200 11441.0000 1.0000
67.5800 11372.0000 1.0000
67.6400 11560.0000 1.0000
67.7000 11715.0000 1.0000
67.7600 11505.0000 1.0000
67.8200 11547.0000 1.0000
67.8800 11501.0000 1.0000
67.9400 11948.0000 1.0000
68.0000 11940.0000 1.0000
68.0600 12182.0000 1.0000
68.1200 13093.0000 1.0000
68.1800 14623.0000 1.0000
68.2400 14189.0000 1.0000
68.3000 13219.0000 1.0000
68.3600 13118.0000 1.0000
68.4200 12781.0000 1.0000
68.4800 12128.0000 1.0000
68.5400 11924.0000 1.0000
68.6000 11514.0000 1.0000
68.6600 11304.0000 1.0000
68.7200 11392.0000 1.0000
68.7800 11369.0000 1.0000
68.8400 11247.0000 1.0000
68.9000 11467.0000 1.0000
68.9600 11296.0000 1.0000
69.0200 11308.0000 1.0000
69.0800 11172.0000 1.0000
69.1400 11219.0000 1.0000
69.2000 11399.0000 1.0000
69.2600 11546.0000 1.0000
69.3200 11243.0000 1.0000
69.3800 11377.0000 1.0000
69.4400 11488.0000 1.0000
69.5000 11349.0000 1.0000
69.5600 11642.0000 1.0000
69.6200 11733.0000 1.0000
69.6800 11295.0000 1.0000
69.7400 11349.0000 1.0000
69.8000 11387.0000 1.0000
69.8600 11411.0000 1.0000
69.9200 11277.0000 1.0000
69.9800 11324.0000 1.0000
70.0400 11085.0000 1.0000
70.1000 11232.0000 1.0000
70.1600 11273.0000 1.0000
70.2200 11242.0000 1.0000
70.2800 11330.0000 1.0000
70.3400 11522.0000 1.0000
70.4000 11352.0000 1.0000
70.4600 11231.0000 1.0000
70.5200 11237.0000 1.0000
70.5800 11179.0000 1.0000
70.6400 11277.0000 1.0000
70.7000 11133.0000 1.0000
70.7600 11205.0000 1.0000
70.8200 11365.0000 1.0000
70.8800 11221.0000 1.0000
70.9400 11372.0000 1.0000
71.0000 11688.0000 1.0000
71.0600 11674.0000 1.0000
71.1200 11596.0000 1.0000
71.1800 11396.0000 1.0000
71.2400 11582.0000 1.0000
71.3000 11309.0000 1.0000
71.3600 11238.0000 1.0000
71.4200 11229.0000 1.0000
71.4800 11316.0000 1.0000
71.5400 11288.0000 1.0000
71.6000 11353.0000 1.0000
71.6600 11347.0000 1.0000
71.7200 11396.0000 1.0000
71.7800 11403.0000 1.0000
71.8400 11598.0000 1.0000
71.9000 12169.0000 1.0000
71.9600 12380.0000 1.0000
72.0200 11929.0000 1.0000
72.0800 11711.0000 1.0000
72.1400 11915.0000 1.0000
72.2000 11778.0000 1.0000
72.2600 11616.0000 1.0000
72.3200 11653.0000 1.0000
72.3800 11435.0000 1.0000
72.4400 11510.0000 1.0000
72.5000 11473.0000 1.0000
72.5600 11207.0000 1.0000
72.6200 11527.0000 1.0000
72.6800 11053.0000 1.0000
72.7400 11360.0000 1.0000
72.8000 11381.0000 1.0000
72.8600 11199.0000 1.0000
72.9200 11167.0000 1.0000
72.9800 11389.0000 1.0000
73.0400 11454.0000 1.0000
73.1000 11480.0000 1.0000
73.1600 11356.0000 1.0000
73.2200 11352.0000 1.0000
73.2800 11299.0000 1.0000
73.3400 11463.0000 1.0000
73.4000 11525.0000 1.0000
73.4600 12058.0000 1.0000
73.5200 11458.0000 1.0000
73.5800 11350.0000 1.0000
73.6400 11326.0000 1.0000
73.7000 11474.0000 1.0000
73.7600 11235.0000 1.0000
73.8200 11450.0000 1.0000
73.8800 11528.0000 1.0000
73.9400 11623.0000 1.0000
74.0000 11483.0000 1.0000
74.0600 12005.0000 1.0000
74.1200 11730.0000 1.0000
74.1800 11625.0000 1.0000
74.2400 11961.0000 1.0000
74.3000 11762.0000 1.0000
74.3600 11389.0000 1.0000
74.4200 11504.0000 1.0000
74.4800 11544.0000 1.0000
74.5400 11313.0000 1.0000
74.6000 11368.0000 1.0000
74.6600 11342.0000 1.0000
74.7200 11390.0000 1.0000
74.7800 11377.0000 1.0000
74.8400 11370.0000 1.0000
74.9000 11446.0000 1.0000
74.9600 11371.0000 1.0000
75.0200 11432.0000 1.0000
75.0800 11657.0000 1.0000
75.1400 11529.0000 1.0000
75.2000 11614.0000 1.0000
75.2600 11475.0000 1.0000
75.3200 11608.0000 1.0000
75.3800 11719.0000 1.0000
75.4400 11916.0000 1.0000
75.5000 11933.0000 1.0000
75.5600 11602.0000 1.0000
75.6200 11930.0000 1.0000
75.6800 12109.0000 1.0000
75.7400 11578.0000 1.0000
75.8000 11611.0000 1.0000
75.8600 11531.0000 1.0000
75.9200 11482.0000 1.0000
75.9800 11216.0000 1.0000
76.0400 11302.0000 1.0000
76.1000 11258.0000 1.0000
76.1600 11275.0000 1.0000
76.2200 11322.0000 1.0000
76.2800 11272.0000 1.0000
76.3400 11279.0000 1.0000
76.4000 11330.0000 1.0000
76.4600 11506.0000 1.0000
76.5200 11295.0000 1.0000
76.5800 11349.0000 1.0000
76.6400 11087.0000 1.0000
76.7000 11653.0000 1.0000
76.7600 11740.0000 1.0000
76.8200 11994.0000 1.0000
76.8800 12091.0000 1.0000
76.9400 11762.0000 1.0000
77.0000 11808.0000 1.0000
77.0600 11889.0000 1.0000
77.1200 11830.0000 1.0000
77.1800 11644.0000 1.0000
77.2400 11863.0000 1.0000
77.3000 11518.0000 1.0000
77.3600 11439.0000 1.0000
77.4200 11484.0000 1.0000
77.4800 11474.0000 1.0000
77.5400 11278.0000 1.0000
77.6000 11343.0000 1.0000
77.6600 11370.0000 1.0000
77.7200 11586.0000 1.0000
77.7800 11411.0000 1.0000
77.8400 11344.0000 1.0000
77.9000 11524.0000 1.0000
77.9600 11573.0000 1.0000
78.0200 11540.0000 1.0000
78.0800 11323.0000 1.0000
78.1400 11201.0000 1.0000
78.2000 11113.0000 1.0000
78.2600 11107.0000 1.0000
78.3200 11395.0000 1.0000
78.3800 11209.0000 1.0000
78.4400 11256.0000 1.0000
78.5000 11325.0000 1.0000
78.5600 11275.0000 1.0000
78.6200 11338.0000 1.0000
78.6800 11237.0000 1.0000
78.7400 11354.0000 1.0000
78.8000 11309.0000 1.0000
78.8600 11199.0000 1.0000
78.9200 11400.0000 1.0000
78.9800 11306.0000 1.0000
79.0400 11451.0000 1.0000
79.1000 11362.0000 1.0000
79.1600 11194.0000 1.0000
79.2200 11210.0000 1.0000
79.2800 11357.0000 1.0000
79.3400 11354.0000 1.0000
79.4000 11281.0000 1.0000
79.4600 11345.0000 1.0000
79.5200 11266.0000 1.0000
79.5800 11061.0000 1.0000
79.6400 11326.0000 1.0000
79.7000 11356.0000 1.0000
79.7600 11397.0000 1.0000
79.8200 11595.0000 1.0000
79.8800 11806.0000 1.0000
79.9400 11358.0000 1.0000
80.0000 11450.0000 1.0000
80.0600 11409.0000 1.0000
80.1200 11741.0000 1.0000
80.1800 11303.0000 1.0000
80.2400 11428.0000 1.0000
80.3000 11274.0000 1.0000
80.3600 11490.0000 1.0000
80.4200 11420.0000 1.0000
80.4800 11431.0000 1.0000
80.5400 11552.0000 1.0000
80.6000 11750.0000 1.0000
80.6600 11895.0000 1.0000
80.7200 11891.0000 1.0000
80.7800 11740.0000 1.0000
80.8400 11467.0000 1.0000
80.9000 11772.0000 1.0000
80.9600 11842.0000 1.0000
81.0200 11475.0000 1.0000
81.0800 11519.0000 1.0000
81.1400 11475.0000 1.0000
81.2000 11429.0000 1.0000
81.2600 11229.0000 1.0000
81.3200 11365.0000 1.0000
81.3800 11239.0000 1.0000
81.4400 11500.0000 1.0000
81.5000 11300.0000 1.0000
81.5600 11331.0000 1.0000
81.6200 11250.0000 1.0000
81.6800 11147.0000 1.0000
81.7400 11259.0000 1.0000
81.8000 11161.0000 1.0000
81.8600 11385.0000 1.0000
81.9200 11055.0000 1.0000
81.9800 11300.0000 1.0000
82.0400 11102.0000 1.0000
82.1000 11222.0000 1.0000
82.1600 11221.0000 1.0000
82.2200 11151.0000 1.0000
82.2800 11120.0000 1.0000
82.3400 11247.0000 1.0000
82.4000 11263.0000 1.0000
82.4600 11041.0000 1.0000
82.5200 11394.0000 1.0000
82.5800 11423.0000 1.0000
82.6400 11294.0000 1.0000
82.7000 11221.0000 1.0000
82.7600 11284.0000 1.0000
82.8200 11365.0000 1.0000
82.8800 11512.0000 1.0000
82.9400 11956.0000 1.0000
83.0000 11600.0000 1.0000
83.0600 11446.0000 1.0000
83.1200 11394.0000 1.0000
83.1800 11542.0000 1.0000
83.2400 11501.0000 1.0000
83.3000 11286.0000 1.0000
83.3600 11386.0000 1.0000
83.4200 11336.0000 1.0000
83.4800 11400.0000 1.0000
83.5400 11289.0000 1.0000
83.6000 10983.0000 1.0000
83.6600 11223.0000 1.0000
83.7200 11474.0000 1.0000
83.7800 11218.0000 1.0000
83.8400 11309.0000 1.0000
83.9000 11237.0000 1.0000
83.9600 11272.0000 1.0000
84.0200 11295.0000 1.0000
84.0800 11351.0000 1.0000
84.1400 11226.0000 1.0000
84.2000 11381.0000 1.0000
84.2600 11408.0000 1.0000
84.3200 11434.0000 1.0000
84.3800 11322.0000 1.0000
84.4400 11275.0000 1.0000
84.5000 11260.0000 1.0000
84.5600 11452.0000 1.0000
84.6200 11384.0000 1.0000
84.6800 11270.0000 1.0000
84.7400 11505.0000 1.0000
84.8000 11670.0000 1.0000
84.8600 11839.0000 1.0000
84.9200 11959.0000 1.0000
84.9800 11780.0000 1.0000
85.0400 11563.0000 1.0000
85.1000 11329.0000 1.0000
85.1600 11598.0000 1.0000
85.2200 11674.0000 1.0000
85.2800 11286.0000 1.0000
85.3400 11378.0000 1.0000
85.4000 11286.0000 1.0000
85.4600 11220.0000 1.0000
85.5200 11222.0000 1.0000
85.5800 11264.0000 1.0000
85.6400 11262.0000 1.0000
85.7000 11234.0000 1.0000
85.7600 11155.0000 1.0000
85.8200 11314.0000 1.0000
85.8800 11369.0000 1.0000
85.9400 11303.0000 1.0000
86.0000 11133.0000 1.0000
86.0600 11402.0000 1.0000
86.1200 11127.0000 1.0000
86.1800 11465.0000 1.0000
86.2400 11378.0000 1.0000
86.3000 11489.0000 1.0000
86.3600 11469.0000 1.0000
86.4200 11305.0000 1.0000
86.4800 11445.0000 1.0000
86.5400 11524.0000 1.0000
86.6000 11433.0000 1.0000
86.6600 11347.0000 1.0000
86.7200 11167.0000 1.0000
86.7800 11597.0000 1.0000
86.8400 11547.0000 1.0000
86.9000 11515.0000 1.0000
86.9600 11487.0000 1.0000
87.0200 11249.0000 1.0000
87.0800 11292.0000 1.0000
87.1400 11487.0000 1.0000
87.2000 11439.0000 1.0000
87.2600 11193.0000 1.0000
87.3200 11104.0000 1.0000
87.3800 11275.0000 1.0000
87.4400 11314.0000 1.0000
87.5000 11398.0000 1.0000
87.5600 11294.0000 1.0000
87.6200 11142.0000 1.0000
87.6800 11380.0000 1.0000
87.7400 11251.0000 1.0000
87.8000 11032.0000 1.0000
87.8600 11038.0000 1.0000
87.9200 11099.0000 1.0000
87.9800 11272.0000 1.0000
88.0400 11356.0000 1.0000
88.1000 11127.0000 1.0000
88.1600 11180.0000 1.0000
88.2200 11322.0000 1.0000
88.2800 11377.0000 1.0000
88.3400 11197.0000 1.0000
88.4000 11397.0000 1.0000
88.4600 11516.0000 1.0000
88.5200 11955.0000 1.0000
88.5800 11947.0000 1.0000
88.6400 11489.0000 1.0000
88.7000 11574.0000 1.0000
88.7600 11666.0000 1.0000
88.8200 11598.0000 1.0000
88.8800 11709.0000 1.0000
88.9400 11453.0000 1.0000
89.0000 11713.0000 1.0000
89.0600 11468.0000 1.0000
89.1200 11344.0000 1.0000
89.1800 11536.0000 1.0000
89.2400 11341.0000 1.0000
89.3000 11482.0000 1.0000
89.3600 11386.0000 1.0000
89.4200 11219.0000 1.0000
89.4800 11447.0000 1.0000
89.5400 11456.0000 1.0000
89.6000 11483.0000 1.0000
89.6600 11713.0000 1.0000
89.7200 11901.0000 1.0000
89.7800 12087.0000 1.0000
89.8400 11763.0000 1.0000
89.9000 11631.0000 1.0000
89.9600 11787.0000 1.0000
90.0000 11667.0000 1.0000
*RAS_INT_END
*RAS_TEMPERATURE_START
*RAS_TEMPERATURE_END
*RAS_DATA_END