File: XRD/Data/20200918_mix_10.ras
*RAS_DATA_START
*RAS_HEADER_START
*DISP_FMT_X "%.2f"
*DISP_FMT_Y "%.0f"
*DISP_FULLSCALE "73239.0000000000"
*DISP_LINE_COLOR "255.0000000000"
*DISP_LINE_STYLE "0.0000000000"
*DISP_LINE_WIDTH "0.2500000000"
*DISP_NOTE "測定データ-1"
*DISP_OFFSET_Y "0.0000000000"
*DISP_PEAKSEARCH_UNIT_Y "cps"
*DISP_RANGE_BOTTOM "0.0000000000"
*DISP_RANGE_LEFT "20.0000000000"
*DISP_RANGE_LOGCUTOFF "0.0100000000"
*DISP_RANGE_RIGHT "90.0000000000"
*DISP_RANGE_TOP "73239.0000000000"
*DISP_SCALE_MODE_Y "0.0000000000"
*DISP_TAB_NAME "2θ/θ"
*DISP_TITLE_Y "強度"
*DISP_UNIT_Y "cps"
*DISP_WINDOW_NAME "MSG_MACROENGINE"
*FILE_COMMENT " "
*FILE_MD5 ""
*FILE_MEMO " "
*FILE_OPERATOR "Administrator"
*FILE_SAMPLE " "
*FILE_TYPE "RAS_RAW"
*FILE_USERGROUP "システムマネージャ"
*FILE_VERSION "1.0000000000"
*HW_ATTACHMENT_ID "ATT0025"
*HW_ATTACHMENT_NAME "標準|Standard"
*HW_COUNTER_ID-0 "CUT0025"
*HW_COUNTER_ID-1 "CUT0020"
*HW_COUNTER_ID-2 "CUT0020"
*HW_COUNTER_ID-3 "CSL0021"
*HW_COUNTER_ID-4 "CMC0021"
*HW_COUNTER_NAME-0 "D/teX Ultra|D/teX Ultra"
*HW_COUNTER_NAME-1 "None|None"
*HW_COUNTER_NAME-2 "None|None"
*HW_COUNTER_NAME-3 "BBM|BBM"
*HW_COUNTER_NAME-4 "検出器モノクロメータ|Detector monochromator"
*HW_COUNTER_SELECT_NAME "D/teX Ultra|D/teX Ultra"
*HW_GONIOMETER_ID "GON0023"
*HW_GONIOMETER_NAME "SmartLab|SmartLab"
*HW_GONIOMETER_RADIUS-0 "90.0"
*HW_GONIOMETER_RADIUS-1 "114.0"
*HW_GONIOMETER_RADIUS-2 "190.0"
*HW_GONIOMETER_RADIUS-3 "300.0"
*HW_GONIOMETER_RADIUS-4 "187.0"
*HW_GONIOMETER_RADIUS-5 "300.0"
*HW_GONIOMETER_RADIUS-6 "113.0"
*HW_GONIOMETER_RADIUS-7 "331.0"
*HW_I_OPT_ID-0 "CBO0021"
*HW_I_OPT_ID-1 "ICR0023"
*HW_I_OPT_ID-2 "ISL0021"
*HW_I_OPT_ID-3 "ISO0021"
*HW_I_OPT_ID-4 "IAD0021"
*HW_I_OPT_ID-5 "IPR0001"
*HW_I_OPT_NAME-0 "CBOユニット|CBO unit"
*HW_I_OPT_NAME-1 "標準入射光学ユニット|Standard incident optical unit"
*HW_I_OPT_NAME-2 "標準入射スリットボックス|Standard incident slit box"
*HW_I_OPT_NAME-3 "入射平行スリット|Incident parallel slit"
*HW_I_OPT_NAME-4 "長手制限スリット|Length limiting slit"
*HW_I_OPT_NAME-5 "None|None"
*HW_R_ATTENUATER_AUTOMODE "0"
*HW_R_OPT_ID-0 "RSS0021"
*HW_R_OPT_ID-1 "RCR0023"
*HW_R_OPT_ID-2 "RSO0021"
*HW_R_OPT_ID-3 "RRS0021"
*HW_R_OPT_ID-4 "ATN0021"
*HW_R_OPT_ID-5 "RFL0021"
*HW_R_OPT_ID-6 "RAD0021"
*HW_R_OPT_NAME-0 "標準受光スリットボックス1|Standard receiving slit box # 1"
*HW_R_OPT_NAME-1 "標準受光光学ユニット1|Standard receiving unit # 1"
*HW_R_OPT_NAME-2 "標準受光光学ユニット2|Standard receiving optical unit # 2"
*HW_R_OPT_NAME-3 "標準受光スリットボックス2|Standard receiving slit box # 2"
*HW_R_OPT_NAME-4 "標準アッテネータ|Standard Attenuator"
*HW_R_OPT_NAME-5 "Cu Kβ|Cu K-beta"
*HW_R_OPT_NAME-6 "調整用受光スリット|Alignment receiving slit"
*HW_SAMPLE_HOLDER_ID "SMP0023"
*HW_SAMPLE_HOLDER_NAME "標準Zステージ|Standard Z stage"
*HW_XG_CURRENT_MAX "50"
*HW_XG_CURRENT_MIN "2"
*HW_XG_CURRENT_RESOLUTION "2"
*HW_XG_CURRENT_UNIT "mA"
*HW_XG_FOCUS "1mm x 10mm"
*HW_XG_FOCUS_TYPE "Normal"
*HW_XG_ID ""
*HW_XG_NAME "3kW 封入管(ID:1200)|3kW Sealed tube(ID:1200)"
*HW_XG_TARGET_ATOMIC_NUMBER "29.0000000000"
*HW_XG_TARGET_NAME "Cu"
*HW_XG_TYPE "Hermetic"
*HW_XG_VOLTAGE_MAX "60"
*HW_XG_VOLTAGE_MIN "20"
*HW_XG_VOLTAGE_RESOLUTION "2"
*HW_XG_VOLTAGE_UNIT "kV"
*HW_XG_WATT_MAX "2"
*HW_XG_WATT_UNIT "kW"
*HW_XG_WAVE_LENGTH_ALPHA1 "1.540593"
*HW_XG_WAVE_LENGTH_ALPHA2 "1.544414"
*HW_XG_WAVE_LENGTH_BETA "1.392250"
*MEAS_COND_AXIS_NAME-0 "2θ/θ"
*MEAS_COND_AXIS_NAME-1 "2θ"
*MEAS_COND_AXIS_NAME-2 "ω"
*MEAS_COND_AXIS_NAME-3 "Z"
*MEAS_COND_AXIS_NAME-4 "2θ/ω"
*MEAS_COND_AXIS_NAME-5 "θs"
*MEAS_COND_AXIS_NAME-6 "θd"
*MEAS_COND_AXIS_NAME-7 "Ts"
*MEAS_COND_AXIS_NAME-8 "CBO選択スリット"
*MEAS_COND_AXIS_NAME-9 "M"
*MEAS_COND_AXIS_NAME-10 "入射平行スリット"
*MEAS_COND_AXIS_NAME-11 "入射スリット"
*MEAS_COND_AXIS_NAME-12 ""
*MEAS_COND_AXIS_NAME-13 "Zs"
*MEAS_COND_AXIS_NAME-14 "入射光学素子"
*MEAS_COND_AXIS_NAME-15 "長手制限スリット"
*MEAS_COND_AXIS_NAME-16 "センタースリット"
*MEAS_COND_AXIS_NAME-17 "フィルター"
*MEAS_COND_AXIS_NAME-18 "受光スリット1"
*MEAS_COND_AXIS_NAME-19 "受光スリット2"
*MEAS_COND_AXIS_NAME-20 "受光光学素子"
*MEAS_COND_AXIS_NAME-21 "受光平行スリット"
*MEAS_COND_AXIS_NAME-22 "調整用受光スリット"
*MEAS_COND_AXIS_NAME-23 ""
*MEAS_COND_AXIS_NAME-24 ""
*MEAS_COND_AXIS_NAME-25 "Zd"
*MEAS_COND_AXIS_NAME-26 "アッテネータ"
*MEAS_COND_AXIS_NAME-27 "検出器モノクロメータ"
*MEAS_COND_AXIS_NAME-28 "モノクロメータスリット"
*MEAS_COND_AXIS_NAME-29 "プライマリビーム"
*MEAS_COND_AXIS_NAME-30 "PHA"
*MEAS_COND_AXIS_NAME_INTERNAL-0 "TwoThetaTheta"
*MEAS_COND_AXIS_NAME_INTERNAL-1 "TwoTheta"
*MEAS_COND_AXIS_NAME_INTERNAL-2 "Omega"
*MEAS_COND_AXIS_NAME_INTERNAL-3 "Z"
*MEAS_COND_AXIS_NAME_INTERNAL-4 "TwoThetaOmega"
*MEAS_COND_AXIS_NAME_INTERNAL-5 "ThetaS"
*MEAS_COND_AXIS_NAME_INTERNAL-6 "ThetaD"
*MEAS_COND_AXIS_NAME_INTERNAL-7 "Ts"
*MEAS_COND_AXIS_NAME_INTERNAL-8 "CBO"
*MEAS_COND_AXIS_NAME_INTERNAL-9 "CBO-M"
*MEAS_COND_AXIS_NAME_INTERNAL-10 "IncidentSollerSlit"
*MEAS_COND_AXIS_NAME_INTERNAL-11 "IncidentSlitBox"
*MEAS_COND_AXIS_NAME_INTERNAL-12 "IncidentSlitBox-_Axis"
*MEAS_COND_AXIS_NAME_INTERNAL-13 "Zs"
*MEAS_COND_AXIS_NAME_INTERNAL-14 "IncidentMonochromator"
*MEAS_COND_AXIS_NAME_INTERNAL-15 "IncidentAxdSlit"
*MEAS_COND_AXIS_NAME_INTERNAL-16 "CenterSlit"
*MEAS_COND_AXIS_NAME_INTERNAL-17 "Filter"
*MEAS_COND_AXIS_NAME_INTERNAL-18 "ReceivingSlitBox1"
*MEAS_COND_AXIS_NAME_INTERNAL-19 "ReceivingSlitBox2"
*MEAS_COND_AXIS_NAME_INTERNAL-20 "ReceivingOptics"
*MEAS_COND_AXIS_NAME_INTERNAL-21 "ReceivingSollerSlit"
*MEAS_COND_AXIS_NAME_INTERNAL-22 "ReceivingAxdSlit"
*MEAS_COND_AXIS_NAME_INTERNAL-23 "ReceivingSlitBox1-_Axis"
*MEAS_COND_AXIS_NAME_INTERNAL-24 "ReceivingSlitBox2-_Axis"
*MEAS_COND_AXIS_NAME_INTERNAL-25 "ReceivingSlitBox2-Zd"
*MEAS_COND_AXIS_NAME_INTERNAL-26 "Attenuator"
*MEAS_COND_AXIS_NAME_INTERNAL-27 "CounterMonochromator"
*MEAS_COND_AXIS_NAME_INTERNAL-28 "CounterSlit"
*MEAS_COND_AXIS_NAME_INTERNAL-29 "IncidentPrimary"
*MEAS_COND_AXIS_NAME_INTERNAL-30 "PHA"
*MEAS_COND_AXIS_NAME_MAGICNO-0 "83951616.0000000000"
*MEAS_COND_AXIS_NAME_MAGICNO-1 "268632064.0000000000"
*MEAS_COND_AXIS_NAME_MAGICNO-2 "268500992.0000000000"
*MEAS_COND_AXIS_NAME_MAGICNO-3 "285278208.0000000000"
*MEAS_COND_AXIS_NAME_MAGICNO-4 "83951616.0000000000"
*MEAS_COND_AXIS_NAME_MAGICNO-5 "131072.0000000000"
*MEAS_COND_AXIS_NAME_MAGICNO-6 "131072.0000000000"
*MEAS_COND_AXIS_NAME_MAGICNO-7 "318898176.0000000000"
*MEAS_COND_AXIS_NAME_MAGICNO-8 "20971521.0000000000"
*MEAS_COND_AXIS_NAME_MAGICNO-9 "285343744.0000000000"
*MEAS_COND_AXIS_NAME_MAGICNO-10 "20971521.0000000000"
*MEAS_COND_AXIS_NAME_MAGICNO-11 "22020097.0000000000"
*MEAS_COND_AXIS_NAME_MAGICNO-12 "25165824.0000000000"
*MEAS_COND_AXIS_NAME_MAGICNO-13 "318898176.0000000000"
*MEAS_COND_AXIS_NAME_MAGICNO-14 "1.0000000000"
*MEAS_COND_AXIS_NAME_MAGICNO-15 "20971521.0000000000"
*MEAS_COND_AXIS_NAME_MAGICNO-16 "20971521.0000000000"
*MEAS_COND_AXIS_NAME_MAGICNO-17 "20971521.0000000000"
*MEAS_COND_AXIS_NAME_MAGICNO-18 "23068673.0000000000"
*MEAS_COND_AXIS_NAME_MAGICNO-19 "23068673.0000000000"
*MEAS_COND_AXIS_NAME_MAGICNO-20 "20971521.0000000000"
*MEAS_COND_AXIS_NAME_MAGICNO-21 "20971521.0000000000"
*MEAS_COND_AXIS_NAME_MAGICNO-22 "20971521.0000000000"
*MEAS_COND_AXIS_NAME_MAGICNO-23 "25165824.0000000000"
*MEAS_COND_AXIS_NAME_MAGICNO-24 "25165824.0000000000"
*MEAS_COND_AXIS_NAME_MAGICNO-25 "285343744.0000000000"
*MEAS_COND_AXIS_NAME_MAGICNO-26 "17301505.0000000000"
*MEAS_COND_AXIS_NAME_MAGICNO-27 "20971521.0000000000"
*MEAS_COND_AXIS_NAME_MAGICNO-28 "20971521.0000000000"
*MEAS_COND_AXIS_NAME_MAGICNO-29 "20971521.0000000000"
*MEAS_COND_AXIS_NAME_MAGICNO-30 "0.0000000000"
*MEAS_COND_AXIS_OFFSET-0 "-"
*MEAS_COND_AXIS_OFFSET-1 "-0.1081000000"
*MEAS_COND_AXIS_OFFSET-2 "0.3758000000"
*MEAS_COND_AXIS_OFFSET-3 "-"
*MEAS_COND_AXIS_OFFSET-4 "-"
*MEAS_COND_AXIS_OFFSET-5 "0.3758000000"
*MEAS_COND_AXIS_OFFSET-6 "-0.4839000000"
*MEAS_COND_AXIS_OFFSET-7 "-"
*MEAS_COND_AXIS_OFFSET-8 "-"
*MEAS_COND_AXIS_OFFSET-9 "-"
*MEAS_COND_AXIS_OFFSET-10 "-"
*MEAS_COND_AXIS_OFFSET-11 "-"
*MEAS_COND_AXIS_OFFSET-12 "-"
*MEAS_COND_AXIS_OFFSET-13 "-"
*MEAS_COND_AXIS_OFFSET-14 "-"
*MEAS_COND_AXIS_OFFSET-15 "-"
*MEAS_COND_AXIS_OFFSET-16 "-"
*MEAS_COND_AXIS_OFFSET-17 "-"
*MEAS_COND_AXIS_OFFSET-18 "-"
*MEAS_COND_AXIS_OFFSET-19 "-"
*MEAS_COND_AXIS_OFFSET-20 "-"
*MEAS_COND_AXIS_OFFSET-21 "-"
*MEAS_COND_AXIS_OFFSET-22 "-"
*MEAS_COND_AXIS_OFFSET-23 "-"
*MEAS_COND_AXIS_OFFSET-24 "-"
*MEAS_COND_AXIS_OFFSET-25 "-"
*MEAS_COND_AXIS_OFFSET-26 "-"
*MEAS_COND_AXIS_OFFSET-27 "-"
*MEAS_COND_AXIS_OFFSET-28 "-"
*MEAS_COND_AXIS_OFFSET-29 "-"
*MEAS_COND_AXIS_OFFSET-30 "-"
*MEAS_COND_AXIS_POSITION-0 "0.0000000000"
*MEAS_COND_AXIS_POSITION-1 "0.0000000000"
*MEAS_COND_AXIS_POSITION-2 "0.0000000000"
*MEAS_COND_AXIS_POSITION-3 "-0.5500000000"
*MEAS_COND_AXIS_POSITION-4 "0.0000000000"
*MEAS_COND_AXIS_POSITION-5 "0.0000000000"
*MEAS_COND_AXIS_POSITION-6 "0.0000000000"
*MEAS_COND_AXIS_POSITION-7 "-0.4278800000"
*MEAS_COND_AXIS_POSITION-8 "BB"
*MEAS_COND_AXIS_POSITION-9 "0.0000000000"
*MEAS_COND_AXIS_POSITION-10 "Soller_slit_5.0deg"
*MEAS_COND_AXIS_POSITION-11 "2/3deg"
*MEAS_COND_AXIS_POSITION-12 "2.2088000000"
*MEAS_COND_AXIS_POSITION-13 "-0.4140600000"
*MEAS_COND_AXIS_POSITION-14 "0.0000000000"
*MEAS_COND_AXIS_POSITION-15 "10.0mm"
*MEAS_COND_AXIS_POSITION-16 "None"
*MEAS_COND_AXIS_POSITION-17 "Cu_K-beta"
*MEAS_COND_AXIS_POSITION-18 "13.000mm"
*MEAS_COND_AXIS_POSITION-19 "13.000mm"
*MEAS_COND_AXIS_POSITION-20 "No_unit"
*MEAS_COND_AXIS_POSITION-21 "Soller_slit_5.0deg"
*MEAS_COND_AXIS_POSITION-22 "None"
*MEAS_COND_AXIS_POSITION-23 "13.0000000000"
*MEAS_COND_AXIS_POSITION-24 "13.0000000000"
*MEAS_COND_AXIS_POSITION-25 "0.0109400000"
*MEAS_COND_AXIS_POSITION-26 "Open"
*MEAS_COND_AXIS_POSITION-27 "None"
*MEAS_COND_AXIS_POSITION-28 "None"
*MEAS_COND_AXIS_POSITION-29 "None"
*MEAS_COND_AXIS_POSITION-30 "38.0000000000"
*MEAS_COND_AXIS_UNIT-0 "deg"
*MEAS_COND_AXIS_UNIT-1 "deg"
*MEAS_COND_AXIS_UNIT-2 "deg"
*MEAS_COND_AXIS_UNIT-3 "mm"
*MEAS_COND_AXIS_UNIT-4 "deg"
*MEAS_COND_AXIS_UNIT-5 "deg"
*MEAS_COND_AXIS_UNIT-6 "deg"
*MEAS_COND_AXIS_UNIT-7 "mm"
*MEAS_COND_AXIS_UNIT-8 ""
*MEAS_COND_AXIS_UNIT-9 "pulse"
*MEAS_COND_AXIS_UNIT-10 ""
*MEAS_COND_AXIS_UNIT-11 ""
*MEAS_COND_AXIS_UNIT-12 "mm"
*MEAS_COND_AXIS_UNIT-13 "mm"
*MEAS_COND_AXIS_UNIT-14 ""
*MEAS_COND_AXIS_UNIT-15 ""
*MEAS_COND_AXIS_UNIT-16 ""
*MEAS_COND_AXIS_UNIT-17 ""
*MEAS_COND_AXIS_UNIT-18 ""
*MEAS_COND_AXIS_UNIT-19 ""
*MEAS_COND_AXIS_UNIT-20 ""
*MEAS_COND_AXIS_UNIT-21 ""
*MEAS_COND_AXIS_UNIT-22 ""
*MEAS_COND_AXIS_UNIT-23 "mm"
*MEAS_COND_AXIS_UNIT-24 "mm"
*MEAS_COND_AXIS_UNIT-25 "mm"
*MEAS_COND_AXIS_UNIT-26 ""
*MEAS_COND_AXIS_UNIT-27 ""
*MEAS_COND_AXIS_UNIT-28 ""
*MEAS_COND_AXIS_UNIT-29 ""
*MEAS_COND_AXIS_UNIT-30 "div"
*MEAS_COND_COUNTER_CNTLOSS_CORR "0.0000000000"
*MEAS_COND_COUNTER_PHABASE "38.0000000000"
*MEAS_COND_COUNTER_PHAWINDOW "16.0000000000"
*MEAS_COND_COUNTER_PHA_UNIT "div"
*MEAS_COND_COUNTER_TAUDIFF "30.0000000000"
*MEAS_COND_COUNTER_TAUINT "0.0000000000"
*MEAS_COND_IRRADIATION_MODE "OFF"
*MEAS_COND_IRRADIATION_WIDTH ""
*MEAS_COND_OPT_ATTR "集中法"
*MEAS_COND_OPT_NAME "@集中法"
*MEAS_COND_UNSYMMETRIC_MODE "OFF"
*MEAS_COND_XG_CURRENT "30.0000000000"
*MEAS_COND_XG_VOLTAGE "40.0000000000"
*MEAS_COND_XG_WAVE_TYPE "Ka"
*MEAS_DATA_COUNT "3501.0000000000"
*MEAS_SCAN_AXIS_X "2θ/θ"
*MEAS_SCAN_AXIS_X_INTERNAL "TwoThetaTheta"
*MEAS_SCAN_END_TIME "09/18/20 13:44:55"
*MEAS_SCAN_MODE "CONTINUOUS"
*MEAS_SCAN_MONITOR "0"
*MEAS_SCAN_RESOLUTION_X "0.0002"
*MEAS_SCAN_SPEED "1.0"
*MEAS_SCAN_SPEED_UNIT "deg/min"
*MEAS_SCAN_START "20.0000000000"
*MEAS_SCAN_START_TIME "09/18/20 12:32:02"
*MEAS_SCAN_STEP "0.0200000000"
*MEAS_SCAN_STOP "90.0000000000"
*MEAS_SCAN_UNIT_X "deg"
*MEAS_SCAN_UNIT_Y "counts"
*RAS_HEADER_END
*RAS_INT_START
20.0000 10367.0000 1.0000
20.0600 10639.0000 1.0000
20.1200 10556.0000 1.0000
20.1800 10572.0000 1.0000
20.2400 10642.0000 1.0000
20.3000 10511.0000 1.0000
20.3600 10650.0000 1.0000
20.4200 10510.0000 1.0000
20.4800 10603.0000 1.0000
20.5400 10593.0000 1.0000
20.6000 10786.0000 1.0000
20.6600 11140.0000 1.0000
20.7200 12167.0000 1.0000
20.7800 13553.0000 1.0000
20.8400 16081.0000 1.0000
20.9000 17027.0000 1.0000
20.9600 12407.0000 1.0000
21.0200 10937.0000 1.0000
21.0800 10597.0000 1.0000
21.1400 10489.0000 1.0000
21.2000 10405.0000 1.0000
21.2600 10265.0000 1.0000
21.3200 10233.0000 1.0000
21.3800 10100.0000 1.0000
21.4400 10071.0000 1.0000
21.5000 10082.0000 1.0000
21.5600 10146.0000 1.0000
21.6200 10036.0000 1.0000
21.6800 9984.0000 1.0000
21.7400 9940.0000 1.0000
21.8000 10016.0000 1.0000
21.8600 9903.0000 1.0000
21.9200 9869.0000 1.0000
21.9800 9710.0000 1.0000
22.0400 9893.0000 1.0000
22.1000 9863.0000 1.0000
22.1600 9814.0000 1.0000
22.2200 9726.0000 1.0000
22.2800 9735.0000 1.0000
22.3400 9702.0000 1.0000
22.4000 9666.0000 1.0000
22.4600 9703.0000 1.0000
22.5200 9564.0000 1.0000
22.5800 9721.0000 1.0000
22.6400 9413.0000 1.0000
22.7000 9585.0000 1.0000
22.7600 9568.0000 1.0000
22.8200 9449.0000 1.0000
22.8800 9516.0000 1.0000
22.9400 9562.0000 1.0000
23.0000 9481.0000 1.0000
23.0600 9360.0000 1.0000
23.1200 9421.0000 1.0000
23.1800 9516.0000 1.0000
23.2400 9425.0000 1.0000
23.3000 9398.0000 1.0000
23.3600 9280.0000 1.0000
23.4200 9454.0000 1.0000
23.4800 9204.0000 1.0000
23.5400 9187.0000 1.0000
23.6000 9395.0000 1.0000
23.6600 9170.0000 1.0000
23.7200 9313.0000 1.0000
23.7800 9196.0000 1.0000
23.8400 9151.0000 1.0000
23.9000 9340.0000 1.0000
23.9600 9691.0000 1.0000
24.0200 10027.0000 1.0000
24.0800 10721.0000 1.0000
24.1400 12057.0000 1.0000
24.2000 11915.0000 1.0000
24.2600 10520.0000 1.0000
24.3200 9698.0000 1.0000
24.3800 9452.0000 1.0000
24.4400 9283.0000 1.0000
24.5000 9209.0000 1.0000
24.5600 9095.0000 1.0000
24.6200 9100.0000 1.0000
24.6800 9192.0000 1.0000
24.7400 9105.0000 1.0000
24.8000 9234.0000 1.0000
24.8600 9104.0000 1.0000
24.9200 9210.0000 1.0000
24.9800 9063.0000 1.0000
25.0400 9068.0000 1.0000
25.1000 9284.0000 1.0000
25.1600 9266.0000 1.0000
25.2200 9198.0000 1.0000
25.2800 9380.0000 1.0000
25.3400 9448.0000 1.0000
25.4000 9844.0000 1.0000
25.4600 10441.0000 1.0000
25.5200 11424.0000 1.0000
25.5800 13387.0000 1.0000
25.6400 12075.0000 1.0000
25.7000 10449.0000 1.0000
25.7600 9782.0000 1.0000
25.8200 9656.0000 1.0000
25.8800 9464.0000 1.0000
25.9400 9335.0000 1.0000
26.0000 9373.0000 1.0000
26.0600 9305.0000 1.0000
26.1200 9295.0000 1.0000
26.1800 9448.0000 1.0000
26.2400 9176.0000 1.0000
26.3000 9593.0000 1.0000
26.3600 10398.0000 1.0000
26.4200 11117.0000 1.0000
26.4800 13017.0000 1.0000
26.5400 17375.0000 1.0000
26.6000 29877.0000 1.0000
26.6600 73239.0000 1.0000
26.7200 41243.0000 1.0000
26.7800 14695.0000 1.0000
26.8400 11110.0000 1.0000
26.9000 9718.0000 1.0000
26.9600 9203.0000 1.0000
27.0200 9053.0000 1.0000
27.0800 9251.0000 1.0000
27.1400 9109.0000 1.0000
27.2000 9056.0000 1.0000
27.2600 9099.0000 1.0000
27.3200 8958.0000 1.0000
27.3800 9048.0000 1.0000
27.4400 9119.0000 1.0000
27.5000 9066.0000 1.0000
27.5600 8998.0000 1.0000
27.6200 8983.0000 1.0000
27.6800 8808.0000 1.0000
27.7400 9169.0000 1.0000
27.8000 8738.0000 1.0000
27.8600 9030.0000 1.0000
27.9200 8895.0000 1.0000
27.9800 8863.0000 1.0000
28.0400 8897.0000 1.0000
28.1000 8706.0000 1.0000
28.1600 8804.0000 1.0000
28.2200 8935.0000 1.0000
28.2800 8509.0000 1.0000
28.3400 8652.0000 1.0000
28.4000 8892.0000 1.0000
28.4600 8737.0000 1.0000
28.5200 8815.0000 1.0000
28.5800 8780.0000 1.0000
28.6400 8781.0000 1.0000
28.7000 8779.0000 1.0000
28.7600 8744.0000 1.0000
28.8200 8762.0000 1.0000
28.8800 8727.0000 1.0000
28.9400 8859.0000 1.0000
29.0000 8688.0000 1.0000
29.0600 8758.0000 1.0000
29.1200 8713.0000 1.0000
29.1800 8596.0000 1.0000
29.2400 8652.0000 1.0000
29.3000 8744.0000 1.0000
29.3600 8514.0000 1.0000
29.4200 8701.0000 1.0000
29.4800 8657.0000 1.0000
29.5400 8626.0000 1.0000
29.6000 8663.0000 1.0000
29.6600 8736.0000 1.0000
29.7200 8543.0000 1.0000
29.7800 8720.0000 1.0000
29.8400 8738.0000 1.0000
29.9000 8920.0000 1.0000
29.9600 8984.0000 1.0000
30.0200 9185.0000 1.0000
30.0800 10182.0000 1.0000
30.1400 11102.0000 1.0000
30.2000 10382.0000 1.0000
30.2600 9637.0000 1.0000
30.3200 8964.0000 1.0000
30.3800 8682.0000 1.0000
30.4400 8690.0000 1.0000
30.5000 8725.0000 1.0000
30.5600 8643.0000 1.0000
30.6200 8597.0000 1.0000
30.6800 8672.0000 1.0000
30.7400 8572.0000 1.0000
30.8000 8441.0000 1.0000
30.8600 8721.0000 1.0000
30.9200 8538.0000 1.0000
30.9800 8587.0000 1.0000
31.0400 8384.0000 1.0000
31.1000 8562.0000 1.0000
31.1600 8431.0000 1.0000
31.2200 8368.0000 1.0000
31.2800 8556.0000 1.0000
31.3400 8456.0000 1.0000
31.4000 8493.0000 1.0000
31.4600 8444.0000 1.0000
31.5200 8286.0000 1.0000
31.5800 8680.0000 1.0000
31.6400 8526.0000 1.0000
31.7000 8393.0000 1.0000
31.7600 8412.0000 1.0000
31.8200 8495.0000 1.0000
31.8800 8502.0000 1.0000
31.9400 8257.0000 1.0000
32.0000 8411.0000 1.0000
32.0600 8532.0000 1.0000
32.1200 8519.0000 1.0000
32.1800 8431.0000 1.0000
32.2400 8425.0000 1.0000
32.3000 8448.0000 1.0000
32.3600 8533.0000 1.0000
32.4200 8588.0000 1.0000
32.4800 8425.0000 1.0000
32.5400 8452.0000 1.0000
32.6000 8407.0000 1.0000
32.6600 8410.0000 1.0000
32.7200 8554.0000 1.0000
32.7800 8577.0000 1.0000
32.8400 8658.0000 1.0000
32.9000 8954.0000 1.0000
32.9600 9250.0000 1.0000
33.0200 10216.0000 1.0000
33.0800 12186.0000 1.0000
33.1400 16667.0000 1.0000
33.2000 17529.0000 1.0000
33.2600 14207.0000 1.0000
33.3200 10668.0000 1.0000
33.3800 9078.0000 1.0000
33.4400 8650.0000 1.0000
33.5000 8539.0000 1.0000
33.5600 8590.0000 1.0000
33.6200 8389.0000 1.0000
33.6800 8257.0000 1.0000
33.7400 8390.0000 1.0000
33.8000 8430.0000 1.0000
33.8600 8344.0000 1.0000
33.9200 8312.0000 1.0000
33.9800 8399.0000 1.0000
34.0400 8369.0000 1.0000
34.1000 8278.0000 1.0000
34.1600 8338.0000 1.0000
34.2200 8282.0000 1.0000
34.2800 8434.0000 1.0000
34.3400 8338.0000 1.0000
34.4000 8458.0000 1.0000
34.4600 8429.0000 1.0000
34.5200 8514.0000 1.0000
34.5800 8292.0000 1.0000
34.6400 8525.0000 1.0000
34.7000 8490.0000 1.0000
34.7600 8556.0000 1.0000
34.8200 8557.0000 1.0000
34.8800 8855.0000 1.0000
34.9400 9048.0000 1.0000
35.0000 9715.0000 1.0000
35.0600 10955.0000 1.0000
35.1200 13713.0000 1.0000
35.1800 14542.0000 1.0000
35.2400 13009.0000 1.0000
35.3000 11132.0000 1.0000
35.3600 11062.0000 1.0000
35.4200 13397.0000 1.0000
35.4800 17092.0000 1.0000
35.5400 17329.0000 1.0000
35.6000 18380.0000 1.0000
35.6600 17600.0000 1.0000
35.7200 14089.0000 1.0000
35.7800 11150.0000 1.0000
35.8400 9524.0000 1.0000
35.9000 8910.0000 1.0000
35.9600 8629.0000 1.0000
36.0200 8498.0000 1.0000
36.0800 8244.0000 1.0000
36.1400 8459.0000 1.0000
36.2000 8319.0000 1.0000
36.2600 8396.0000 1.0000
36.3200 8430.0000 1.0000
36.3800 8671.0000 1.0000
36.4400 8755.0000 1.0000
36.5000 9816.0000 1.0000
36.5600 12934.0000 1.0000
36.6200 10387.0000 1.0000
36.6800 9863.0000 1.0000
36.7400 8383.0000 1.0000
36.8000 8170.0000 1.0000
36.8600 8148.0000 1.0000
36.9200 8300.0000 1.0000
36.9800 8390.0000 1.0000
37.0400 8397.0000 1.0000
37.1000 8588.0000 1.0000
37.1600 8624.0000 1.0000
37.2200 8462.0000 1.0000
37.2800 8518.0000 1.0000
37.3400 8356.0000 1.0000
37.4000 8246.0000 1.0000
37.4600 8085.0000 1.0000
37.5200 8387.0000 1.0000
37.5800 8454.0000 1.0000
37.6400 8849.0000 1.0000
37.7000 9382.0000 1.0000
37.7600 10774.0000 1.0000
37.8200 10272.0000 1.0000
37.8800 9846.0000 1.0000
37.9400 8926.0000 1.0000
38.0000 8533.0000 1.0000
38.0600 8423.0000 1.0000
38.1200 8369.0000 1.0000
38.1800 8089.0000 1.0000
38.2400 8208.0000 1.0000
38.3000 8218.0000 1.0000
38.3600 8476.0000 1.0000
38.4200 8160.0000 1.0000
38.4800 8238.0000 1.0000
38.5400 8127.0000 1.0000
38.6000 8077.0000 1.0000
38.6600 8180.0000 1.0000
38.7200 8242.0000 1.0000
38.7800 8222.0000 1.0000
38.8400 8049.0000 1.0000
38.9000 8067.0000 1.0000
38.9600 8311.0000 1.0000
39.0200 8271.0000 1.0000
39.0800 8097.0000 1.0000
39.1400 8146.0000 1.0000
39.2000 8228.0000 1.0000
39.2600 8468.0000 1.0000
39.3200 8592.0000 1.0000
39.3800 8884.0000 1.0000
39.4400 9245.0000 1.0000
39.5000 10733.0000 1.0000
39.5600 9279.0000 1.0000
39.6200 8698.0000 1.0000
39.6800 8200.0000 1.0000
39.7400 8019.0000 1.0000
39.8000 8228.0000 1.0000
39.8600 8281.0000 1.0000
39.9200 8128.0000 1.0000
39.9800 8013.0000 1.0000
40.0400 8295.0000 1.0000
40.1000 8038.0000 1.0000
40.1600 8104.0000 1.0000
40.2200 8470.0000 1.0000
40.2800 8864.0000 1.0000
40.3400 8635.0000 1.0000
40.4000 8568.0000 1.0000
40.4600 8309.0000 1.0000
40.5200 8168.0000 1.0000
40.5800 8120.0000 1.0000
40.6400 8255.0000 1.0000
40.7000 8411.0000 1.0000
40.7600 8651.0000 1.0000
40.8200 9434.0000 1.0000
40.8800 10205.0000 1.0000
40.9400 9740.0000 1.0000
41.0000 8984.0000 1.0000
41.0600 8495.0000 1.0000
41.1200 8110.0000 1.0000
41.1800 8066.0000 1.0000
41.2400 8149.0000 1.0000
41.3000 8044.0000 1.0000
41.3600 8228.0000 1.0000
41.4200 8265.0000 1.0000
41.4800 8086.0000 1.0000
41.5400 8016.0000 1.0000
41.6000 7981.0000 1.0000
41.6600 8202.0000 1.0000
41.7200 8106.0000 1.0000
41.7800 8064.0000 1.0000
41.8400 8190.0000 1.0000
41.9000 8047.0000 1.0000
41.9600 8132.0000 1.0000
42.0200 8064.0000 1.0000
42.0800 8189.0000 1.0000
42.1400 8257.0000 1.0000
42.2000 8108.0000 1.0000
42.2600 8133.0000 1.0000
42.3200 8216.0000 1.0000
42.3800 8654.0000 1.0000
42.4400 10053.0000 1.0000
42.5000 9593.0000 1.0000
42.5600 9378.0000 1.0000
42.6200 8471.0000 1.0000
42.6800 8175.0000 1.0000
42.7400 8068.0000 1.0000
42.8000 8140.0000 1.0000
42.8600 8227.0000 1.0000
42.9200 8364.0000 1.0000
42.9800 8568.0000 1.0000
43.0400 9155.0000 1.0000
43.1000 10196.0000 1.0000
43.1600 10338.0000 1.0000
43.2200 10933.0000 1.0000
43.2800 12292.0000 1.0000
43.3400 15597.0000 1.0000
43.4000 13996.0000 1.0000
43.4600 12739.0000 1.0000
43.5200 10728.0000 1.0000
43.5800 9088.0000 1.0000
43.6400 8729.0000 1.0000
43.7000 8361.0000 1.0000
43.7600 8373.0000 1.0000
43.8200 8135.0000 1.0000
43.8800 8185.0000 1.0000
43.9400 8084.0000 1.0000
44.0000 7980.0000 1.0000
44.0600 8041.0000 1.0000
44.1200 8001.0000 1.0000
44.1800 8095.0000 1.0000
44.2400 7870.0000 1.0000
44.3000 7912.0000 1.0000
44.3600 8084.0000 1.0000
44.4200 8017.0000 1.0000
44.4800 7922.0000 1.0000
44.5400 7934.0000 1.0000
44.6000 7907.0000 1.0000
44.6600 8004.0000 1.0000
44.7200 8111.0000 1.0000
44.7800 8242.0000 1.0000
44.8400 7967.0000 1.0000
44.9000 7868.0000 1.0000
44.9600 8014.0000 1.0000
45.0200 7986.0000 1.0000
45.0800 7861.0000 1.0000
45.1400 8020.0000 1.0000
45.2000 7936.0000 1.0000
45.2600 7916.0000 1.0000
45.3200 7885.0000 1.0000
45.3800 7863.0000 1.0000
45.4400 8050.0000 1.0000
45.5000 7855.0000 1.0000
45.5600 7943.0000 1.0000
45.6200 8099.0000 1.0000
45.6800 8041.0000 1.0000
45.7400 8135.0000 1.0000
45.8000 8969.0000 1.0000
45.8600 8191.0000 1.0000
45.9200 8509.0000 1.0000
45.9800 8033.0000 1.0000
46.0400 8048.0000 1.0000
46.1000 8087.0000 1.0000
46.1600 7911.0000 1.0000
46.2200 7837.0000 1.0000
46.2800 7940.0000 1.0000
46.3400 7800.0000 1.0000
46.4000 7859.0000 1.0000
46.4600 7952.0000 1.0000
46.5200 7801.0000 1.0000
46.5800 7958.0000 1.0000
46.6400 8014.0000 1.0000
46.7000 7957.0000 1.0000
46.7600 7924.0000 1.0000
46.8200 7865.0000 1.0000
46.8800 7879.0000 1.0000
46.9400 7858.0000 1.0000
47.0000 7967.0000 1.0000
47.0600 8002.0000 1.0000
47.1200 7891.0000 1.0000
47.1800 7925.0000 1.0000
47.2400 7987.0000 1.0000
47.3000 7907.0000 1.0000
47.3600 7835.0000 1.0000
47.4200 7906.0000 1.0000
47.4800 7976.0000 1.0000
47.5400 7796.0000 1.0000
47.6000 7994.0000 1.0000
47.6600 7817.0000 1.0000
47.7200 8035.0000 1.0000
47.7800 7953.0000 1.0000
47.8400 7808.0000 1.0000
47.9000 7821.0000 1.0000
47.9600 7869.0000 1.0000
48.0200 7881.0000 1.0000
48.0800 7974.0000 1.0000
48.1400 7926.0000 1.0000
48.2000 7788.0000 1.0000
48.2600 8049.0000 1.0000
48.3200 7994.0000 1.0000
48.3800 8027.0000 1.0000
48.4400 7983.0000 1.0000
48.5000 7840.0000 1.0000
48.5600 7855.0000 1.0000
48.6200 7942.0000 1.0000
48.6800 7792.0000 1.0000
48.7400 7867.0000 1.0000
48.8000 8002.0000 1.0000
48.8600 7923.0000 1.0000
48.9200 7874.0000 1.0000
48.9800 8033.0000 1.0000
49.0400 7895.0000 1.0000
49.1000 7981.0000 1.0000
49.1600 7699.0000 1.0000
49.2200 8334.0000 1.0000
49.2800 8257.0000 1.0000
49.3400 8858.0000 1.0000
49.4000 9706.0000 1.0000
49.4600 11421.0000 1.0000
49.5200 10340.0000 1.0000
49.5800 9895.0000 1.0000
49.6400 9277.0000 1.0000
49.7000 8455.0000 1.0000
49.7600 8163.0000 1.0000
49.8200 8019.0000 1.0000
49.8800 8174.0000 1.0000
49.9400 8211.0000 1.0000
50.0000 8475.0000 1.0000
50.0600 8986.0000 1.0000
50.1200 12999.0000 1.0000
50.1800 11239.0000 1.0000
50.2400 10020.0000 1.0000
50.3000 10300.0000 1.0000
50.3600 8219.0000 1.0000
50.4200 7979.0000 1.0000
50.4800 7905.0000 1.0000
50.5400 8163.0000 1.0000
50.6000 7893.0000 1.0000
50.6600 7900.0000 1.0000
50.7200 7960.0000 1.0000
50.7800 7886.0000 1.0000
50.8400 7979.0000 1.0000
50.9000 7866.0000 1.0000
50.9600 7919.0000 1.0000
51.0200 7913.0000 1.0000
51.0800 8030.0000 1.0000
51.1400 7937.0000 1.0000
51.2000 7746.0000 1.0000
51.2600 7973.0000 1.0000
51.3200 7802.0000 1.0000
51.3800 7913.0000 1.0000
51.4400 7863.0000 1.0000
51.5000 7915.0000 1.0000
51.5600 7907.0000 1.0000
51.6200 7964.0000 1.0000
51.6800 7898.0000 1.0000
51.7400 7986.0000 1.0000
51.8000 8164.0000 1.0000
51.8600 7782.0000 1.0000
51.9200 7708.0000 1.0000
51.9800 7883.0000 1.0000
52.0400 7820.0000 1.0000
52.1000 7886.0000 1.0000
52.1600 8078.0000 1.0000
52.2200 7806.0000 1.0000
52.2800 8093.0000 1.0000
52.3400 8497.0000 1.0000
52.4000 8510.0000 1.0000
52.4600 9332.0000 1.0000
52.5200 10484.0000 1.0000
52.5800 10580.0000 1.0000
52.6400 9483.0000 1.0000
52.7000 9641.0000 1.0000
52.7600 8597.0000 1.0000
52.8200 8226.0000 1.0000
52.8800 8271.0000 1.0000
52.9400 8018.0000 1.0000
53.0000 8020.0000 1.0000
53.0600 7974.0000 1.0000
53.1200 8019.0000 1.0000
53.1800 7992.0000 1.0000
53.2400 8065.0000 1.0000
53.3000 8171.0000 1.0000
53.3600 7999.0000 1.0000
53.4200 8288.0000 1.0000
53.4800 8666.0000 1.0000
53.5400 8490.0000 1.0000
53.6000 8560.0000 1.0000
53.6600 8244.0000 1.0000
53.7200 8271.0000 1.0000
53.7800 8214.0000 1.0000
53.8400 8282.0000 1.0000
53.9000 8592.0000 1.0000
53.9600 8997.0000 1.0000
54.0200 10399.0000 1.0000
54.0800 11928.0000 1.0000
54.1400 10369.0000 1.0000
54.2000 10140.0000 1.0000
54.2600 9581.0000 1.0000
54.3200 8506.0000 1.0000
54.3800 8051.0000 1.0000
54.4400 8050.0000 1.0000
54.5000 8085.0000 1.0000
54.5600 7906.0000 1.0000
54.6200 7950.0000 1.0000
54.6800 8009.0000 1.0000
54.7400 8116.0000 1.0000
54.8000 8315.0000 1.0000
54.8600 9140.0000 1.0000
54.9200 8855.0000 1.0000
54.9800 8452.0000 1.0000
55.0400 8823.0000 1.0000
55.1000 8211.0000 1.0000
55.1600 7956.0000 1.0000
55.2200 8137.0000 1.0000
55.2800 8077.0000 1.0000
55.3400 8503.0000 1.0000
55.4000 8029.0000 1.0000
55.4600 8154.0000 1.0000
55.5200 7916.0000 1.0000
55.5800 7885.0000 1.0000
55.6400 7767.0000 1.0000
55.7000 8080.0000 1.0000
55.7600 7939.0000 1.0000
55.8200 8075.0000 1.0000
55.8800 7914.0000 1.0000
55.9400 7852.0000 1.0000
56.0000 7790.0000 1.0000
56.0600 8010.0000 1.0000
56.1200 8017.0000 1.0000
56.1800 7971.0000 1.0000
56.2400 8045.0000 1.0000
56.3000 7849.0000 1.0000
56.3600 7941.0000 1.0000
56.4200 7983.0000 1.0000
56.4800 7961.0000 1.0000
56.5400 7857.0000 1.0000
56.6000 8021.0000 1.0000
56.6600 7902.0000 1.0000
56.7200 8159.0000 1.0000
56.7800 8099.0000 1.0000
56.8400 8268.0000 1.0000
56.9000 8449.0000 1.0000
56.9600 9071.0000 1.0000
57.0200 9921.0000 1.0000
57.0800 9678.0000 1.0000
57.1400 9930.0000 1.0000
57.2000 9691.0000 1.0000
57.2600 9505.0000 1.0000
57.3200 9577.0000 1.0000
57.3800 10347.0000 1.0000
57.4400 12313.0000 1.0000
57.5000 14608.0000 1.0000
57.5600 12403.0000 1.0000
57.6200 12255.0000 1.0000
57.6800 11367.0000 1.0000
57.7400 9759.0000 1.0000
57.8000 8929.0000 1.0000
57.8600 8445.0000 1.0000
57.9200 8195.0000 1.0000
57.9800 8188.0000 1.0000
58.0400 8070.0000 1.0000
58.1000 8017.0000 1.0000
58.1600 8123.0000 1.0000
58.2200 8153.0000 1.0000
58.2800 8136.0000 1.0000
58.3400 8050.0000 1.0000
58.4000 7805.0000 1.0000
58.4600 8009.0000 1.0000
58.5200 7967.0000 1.0000
58.5800 8018.0000 1.0000
58.6400 7832.0000 1.0000
58.7000 8020.0000 1.0000
58.7600 7816.0000 1.0000
58.8200 7921.0000 1.0000
58.8800 7882.0000 1.0000
58.9400 7910.0000 1.0000
59.0000 7958.0000 1.0000
59.0600 8162.0000 1.0000
59.1200 8020.0000 1.0000
59.1800 8092.0000 1.0000
59.2400 7853.0000 1.0000
59.3000 8008.0000 1.0000
59.3600 7813.0000 1.0000
59.4200 7965.0000 1.0000
59.4800 7857.0000 1.0000
59.5400 8016.0000 1.0000
59.6000 8187.0000 1.0000
59.6600 8174.0000 1.0000
59.7200 8184.0000 1.0000
59.7800 8228.0000 1.0000
59.8400 8330.0000 1.0000
59.9000 8937.0000 1.0000
59.9600 11413.0000 1.0000
60.0200 9104.0000 1.0000
60.0800 8872.0000 1.0000
60.1400 9804.0000 1.0000
60.2000 8219.0000 1.0000
60.2600 8067.0000 1.0000
60.3200 8074.0000 1.0000
60.3800 8078.0000 1.0000
60.4400 7990.0000 1.0000
60.5000 7948.0000 1.0000
60.5600 8021.0000 1.0000
60.6200 7884.0000 1.0000
60.6800 7867.0000 1.0000
60.7400 7931.0000 1.0000
60.8000 7981.0000 1.0000
60.8600 8044.0000 1.0000
60.9200 8004.0000 1.0000
60.9800 7937.0000 1.0000
61.0400 8020.0000 1.0000
61.1000 8164.0000 1.0000
61.1600 8132.0000 1.0000
61.2200 8275.0000 1.0000
61.2800 8387.0000 1.0000
61.3400 8394.0000 1.0000
61.4000 8218.0000 1.0000
61.4600 8113.0000 1.0000
61.5200 8039.0000 1.0000
61.5800 8013.0000 1.0000
61.6400 8102.0000 1.0000
61.7000 8049.0000 1.0000
61.7600 8020.0000 1.0000
61.8200 8019.0000 1.0000
61.8800 8045.0000 1.0000
61.9400 8090.0000 1.0000
62.0000 8067.0000 1.0000
62.0600 8198.0000 1.0000
62.1200 8044.0000 1.0000
62.1800 8241.0000 1.0000
62.2400 8330.0000 1.0000
62.3000 8529.0000 1.0000
62.3600 9272.0000 1.0000
62.4200 10735.0000 1.0000
62.4800 10469.0000 1.0000
62.5400 10236.0000 1.0000
62.6000 11744.0000 1.0000
62.6600 11242.0000 1.0000
62.7200 10111.0000 1.0000
62.7800 9925.0000 1.0000
62.8400 9637.0000 1.0000
62.9000 8715.0000 1.0000
62.9600 8508.0000 1.0000
63.0200 8206.0000 1.0000
63.0800 8196.0000 1.0000
63.1400 8164.0000 1.0000
63.2000 8004.0000 1.0000
63.2600 8003.0000 1.0000
63.3200 7954.0000 1.0000
63.3800 7947.0000 1.0000
63.4400 7940.0000 1.0000
63.5000 8047.0000 1.0000
63.5600 8068.0000 1.0000
63.6200 7979.0000 1.0000
63.6800 8075.0000 1.0000
63.7400 8190.0000 1.0000
63.8000 8327.0000 1.0000
63.8600 8593.0000 1.0000
63.9200 9008.0000 1.0000
63.9800 10334.0000 1.0000
64.0400 10912.0000 1.0000
64.1000 9205.0000 1.0000
64.1600 9420.0000 1.0000
64.2200 9433.0000 1.0000
64.2800 8560.0000 1.0000
64.3400 8231.0000 1.0000
64.4000 8127.0000 1.0000
64.4600 8045.0000 1.0000
64.5200 8162.0000 1.0000
64.5800 8024.0000 1.0000
64.6400 7930.0000 1.0000
64.7000 8048.0000 1.0000
64.7600 7901.0000 1.0000
64.8200 8065.0000 1.0000
64.8800 7920.0000 1.0000
64.9400 7924.0000 1.0000
65.0000 8002.0000 1.0000
65.0600 8022.0000 1.0000
65.1200 7904.0000 1.0000
65.1800 8151.0000 1.0000
65.2400 7947.0000 1.0000
65.3000 7893.0000 1.0000
65.3600 7884.0000 1.0000
65.4200 7861.0000 1.0000
65.4800 7885.0000 1.0000
65.5400 7748.0000 1.0000
65.6000 8042.0000 1.0000
65.6600 8169.0000 1.0000
65.7200 8062.0000 1.0000
65.7800 8358.0000 1.0000
65.8400 8188.0000 1.0000
65.9000 8093.0000 1.0000
65.9600 8095.0000 1.0000
66.0200 8208.0000 1.0000
66.0800 8021.0000 1.0000
66.1400 7970.0000 1.0000
66.2000 8251.0000 1.0000
66.2600 8315.0000 1.0000
66.3200 8394.0000 1.0000
66.3800 8546.0000 1.0000
66.4400 9289.0000 1.0000
66.5000 10202.0000 1.0000
66.5600 9637.0000 1.0000
66.6200 9190.0000 1.0000
66.6800 9266.0000 1.0000
66.7400 8799.0000 1.0000
66.8000 8289.0000 1.0000
66.8600 8334.0000 1.0000
66.9200 8163.0000 1.0000
66.9800 8230.0000 1.0000
67.0400 8098.0000 1.0000
67.1000 7989.0000 1.0000
67.1600 8294.0000 1.0000
67.2200 8071.0000 1.0000
67.2800 8032.0000 1.0000
67.3400 8083.0000 1.0000
67.4000 8169.0000 1.0000
67.4600 7994.0000 1.0000
67.5200 8016.0000 1.0000
67.5800 8246.0000 1.0000
67.6400 8505.0000 1.0000
67.7000 9179.0000 1.0000
67.7600 10274.0000 1.0000
67.8200 8779.0000 1.0000
67.8800 8758.0000 1.0000
67.9400 9521.0000 1.0000
68.0000 8940.0000 1.0000
68.0600 9677.0000 1.0000
68.1200 11815.0000 1.0000
68.1800 12750.0000 1.0000
68.2400 11574.0000 1.0000
68.3000 13680.0000 1.0000
68.3600 12331.0000 1.0000
68.4200 10328.0000 1.0000
68.4800 10116.0000 1.0000
68.5400 9753.0000 1.0000
68.6000 8692.0000 1.0000
68.6600 8100.0000 1.0000
68.7200 8152.0000 1.0000
68.7800 8071.0000 1.0000
68.8400 7953.0000 1.0000
68.9000 7893.0000 1.0000
68.9600 8027.0000 1.0000
69.0200 8006.0000 1.0000
69.0800 7928.0000 1.0000
69.1400 7985.0000 1.0000
69.2000 8054.0000 1.0000
69.2600 7994.0000 1.0000
69.3200 8200.0000 1.0000
69.3800 8130.0000 1.0000
69.4400 8159.0000 1.0000
69.5000 8063.0000 1.0000
69.5600 8326.0000 1.0000
69.6200 8287.0000 1.0000
69.6800 8204.0000 1.0000
69.7400 8128.0000 1.0000
69.8000 8176.0000 1.0000
69.8600 8139.0000 1.0000
69.9200 8113.0000 1.0000
69.9800 8088.0000 1.0000
70.0400 7970.0000 1.0000
70.1000 8011.0000 1.0000
70.1600 7986.0000 1.0000
70.2200 7946.0000 1.0000
70.2800 7930.0000 1.0000
70.3400 8090.0000 1.0000
70.4000 7956.0000 1.0000
70.4600 8004.0000 1.0000
70.5200 7957.0000 1.0000
70.5800 8002.0000 1.0000
70.6400 8154.0000 1.0000
70.7000 8045.0000 1.0000
70.7600 8010.0000 1.0000
70.8200 7879.0000 1.0000
70.8800 8120.0000 1.0000
70.9400 8108.0000 1.0000
71.0000 8063.0000 1.0000
71.0600 8100.0000 1.0000
71.1200 8130.0000 1.0000
71.1800 8165.0000 1.0000
71.2400 8238.0000 1.0000
71.3000 8314.0000 1.0000
71.3600 8085.0000 1.0000
71.4200 8230.0000 1.0000
71.4800 7949.0000 1.0000
71.5400 8127.0000 1.0000
71.6000 7847.0000 1.0000
71.6600 7977.0000 1.0000
71.7200 8176.0000 1.0000
71.7800 8374.0000 1.0000
71.8400 8218.0000 1.0000
71.9000 8591.0000 1.0000
71.9600 8905.0000 1.0000
72.0200 8587.0000 1.0000
72.0800 8487.0000 1.0000
72.1400 8543.0000 1.0000
72.2000 8439.0000 1.0000
72.2600 8280.0000 1.0000
72.3200 8281.0000 1.0000
72.3800 8062.0000 1.0000
72.4400 7863.0000 1.0000
72.5000 8204.0000 1.0000
72.5600 8125.0000 1.0000
72.6200 7909.0000 1.0000
72.6800 8036.0000 1.0000
72.7400 8101.0000 1.0000
72.8000 8063.0000 1.0000
72.8600 7899.0000 1.0000
72.9200 8074.0000 1.0000
72.9800 8117.0000 1.0000
73.0400 8103.0000 1.0000
73.1000 8006.0000 1.0000
73.1600 8189.0000 1.0000
73.2200 8264.0000 1.0000
73.2800 8157.0000 1.0000
73.3400 8088.0000 1.0000
73.4000 8273.0000 1.0000
73.4600 9265.0000 1.0000
73.5200 8394.0000 1.0000
73.5800 8164.0000 1.0000
73.6400 8247.0000 1.0000
73.7000 8539.0000 1.0000
73.7600 7975.0000 1.0000
73.8200 8105.0000 1.0000
73.8800 8086.0000 1.0000
73.9400 8208.0000 1.0000
74.0000 8185.0000 1.0000
74.0600 8388.0000 1.0000
74.1200 8540.0000 1.0000
74.1800 8507.0000 1.0000
74.2400 8180.0000 1.0000
74.3000 8388.0000 1.0000
74.3600 8375.0000 1.0000
74.4200 8210.0000 1.0000
74.4800 8244.0000 1.0000
74.5400 8220.0000 1.0000
74.6000 8046.0000 1.0000
74.6600 8093.0000 1.0000
74.7200 8235.0000 1.0000
74.7800 7945.0000 1.0000
74.8400 8096.0000 1.0000
74.9000 8040.0000 1.0000
74.9600 8089.0000 1.0000
75.0200 8193.0000 1.0000
75.0800 8280.0000 1.0000
75.1400 8242.0000 1.0000
75.2000 8182.0000 1.0000
75.2600 8327.0000 1.0000
75.3200 8319.0000 1.0000
75.3800 8453.0000 1.0000
75.4400 8773.0000 1.0000
75.5000 8558.0000 1.0000
75.5600 8520.0000 1.0000
75.6200 8650.0000 1.0000
75.6800 9233.0000 1.0000
75.7400 8317.0000 1.0000
75.8000 8357.0000 1.0000
75.8600 8487.0000 1.0000
75.9200 8303.0000 1.0000
75.9800 8130.0000 1.0000
76.0400 7969.0000 1.0000
76.1000 8078.0000 1.0000
76.1600 8139.0000 1.0000
76.2200 8169.0000 1.0000
76.2800 8121.0000 1.0000
76.3400 8074.0000 1.0000
76.4000 8118.0000 1.0000
76.4600 7931.0000 1.0000
76.5200 8095.0000 1.0000
76.5800 8300.0000 1.0000
76.6400 8168.0000 1.0000
76.7000 8259.0000 1.0000
76.7600 8434.0000 1.0000
76.8200 8819.0000 1.0000
76.8800 9043.0000 1.0000
76.9400 8661.0000 1.0000
77.0000 8551.0000 1.0000
77.0600 8669.0000 1.0000
77.1200 8775.0000 1.0000
77.1800 8574.0000 1.0000
77.2400 8638.0000 1.0000
77.3000 8231.0000 1.0000
77.3600 8291.0000 1.0000
77.4200 8346.0000 1.0000
77.4800 8376.0000 1.0000
77.5400 8274.0000 1.0000
77.6000 8452.0000 1.0000
77.6600 8976.0000 1.0000
77.7200 8656.0000 1.0000
77.7800 8376.0000 1.0000
77.8400 8363.0000 1.0000
77.9000 8805.0000 1.0000
77.9600 8378.0000 1.0000
78.0200 8080.0000 1.0000
78.0800 8227.0000 1.0000
78.1400 8058.0000 1.0000
78.2000 8084.0000 1.0000
78.2600 8109.0000 1.0000
78.3200 8114.0000 1.0000
78.3800 8029.0000 1.0000
78.4400 8055.0000 1.0000
78.5000 8168.0000 1.0000
78.5600 8204.0000 1.0000
78.6200 8152.0000 1.0000
78.6800 8194.0000 1.0000
78.7400 8059.0000 1.0000
78.8000 8096.0000 1.0000
78.8600 8232.0000 1.0000
78.9200 8303.0000 1.0000
78.9800 8160.0000 1.0000
79.0400 8316.0000 1.0000
79.1000 8236.0000 1.0000
79.1600 8226.0000 1.0000
79.2200 8188.0000 1.0000
79.2800 8020.0000 1.0000
79.3400 8196.0000 1.0000
79.4000 8291.0000 1.0000
79.4600 8281.0000 1.0000
79.5200 8091.0000 1.0000
79.5800 8149.0000 1.0000
79.6400 8168.0000 1.0000
79.7000 8233.0000 1.0000
79.7600 8259.0000 1.0000
79.8200 8442.0000 1.0000
79.8800 9186.0000 1.0000
79.9400 8618.0000 1.0000
80.0000 8540.0000 1.0000
80.0600 8734.0000 1.0000
80.1200 8576.0000 1.0000
80.1800 8395.0000 1.0000
80.2400 8284.0000 1.0000
80.3000 8358.0000 1.0000
80.3600 8385.0000 1.0000
80.4200 8199.0000 1.0000
80.4800 8216.0000 1.0000
80.5400 8431.0000 1.0000
80.6000 8545.0000 1.0000
80.6600 8698.0000 1.0000
80.7200 8650.0000 1.0000
80.7800 8644.0000 1.0000
80.8400 8463.0000 1.0000
80.9000 8496.0000 1.0000
80.9600 8480.0000 1.0000
81.0200 8401.0000 1.0000
81.0800 8428.0000 1.0000
81.1400 8935.0000 1.0000
81.2000 8640.0000 1.0000
81.2600 8372.0000 1.0000
81.3200 8329.0000 1.0000
81.3800 8606.0000 1.0000
81.4400 8876.0000 1.0000
81.5000 9080.0000 1.0000
81.5600 8352.0000 1.0000
81.6200 8485.0000 1.0000
81.6800 8432.0000 1.0000
81.7400 8550.0000 1.0000
81.8000 8229.0000 1.0000
81.8600 8098.0000 1.0000
81.9200 8099.0000 1.0000
81.9800 8351.0000 1.0000
82.0400 8179.0000 1.0000
82.1000 8189.0000 1.0000
82.1600 8000.0000 1.0000
82.2200 8191.0000 1.0000
82.2800 8078.0000 1.0000
82.3400 8231.0000 1.0000
82.4000 8096.0000 1.0000
82.4600 8221.0000 1.0000
82.5200 8103.0000 1.0000
82.5800 8093.0000 1.0000
82.6400 8034.0000 1.0000
82.7000 8266.0000 1.0000
82.7600 8288.0000 1.0000
82.8200 8319.0000 1.0000
82.8800 8475.0000 1.0000
82.9400 8494.0000 1.0000
83.0000 8524.0000 1.0000
83.0600 8379.0000 1.0000
83.1200 8298.0000 1.0000
83.1800 8600.0000 1.0000
83.2400 8401.0000 1.0000
83.3000 8384.0000 1.0000
83.3600 8150.0000 1.0000
83.4200 8198.0000 1.0000
83.4800 8211.0000 1.0000
83.5400 8156.0000 1.0000
83.6000 8098.0000 1.0000
83.6600 8238.0000 1.0000
83.7200 8309.0000 1.0000
83.7800 8459.0000 1.0000
83.8400 9019.0000 1.0000
83.9000 8403.0000 1.0000
83.9600 8254.0000 1.0000
84.0200 8369.0000 1.0000
84.0800 8622.0000 1.0000
84.1400 8475.0000 1.0000
84.2000 8277.0000 1.0000
84.2600 8312.0000 1.0000
84.3200 8413.0000 1.0000
84.3800 8519.0000 1.0000
84.4400 8266.0000 1.0000
84.5000 8291.0000 1.0000
84.5600 8222.0000 1.0000
84.6200 8360.0000 1.0000
84.6800 8395.0000 1.0000
84.7400 8221.0000 1.0000
84.8000 8431.0000 1.0000
84.8600 8629.0000 1.0000
84.9200 8828.0000 1.0000
84.9800 8654.0000 1.0000
85.0400 8416.0000 1.0000
85.1000 8395.0000 1.0000
85.1600 8524.0000 1.0000
85.2200 8666.0000 1.0000
85.2800 8211.0000 1.0000
85.3400 8267.0000 1.0000
85.4000 8110.0000 1.0000
85.4600 8152.0000 1.0000
85.5200 8239.0000 1.0000
85.5800 8231.0000 1.0000
85.6400 8281.0000 1.0000
85.7000 8325.0000 1.0000
85.7600 8107.0000 1.0000
85.8200 8185.0000 1.0000
85.8800 8093.0000 1.0000
85.9400 8107.0000 1.0000
86.0000 8145.0000 1.0000
86.0600 8267.0000 1.0000
86.1200 8139.0000 1.0000
86.1800 8507.0000 1.0000
86.2400 8233.0000 1.0000
86.3000 8314.0000 1.0000
86.3600 8497.0000 1.0000
86.4200 8329.0000 1.0000
86.4800 8519.0000 1.0000
86.5400 8406.0000 1.0000
86.6000 8387.0000 1.0000
86.6600 8380.0000 1.0000
86.7200 8384.0000 1.0000
86.7800 8362.0000 1.0000
86.8400 8434.0000 1.0000
86.9000 8316.0000 1.0000
86.9600 8258.0000 1.0000
87.0200 8384.0000 1.0000
87.0800 8471.0000 1.0000
87.1400 8326.0000 1.0000
87.2000 8177.0000 1.0000
87.2600 8403.0000 1.0000
87.3200 8256.0000 1.0000
87.3800 8279.0000 1.0000
87.4400 8344.0000 1.0000
87.5000 8285.0000 1.0000
87.5600 8432.0000 1.0000
87.6200 8200.0000 1.0000
87.6800 8306.0000 1.0000
87.7400 8243.0000 1.0000
87.8000 8183.0000 1.0000
87.8600 8331.0000 1.0000
87.9200 8375.0000 1.0000
87.9800 8247.0000 1.0000
88.0400 8364.0000 1.0000
88.1000 8313.0000 1.0000
88.1600 8214.0000 1.0000
88.2200 8247.0000 1.0000
88.2800 8170.0000 1.0000
88.3400 8203.0000 1.0000
88.4000 8295.0000 1.0000
88.4600 8440.0000 1.0000
88.5200 8534.0000 1.0000
88.5800 8850.0000 1.0000
88.6400 8596.0000 1.0000
88.7000 8574.0000 1.0000
88.7600 8522.0000 1.0000
88.8200 8633.0000 1.0000
88.8800 8682.0000 1.0000
88.9400 8539.0000 1.0000
89.0000 8577.0000 1.0000
89.0600 8525.0000 1.0000
89.1200 8561.0000 1.0000
89.1800 8373.0000 1.0000
89.2400 8461.0000 1.0000
89.3000 8492.0000 1.0000
89.3600 8412.0000 1.0000
89.4200 8171.0000 1.0000
89.4800 8429.0000 1.0000
89.5400 8285.0000 1.0000
89.6000 8468.0000 1.0000
89.6600 8578.0000 1.0000
89.7200 8709.0000 1.0000
89.7800 8914.0000 1.0000
89.8400 8694.0000 1.0000
89.9000 8570.0000 1.0000
89.9600 8572.0000 1.0000
90.0000 8547.0000 1.0000
*RAS_INT_END
*RAS_TEMPERATURE_START
*RAS_TEMPERATURE_END
*RAS_DATA_END