File: XRD/Data/20200826_mix_05.ras
*RAS_DATA_START
*RAS_HEADER_START
*DISP_FMT_X "%.2f"
*DISP_FMT_Y "%.0f"
*DISP_FULLSCALE "130792.0000000000"
*DISP_LINE_COLOR "255.0000000000"
*DISP_LINE_STYLE "0.0000000000"
*DISP_LINE_WIDTH "0.2500000000"
*DISP_NOTE "測定データ-4"
*DISP_OFFSET_Y "0.0000000000"
*DISP_PEAKSEARCH_UNIT_Y "cps"
*DISP_RANGE_BOTTOM "0.0000000000"
*DISP_RANGE_LEFT "20.0000000000"
*DISP_RANGE_LOGCUTOFF "0.0100000000"
*DISP_RANGE_RIGHT "90.0000000000"
*DISP_RANGE_TOP "130792.0000000000"
*DISP_SCALE_MODE_Y "0.0000000000"
*DISP_TAB_NAME "2θ/θ"
*DISP_TITLE_Y "強度"
*DISP_UNIT_Y "cps"
*DISP_WINDOW_NAME "MSG_MACROENGINE"
*FILE_COMMENT " "
*FILE_MD5 ""
*FILE_MEMO " "
*FILE_OPERATOR "Administrator"
*FILE_SAMPLE " "
*FILE_TYPE "RAS_RAW"
*FILE_USERGROUP "システムマネージャ"
*FILE_VERSION "1.0000000000"
*HW_ATTACHMENT_ID "ATT0025"
*HW_ATTACHMENT_NAME "標準|Standard"
*HW_COUNTER_ID-0 "CUT0025"
*HW_COUNTER_ID-1 "CUT0020"
*HW_COUNTER_ID-2 "CUT0020"
*HW_COUNTER_ID-3 "CSL0021"
*HW_COUNTER_ID-4 "CMC0021"
*HW_COUNTER_NAME-0 "D/teX Ultra|D/teX Ultra"
*HW_COUNTER_NAME-1 "None|None"
*HW_COUNTER_NAME-2 "None|None"
*HW_COUNTER_NAME-3 "BBM|BBM"
*HW_COUNTER_NAME-4 "検出器モノクロメータ|Detector monochromator"
*HW_COUNTER_SELECT_NAME "D/teX Ultra|D/teX Ultra"
*HW_GONIOMETER_ID "GON0023"
*HW_GONIOMETER_NAME "SmartLab|SmartLab"
*HW_GONIOMETER_RADIUS-0 "90.0"
*HW_GONIOMETER_RADIUS-1 "114.0"
*HW_GONIOMETER_RADIUS-2 "190.0"
*HW_GONIOMETER_RADIUS-3 "300.0"
*HW_GONIOMETER_RADIUS-4 "187.0"
*HW_GONIOMETER_RADIUS-5 "300.0"
*HW_GONIOMETER_RADIUS-6 "113.0"
*HW_GONIOMETER_RADIUS-7 "331.0"
*HW_I_OPT_ID-0 "CBO0021"
*HW_I_OPT_ID-1 "ICR0023"
*HW_I_OPT_ID-2 "ISL0021"
*HW_I_OPT_ID-3 "ISO0021"
*HW_I_OPT_ID-4 "IAD0021"
*HW_I_OPT_ID-5 "IPR0001"
*HW_I_OPT_NAME-0 "CBOユニット|CBO unit"
*HW_I_OPT_NAME-1 "標準入射光学ユニット|Standard incident optical unit"
*HW_I_OPT_NAME-2 "標準入射スリットボックス|Standard incident slit box"
*HW_I_OPT_NAME-3 "入射平行スリット|Incident parallel slit"
*HW_I_OPT_NAME-4 "長手制限スリット|Length limiting slit"
*HW_I_OPT_NAME-5 "None|None"
*HW_R_ATTENUATER_AUTOMODE "0"
*HW_R_OPT_ID-0 "RSS0021"
*HW_R_OPT_ID-1 "RCR0023"
*HW_R_OPT_ID-2 "RSO0021"
*HW_R_OPT_ID-3 "RRS0021"
*HW_R_OPT_ID-4 "ATN0021"
*HW_R_OPT_ID-5 "RFL0021"
*HW_R_OPT_ID-6 "RAD0021"
*HW_R_OPT_NAME-0 "標準受光スリットボックス1|Standard receiving slit box # 1"
*HW_R_OPT_NAME-1 "標準受光光学ユニット1|Standard receiving unit # 1"
*HW_R_OPT_NAME-2 "標準受光光学ユニット2|Standard receiving optical unit # 2"
*HW_R_OPT_NAME-3 "標準受光スリットボックス2|Standard receiving slit box # 2"
*HW_R_OPT_NAME-4 "標準アッテネータ|Standard Attenuator"
*HW_R_OPT_NAME-5 "Cu Kβ|Cu K-beta"
*HW_R_OPT_NAME-6 "調整用受光スリット|Alignment receiving slit"
*HW_SAMPLE_HOLDER_ID "SMP0023"
*HW_SAMPLE_HOLDER_NAME "標準Zステージ|Standard Z stage"
*HW_XG_CURRENT_MAX "50"
*HW_XG_CURRENT_MIN "2"
*HW_XG_CURRENT_RESOLUTION "2"
*HW_XG_CURRENT_UNIT "mA"
*HW_XG_FOCUS "1mm x 10mm"
*HW_XG_FOCUS_TYPE "Normal"
*HW_XG_ID ""
*HW_XG_NAME "3kW 封入管(ID:1200)|3kW Sealed tube(ID:1200)"
*HW_XG_TARGET_ATOMIC_NUMBER "29.0000000000"
*HW_XG_TARGET_NAME "Cu"
*HW_XG_TYPE "Hermetic"
*HW_XG_VOLTAGE_MAX "60"
*HW_XG_VOLTAGE_MIN "20"
*HW_XG_VOLTAGE_RESOLUTION "2"
*HW_XG_VOLTAGE_UNIT "kV"
*HW_XG_WATT_MAX "2"
*HW_XG_WATT_UNIT "kW"
*HW_XG_WAVE_LENGTH_ALPHA1 "1.540593"
*HW_XG_WAVE_LENGTH_ALPHA2 "1.544414"
*HW_XG_WAVE_LENGTH_BETA "1.392250"
*MEAS_COND_AXIS_NAME-0 "2θ/θ"
*MEAS_COND_AXIS_NAME-1 "2θ"
*MEAS_COND_AXIS_NAME-2 "ω"
*MEAS_COND_AXIS_NAME-3 "Z"
*MEAS_COND_AXIS_NAME-4 "2θ/ω"
*MEAS_COND_AXIS_NAME-5 "θs"
*MEAS_COND_AXIS_NAME-6 "θd"
*MEAS_COND_AXIS_NAME-7 "Ts"
*MEAS_COND_AXIS_NAME-8 "CBO選択スリット"
*MEAS_COND_AXIS_NAME-9 "M"
*MEAS_COND_AXIS_NAME-10 "入射平行スリット"
*MEAS_COND_AXIS_NAME-11 "入射スリット"
*MEAS_COND_AXIS_NAME-12 ""
*MEAS_COND_AXIS_NAME-13 "Zs"
*MEAS_COND_AXIS_NAME-14 "入射光学素子"
*MEAS_COND_AXIS_NAME-15 "長手制限スリット"
*MEAS_COND_AXIS_NAME-16 "センタースリット"
*MEAS_COND_AXIS_NAME-17 "フィルター"
*MEAS_COND_AXIS_NAME-18 "受光スリット1"
*MEAS_COND_AXIS_NAME-19 "受光スリット2"
*MEAS_COND_AXIS_NAME-20 "受光光学素子"
*MEAS_COND_AXIS_NAME-21 "受光平行スリット"
*MEAS_COND_AXIS_NAME-22 "調整用受光スリット"
*MEAS_COND_AXIS_NAME-23 ""
*MEAS_COND_AXIS_NAME-24 ""
*MEAS_COND_AXIS_NAME-25 "Zd"
*MEAS_COND_AXIS_NAME-26 "アッテネータ"
*MEAS_COND_AXIS_NAME-27 "検出器モノクロメータ"
*MEAS_COND_AXIS_NAME-28 "モノクロメータスリット"
*MEAS_COND_AXIS_NAME-29 "プライマリビーム"
*MEAS_COND_AXIS_NAME-30 "PHA"
*MEAS_COND_AXIS_NAME_INTERNAL-0 "TwoThetaTheta"
*MEAS_COND_AXIS_NAME_INTERNAL-1 "TwoTheta"
*MEAS_COND_AXIS_NAME_INTERNAL-2 "Omega"
*MEAS_COND_AXIS_NAME_INTERNAL-3 "Z"
*MEAS_COND_AXIS_NAME_INTERNAL-4 "TwoThetaOmega"
*MEAS_COND_AXIS_NAME_INTERNAL-5 "ThetaS"
*MEAS_COND_AXIS_NAME_INTERNAL-6 "ThetaD"
*MEAS_COND_AXIS_NAME_INTERNAL-7 "Ts"
*MEAS_COND_AXIS_NAME_INTERNAL-8 "CBO"
*MEAS_COND_AXIS_NAME_INTERNAL-9 "CBO-M"
*MEAS_COND_AXIS_NAME_INTERNAL-10 "IncidentSollerSlit"
*MEAS_COND_AXIS_NAME_INTERNAL-11 "IncidentSlitBox"
*MEAS_COND_AXIS_NAME_INTERNAL-12 "IncidentSlitBox-_Axis"
*MEAS_COND_AXIS_NAME_INTERNAL-13 "Zs"
*MEAS_COND_AXIS_NAME_INTERNAL-14 "IncidentMonochromator"
*MEAS_COND_AXIS_NAME_INTERNAL-15 "IncidentAxdSlit"
*MEAS_COND_AXIS_NAME_INTERNAL-16 "CenterSlit"
*MEAS_COND_AXIS_NAME_INTERNAL-17 "Filter"
*MEAS_COND_AXIS_NAME_INTERNAL-18 "ReceivingSlitBox1"
*MEAS_COND_AXIS_NAME_INTERNAL-19 "ReceivingSlitBox2"
*MEAS_COND_AXIS_NAME_INTERNAL-20 "ReceivingOptics"
*MEAS_COND_AXIS_NAME_INTERNAL-21 "ReceivingSollerSlit"
*MEAS_COND_AXIS_NAME_INTERNAL-22 "ReceivingAxdSlit"
*MEAS_COND_AXIS_NAME_INTERNAL-23 "ReceivingSlitBox1-_Axis"
*MEAS_COND_AXIS_NAME_INTERNAL-24 "ReceivingSlitBox2-_Axis"
*MEAS_COND_AXIS_NAME_INTERNAL-25 "ReceivingSlitBox2-Zd"
*MEAS_COND_AXIS_NAME_INTERNAL-26 "Attenuator"
*MEAS_COND_AXIS_NAME_INTERNAL-27 "CounterMonochromator"
*MEAS_COND_AXIS_NAME_INTERNAL-28 "CounterSlit"
*MEAS_COND_AXIS_NAME_INTERNAL-29 "IncidentPrimary"
*MEAS_COND_AXIS_NAME_INTERNAL-30 "PHA"
*MEAS_COND_AXIS_NAME_MAGICNO-0 "83951616.0000000000"
*MEAS_COND_AXIS_NAME_MAGICNO-1 "268632064.0000000000"
*MEAS_COND_AXIS_NAME_MAGICNO-2 "268500992.0000000000"
*MEAS_COND_AXIS_NAME_MAGICNO-3 "285278208.0000000000"
*MEAS_COND_AXIS_NAME_MAGICNO-4 "83951616.0000000000"
*MEAS_COND_AXIS_NAME_MAGICNO-5 "131072.0000000000"
*MEAS_COND_AXIS_NAME_MAGICNO-6 "131072.0000000000"
*MEAS_COND_AXIS_NAME_MAGICNO-7 "318898176.0000000000"
*MEAS_COND_AXIS_NAME_MAGICNO-8 "20971521.0000000000"
*MEAS_COND_AXIS_NAME_MAGICNO-9 "285343744.0000000000"
*MEAS_COND_AXIS_NAME_MAGICNO-10 "20971521.0000000000"
*MEAS_COND_AXIS_NAME_MAGICNO-11 "22020097.0000000000"
*MEAS_COND_AXIS_NAME_MAGICNO-12 "25165824.0000000000"
*MEAS_COND_AXIS_NAME_MAGICNO-13 "318898176.0000000000"
*MEAS_COND_AXIS_NAME_MAGICNO-14 "1.0000000000"
*MEAS_COND_AXIS_NAME_MAGICNO-15 "20971521.0000000000"
*MEAS_COND_AXIS_NAME_MAGICNO-16 "20971521.0000000000"
*MEAS_COND_AXIS_NAME_MAGICNO-17 "20971521.0000000000"
*MEAS_COND_AXIS_NAME_MAGICNO-18 "23068673.0000000000"
*MEAS_COND_AXIS_NAME_MAGICNO-19 "23068673.0000000000"
*MEAS_COND_AXIS_NAME_MAGICNO-20 "20971521.0000000000"
*MEAS_COND_AXIS_NAME_MAGICNO-21 "20971521.0000000000"
*MEAS_COND_AXIS_NAME_MAGICNO-22 "20971521.0000000000"
*MEAS_COND_AXIS_NAME_MAGICNO-23 "25165824.0000000000"
*MEAS_COND_AXIS_NAME_MAGICNO-24 "25165824.0000000000"
*MEAS_COND_AXIS_NAME_MAGICNO-25 "285343744.0000000000"
*MEAS_COND_AXIS_NAME_MAGICNO-26 "17301505.0000000000"
*MEAS_COND_AXIS_NAME_MAGICNO-27 "20971521.0000000000"
*MEAS_COND_AXIS_NAME_MAGICNO-28 "20971521.0000000000"
*MEAS_COND_AXIS_NAME_MAGICNO-29 "20971521.0000000000"
*MEAS_COND_AXIS_NAME_MAGICNO-30 "0.0000000000"
*MEAS_COND_AXIS_OFFSET-0 "-"
*MEAS_COND_AXIS_OFFSET-1 "-0.1081000000"
*MEAS_COND_AXIS_OFFSET-2 "0.3758000000"
*MEAS_COND_AXIS_OFFSET-3 "-"
*MEAS_COND_AXIS_OFFSET-4 "-"
*MEAS_COND_AXIS_OFFSET-5 "0.3758000000"
*MEAS_COND_AXIS_OFFSET-6 "-0.4839000000"
*MEAS_COND_AXIS_OFFSET-7 "-"
*MEAS_COND_AXIS_OFFSET-8 "-"
*MEAS_COND_AXIS_OFFSET-9 "-"
*MEAS_COND_AXIS_OFFSET-10 "-"
*MEAS_COND_AXIS_OFFSET-11 "-"
*MEAS_COND_AXIS_OFFSET-12 "-"
*MEAS_COND_AXIS_OFFSET-13 "-"
*MEAS_COND_AXIS_OFFSET-14 "-"
*MEAS_COND_AXIS_OFFSET-15 "-"
*MEAS_COND_AXIS_OFFSET-16 "-"
*MEAS_COND_AXIS_OFFSET-17 "-"
*MEAS_COND_AXIS_OFFSET-18 "-"
*MEAS_COND_AXIS_OFFSET-19 "-"
*MEAS_COND_AXIS_OFFSET-20 "-"
*MEAS_COND_AXIS_OFFSET-21 "-"
*MEAS_COND_AXIS_OFFSET-22 "-"
*MEAS_COND_AXIS_OFFSET-23 "-"
*MEAS_COND_AXIS_OFFSET-24 "-"
*MEAS_COND_AXIS_OFFSET-25 "-"
*MEAS_COND_AXIS_OFFSET-26 "-"
*MEAS_COND_AXIS_OFFSET-27 "-"
*MEAS_COND_AXIS_OFFSET-28 "-"
*MEAS_COND_AXIS_OFFSET-29 "-"
*MEAS_COND_AXIS_OFFSET-30 "-"
*MEAS_COND_AXIS_POSITION-0 "0.0000000000"
*MEAS_COND_AXIS_POSITION-1 "0.0000000000"
*MEAS_COND_AXIS_POSITION-2 "0.0000000000"
*MEAS_COND_AXIS_POSITION-3 "-0.5500000000"
*MEAS_COND_AXIS_POSITION-4 "0.0000000000"
*MEAS_COND_AXIS_POSITION-5 "0.0000000000"
*MEAS_COND_AXIS_POSITION-6 "0.0000000000"
*MEAS_COND_AXIS_POSITION-7 "-0.4278800000"
*MEAS_COND_AXIS_POSITION-8 "BB"
*MEAS_COND_AXIS_POSITION-9 "0.0000000000"
*MEAS_COND_AXIS_POSITION-10 "Soller_slit_5.0deg"
*MEAS_COND_AXIS_POSITION-11 "2/3deg"
*MEAS_COND_AXIS_POSITION-12 "2.2088000000"
*MEAS_COND_AXIS_POSITION-13 "-0.4140600000"
*MEAS_COND_AXIS_POSITION-14 "0.0000000000"
*MEAS_COND_AXIS_POSITION-15 "10.0mm"
*MEAS_COND_AXIS_POSITION-16 "None"
*MEAS_COND_AXIS_POSITION-17 "Cu_K-beta"
*MEAS_COND_AXIS_POSITION-18 "13.000mm"
*MEAS_COND_AXIS_POSITION-19 "13.000mm"
*MEAS_COND_AXIS_POSITION-20 "No_unit"
*MEAS_COND_AXIS_POSITION-21 "Soller_slit_5.0deg"
*MEAS_COND_AXIS_POSITION-22 "None"
*MEAS_COND_AXIS_POSITION-23 "13.0000000000"
*MEAS_COND_AXIS_POSITION-24 "13.0000000000"
*MEAS_COND_AXIS_POSITION-25 "0.0109400000"
*MEAS_COND_AXIS_POSITION-26 "Open"
*MEAS_COND_AXIS_POSITION-27 "None"
*MEAS_COND_AXIS_POSITION-28 "None"
*MEAS_COND_AXIS_POSITION-29 "None"
*MEAS_COND_AXIS_POSITION-30 "38.0000000000"
*MEAS_COND_AXIS_UNIT-0 "deg"
*MEAS_COND_AXIS_UNIT-1 "deg"
*MEAS_COND_AXIS_UNIT-2 "deg"
*MEAS_COND_AXIS_UNIT-3 "mm"
*MEAS_COND_AXIS_UNIT-4 "deg"
*MEAS_COND_AXIS_UNIT-5 "deg"
*MEAS_COND_AXIS_UNIT-6 "deg"
*MEAS_COND_AXIS_UNIT-7 "mm"
*MEAS_COND_AXIS_UNIT-8 ""
*MEAS_COND_AXIS_UNIT-9 "pulse"
*MEAS_COND_AXIS_UNIT-10 ""
*MEAS_COND_AXIS_UNIT-11 ""
*MEAS_COND_AXIS_UNIT-12 "mm"
*MEAS_COND_AXIS_UNIT-13 "mm"
*MEAS_COND_AXIS_UNIT-14 ""
*MEAS_COND_AXIS_UNIT-15 ""
*MEAS_COND_AXIS_UNIT-16 ""
*MEAS_COND_AXIS_UNIT-17 ""
*MEAS_COND_AXIS_UNIT-18 ""
*MEAS_COND_AXIS_UNIT-19 ""
*MEAS_COND_AXIS_UNIT-20 ""
*MEAS_COND_AXIS_UNIT-21 ""
*MEAS_COND_AXIS_UNIT-22 ""
*MEAS_COND_AXIS_UNIT-23 "mm"
*MEAS_COND_AXIS_UNIT-24 "mm"
*MEAS_COND_AXIS_UNIT-25 "mm"
*MEAS_COND_AXIS_UNIT-26 ""
*MEAS_COND_AXIS_UNIT-27 ""
*MEAS_COND_AXIS_UNIT-28 ""
*MEAS_COND_AXIS_UNIT-29 ""
*MEAS_COND_AXIS_UNIT-30 "div"
*MEAS_COND_COUNTER_CNTLOSS_CORR "0.0000000000"
*MEAS_COND_COUNTER_PHABASE "38.0000000000"
*MEAS_COND_COUNTER_PHAWINDOW "16.0000000000"
*MEAS_COND_COUNTER_PHA_UNIT "div"
*MEAS_COND_COUNTER_TAUDIFF "30.0000000000"
*MEAS_COND_COUNTER_TAUINT "0.0000000000"
*MEAS_COND_IRRADIATION_MODE "OFF"
*MEAS_COND_IRRADIATION_WIDTH ""
*MEAS_COND_OPT_ATTR "集中法"
*MEAS_COND_OPT_NAME "@集中法"
*MEAS_COND_UNSYMMETRIC_MODE "OFF"
*MEAS_COND_XG_CURRENT "30.0000000000"
*MEAS_COND_XG_VOLTAGE "40.0000000000"
*MEAS_COND_XG_WAVE_TYPE "Ka"
*MEAS_DATA_COUNT "3501.0000000000"
*MEAS_SCAN_AXIS_X "2θ/θ"
*MEAS_SCAN_AXIS_X_INTERNAL "TwoThetaTheta"
*MEAS_SCAN_END_TIME "08/26/20 17:04:15"
*MEAS_SCAN_MODE "CONTINUOUS"
*MEAS_SCAN_MONITOR "0"
*MEAS_SCAN_RESOLUTION_X "0.0002"
*MEAS_SCAN_SPEED "1.0"
*MEAS_SCAN_SPEED_UNIT "deg/min"
*MEAS_SCAN_START "20.0000000000"
*MEAS_SCAN_START_TIME "08/26/20 15:51:21"
*MEAS_SCAN_STEP "0.0200000000"
*MEAS_SCAN_STOP "90.0000000000"
*MEAS_SCAN_UNIT_X "deg"
*MEAS_SCAN_UNIT_Y "counts"
*RAS_HEADER_END
*RAS_INT_START
20.0000 6841.0000 1.0000
20.0600 6955.0000 1.0000
20.1200 6864.0000 1.0000
20.1800 6914.0000 1.0000
20.2400 6963.0000 1.0000
20.3000 6973.0000 1.0000
20.3600 6942.0000 1.0000
20.4200 7013.0000 1.0000
20.4800 7069.0000 1.0000
20.5400 7500.0000 1.0000
20.6000 7829.0000 1.0000
20.6600 8675.0000 1.0000
20.7200 10135.0000 1.0000
20.7800 14426.0000 1.0000
20.8400 26950.0000 1.0000
20.9000 23123.0000 1.0000
20.9600 10074.0000 1.0000
21.0200 7694.0000 1.0000
21.0800 7095.0000 1.0000
21.1400 6996.0000 1.0000
21.2000 6870.0000 1.0000
21.2600 6740.0000 1.0000
21.3200 6723.0000 1.0000
21.3800 6572.0000 1.0000
21.4400 6658.0000 1.0000
21.5000 6576.0000 1.0000
21.5600 6660.0000 1.0000
21.6200 6550.0000 1.0000
21.6800 6753.0000 1.0000
21.7400 6610.0000 1.0000
21.8000 6735.0000 1.0000
21.8600 6705.0000 1.0000
21.9200 6457.0000 1.0000
21.9800 6517.0000 1.0000
22.0400 6552.0000 1.0000
22.1000 6712.0000 1.0000
22.1600 6451.0000 1.0000
22.2200 6568.0000 1.0000
22.2800 6401.0000 1.0000
22.3400 6721.0000 1.0000
22.4000 6531.0000 1.0000
22.4600 6565.0000 1.0000
22.5200 6410.0000 1.0000
22.5800 6347.0000 1.0000
22.6400 6450.0000 1.0000
22.7000 6617.0000 1.0000
22.7600 6389.0000 1.0000
22.8200 6360.0000 1.0000
22.8800 6404.0000 1.0000
22.9400 6321.0000 1.0000
23.0000 6411.0000 1.0000
23.0600 6455.0000 1.0000
23.1200 6395.0000 1.0000
23.1800 6311.0000 1.0000
23.2400 6468.0000 1.0000
23.3000 6323.0000 1.0000
23.3600 6249.0000 1.0000
23.4200 6380.0000 1.0000
23.4800 6369.0000 1.0000
23.5400 6310.0000 1.0000
23.6000 6348.0000 1.0000
23.6600 6444.0000 1.0000
23.7200 6316.0000 1.0000
23.7800 6453.0000 1.0000
23.8400 6296.0000 1.0000
23.9000 6621.0000 1.0000
23.9600 6820.0000 1.0000
24.0200 7897.0000 1.0000
24.0800 7785.0000 1.0000
24.1400 8386.0000 1.0000
24.2000 7632.0000 1.0000
24.2600 6761.0000 1.0000
24.3200 6359.0000 1.0000
24.3800 6225.0000 1.0000
24.4400 6076.0000 1.0000
24.5000 6278.0000 1.0000
24.5600 6312.0000 1.0000
24.6200 6338.0000 1.0000
24.6800 6218.0000 1.0000
24.7400 6281.0000 1.0000
24.8000 6302.0000 1.0000
24.8600 6069.0000 1.0000
24.9200 6155.0000 1.0000
24.9800 6104.0000 1.0000
25.0400 6193.0000 1.0000
25.1000 6269.0000 1.0000
25.1600 6269.0000 1.0000
25.2200 6326.0000 1.0000
25.2800 6573.0000 1.0000
25.3400 6965.0000 1.0000
25.4000 7419.0000 1.0000
25.4600 8768.0000 1.0000
25.5200 11522.0000 1.0000
25.5800 13508.0000 1.0000
25.6400 10456.0000 1.0000
25.7000 7809.0000 1.0000
25.7600 7241.0000 1.0000
25.8200 6813.0000 1.0000
25.8800 6816.0000 1.0000
25.9400 6673.0000 1.0000
26.0000 6674.0000 1.0000
26.0600 6709.0000 1.0000
26.1200 6865.0000 1.0000
26.1800 6680.0000 1.0000
26.2400 6945.0000 1.0000
26.3000 7450.0000 1.0000
26.3600 9006.0000 1.0000
26.4200 12680.0000 1.0000
26.4800 19944.0000 1.0000
26.5400 34056.0000 1.0000
26.6000 86654.0000 1.0000
26.6600 109118.0000 1.0000
26.7200 57650.0000 1.0000
26.7800 14580.0000 1.0000
26.8400 9503.0000 1.0000
26.9000 7376.0000 1.0000
26.9600 6745.0000 1.0000
27.0200 6613.0000 1.0000
27.0800 6552.0000 1.0000
27.1400 6551.0000 1.0000
27.2000 6422.0000 1.0000
27.2600 6412.0000 1.0000
27.3200 6238.0000 1.0000
27.3800 6331.0000 1.0000
27.4400 6428.0000 1.0000
27.5000 6291.0000 1.0000
27.5600 6331.0000 1.0000
27.6200 6275.0000 1.0000
27.6800 6088.0000 1.0000
27.7400 6219.0000 1.0000
27.8000 6034.0000 1.0000
27.8600 6169.0000 1.0000
27.9200 6090.0000 1.0000
27.9800 6207.0000 1.0000
28.0400 6065.0000 1.0000
28.1000 6032.0000 1.0000
28.1600 6069.0000 1.0000
28.2200 6111.0000 1.0000
28.2800 6109.0000 1.0000
28.3400 6060.0000 1.0000
28.4000 6006.0000 1.0000
28.4600 6004.0000 1.0000
28.5200 5960.0000 1.0000
28.5800 6121.0000 1.0000
28.6400 6143.0000 1.0000
28.7000 5872.0000 1.0000
28.7600 5976.0000 1.0000
28.8200 5872.0000 1.0000
28.8800 5919.0000 1.0000
28.9400 5821.0000 1.0000
29.0000 6037.0000 1.0000
29.0600 5943.0000 1.0000
29.1200 6011.0000 1.0000
29.1800 5868.0000 1.0000
29.2400 5806.0000 1.0000
29.3000 5844.0000 1.0000
29.3600 5912.0000 1.0000
29.4200 5866.0000 1.0000
29.4800 5808.0000 1.0000
29.5400 5858.0000 1.0000
29.6000 5851.0000 1.0000
29.6600 5953.0000 1.0000
29.7200 5825.0000 1.0000
29.7800 5859.0000 1.0000
29.8400 6030.0000 1.0000
29.9000 6007.0000 1.0000
29.9600 6192.0000 1.0000
30.0200 6762.0000 1.0000
30.0800 7753.0000 1.0000
30.1400 8144.0000 1.0000
30.2000 7424.0000 1.0000
30.2600 6667.0000 1.0000
30.3200 6236.0000 1.0000
30.3800 6032.0000 1.0000
30.4400 5857.0000 1.0000
30.5000 5759.0000 1.0000
30.5600 5909.0000 1.0000
30.6200 5755.0000 1.0000
30.6800 5748.0000 1.0000
30.7400 5645.0000 1.0000
30.8000 5647.0000 1.0000
30.8600 5752.0000 1.0000
30.9200 5730.0000 1.0000
30.9800 5642.0000 1.0000
31.0400 5745.0000 1.0000
31.1000 5697.0000 1.0000
31.1600 5756.0000 1.0000
31.2200 5586.0000 1.0000
31.2800 5805.0000 1.0000
31.3400 5701.0000 1.0000
31.4000 5654.0000 1.0000
31.4600 5758.0000 1.0000
31.5200 5682.0000 1.0000
31.5800 5552.0000 1.0000
31.6400 5768.0000 1.0000
31.7000 5633.0000 1.0000
31.7600 5572.0000 1.0000
31.8200 5610.0000 1.0000
31.8800 5580.0000 1.0000
31.9400 5686.0000 1.0000
32.0000 5681.0000 1.0000
32.0600 5762.0000 1.0000
32.1200 5626.0000 1.0000
32.1800 5775.0000 1.0000
32.2400 5570.0000 1.0000
32.3000 5558.0000 1.0000
32.3600 5622.0000 1.0000
32.4200 5551.0000 1.0000
32.4800 5658.0000 1.0000
32.5400 5426.0000 1.0000
32.6000 5589.0000 1.0000
32.6600 5473.0000 1.0000
32.7200 5559.0000 1.0000
32.7800 5699.0000 1.0000
32.8400 5984.0000 1.0000
32.9000 5900.0000 1.0000
32.9600 6295.0000 1.0000
33.0200 7023.0000 1.0000
33.0800 8862.0000 1.0000
33.1400 12211.0000 1.0000
33.2000 10774.0000 1.0000
33.2600 8658.0000 1.0000
33.3200 6597.0000 1.0000
33.3800 5924.0000 1.0000
33.4400 5718.0000 1.0000
33.5000 5633.0000 1.0000
33.5600 5539.0000 1.0000
33.6200 5535.0000 1.0000
33.6800 5424.0000 1.0000
33.7400 5428.0000 1.0000
33.8000 5479.0000 1.0000
33.8600 5328.0000 1.0000
33.9200 5506.0000 1.0000
33.9800 5736.0000 1.0000
34.0400 5525.0000 1.0000
34.1000 5385.0000 1.0000
34.1600 5452.0000 1.0000
34.2200 5413.0000 1.0000
34.2800 5541.0000 1.0000
34.3400 5460.0000 1.0000
34.4000 5547.0000 1.0000
34.4600 5564.0000 1.0000
34.5200 5570.0000 1.0000
34.5800 5657.0000 1.0000
34.6400 5548.0000 1.0000
34.7000 5646.0000 1.0000
34.7600 5678.0000 1.0000
34.8200 5952.0000 1.0000
34.8800 6302.0000 1.0000
34.9400 6996.0000 1.0000
35.0000 8147.0000 1.0000
35.0600 11114.0000 1.0000
35.1200 17034.0000 1.0000
35.1800 14919.0000 1.0000
35.2400 12350.0000 1.0000
35.3000 8994.0000 1.0000
35.3600 8938.0000 1.0000
35.4200 11880.0000 1.0000
35.4800 14608.0000 1.0000
35.5400 13868.0000 1.0000
35.6000 13947.0000 1.0000
35.6600 11286.0000 1.0000
35.7200 9188.0000 1.0000
35.7800 7000.0000 1.0000
35.8400 6074.0000 1.0000
35.9000 5891.0000 1.0000
35.9600 5650.0000 1.0000
36.0200 5447.0000 1.0000
36.0800 5463.0000 1.0000
36.1400 5576.0000 1.0000
36.2000 5508.0000 1.0000
36.2600 5691.0000 1.0000
36.3200 6040.0000 1.0000
36.3800 6487.0000 1.0000
36.4400 8025.0000 1.0000
36.5000 12548.0000 1.0000
36.5600 14161.0000 1.0000
36.6200 12060.0000 1.0000
36.6800 7070.0000 1.0000
36.7400 5718.0000 1.0000
36.8000 5386.0000 1.0000
36.8600 5364.0000 1.0000
36.9200 5360.0000 1.0000
36.9800 5400.0000 1.0000
37.0400 5554.0000 1.0000
37.1000 5667.0000 1.0000
37.1600 5697.0000 1.0000
37.2200 5531.0000 1.0000
37.2800 5473.0000 1.0000
37.3400 5364.0000 1.0000
37.4000 5316.0000 1.0000
37.4600 5465.0000 1.0000
37.5200 5864.0000 1.0000
37.5800 6021.0000 1.0000
37.6400 6550.0000 1.0000
37.7000 8110.0000 1.0000
37.7600 10309.0000 1.0000
37.8200 8638.0000 1.0000
37.8800 7694.0000 1.0000
37.9400 6095.0000 1.0000
38.0000 5616.0000 1.0000
38.0600 5345.0000 1.0000
38.1200 5340.0000 1.0000
38.1800 5428.0000 1.0000
38.2400 5317.0000 1.0000
38.3000 5307.0000 1.0000
38.3600 5281.0000 1.0000
38.4200 5234.0000 1.0000
38.4800 5266.0000 1.0000
38.5400 5262.0000 1.0000
38.6000 5267.0000 1.0000
38.6600 5264.0000 1.0000
38.7200 5124.0000 1.0000
38.7800 5216.0000 1.0000
38.8400 5248.0000 1.0000
38.9000 5317.0000 1.0000
38.9600 5333.0000 1.0000
39.0200 5290.0000 1.0000
39.0800 5191.0000 1.0000
39.1400 5179.0000 1.0000
39.2000 5523.0000 1.0000
39.2600 5809.0000 1.0000
39.3200 6016.0000 1.0000
39.3800 7338.0000 1.0000
39.4400 13060.0000 1.0000
39.5000 9370.0000 1.0000
39.5600 9876.0000 1.0000
39.6200 5956.0000 1.0000
39.6800 5435.0000 1.0000
39.7400 5231.0000 1.0000
39.8000 5195.0000 1.0000
39.8600 5186.0000 1.0000
39.9200 5206.0000 1.0000
39.9800 5161.0000 1.0000
40.0400 5315.0000 1.0000
40.1000 5351.0000 1.0000
40.1600 5660.0000 1.0000
40.2200 6799.0000 1.0000
40.2800 10351.0000 1.0000
40.3400 7094.0000 1.0000
40.4000 7343.0000 1.0000
40.4600 5554.0000 1.0000
40.5200 5313.0000 1.0000
40.5800 5217.0000 1.0000
40.6400 5293.0000 1.0000
40.7000 5305.0000 1.0000
40.7600 5707.0000 1.0000
40.8200 6317.0000 1.0000
40.8800 6332.0000 1.0000
40.9400 5997.0000 1.0000
41.0000 5448.0000 1.0000
41.0600 5298.0000 1.0000
41.1200 5269.0000 1.0000
41.1800 5271.0000 1.0000
41.2400 5136.0000 1.0000
41.3000 5244.0000 1.0000
41.3600 5150.0000 1.0000
41.4200 5093.0000 1.0000
41.4800 5048.0000 1.0000
41.5400 5099.0000 1.0000
41.6000 5232.0000 1.0000
41.6600 5240.0000 1.0000
41.7200 5250.0000 1.0000
41.7800 5208.0000 1.0000
41.8400 5102.0000 1.0000
41.9000 5129.0000 1.0000
41.9600 4998.0000 1.0000
42.0200 5111.0000 1.0000
42.0800 5109.0000 1.0000
42.1400 5062.0000 1.0000
42.2000 5333.0000 1.0000
42.2600 5474.0000 1.0000
42.3200 5912.0000 1.0000
42.3800 7248.0000 1.0000
42.4400 10988.0000 1.0000
42.5000 7021.0000 1.0000
42.5600 7767.0000 1.0000
42.6200 5583.0000 1.0000
42.6800 5423.0000 1.0000
42.7400 5163.0000 1.0000
42.8000 5319.0000 1.0000
42.8600 5441.0000 1.0000
42.9200 5640.0000 1.0000
42.9800 5835.0000 1.0000
43.0400 6617.0000 1.0000
43.1000 7927.0000 1.0000
43.1600 8528.0000 1.0000
43.2200 9764.0000 1.0000
43.2800 13521.0000 1.0000
43.3400 18395.0000 1.0000
43.4000 13442.0000 1.0000
43.4600 12182.0000 1.0000
43.5200 8051.0000 1.0000
43.5800 6628.0000 1.0000
43.6400 5928.0000 1.0000
43.7000 5620.0000 1.0000
43.7600 5361.0000 1.0000
43.8200 5290.0000 1.0000
43.8800 5167.0000 1.0000
43.9400 5101.0000 1.0000
44.0000 5208.0000 1.0000
44.0600 5162.0000 1.0000
44.1200 5048.0000 1.0000
44.1800 5130.0000 1.0000
44.2400 5007.0000 1.0000
44.3000 4991.0000 1.0000
44.3600 4982.0000 1.0000
44.4200 4934.0000 1.0000
44.4800 5008.0000 1.0000
44.5400 5067.0000 1.0000
44.6000 4954.0000 1.0000
44.6600 4948.0000 1.0000
44.7200 4904.0000 1.0000
44.7800 4997.0000 1.0000
44.8400 5069.0000 1.0000
44.9000 5066.0000 1.0000
44.9600 5060.0000 1.0000
45.0200 4994.0000 1.0000
45.0800 4972.0000 1.0000
45.1400 4853.0000 1.0000
45.2000 4930.0000 1.0000
45.2600 4881.0000 1.0000
45.3200 4979.0000 1.0000
45.3800 4968.0000 1.0000
45.4400 4999.0000 1.0000
45.5000 5040.0000 1.0000
45.5600 5236.0000 1.0000
45.6200 5404.0000 1.0000
45.6800 5669.0000 1.0000
45.7400 8106.0000 1.0000
45.8000 9348.0000 1.0000
45.8600 6975.0000 1.0000
45.9200 7276.0000 1.0000
45.9800 5253.0000 1.0000
46.0400 4990.0000 1.0000
46.1000 5036.0000 1.0000
46.1600 5026.0000 1.0000
46.2200 4929.0000 1.0000
46.2800 5041.0000 1.0000
46.3400 5000.0000 1.0000
46.4000 4908.0000 1.0000
46.4600 4795.0000 1.0000
46.5200 4894.0000 1.0000
46.5800 4954.0000 1.0000
46.6400 4898.0000 1.0000
46.7000 4894.0000 1.0000
46.7600 4892.0000 1.0000
46.8200 4950.0000 1.0000
46.8800 4880.0000 1.0000
46.9400 4835.0000 1.0000
47.0000 4779.0000 1.0000
47.0600 4932.0000 1.0000
47.1200 5050.0000 1.0000
47.1800 4962.0000 1.0000
47.2400 4866.0000 1.0000
47.3000 4823.0000 1.0000
47.3600 4947.0000 1.0000
47.4200 4904.0000 1.0000
47.4800 4778.0000 1.0000
47.5400 4912.0000 1.0000
47.6000 4828.0000 1.0000
47.6600 4946.0000 1.0000
47.7200 4897.0000 1.0000
47.7800 4842.0000 1.0000
47.8400 4769.0000 1.0000
47.9000 4930.0000 1.0000
47.9600 4726.0000 1.0000
48.0200 4876.0000 1.0000
48.0800 4810.0000 1.0000
48.1400 4803.0000 1.0000
48.2000 4816.0000 1.0000
48.2600 4857.0000 1.0000
48.3200 4937.0000 1.0000
48.3800 4730.0000 1.0000
48.4400 4908.0000 1.0000
48.5000 4966.0000 1.0000
48.5600 4838.0000 1.0000
48.6200 4875.0000 1.0000
48.6800 4887.0000 1.0000
48.7400 5093.0000 1.0000
48.8000 4854.0000 1.0000
48.8600 4791.0000 1.0000
48.9200 4894.0000 1.0000
48.9800 4923.0000 1.0000
49.0400 4930.0000 1.0000
49.1000 4968.0000 1.0000
49.1600 5060.0000 1.0000
49.2200 5152.0000 1.0000
49.2800 5223.0000 1.0000
49.3400 5659.0000 1.0000
49.4000 6303.0000 1.0000
49.4600 7110.0000 1.0000
49.5200 6155.0000 1.0000
49.5800 6342.0000 1.0000
49.6400 5607.0000 1.0000
49.7000 5219.0000 1.0000
49.7600 5218.0000 1.0000
49.8200 5209.0000 1.0000
49.8800 5598.0000 1.0000
49.9400 5810.0000 1.0000
50.0000 6403.0000 1.0000
50.0600 9880.0000 1.0000
50.1200 22283.0000 1.0000
50.1800 10225.0000 1.0000
50.2400 12783.0000 1.0000
50.3000 8770.0000 1.0000
50.3600 5581.0000 1.0000
50.4200 5349.0000 1.0000
50.4800 5175.0000 1.0000
50.5400 5016.0000 1.0000
50.6000 5185.0000 1.0000
50.6600 5103.0000 1.0000
50.7200 5179.0000 1.0000
50.7800 4947.0000 1.0000
50.8400 4922.0000 1.0000
50.9000 4899.0000 1.0000
50.9600 4924.0000 1.0000
51.0200 4796.0000 1.0000
51.0800 4992.0000 1.0000
51.1400 4785.0000 1.0000
51.2000 4892.0000 1.0000
51.2600 4870.0000 1.0000
51.3200 4941.0000 1.0000
51.3800 4941.0000 1.0000
51.4400 4835.0000 1.0000
51.5000 5026.0000 1.0000
51.5600 4949.0000 1.0000
51.6200 4937.0000 1.0000
51.6800 4777.0000 1.0000
51.7400 4849.0000 1.0000
51.8000 4894.0000 1.0000
51.8600 4936.0000 1.0000
51.9200 4921.0000 1.0000
51.9800 4827.0000 1.0000
52.0400 5009.0000 1.0000
52.1000 5013.0000 1.0000
52.1600 5125.0000 1.0000
52.2200 5344.0000 1.0000
52.2800 5425.0000 1.0000
52.3400 5702.0000 1.0000
52.4000 6191.0000 1.0000
52.4600 7797.0000 1.0000
52.5200 10187.0000 1.0000
52.5800 8672.0000 1.0000
52.6400 8013.0000 1.0000
52.7000 7532.0000 1.0000
52.7600 5914.0000 1.0000
52.8200 5500.0000 1.0000
52.8800 5016.0000 1.0000
52.9400 5094.0000 1.0000
53.0000 5004.0000 1.0000
53.0600 4961.0000 1.0000
53.1200 4873.0000 1.0000
53.1800 4934.0000 1.0000
53.2400 5042.0000 1.0000
53.3000 5033.0000 1.0000
53.3600 5131.0000 1.0000
53.4200 5294.0000 1.0000
53.4800 5554.0000 1.0000
53.5400 5386.0000 1.0000
53.6000 5401.0000 1.0000
53.6600 5479.0000 1.0000
53.7200 5102.0000 1.0000
53.7800 5133.0000 1.0000
53.8400 5175.0000 1.0000
53.9000 5296.0000 1.0000
53.9600 5786.0000 1.0000
54.0200 7038.0000 1.0000
54.0800 7236.0000 1.0000
54.1400 6267.0000 1.0000
54.2000 6418.0000 1.0000
54.2600 5544.0000 1.0000
54.3200 5172.0000 1.0000
54.3800 5233.0000 1.0000
54.4400 4763.0000 1.0000
54.5000 5045.0000 1.0000
54.5600 4916.0000 1.0000
54.6200 5074.0000 1.0000
54.6800 5234.0000 1.0000
54.7400 5477.0000 1.0000
54.8000 6843.0000 1.0000
54.8600 10203.0000 1.0000
54.9200 6432.0000 1.0000
54.9800 6921.0000 1.0000
55.0400 6922.0000 1.0000
55.1000 5258.0000 1.0000
55.1600 5028.0000 1.0000
55.2200 5333.0000 1.0000
55.2800 5819.0000 1.0000
55.3400 5946.0000 1.0000
55.4000 5297.0000 1.0000
55.4600 5710.0000 1.0000
55.5200 5154.0000 1.0000
55.5800 5002.0000 1.0000
55.6400 4880.0000 1.0000
55.7000 4743.0000 1.0000
55.7600 4828.0000 1.0000
55.8200 4812.0000 1.0000
55.8800 4930.0000 1.0000
55.9400 4882.0000 1.0000
56.0000 4928.0000 1.0000
56.0600 4754.0000 1.0000
56.1200 4998.0000 1.0000
56.1800 4919.0000 1.0000
56.2400 4827.0000 1.0000
56.3000 4842.0000 1.0000
56.3600 4929.0000 1.0000
56.4200 4844.0000 1.0000
56.4800 5002.0000 1.0000
56.5400 4949.0000 1.0000
56.6000 4928.0000 1.0000
56.6600 5019.0000 1.0000
56.7200 4986.0000 1.0000
56.7800 5129.0000 1.0000
56.8400 5258.0000 1.0000
56.9000 5519.0000 1.0000
56.9600 6517.0000 1.0000
57.0200 7109.0000 1.0000
57.0800 6805.0000 1.0000
57.1400 7067.0000 1.0000
57.2000 6994.0000 1.0000
57.2600 7085.0000 1.0000
57.3200 7645.0000 1.0000
57.3800 9420.0000 1.0000
57.4400 13769.0000 1.0000
57.5000 14939.0000 1.0000
57.5600 11092.0000 1.0000
57.6200 11558.0000 1.0000
57.6800 9168.0000 1.0000
57.7400 6801.0000 1.0000
57.8000 5993.0000 1.0000
57.8600 5388.0000 1.0000
57.9200 5426.0000 1.0000
57.9800 5287.0000 1.0000
58.0400 5106.0000 1.0000
58.1000 5025.0000 1.0000
58.1600 5012.0000 1.0000
58.2200 4888.0000 1.0000
58.2800 4935.0000 1.0000
58.3400 4907.0000 1.0000
58.4000 4794.0000 1.0000
58.4600 4949.0000 1.0000
58.5200 4815.0000 1.0000
58.5800 4858.0000 1.0000
58.6400 4841.0000 1.0000
58.7000 4964.0000 1.0000
58.7600 4865.0000 1.0000
58.8200 4938.0000 1.0000
58.8800 4923.0000 1.0000
58.9400 4792.0000 1.0000
59.0000 4830.0000 1.0000
59.0600 4737.0000 1.0000
59.1200 4887.0000 1.0000
59.1800 4883.0000 1.0000
59.2400 4873.0000 1.0000
59.3000 4929.0000 1.0000
59.3600 4858.0000 1.0000
59.4200 4977.0000 1.0000
59.4800 4907.0000 1.0000
59.5400 4957.0000 1.0000
59.6000 5039.0000 1.0000
59.6600 5283.0000 1.0000
59.7200 5491.0000 1.0000
59.7800 5777.0000 1.0000
59.8400 6725.0000 1.0000
59.9000 12009.0000 1.0000
59.9600 13756.0000 1.0000
60.0200 6986.0000 1.0000
60.0800 9792.0000 1.0000
60.1400 7962.0000 1.0000
60.2000 5392.0000 1.0000
60.2600 5251.0000 1.0000
60.3200 4996.0000 1.0000
60.3800 5070.0000 1.0000
60.4400 4978.0000 1.0000
60.5000 4981.0000 1.0000
60.5600 4953.0000 1.0000
60.6200 4860.0000 1.0000
60.6800 4921.0000 1.0000
60.7400 5000.0000 1.0000
60.8000 4958.0000 1.0000
60.8600 4936.0000 1.0000
60.9200 5008.0000 1.0000
60.9800 5088.0000 1.0000
61.0400 5129.0000 1.0000
61.1000 5325.0000 1.0000
61.1600 5253.0000 1.0000
61.2200 5411.0000 1.0000
61.2800 5851.0000 1.0000
61.3400 5569.0000 1.0000
61.4000 5174.0000 1.0000
61.4600 5335.0000 1.0000
61.5200 5032.0000 1.0000
61.5800 5006.0000 1.0000
61.6400 4745.0000 1.0000
61.7000 4896.0000 1.0000
61.7600 4811.0000 1.0000
61.8200 4784.0000 1.0000
61.8800 4897.0000 1.0000
61.9400 4802.0000 1.0000
62.0000 4862.0000 1.0000
62.0600 4956.0000 1.0000
62.1200 5001.0000 1.0000
62.1800 4927.0000 1.0000
62.2400 5046.0000 1.0000
62.3000 5355.0000 1.0000
62.3600 6141.0000 1.0000
62.4200 6899.0000 1.0000
62.4800 6344.0000 1.0000
62.5400 7267.0000 1.0000
62.6000 8340.0000 1.0000
62.6600 7427.0000 1.0000
62.7200 6818.0000 1.0000
62.7800 6609.0000 1.0000
62.8400 6095.0000 1.0000
62.9000 5553.0000 1.0000
62.9600 5286.0000 1.0000
63.0200 5011.0000 1.0000
63.0800 4944.0000 1.0000
63.1400 5048.0000 1.0000
63.2000 4935.0000 1.0000
63.2600 4817.0000 1.0000
63.3200 4928.0000 1.0000
63.3800 4863.0000 1.0000
63.4400 4855.0000 1.0000
63.5000 4797.0000 1.0000
63.5600 4790.0000 1.0000
63.6200 4934.0000 1.0000
63.6800 4891.0000 1.0000
63.7400 4961.0000 1.0000
63.8000 5148.0000 1.0000
63.8600 5364.0000 1.0000
63.9200 6115.0000 1.0000
63.9800 7790.0000 1.0000
64.0400 7780.0000 1.0000
64.1000 5954.0000 1.0000
64.1600 6472.0000 1.0000
64.2200 6396.0000 1.0000
64.2800 5197.0000 1.0000
64.3400 5040.0000 1.0000
64.4000 4867.0000 1.0000
64.4600 4979.0000 1.0000
64.5200 4794.0000 1.0000
64.5800 4786.0000 1.0000
64.6400 4813.0000 1.0000
64.7000 4833.0000 1.0000
64.7600 4683.0000 1.0000
64.8200 4869.0000 1.0000
64.8800 4844.0000 1.0000
64.9400 4704.0000 1.0000
65.0000 4825.0000 1.0000
65.0600 4909.0000 1.0000
65.1200 4758.0000 1.0000
65.1800 4814.0000 1.0000
65.2400 4737.0000 1.0000
65.3000 4811.0000 1.0000
65.3600 4909.0000 1.0000
65.4200 4897.0000 1.0000
65.4800 4791.0000 1.0000
65.5400 4873.0000 1.0000
65.6000 4849.0000 1.0000
65.6600 4844.0000 1.0000
65.7200 5051.0000 1.0000
65.7800 5307.0000 1.0000
65.8400 5087.0000 1.0000
65.9000 5024.0000 1.0000
65.9600 5141.0000 1.0000
66.0200 5081.0000 1.0000
66.0800 5165.0000 1.0000
66.1400 5036.0000 1.0000
66.2000 5262.0000 1.0000
66.2600 5251.0000 1.0000
66.3200 5710.0000 1.0000
66.3800 6041.0000 1.0000
66.4400 7587.0000 1.0000
66.5000 8824.0000 1.0000
66.5600 6846.0000 1.0000
66.6200 6719.0000 1.0000
66.6800 7009.0000 1.0000
66.7400 6021.0000 1.0000
66.8000 5473.0000 1.0000
66.8600 5268.0000 1.0000
66.9200 5021.0000 1.0000
66.9800 5096.0000 1.0000
67.0400 4983.0000 1.0000
67.1000 5011.0000 1.0000
67.1600 4970.0000 1.0000
67.2200 5082.0000 1.0000
67.2800 5110.0000 1.0000
67.3400 4985.0000 1.0000
67.4000 5131.0000 1.0000
67.4600 5052.0000 1.0000
67.5200 5374.0000 1.0000
67.5800 5465.0000 1.0000
67.6400 6752.0000 1.0000
67.7000 11180.0000 1.0000
67.7600 8137.0000 1.0000
67.8200 6441.0000 1.0000
67.8800 8227.0000 1.0000
67.9400 8207.0000 1.0000
68.0000 7274.0000 1.0000
68.0600 9759.0000 1.0000
68.1200 17238.0000 1.0000
68.1800 13899.0000 1.0000
68.2400 12940.0000 1.0000
68.3000 18474.0000 1.0000
68.3600 11296.0000 1.0000
68.4200 8827.0000 1.0000
68.4800 9702.0000 1.0000
68.5400 6414.0000 1.0000
68.6000 5580.0000 1.0000
68.6600 5266.0000 1.0000
68.7200 5159.0000 1.0000
68.7800 5058.0000 1.0000
68.8400 4970.0000 1.0000
68.9000 4979.0000 1.0000
68.9600 4907.0000 1.0000
69.0200 4975.0000 1.0000
69.0800 4919.0000 1.0000
69.1400 4878.0000 1.0000
69.2000 4847.0000 1.0000
69.2600 4941.0000 1.0000
69.3200 4928.0000 1.0000
69.3800 4757.0000 1.0000
69.4400 5018.0000 1.0000
69.5000 4942.0000 1.0000
69.5600 4923.0000 1.0000
69.6200 5076.0000 1.0000
69.6800 4860.0000 1.0000
69.7400 4923.0000 1.0000
69.8000 4887.0000 1.0000
69.8600 4823.0000 1.0000
69.9200 4734.0000 1.0000
69.9800 4798.0000 1.0000
70.0400 4841.0000 1.0000
70.1000 4803.0000 1.0000
70.1600 4989.0000 1.0000
70.2200 4823.0000 1.0000
70.2800 4886.0000 1.0000
70.3400 4844.0000 1.0000
70.4000 4837.0000 1.0000
70.4600 4885.0000 1.0000
70.5200 4896.0000 1.0000
70.5800 4777.0000 1.0000
70.6400 4668.0000 1.0000
70.7000 4903.0000 1.0000
70.7600 4682.0000 1.0000
70.8200 4840.0000 1.0000
70.8800 4734.0000 1.0000
70.9400 4925.0000 1.0000
71.0000 5014.0000 1.0000
71.0600 4844.0000 1.0000
71.1200 4885.0000 1.0000
71.1800 4925.0000 1.0000
71.2400 4931.0000 1.0000
71.3000 4808.0000 1.0000
71.3600 4757.0000 1.0000
71.4200 4807.0000 1.0000
71.4800 4838.0000 1.0000
71.5400 4764.0000 1.0000
71.6000 4866.0000 1.0000
71.6600 4800.0000 1.0000
71.7200 4861.0000 1.0000
71.7800 4977.0000 1.0000
71.8400 5058.0000 1.0000
71.9000 5222.0000 1.0000
71.9600 5113.0000 1.0000
72.0200 4943.0000 1.0000
72.0800 4997.0000 1.0000
72.1400 5078.0000 1.0000
72.2000 4963.0000 1.0000
72.2600 4897.0000 1.0000
72.3200 4766.0000 1.0000
72.3800 4792.0000 1.0000
72.4400 4856.0000 1.0000
72.5000 4858.0000 1.0000
72.5600 4782.0000 1.0000
72.6200 4828.0000 1.0000
72.6800 4699.0000 1.0000
72.7400 4835.0000 1.0000
72.8000 4816.0000 1.0000
72.8600 4799.0000 1.0000
72.9200 4754.0000 1.0000
72.9800 4795.0000 1.0000
73.0400 4756.0000 1.0000
73.1000 4909.0000 1.0000
73.1600 4769.0000 1.0000
73.2200 4815.0000 1.0000
73.2800 4780.0000 1.0000
73.3400 4902.0000 1.0000
73.4000 5691.0000 1.0000
73.4600 6318.0000 1.0000
73.5200 5177.0000 1.0000
73.5800 5069.0000 1.0000
73.6400 5580.0000 1.0000
73.7000 5237.0000 1.0000
73.7600 4890.0000 1.0000
73.8200 4927.0000 1.0000
73.8800 4812.0000 1.0000
73.9400 4958.0000 1.0000
74.0000 4926.0000 1.0000
74.0600 5169.0000 1.0000
74.1200 5150.0000 1.0000
74.1800 5166.0000 1.0000
74.2400 5149.0000 1.0000
74.3000 5000.0000 1.0000
74.3600 4868.0000 1.0000
74.4200 4911.0000 1.0000
74.4800 4757.0000 1.0000
74.5400 4839.0000 1.0000
74.6000 4748.0000 1.0000
74.6600 4897.0000 1.0000
74.7200 4865.0000 1.0000
74.7800 4725.0000 1.0000
74.8400 4780.0000 1.0000
74.9000 4746.0000 1.0000
74.9600 4800.0000 1.0000
75.0200 4935.0000 1.0000
75.0800 4887.0000 1.0000
75.1400 4897.0000 1.0000
75.2000 4842.0000 1.0000
75.2600 5085.0000 1.0000
75.3200 5085.0000 1.0000
75.3800 5294.0000 1.0000
75.4400 5327.0000 1.0000
75.5000 5245.0000 1.0000
75.5600 5795.0000 1.0000
75.6200 7856.0000 1.0000
75.6800 6110.0000 1.0000
75.7400 5267.0000 1.0000
75.8000 5666.0000 1.0000
75.8600 6296.0000 1.0000
75.9200 5272.0000 1.0000
75.9800 4958.0000 1.0000
76.0400 4873.0000 1.0000
76.1000 4803.0000 1.0000
76.1600 4799.0000 1.0000
76.2200 4783.0000 1.0000
76.2800 4899.0000 1.0000
76.3400 4872.0000 1.0000
76.4000 4774.0000 1.0000
76.4600 4916.0000 1.0000
76.5200 4907.0000 1.0000
76.5800 4914.0000 1.0000
76.6400 5025.0000 1.0000
76.7000 5218.0000 1.0000
76.7600 5507.0000 1.0000
76.8200 6287.0000 1.0000
76.8800 6221.0000 1.0000
76.9400 5550.0000 1.0000
77.0000 5627.0000 1.0000
77.0600 5946.0000 1.0000
77.1200 5702.0000 1.0000
77.1800 5819.0000 1.0000
77.2400 5726.0000 1.0000
77.3000 5222.0000 1.0000
77.3600 5266.0000 1.0000
77.4200 5298.0000 1.0000
77.4800 5259.0000 1.0000
77.5400 5296.0000 1.0000
77.6000 5860.0000 1.0000
77.6600 6619.0000 1.0000
77.7200 5375.0000 1.0000
77.7800 5152.0000 1.0000
77.8400 5445.0000 1.0000
77.9000 5511.0000 1.0000
77.9600 4925.0000 1.0000
78.0200 4900.0000 1.0000
78.0800 4857.0000 1.0000
78.1400 4805.0000 1.0000
78.2000 4764.0000 1.0000
78.2600 4717.0000 1.0000
78.3200 4652.0000 1.0000
78.3800 4782.0000 1.0000
78.4400 4701.0000 1.0000
78.5000 4730.0000 1.0000
78.5600 4825.0000 1.0000
78.6200 4826.0000 1.0000
78.6800 4782.0000 1.0000
78.7400 4776.0000 1.0000
78.8000 4946.0000 1.0000
78.8600 4792.0000 1.0000
78.9200 4866.0000 1.0000
78.9800 4805.0000 1.0000
79.0400 4848.0000 1.0000
79.1000 4848.0000 1.0000
79.1600 4954.0000 1.0000
79.2200 4847.0000 1.0000
79.2800 4903.0000 1.0000
79.3400 4856.0000 1.0000
79.4000 4681.0000 1.0000
79.4600 4776.0000 1.0000
79.5200 4891.0000 1.0000
79.5800 4803.0000 1.0000
79.6400 5014.0000 1.0000
79.7000 4873.0000 1.0000
79.7600 5157.0000 1.0000
79.8200 6556.0000 1.0000
79.8800 7154.0000 1.0000
79.9400 5451.0000 1.0000
80.0000 5950.0000 1.0000
80.0600 6130.0000 1.0000
80.1200 6007.0000 1.0000
80.1800 5137.0000 1.0000
80.2400 5303.0000 1.0000
80.3000 5110.0000 1.0000
80.3600 4881.0000 1.0000
80.4200 5076.0000 1.0000
80.4800 5058.0000 1.0000
80.5400 5010.0000 1.0000
80.6000 5365.0000 1.0000
80.6600 5614.0000 1.0000
80.7200 5349.0000 1.0000
80.7800 5274.0000 1.0000
80.8400 5134.0000 1.0000
80.9000 5212.0000 1.0000
80.9600 5034.0000 1.0000
81.0200 5158.0000 1.0000
81.0800 5407.0000 1.0000
81.1400 6686.0000 1.0000
81.2000 5654.0000 1.0000
81.2600 5247.0000 1.0000
81.3200 5438.0000 1.0000
81.3800 6404.0000 1.0000
81.4400 7838.0000 1.0000
81.5000 6400.0000 1.0000
81.5600 5173.0000 1.0000
81.6200 5138.0000 1.0000
81.6800 6007.0000 1.0000
81.7400 5618.0000 1.0000
81.8000 5030.0000 1.0000
81.8600 4739.0000 1.0000
81.9200 4809.0000 1.0000
81.9800 4797.0000 1.0000
82.0400 4807.0000 1.0000
82.1000 4750.0000 1.0000
82.1600 4881.0000 1.0000
82.2200 4781.0000 1.0000
82.2800 4895.0000 1.0000
82.3400 4683.0000 1.0000
82.4000 4817.0000 1.0000
82.4600 4731.0000 1.0000
82.5200 4765.0000 1.0000
82.5800 4890.0000 1.0000
82.6400 4674.0000 1.0000
82.7000 4789.0000 1.0000
82.7600 4779.0000 1.0000
82.8200 4884.0000 1.0000
82.8800 4927.0000 1.0000
82.9400 4897.0000 1.0000
83.0000 4992.0000 1.0000
83.0600 4777.0000 1.0000
83.1200 4895.0000 1.0000
83.1800 4938.0000 1.0000
83.2400 4903.0000 1.0000
83.3000 4875.0000 1.0000
83.3600 4768.0000 1.0000
83.4200 4804.0000 1.0000
83.4800 4728.0000 1.0000
83.5400 4838.0000 1.0000
83.6000 4889.0000 1.0000
83.6600 4882.0000 1.0000
83.7200 5125.0000 1.0000
83.7800 6231.0000 1.0000
83.8400 5850.0000 1.0000
83.9000 5115.0000 1.0000
83.9600 4876.0000 1.0000
84.0200 5307.0000 1.0000
84.0800 5594.0000 1.0000
84.1400 5013.0000 1.0000
84.2000 4891.0000 1.0000
84.2600 4983.0000 1.0000
84.3200 5144.0000 1.0000
84.3800 4985.0000 1.0000
84.4400 4776.0000 1.0000
84.5000 4953.0000 1.0000
84.5600 4910.0000 1.0000
84.6200 4912.0000 1.0000
84.6800 4915.0000 1.0000
84.7400 4834.0000 1.0000
84.8000 4984.0000 1.0000
84.8600 5144.0000 1.0000
84.9200 5388.0000 1.0000
84.9800 5132.0000 1.0000
85.0400 4867.0000 1.0000
85.1000 5028.0000 1.0000
85.1600 5129.0000 1.0000
85.2200 5013.0000 1.0000
85.2800 4757.0000 1.0000
85.3400 4853.0000 1.0000
85.4000 4752.0000 1.0000
85.4600 4714.0000 1.0000
85.5200 4742.0000 1.0000
85.5800 4567.0000 1.0000
85.6400 4702.0000 1.0000
85.7000 4713.0000 1.0000
85.7600 4806.0000 1.0000
85.8200 4709.0000 1.0000
85.8800 4726.0000 1.0000
85.9400 4830.0000 1.0000
86.0000 4746.0000 1.0000
86.0600 4798.0000 1.0000
86.1200 4743.0000 1.0000
86.1800 4921.0000 1.0000
86.2400 5079.0000 1.0000
86.3000 5103.0000 1.0000
86.3600 5194.0000 1.0000
86.4200 5130.0000 1.0000
86.4800 5040.0000 1.0000
86.5400 5034.0000 1.0000
86.6000 4905.0000 1.0000
86.6600 5025.0000 1.0000
86.7200 5024.0000 1.0000
86.7800 4966.0000 1.0000
86.8400 4951.0000 1.0000
86.9000 5007.0000 1.0000
86.9600 4989.0000 1.0000
87.0200 4896.0000 1.0000
87.0800 4883.0000 1.0000
87.1400 4833.0000 1.0000
87.2000 4818.0000 1.0000
87.2600 4865.0000 1.0000
87.3200 4868.0000 1.0000
87.3800 5093.0000 1.0000
87.4400 5188.0000 1.0000
87.5000 4870.0000 1.0000
87.5600 4698.0000 1.0000
87.6200 4663.0000 1.0000
87.6800 4960.0000 1.0000
87.7400 4893.0000 1.0000
87.8000 4584.0000 1.0000
87.8600 4774.0000 1.0000
87.9200 4697.0000 1.0000
87.9800 4811.0000 1.0000
88.0400 4797.0000 1.0000
88.1000 4603.0000 1.0000
88.1600 4721.0000 1.0000
88.2200 4706.0000 1.0000
88.2800 4802.0000 1.0000
88.3400 4865.0000 1.0000
88.4000 4873.0000 1.0000
88.4600 4943.0000 1.0000
88.5200 5115.0000 1.0000
88.5800 5005.0000 1.0000
88.6400 4897.0000 1.0000
88.7000 5007.0000 1.0000
88.7600 5018.0000 1.0000
88.8200 5179.0000 1.0000
88.8800 5133.0000 1.0000
88.9400 5474.0000 1.0000
89.0000 5288.0000 1.0000
89.0600 5075.0000 1.0000
89.1200 5040.0000 1.0000
89.1800 4986.0000 1.0000
89.2400 5243.0000 1.0000
89.3000 4845.0000 1.0000
89.3600 4907.0000 1.0000
89.4200 4792.0000 1.0000
89.4800 4829.0000 1.0000
89.5400 4895.0000 1.0000
89.6000 4934.0000 1.0000
89.6600 5121.0000 1.0000
89.7200 5213.0000 1.0000
89.7800 5282.0000 1.0000
89.8400 5134.0000 1.0000
89.9000 5120.0000 1.0000
89.9600 5122.0000 1.0000
90.0000 5128.0000 1.0000
*RAS_INT_END
*RAS_TEMPERATURE_START
*RAS_TEMPERATURE_END
*RAS_DATA_END