File: XRD/Data/20200910_mix_07.ras
*RAS_DATA_START
*RAS_HEADER_START
*DISP_FMT_X "%.2f"
*DISP_FMT_Y "%.0f"
*DISP_FULLSCALE "39216.0000000000"
*DISP_LINE_COLOR "255.0000000000"
*DISP_LINE_STYLE "0.0000000000"
*DISP_LINE_WIDTH "0.2500000000"
*DISP_NOTE "測定データ-1"
*DISP_OFFSET_Y "0.0000000000"
*DISP_PEAKSEARCH_UNIT_Y "cps"
*DISP_RANGE_BOTTOM "0.0000000000"
*DISP_RANGE_LEFT "20.0000000000"
*DISP_RANGE_LOGCUTOFF "0.0100000000"
*DISP_RANGE_RIGHT "90.0000000000"
*DISP_RANGE_TOP "39216.0000000000"
*DISP_SCALE_MODE_Y "0.0000000000"
*DISP_TAB_NAME "2θ/θ"
*DISP_TITLE_Y "強度"
*DISP_UNIT_Y "cps"
*DISP_WINDOW_NAME "MSG_MACROENGINE"
*FILE_COMMENT " "
*FILE_MD5 ""
*FILE_MEMO " "
*FILE_OPERATOR "Administrator"
*FILE_SAMPLE " "
*FILE_TYPE "RAS_RAW"
*FILE_USERGROUP "システムマネージャ"
*FILE_VERSION "1.0000000000"
*HW_ATTACHMENT_ID "ATT0025"
*HW_ATTACHMENT_NAME "標準|Standard"
*HW_COUNTER_ID-0 "CUT0025"
*HW_COUNTER_ID-1 "CUT0020"
*HW_COUNTER_ID-2 "CUT0020"
*HW_COUNTER_ID-3 "CSL0021"
*HW_COUNTER_ID-4 "CMC0021"
*HW_COUNTER_NAME-0 "D/teX Ultra|D/teX Ultra"
*HW_COUNTER_NAME-1 "None|None"
*HW_COUNTER_NAME-2 "None|None"
*HW_COUNTER_NAME-3 "BBM|BBM"
*HW_COUNTER_NAME-4 "検出器モノクロメータ|Detector monochromator"
*HW_COUNTER_SELECT_NAME "D/teX Ultra|D/teX Ultra"
*HW_GONIOMETER_ID "GON0023"
*HW_GONIOMETER_NAME "SmartLab|SmartLab"
*HW_GONIOMETER_RADIUS-0 "90.0"
*HW_GONIOMETER_RADIUS-1 "114.0"
*HW_GONIOMETER_RADIUS-2 "190.0"
*HW_GONIOMETER_RADIUS-3 "300.0"
*HW_GONIOMETER_RADIUS-4 "187.0"
*HW_GONIOMETER_RADIUS-5 "300.0"
*HW_GONIOMETER_RADIUS-6 "113.0"
*HW_GONIOMETER_RADIUS-7 "331.0"
*HW_I_OPT_ID-0 "CBO0021"
*HW_I_OPT_ID-1 "ICR0023"
*HW_I_OPT_ID-2 "ISL0021"
*HW_I_OPT_ID-3 "ISO0021"
*HW_I_OPT_ID-4 "IAD0021"
*HW_I_OPT_ID-5 "IPR0001"
*HW_I_OPT_NAME-0 "CBOユニット|CBO unit"
*HW_I_OPT_NAME-1 "標準入射光学ユニット|Standard incident optical unit"
*HW_I_OPT_NAME-2 "標準入射スリットボックス|Standard incident slit box"
*HW_I_OPT_NAME-3 "入射平行スリット|Incident parallel slit"
*HW_I_OPT_NAME-4 "長手制限スリット|Length limiting slit"
*HW_I_OPT_NAME-5 "None|None"
*HW_R_ATTENUATER_AUTOMODE "0"
*HW_R_OPT_ID-0 "RSS0021"
*HW_R_OPT_ID-1 "RCR0023"
*HW_R_OPT_ID-2 "RSO0021"
*HW_R_OPT_ID-3 "RRS0021"
*HW_R_OPT_ID-4 "ATN0021"
*HW_R_OPT_ID-5 "RFL0021"
*HW_R_OPT_ID-6 "RAD0021"
*HW_R_OPT_NAME-0 "標準受光スリットボックス1|Standard receiving slit box # 1"
*HW_R_OPT_NAME-1 "標準受光光学ユニット1|Standard receiving unit # 1"
*HW_R_OPT_NAME-2 "標準受光光学ユニット2|Standard receiving optical unit # 2"
*HW_R_OPT_NAME-3 "標準受光スリットボックス2|Standard receiving slit box # 2"
*HW_R_OPT_NAME-4 "標準アッテネータ|Standard Attenuator"
*HW_R_OPT_NAME-5 "Cu Kβ|Cu K-beta"
*HW_R_OPT_NAME-6 "調整用受光スリット|Alignment receiving slit"
*HW_SAMPLE_HOLDER_ID "SMP0023"
*HW_SAMPLE_HOLDER_NAME "標準Zステージ|Standard Z stage"
*HW_XG_CURRENT_MAX "50"
*HW_XG_CURRENT_MIN "2"
*HW_XG_CURRENT_RESOLUTION "2"
*HW_XG_CURRENT_UNIT "mA"
*HW_XG_FOCUS "1mm x 10mm"
*HW_XG_FOCUS_TYPE "Normal"
*HW_XG_ID ""
*HW_XG_NAME "3kW 封入管(ID:1200)|3kW Sealed tube(ID:1200)"
*HW_XG_TARGET_ATOMIC_NUMBER "29.0000000000"
*HW_XG_TARGET_NAME "Cu"
*HW_XG_TYPE "Hermetic"
*HW_XG_VOLTAGE_MAX "60"
*HW_XG_VOLTAGE_MIN "20"
*HW_XG_VOLTAGE_RESOLUTION "2"
*HW_XG_VOLTAGE_UNIT "kV"
*HW_XG_WATT_MAX "2"
*HW_XG_WATT_UNIT "kW"
*HW_XG_WAVE_LENGTH_ALPHA1 "1.540593"
*HW_XG_WAVE_LENGTH_ALPHA2 "1.544414"
*HW_XG_WAVE_LENGTH_BETA "1.392250"
*MEAS_COND_AXIS_NAME-0 "2θ/θ"
*MEAS_COND_AXIS_NAME-1 "2θ"
*MEAS_COND_AXIS_NAME-2 "ω"
*MEAS_COND_AXIS_NAME-3 "Z"
*MEAS_COND_AXIS_NAME-4 "2θ/ω"
*MEAS_COND_AXIS_NAME-5 "θs"
*MEAS_COND_AXIS_NAME-6 "θd"
*MEAS_COND_AXIS_NAME-7 "Ts"
*MEAS_COND_AXIS_NAME-8 "CBO選択スリット"
*MEAS_COND_AXIS_NAME-9 "M"
*MEAS_COND_AXIS_NAME-10 "入射平行スリット"
*MEAS_COND_AXIS_NAME-11 "入射スリット"
*MEAS_COND_AXIS_NAME-12 ""
*MEAS_COND_AXIS_NAME-13 "Zs"
*MEAS_COND_AXIS_NAME-14 "入射光学素子"
*MEAS_COND_AXIS_NAME-15 "長手制限スリット"
*MEAS_COND_AXIS_NAME-16 "センタースリット"
*MEAS_COND_AXIS_NAME-17 "フィルター"
*MEAS_COND_AXIS_NAME-18 "受光スリット1"
*MEAS_COND_AXIS_NAME-19 "受光スリット2"
*MEAS_COND_AXIS_NAME-20 "受光光学素子"
*MEAS_COND_AXIS_NAME-21 "受光平行スリット"
*MEAS_COND_AXIS_NAME-22 "調整用受光スリット"
*MEAS_COND_AXIS_NAME-23 ""
*MEAS_COND_AXIS_NAME-24 ""
*MEAS_COND_AXIS_NAME-25 "Zd"
*MEAS_COND_AXIS_NAME-26 "アッテネータ"
*MEAS_COND_AXIS_NAME-27 "検出器モノクロメータ"
*MEAS_COND_AXIS_NAME-28 "モノクロメータスリット"
*MEAS_COND_AXIS_NAME-29 "プライマリビーム"
*MEAS_COND_AXIS_NAME-30 "PHA"
*MEAS_COND_AXIS_NAME_INTERNAL-0 "TwoThetaTheta"
*MEAS_COND_AXIS_NAME_INTERNAL-1 "TwoTheta"
*MEAS_COND_AXIS_NAME_INTERNAL-2 "Omega"
*MEAS_COND_AXIS_NAME_INTERNAL-3 "Z"
*MEAS_COND_AXIS_NAME_INTERNAL-4 "TwoThetaOmega"
*MEAS_COND_AXIS_NAME_INTERNAL-5 "ThetaS"
*MEAS_COND_AXIS_NAME_INTERNAL-6 "ThetaD"
*MEAS_COND_AXIS_NAME_INTERNAL-7 "Ts"
*MEAS_COND_AXIS_NAME_INTERNAL-8 "CBO"
*MEAS_COND_AXIS_NAME_INTERNAL-9 "CBO-M"
*MEAS_COND_AXIS_NAME_INTERNAL-10 "IncidentSollerSlit"
*MEAS_COND_AXIS_NAME_INTERNAL-11 "IncidentSlitBox"
*MEAS_COND_AXIS_NAME_INTERNAL-12 "IncidentSlitBox-_Axis"
*MEAS_COND_AXIS_NAME_INTERNAL-13 "Zs"
*MEAS_COND_AXIS_NAME_INTERNAL-14 "IncidentMonochromator"
*MEAS_COND_AXIS_NAME_INTERNAL-15 "IncidentAxdSlit"
*MEAS_COND_AXIS_NAME_INTERNAL-16 "CenterSlit"
*MEAS_COND_AXIS_NAME_INTERNAL-17 "Filter"
*MEAS_COND_AXIS_NAME_INTERNAL-18 "ReceivingSlitBox1"
*MEAS_COND_AXIS_NAME_INTERNAL-19 "ReceivingSlitBox2"
*MEAS_COND_AXIS_NAME_INTERNAL-20 "ReceivingOptics"
*MEAS_COND_AXIS_NAME_INTERNAL-21 "ReceivingSollerSlit"
*MEAS_COND_AXIS_NAME_INTERNAL-22 "ReceivingAxdSlit"
*MEAS_COND_AXIS_NAME_INTERNAL-23 "ReceivingSlitBox1-_Axis"
*MEAS_COND_AXIS_NAME_INTERNAL-24 "ReceivingSlitBox2-_Axis"
*MEAS_COND_AXIS_NAME_INTERNAL-25 "ReceivingSlitBox2-Zd"
*MEAS_COND_AXIS_NAME_INTERNAL-26 "Attenuator"
*MEAS_COND_AXIS_NAME_INTERNAL-27 "CounterMonochromator"
*MEAS_COND_AXIS_NAME_INTERNAL-28 "CounterSlit"
*MEAS_COND_AXIS_NAME_INTERNAL-29 "IncidentPrimary"
*MEAS_COND_AXIS_NAME_INTERNAL-30 "PHA"
*MEAS_COND_AXIS_NAME_MAGICNO-0 "83951616.0000000000"
*MEAS_COND_AXIS_NAME_MAGICNO-1 "268632064.0000000000"
*MEAS_COND_AXIS_NAME_MAGICNO-2 "268500992.0000000000"
*MEAS_COND_AXIS_NAME_MAGICNO-3 "285278208.0000000000"
*MEAS_COND_AXIS_NAME_MAGICNO-4 "83951616.0000000000"
*MEAS_COND_AXIS_NAME_MAGICNO-5 "131072.0000000000"
*MEAS_COND_AXIS_NAME_MAGICNO-6 "131072.0000000000"
*MEAS_COND_AXIS_NAME_MAGICNO-7 "318898176.0000000000"
*MEAS_COND_AXIS_NAME_MAGICNO-8 "20971521.0000000000"
*MEAS_COND_AXIS_NAME_MAGICNO-9 "285343744.0000000000"
*MEAS_COND_AXIS_NAME_MAGICNO-10 "20971521.0000000000"
*MEAS_COND_AXIS_NAME_MAGICNO-11 "22020097.0000000000"
*MEAS_COND_AXIS_NAME_MAGICNO-12 "25165824.0000000000"
*MEAS_COND_AXIS_NAME_MAGICNO-13 "318898176.0000000000"
*MEAS_COND_AXIS_NAME_MAGICNO-14 "1.0000000000"
*MEAS_COND_AXIS_NAME_MAGICNO-15 "20971521.0000000000"
*MEAS_COND_AXIS_NAME_MAGICNO-16 "20971521.0000000000"
*MEAS_COND_AXIS_NAME_MAGICNO-17 "20971521.0000000000"
*MEAS_COND_AXIS_NAME_MAGICNO-18 "23068673.0000000000"
*MEAS_COND_AXIS_NAME_MAGICNO-19 "23068673.0000000000"
*MEAS_COND_AXIS_NAME_MAGICNO-20 "20971521.0000000000"
*MEAS_COND_AXIS_NAME_MAGICNO-21 "20971521.0000000000"
*MEAS_COND_AXIS_NAME_MAGICNO-22 "20971521.0000000000"
*MEAS_COND_AXIS_NAME_MAGICNO-23 "25165824.0000000000"
*MEAS_COND_AXIS_NAME_MAGICNO-24 "25165824.0000000000"
*MEAS_COND_AXIS_NAME_MAGICNO-25 "285343744.0000000000"
*MEAS_COND_AXIS_NAME_MAGICNO-26 "17301505.0000000000"
*MEAS_COND_AXIS_NAME_MAGICNO-27 "20971521.0000000000"
*MEAS_COND_AXIS_NAME_MAGICNO-28 "20971521.0000000000"
*MEAS_COND_AXIS_NAME_MAGICNO-29 "20971521.0000000000"
*MEAS_COND_AXIS_NAME_MAGICNO-30 "0.0000000000"
*MEAS_COND_AXIS_OFFSET-0 "-"
*MEAS_COND_AXIS_OFFSET-1 "-0.1081000000"
*MEAS_COND_AXIS_OFFSET-2 "0.3758000000"
*MEAS_COND_AXIS_OFFSET-3 "-"
*MEAS_COND_AXIS_OFFSET-4 "-"
*MEAS_COND_AXIS_OFFSET-5 "0.3758000000"
*MEAS_COND_AXIS_OFFSET-6 "-0.4839000000"
*MEAS_COND_AXIS_OFFSET-7 "-"
*MEAS_COND_AXIS_OFFSET-8 "-"
*MEAS_COND_AXIS_OFFSET-9 "-"
*MEAS_COND_AXIS_OFFSET-10 "-"
*MEAS_COND_AXIS_OFFSET-11 "-"
*MEAS_COND_AXIS_OFFSET-12 "-"
*MEAS_COND_AXIS_OFFSET-13 "-"
*MEAS_COND_AXIS_OFFSET-14 "-"
*MEAS_COND_AXIS_OFFSET-15 "-"
*MEAS_COND_AXIS_OFFSET-16 "-"
*MEAS_COND_AXIS_OFFSET-17 "-"
*MEAS_COND_AXIS_OFFSET-18 "-"
*MEAS_COND_AXIS_OFFSET-19 "-"
*MEAS_COND_AXIS_OFFSET-20 "-"
*MEAS_COND_AXIS_OFFSET-21 "-"
*MEAS_COND_AXIS_OFFSET-22 "-"
*MEAS_COND_AXIS_OFFSET-23 "-"
*MEAS_COND_AXIS_OFFSET-24 "-"
*MEAS_COND_AXIS_OFFSET-25 "-"
*MEAS_COND_AXIS_OFFSET-26 "-"
*MEAS_COND_AXIS_OFFSET-27 "-"
*MEAS_COND_AXIS_OFFSET-28 "-"
*MEAS_COND_AXIS_OFFSET-29 "-"
*MEAS_COND_AXIS_OFFSET-30 "-"
*MEAS_COND_AXIS_POSITION-0 "0.0000000000"
*MEAS_COND_AXIS_POSITION-1 "0.0000000000"
*MEAS_COND_AXIS_POSITION-2 "0.0000000000"
*MEAS_COND_AXIS_POSITION-3 "-0.5500000000"
*MEAS_COND_AXIS_POSITION-4 "0.0000000000"
*MEAS_COND_AXIS_POSITION-5 "0.0000000000"
*MEAS_COND_AXIS_POSITION-6 "0.0000000000"
*MEAS_COND_AXIS_POSITION-7 "-0.4278800000"
*MEAS_COND_AXIS_POSITION-8 "BB"
*MEAS_COND_AXIS_POSITION-9 "0.0000000000"
*MEAS_COND_AXIS_POSITION-10 "Soller_slit_5.0deg"
*MEAS_COND_AXIS_POSITION-11 "2/3deg"
*MEAS_COND_AXIS_POSITION-12 "2.2088000000"
*MEAS_COND_AXIS_POSITION-13 "-0.4140600000"
*MEAS_COND_AXIS_POSITION-14 "0.0000000000"
*MEAS_COND_AXIS_POSITION-15 "10.0mm"
*MEAS_COND_AXIS_POSITION-16 "None"
*MEAS_COND_AXIS_POSITION-17 "Cu_K-beta"
*MEAS_COND_AXIS_POSITION-18 "13.000mm"
*MEAS_COND_AXIS_POSITION-19 "13.000mm"
*MEAS_COND_AXIS_POSITION-20 "No_unit"
*MEAS_COND_AXIS_POSITION-21 "Soller_slit_5.0deg"
*MEAS_COND_AXIS_POSITION-22 "None"
*MEAS_COND_AXIS_POSITION-23 "13.0000000000"
*MEAS_COND_AXIS_POSITION-24 "13.0000000000"
*MEAS_COND_AXIS_POSITION-25 "0.0109400000"
*MEAS_COND_AXIS_POSITION-26 "Open"
*MEAS_COND_AXIS_POSITION-27 "None"
*MEAS_COND_AXIS_POSITION-28 "None"
*MEAS_COND_AXIS_POSITION-29 "None"
*MEAS_COND_AXIS_POSITION-30 "38.0000000000"
*MEAS_COND_AXIS_UNIT-0 "deg"
*MEAS_COND_AXIS_UNIT-1 "deg"
*MEAS_COND_AXIS_UNIT-2 "deg"
*MEAS_COND_AXIS_UNIT-3 "mm"
*MEAS_COND_AXIS_UNIT-4 "deg"
*MEAS_COND_AXIS_UNIT-5 "deg"
*MEAS_COND_AXIS_UNIT-6 "deg"
*MEAS_COND_AXIS_UNIT-7 "mm"
*MEAS_COND_AXIS_UNIT-8 ""
*MEAS_COND_AXIS_UNIT-9 "pulse"
*MEAS_COND_AXIS_UNIT-10 ""
*MEAS_COND_AXIS_UNIT-11 ""
*MEAS_COND_AXIS_UNIT-12 "mm"
*MEAS_COND_AXIS_UNIT-13 "mm"
*MEAS_COND_AXIS_UNIT-14 ""
*MEAS_COND_AXIS_UNIT-15 ""
*MEAS_COND_AXIS_UNIT-16 ""
*MEAS_COND_AXIS_UNIT-17 ""
*MEAS_COND_AXIS_UNIT-18 ""
*MEAS_COND_AXIS_UNIT-19 ""
*MEAS_COND_AXIS_UNIT-20 ""
*MEAS_COND_AXIS_UNIT-21 ""
*MEAS_COND_AXIS_UNIT-22 ""
*MEAS_COND_AXIS_UNIT-23 "mm"
*MEAS_COND_AXIS_UNIT-24 "mm"
*MEAS_COND_AXIS_UNIT-25 "mm"
*MEAS_COND_AXIS_UNIT-26 ""
*MEAS_COND_AXIS_UNIT-27 ""
*MEAS_COND_AXIS_UNIT-28 ""
*MEAS_COND_AXIS_UNIT-29 ""
*MEAS_COND_AXIS_UNIT-30 "div"
*MEAS_COND_COUNTER_CNTLOSS_CORR "0.0000000000"
*MEAS_COND_COUNTER_PHABASE "38.0000000000"
*MEAS_COND_COUNTER_PHAWINDOW "16.0000000000"
*MEAS_COND_COUNTER_PHA_UNIT "div"
*MEAS_COND_COUNTER_TAUDIFF "30.0000000000"
*MEAS_COND_COUNTER_TAUINT "0.0000000000"
*MEAS_COND_IRRADIATION_MODE "OFF"
*MEAS_COND_IRRADIATION_WIDTH ""
*MEAS_COND_OPT_ATTR "集中法"
*MEAS_COND_OPT_NAME "@集中法"
*MEAS_COND_UNSYMMETRIC_MODE "OFF"
*MEAS_COND_XG_CURRENT "30.0000000000"
*MEAS_COND_XG_VOLTAGE "40.0000000000"
*MEAS_COND_XG_WAVE_TYPE "Ka"
*MEAS_DATA_COUNT "3501.0000000000"
*MEAS_SCAN_AXIS_X "2θ/θ"
*MEAS_SCAN_AXIS_X_INTERNAL "TwoThetaTheta"
*MEAS_SCAN_END_TIME "09/10/20 13:41:49"
*MEAS_SCAN_MODE "CONTINUOUS"
*MEAS_SCAN_MONITOR "0"
*MEAS_SCAN_RESOLUTION_X "0.0002"
*MEAS_SCAN_SPEED "1.0"
*MEAS_SCAN_SPEED_UNIT "deg/min"
*MEAS_SCAN_START "20.0000000000"
*MEAS_SCAN_START_TIME "09/10/20 12:28:54"
*MEAS_SCAN_STEP "0.0200000000"
*MEAS_SCAN_STOP "90.0000000000"
*MEAS_SCAN_UNIT_X "deg"
*MEAS_SCAN_UNIT_Y "counts"
*RAS_HEADER_END
*RAS_INT_START
20.0000 11115.0000 1.0000
20.0600 11279.0000 1.0000
20.1200 11252.0000 1.0000
20.1800 11087.0000 1.0000
20.2400 11044.0000 1.0000
20.3000 11326.0000 1.0000
20.3600 11115.0000 1.0000
20.4200 10976.0000 1.0000
20.4800 11170.0000 1.0000
20.5400 11053.0000 1.0000
20.6000 11462.0000 1.0000
20.6600 11807.0000 1.0000
20.7200 11963.0000 1.0000
20.7800 12838.0000 1.0000
20.8400 15057.0000 1.0000
20.9000 14444.0000 1.0000
20.9600 11907.0000 1.0000
21.0200 11244.0000 1.0000
21.0800 11313.0000 1.0000
21.1400 11037.0000 1.0000
21.2000 10884.0000 1.0000
21.2600 11271.0000 1.0000
21.3200 10971.0000 1.0000
21.3800 11110.0000 1.0000
21.4400 11128.0000 1.0000
21.5000 10885.0000 1.0000
21.5600 11066.0000 1.0000
21.6200 10926.0000 1.0000
21.6800 10953.0000 1.0000
21.7400 10916.0000 1.0000
21.8000 11007.0000 1.0000
21.8600 10886.0000 1.0000
21.9200 10725.0000 1.0000
21.9800 10749.0000 1.0000
22.0400 10713.0000 1.0000
22.1000 10859.0000 1.0000
22.1600 10779.0000 1.0000
22.2200 10729.0000 1.0000
22.2800 10798.0000 1.0000
22.3400 10804.0000 1.0000
22.4000 10783.0000 1.0000
22.4600 10672.0000 1.0000
22.5200 10646.0000 1.0000
22.5800 10762.0000 1.0000
22.6400 10853.0000 1.0000
22.7000 10758.0000 1.0000
22.7600 10768.0000 1.0000
22.8200 10774.0000 1.0000
22.8800 10711.0000 1.0000
22.9400 10694.0000 1.0000
23.0000 10448.0000 1.0000
23.0600 10720.0000 1.0000
23.1200 10772.0000 1.0000
23.1800 10719.0000 1.0000
23.2400 10599.0000 1.0000
23.3000 10680.0000 1.0000
23.3600 10711.0000 1.0000
23.4200 10643.0000 1.0000
23.4800 10782.0000 1.0000
23.5400 10649.0000 1.0000
23.6000 10742.0000 1.0000
23.6600 10647.0000 1.0000
23.7200 10577.0000 1.0000
23.7800 10646.0000 1.0000
23.8400 10962.0000 1.0000
23.9000 10823.0000 1.0000
23.9600 11090.0000 1.0000
24.0200 11454.0000 1.0000
24.0800 12243.0000 1.0000
24.1400 13879.0000 1.0000
24.2000 13639.0000 1.0000
24.2600 11784.0000 1.0000
24.3200 10802.0000 1.0000
24.3800 10714.0000 1.0000
24.4400 10519.0000 1.0000
24.5000 10615.0000 1.0000
24.5600 10605.0000 1.0000
24.6200 10346.0000 1.0000
24.6800 10508.0000 1.0000
24.7400 10536.0000 1.0000
24.8000 10539.0000 1.0000
24.8600 10498.0000 1.0000
24.9200 10621.0000 1.0000
24.9800 10570.0000 1.0000
25.0400 10529.0000 1.0000
25.1000 10383.0000 1.0000
25.1600 10577.0000 1.0000
25.2200 10388.0000 1.0000
25.2800 10309.0000 1.0000
25.3400 10525.0000 1.0000
25.4000 10836.0000 1.0000
25.4600 10831.0000 1.0000
25.5200 11339.0000 1.0000
25.5800 12274.0000 1.0000
25.6400 11612.0000 1.0000
25.7000 10620.0000 1.0000
25.7600 10657.0000 1.0000
25.8200 10483.0000 1.0000
25.8800 10504.0000 1.0000
25.9400 10558.0000 1.0000
26.0000 10575.0000 1.0000
26.0600 10551.0000 1.0000
26.1200 10545.0000 1.0000
26.1800 10468.0000 1.0000
26.2400 10448.0000 1.0000
26.3000 10684.0000 1.0000
26.3600 10857.0000 1.0000
26.4200 11817.0000 1.0000
26.4800 12635.0000 1.0000
26.5400 15097.0000 1.0000
26.6000 22917.0000 1.0000
26.6600 39216.0000 1.0000
26.7200 25753.0000 1.0000
26.7800 12969.0000 1.0000
26.8400 11495.0000 1.0000
26.9000 10789.0000 1.0000
26.9600 10342.0000 1.0000
27.0200 10326.0000 1.0000
27.0800 10441.0000 1.0000
27.1400 10462.0000 1.0000
27.2000 10370.0000 1.0000
27.2600 10359.0000 1.0000
27.3200 10359.0000 1.0000
27.3800 10275.0000 1.0000
27.4400 10249.0000 1.0000
27.5000 10229.0000 1.0000
27.5600 10448.0000 1.0000
27.6200 10228.0000 1.0000
27.6800 10177.0000 1.0000
27.7400 10403.0000 1.0000
27.8000 10062.0000 1.0000
27.8600 10199.0000 1.0000
27.9200 10322.0000 1.0000
27.9800 10208.0000 1.0000
28.0400 10181.0000 1.0000
28.1000 10178.0000 1.0000
28.1600 10143.0000 1.0000
28.2200 10070.0000 1.0000
28.2800 10213.0000 1.0000
28.3400 10088.0000 1.0000
28.4000 10075.0000 1.0000
28.4600 10055.0000 1.0000
28.5200 10059.0000 1.0000
28.5800 9919.0000 1.0000
28.6400 10199.0000 1.0000
28.7000 10184.0000 1.0000
28.7600 10131.0000 1.0000
28.8200 10183.0000 1.0000
28.8800 10151.0000 1.0000
28.9400 10146.0000 1.0000
29.0000 10330.0000 1.0000
29.0600 10138.0000 1.0000
29.1200 10145.0000 1.0000
29.1800 10321.0000 1.0000
29.2400 10206.0000 1.0000
29.3000 10085.0000 1.0000
29.3600 10064.0000 1.0000
29.4200 10193.0000 1.0000
29.4800 10150.0000 1.0000
29.5400 9833.0000 1.0000
29.6000 10114.0000 1.0000
29.6600 10135.0000 1.0000
29.7200 10244.0000 1.0000
29.7800 10129.0000 1.0000
29.8400 10175.0000 1.0000
29.9000 10420.0000 1.0000
29.9600 10512.0000 1.0000
30.0200 10826.0000 1.0000
30.0800 11622.0000 1.0000
30.1400 12497.0000 1.0000
30.2000 12007.0000 1.0000
30.2600 11081.0000 1.0000
30.3200 10465.0000 1.0000
30.3800 10256.0000 1.0000
30.4400 10281.0000 1.0000
30.5000 10158.0000 1.0000
30.5600 9982.0000 1.0000
30.6200 9966.0000 1.0000
30.6800 10018.0000 1.0000
30.7400 10184.0000 1.0000
30.8000 9911.0000 1.0000
30.8600 10152.0000 1.0000
30.9200 9968.0000 1.0000
30.9800 10041.0000 1.0000
31.0400 9953.0000 1.0000
31.1000 10045.0000 1.0000
31.1600 9906.0000 1.0000
31.2200 10023.0000 1.0000
31.2800 9906.0000 1.0000
31.3400 9999.0000 1.0000
31.4000 10076.0000 1.0000
31.4600 9984.0000 1.0000
31.5200 9952.0000 1.0000
31.5800 9802.0000 1.0000
31.6400 10107.0000 1.0000
31.7000 10023.0000 1.0000
31.7600 10112.0000 1.0000
31.8200 9957.0000 1.0000
31.8800 10016.0000 1.0000
31.9400 10062.0000 1.0000
32.0000 10103.0000 1.0000
32.0600 10029.0000 1.0000
32.1200 10094.0000 1.0000
32.1800 10042.0000 1.0000
32.2400 10183.0000 1.0000
32.3000 10067.0000 1.0000
32.3600 9851.0000 1.0000
32.4200 9842.0000 1.0000
32.4800 10093.0000 1.0000
32.5400 10074.0000 1.0000
32.6000 9931.0000 1.0000
32.6600 9973.0000 1.0000
32.7200 10173.0000 1.0000
32.7800 10282.0000 1.0000
32.8400 10252.0000 1.0000
32.9000 10625.0000 1.0000
32.9600 11111.0000 1.0000
33.0200 11941.0000 1.0000
33.0800 14401.0000 1.0000
33.1400 19331.0000 1.0000
33.2000 20308.0000 1.0000
33.2600 16961.0000 1.0000
33.3200 12784.0000 1.0000
33.3800 11207.0000 1.0000
33.4400 10563.0000 1.0000
33.5000 10160.0000 1.0000
33.5600 9960.0000 1.0000
33.6200 9993.0000 1.0000
33.6800 10042.0000 1.0000
33.7400 9954.0000 1.0000
33.8000 9990.0000 1.0000
33.8600 9787.0000 1.0000
33.9200 10055.0000 1.0000
33.9800 10066.0000 1.0000
34.0400 9782.0000 1.0000
34.1000 9858.0000 1.0000
34.1600 9771.0000 1.0000
34.2200 9762.0000 1.0000
34.2800 9780.0000 1.0000
34.3400 9798.0000 1.0000
34.4000 10065.0000 1.0000
34.4600 9863.0000 1.0000
34.5200 10098.0000 1.0000
34.5800 9778.0000 1.0000
34.6400 10185.0000 1.0000
34.7000 9913.0000 1.0000
34.7600 10182.0000 1.0000
34.8200 10191.0000 1.0000
34.8800 10037.0000 1.0000
34.9400 10337.0000 1.0000
35.0000 10539.0000 1.0000
35.0600 10793.0000 1.0000
35.1200 11831.0000 1.0000
35.1800 12614.0000 1.0000
35.2400 11930.0000 1.0000
35.3000 11765.0000 1.0000
35.3600 12143.0000 1.0000
35.4200 14576.0000 1.0000
35.4800 18973.0000 1.0000
35.5400 19465.0000 1.0000
35.6000 20821.0000 1.0000
35.6600 20276.0000 1.0000
35.7200 16338.0000 1.0000
35.7800 13344.0000 1.0000
35.8400 11193.0000 1.0000
35.9000 10624.0000 1.0000
35.9600 10188.0000 1.0000
36.0200 10102.0000 1.0000
36.0800 10093.0000 1.0000
36.1400 10096.0000 1.0000
36.2000 9999.0000 1.0000
36.2600 9947.0000 1.0000
36.3200 9945.0000 1.0000
36.3800 10056.0000 1.0000
36.4400 9963.0000 1.0000
36.5000 10325.0000 1.0000
36.5600 11631.0000 1.0000
36.6200 10622.0000 1.0000
36.6800 10401.0000 1.0000
36.7400 9875.0000 1.0000
36.8000 9834.0000 1.0000
36.8600 10018.0000 1.0000
36.9200 9788.0000 1.0000
36.9800 9890.0000 1.0000
37.0400 10138.0000 1.0000
37.1000 10262.0000 1.0000
37.1600 10292.0000 1.0000
37.2200 10117.0000 1.0000
37.2800 9972.0000 1.0000
37.3400 9890.0000 1.0000
37.4000 9854.0000 1.0000
37.4600 9928.0000 1.0000
37.5200 9936.0000 1.0000
37.5800 9961.0000 1.0000
37.6400 10073.0000 1.0000
37.7000 10283.0000 1.0000
37.7600 10685.0000 1.0000
37.8200 10829.0000 1.0000
37.8800 10467.0000 1.0000
37.9400 9985.0000 1.0000
38.0000 9937.0000 1.0000
38.0600 9724.0000 1.0000
38.1200 9976.0000 1.0000
38.1800 9860.0000 1.0000
38.2400 9757.0000 1.0000
38.3000 9932.0000 1.0000
38.3600 9755.0000 1.0000
38.4200 9753.0000 1.0000
38.4800 9775.0000 1.0000
38.5400 9739.0000 1.0000
38.6000 9789.0000 1.0000
38.6600 9787.0000 1.0000
38.7200 9667.0000 1.0000
38.7800 9894.0000 1.0000
38.8400 9727.0000 1.0000
38.9000 9812.0000 1.0000
38.9600 9931.0000 1.0000
39.0200 9838.0000 1.0000
39.0800 9631.0000 1.0000
39.1400 9737.0000 1.0000
39.2000 9748.0000 1.0000
39.2600 9910.0000 1.0000
39.3200 10130.0000 1.0000
39.3800 10263.0000 1.0000
39.4400 10934.0000 1.0000
39.5000 10831.0000 1.0000
39.5600 10516.0000 1.0000
39.6200 10213.0000 1.0000
39.6800 9877.0000 1.0000
39.7400 9993.0000 1.0000
39.8000 9925.0000 1.0000
39.8600 9814.0000 1.0000
39.9200 9838.0000 1.0000
39.9800 9688.0000 1.0000
40.0400 9814.0000 1.0000
40.1000 9659.0000 1.0000
40.1600 9872.0000 1.0000
40.2200 9968.0000 1.0000
40.2800 10502.0000 1.0000
40.3400 10430.0000 1.0000
40.4000 10175.0000 1.0000
40.4600 9956.0000 1.0000
40.5200 9827.0000 1.0000
40.5800 9806.0000 1.0000
40.6400 9826.0000 1.0000
40.7000 10286.0000 1.0000
40.7600 10442.0000 1.0000
40.8200 11269.0000 1.0000
40.8800 12261.0000 1.0000
40.9400 11283.0000 1.0000
41.0000 11142.0000 1.0000
41.0600 10304.0000 1.0000
41.1200 9956.0000 1.0000
41.1800 9756.0000 1.0000
41.2400 9557.0000 1.0000
41.3000 9762.0000 1.0000
41.3600 9746.0000 1.0000
41.4200 9655.0000 1.0000
41.4800 9670.0000 1.0000
41.5400 9730.0000 1.0000
41.6000 9724.0000 1.0000
41.6600 9847.0000 1.0000
41.7200 9786.0000 1.0000
41.7800 9614.0000 1.0000
41.8400 9841.0000 1.0000
41.9000 9755.0000 1.0000
41.9600 9842.0000 1.0000
42.0200 9723.0000 1.0000
42.0800 9799.0000 1.0000
42.1400 9865.0000 1.0000
42.2000 9690.0000 1.0000
42.2600 10001.0000 1.0000
42.3200 9804.0000 1.0000
42.3800 10267.0000 1.0000
42.4400 10638.0000 1.0000
42.5000 10270.0000 1.0000
42.5600 10157.0000 1.0000
42.6200 9905.0000 1.0000
42.6800 9709.0000 1.0000
42.7400 9940.0000 1.0000
42.8000 9778.0000 1.0000
42.8600 9778.0000 1.0000
42.9200 9781.0000 1.0000
42.9800 10154.0000 1.0000
43.0400 10510.0000 1.0000
43.1000 11116.0000 1.0000
43.1600 11702.0000 1.0000
43.2200 11598.0000 1.0000
43.2800 11950.0000 1.0000
43.3400 12704.0000 1.0000
43.4000 12092.0000 1.0000
43.4600 11361.0000 1.0000
43.5200 10924.0000 1.0000
43.5800 10350.0000 1.0000
43.6400 10016.0000 1.0000
43.7000 9914.0000 1.0000
43.7600 9713.0000 1.0000
43.8200 9705.0000 1.0000
43.8800 9706.0000 1.0000
43.9400 9914.0000 1.0000
44.0000 9824.0000 1.0000
44.0600 9647.0000 1.0000
44.1200 9443.0000 1.0000
44.1800 9758.0000 1.0000
44.2400 9626.0000 1.0000
44.3000 9623.0000 1.0000
44.3600 9704.0000 1.0000
44.4200 9753.0000 1.0000
44.4800 9708.0000 1.0000
44.5400 9672.0000 1.0000
44.6000 9780.0000 1.0000
44.6600 9763.0000 1.0000
44.7200 9747.0000 1.0000
44.7800 9664.0000 1.0000
44.8400 9616.0000 1.0000
44.9000 9745.0000 1.0000
44.9600 9610.0000 1.0000
45.0200 9631.0000 1.0000
45.0800 9785.0000 1.0000
45.1400 9638.0000 1.0000
45.2000 9595.0000 1.0000
45.2600 9651.0000 1.0000
45.3200 9563.0000 1.0000
45.3800 9680.0000 1.0000
45.4400 9762.0000 1.0000
45.5000 9672.0000 1.0000
45.5600 9729.0000 1.0000
45.6200 9761.0000 1.0000
45.6800 9743.0000 1.0000
45.7400 10115.0000 1.0000
45.8000 10498.0000 1.0000
45.8600 10128.0000 1.0000
45.9200 10183.0000 1.0000
45.9800 9949.0000 1.0000
46.0400 9695.0000 1.0000
46.1000 9685.0000 1.0000
46.1600 9689.0000 1.0000
46.2200 9652.0000 1.0000
46.2800 9589.0000 1.0000
46.3400 9562.0000 1.0000
46.4000 9697.0000 1.0000
46.4600 9632.0000 1.0000
46.5200 9620.0000 1.0000
46.5800 9719.0000 1.0000
46.6400 9521.0000 1.0000
46.7000 9686.0000 1.0000
46.7600 9867.0000 1.0000
46.8200 9415.0000 1.0000
46.8800 9554.0000 1.0000
46.9400 9665.0000 1.0000
47.0000 9653.0000 1.0000
47.0600 9783.0000 1.0000
47.1200 9573.0000 1.0000
47.1800 9724.0000 1.0000
47.2400 9748.0000 1.0000
47.3000 9832.0000 1.0000
47.3600 9602.0000 1.0000
47.4200 9669.0000 1.0000
47.4800 9774.0000 1.0000
47.5400 9719.0000 1.0000
47.6000 9547.0000 1.0000
47.6600 9623.0000 1.0000
47.7200 9723.0000 1.0000
47.7800 9565.0000 1.0000
47.8400 9618.0000 1.0000
47.9000 9573.0000 1.0000
47.9600 9617.0000 1.0000
48.0200 9682.0000 1.0000
48.0800 9454.0000 1.0000
48.1400 9792.0000 1.0000
48.2000 9802.0000 1.0000
48.2600 9767.0000 1.0000
48.3200 9808.0000 1.0000
48.3800 9701.0000 1.0000
48.4400 9674.0000 1.0000
48.5000 9740.0000 1.0000
48.5600 9774.0000 1.0000
48.6200 9629.0000 1.0000
48.6800 9593.0000 1.0000
48.7400 9642.0000 1.0000
48.8000 9663.0000 1.0000
48.8600 9668.0000 1.0000
48.9200 9788.0000 1.0000
48.9800 9654.0000 1.0000
49.0400 9639.0000 1.0000
49.1000 9958.0000 1.0000
49.1600 9803.0000 1.0000
49.2200 10059.0000 1.0000
49.2800 10250.0000 1.0000
49.3400 10683.0000 1.0000
49.4000 11568.0000 1.0000
49.4600 13580.0000 1.0000
49.5200 12643.0000 1.0000
49.5800 12140.0000 1.0000
49.6400 11300.0000 1.0000
49.7000 10199.0000 1.0000
49.7600 10216.0000 1.0000
49.8200 9812.0000 1.0000
49.8800 10189.0000 1.0000
49.9400 9930.0000 1.0000
50.0000 10003.0000 1.0000
50.0600 10209.0000 1.0000
50.1200 12309.0000 1.0000
50.1800 11707.0000 1.0000
50.2400 10628.0000 1.0000
50.3000 11178.0000 1.0000
50.3600 9885.0000 1.0000
50.4200 9770.0000 1.0000
50.4800 9730.0000 1.0000
50.5400 9732.0000 1.0000
50.6000 9770.0000 1.0000
50.6600 9752.0000 1.0000
50.7200 9752.0000 1.0000
50.7800 9651.0000 1.0000
50.8400 9791.0000 1.0000
50.9000 9796.0000 1.0000
50.9600 9757.0000 1.0000
51.0200 9700.0000 1.0000
51.0800 9574.0000 1.0000
51.1400 9834.0000 1.0000
51.2000 9690.0000 1.0000
51.2600 9857.0000 1.0000
51.3200 9593.0000 1.0000
51.3800 9422.0000 1.0000
51.4400 9594.0000 1.0000
51.5000 9747.0000 1.0000
51.5600 9571.0000 1.0000
51.6200 9654.0000 1.0000
51.6800 9611.0000 1.0000
51.7400 9558.0000 1.0000
51.8000 9576.0000 1.0000
51.8600 9710.0000 1.0000
51.9200 9712.0000 1.0000
51.9800 9597.0000 1.0000
52.0400 9775.0000 1.0000
52.1000 9754.0000 1.0000
52.1600 9748.0000 1.0000
52.2200 9745.0000 1.0000
52.2800 9988.0000 1.0000
52.3400 9915.0000 1.0000
52.4000 9977.0000 1.0000
52.4600 10213.0000 1.0000
52.5200 10889.0000 1.0000
52.5800 10824.0000 1.0000
52.6400 10318.0000 1.0000
52.7000 10424.0000 1.0000
52.7600 10042.0000 1.0000
52.8200 9762.0000 1.0000
52.8800 9731.0000 1.0000
52.9400 9721.0000 1.0000
53.0000 9763.0000 1.0000
53.0600 9763.0000 1.0000
53.1200 9760.0000 1.0000
53.1800 9779.0000 1.0000
53.2400 9678.0000 1.0000
53.3000 9634.0000 1.0000
53.3600 10022.0000 1.0000
53.4200 10020.0000 1.0000
53.4800 10285.0000 1.0000
53.5400 10623.0000 1.0000
53.6000 10274.0000 1.0000
53.6600 10259.0000 1.0000
53.7200 10051.0000 1.0000
53.7800 10112.0000 1.0000
53.8400 10110.0000 1.0000
53.9000 10430.0000 1.0000
53.9600 11049.0000 1.0000
54.0200 12667.0000 1.0000
54.0800 14668.0000 1.0000
54.1400 12601.0000 1.0000
54.2000 12516.0000 1.0000
54.2600 11691.0000 1.0000
54.3200 10534.0000 1.0000
54.3800 10137.0000 1.0000
54.4400 9906.0000 1.0000
54.5000 9706.0000 1.0000
54.5600 9813.0000 1.0000
54.6200 9815.0000 1.0000
54.6800 9908.0000 1.0000
54.7400 9890.0000 1.0000
54.8000 9945.0000 1.0000
54.8600 11214.0000 1.0000
54.9200 10699.0000 1.0000
54.9800 10080.0000 1.0000
55.0400 10638.0000 1.0000
55.1000 9913.0000 1.0000
55.1600 9751.0000 1.0000
55.2200 9756.0000 1.0000
55.2800 9875.0000 1.0000
55.3400 10705.0000 1.0000
55.4000 9908.0000 1.0000
55.4600 10013.0000 1.0000
55.5200 9864.0000 1.0000
55.5800 9769.0000 1.0000
55.6400 9756.0000 1.0000
55.7000 9787.0000 1.0000
55.7600 9625.0000 1.0000
55.8200 9807.0000 1.0000
55.8800 9743.0000 1.0000
55.9400 9707.0000 1.0000
56.0000 9892.0000 1.0000
56.0600 9839.0000 1.0000
56.1200 9735.0000 1.0000
56.1800 9914.0000 1.0000
56.2400 9716.0000 1.0000
56.3000 9819.0000 1.0000
56.3600 9640.0000 1.0000
56.4200 9877.0000 1.0000
56.4800 9883.0000 1.0000
56.5400 9821.0000 1.0000
56.6000 9665.0000 1.0000
56.6600 9925.0000 1.0000
56.7200 9848.0000 1.0000
56.7800 9758.0000 1.0000
56.8400 10019.0000 1.0000
56.9000 10279.0000 1.0000
56.9600 11042.0000 1.0000
57.0200 11679.0000 1.0000
57.0800 11614.0000 1.0000
57.1400 11653.0000 1.0000
57.2000 11374.0000 1.0000
57.2600 11139.0000 1.0000
57.3200 10764.0000 1.0000
57.3800 10951.0000 1.0000
57.4400 11856.0000 1.0000
57.5000 12570.0000 1.0000
57.5600 12041.0000 1.0000
57.6200 12079.0000 1.0000
57.6800 11479.0000 1.0000
57.7400 10799.0000 1.0000
57.8000 10465.0000 1.0000
57.8600 10000.0000 1.0000
57.9200 10073.0000 1.0000
57.9800 9990.0000 1.0000
58.0400 9802.0000 1.0000
58.1000 9804.0000 1.0000
58.1600 9814.0000 1.0000
58.2200 9735.0000 1.0000
58.2800 9848.0000 1.0000
58.3400 9750.0000 1.0000
58.4000 9757.0000 1.0000
58.4600 9491.0000 1.0000
58.5200 9810.0000 1.0000
58.5800 9832.0000 1.0000
58.6400 9632.0000 1.0000
58.7000 9712.0000 1.0000
58.7600 9815.0000 1.0000
58.8200 9615.0000 1.0000
58.8800 9771.0000 1.0000
58.9400 9642.0000 1.0000
59.0000 9635.0000 1.0000
59.0600 9842.0000 1.0000
59.1200 9724.0000 1.0000
59.1800 9829.0000 1.0000
59.2400 9770.0000 1.0000
59.3000 9773.0000 1.0000
59.3600 9726.0000 1.0000
59.4200 9637.0000 1.0000
59.4800 9884.0000 1.0000
59.5400 9720.0000 1.0000
59.6000 9635.0000 1.0000
59.6600 9876.0000 1.0000
59.7200 9762.0000 1.0000
59.7800 9858.0000 1.0000
59.8400 9796.0000 1.0000
59.9000 10468.0000 1.0000
59.9600 12019.0000 1.0000
60.0200 10378.0000 1.0000
60.0800 10713.0000 1.0000
60.1400 10947.0000 1.0000
60.2000 9986.0000 1.0000
60.2600 9907.0000 1.0000
60.3200 9856.0000 1.0000
60.3800 9838.0000 1.0000
60.4400 9813.0000 1.0000
60.5000 9782.0000 1.0000
60.5600 9841.0000 1.0000
60.6200 9749.0000 1.0000
60.6800 9775.0000 1.0000
60.7400 9791.0000 1.0000
60.8000 9992.0000 1.0000
60.8600 9752.0000 1.0000
60.9200 9649.0000 1.0000
60.9800 10021.0000 1.0000
61.0400 9788.0000 1.0000
61.1000 9835.0000 1.0000
61.1600 9845.0000 1.0000
61.2200 9885.0000 1.0000
61.2800 9926.0000 1.0000
61.3400 10006.0000 1.0000
61.4000 9959.0000 1.0000
61.4600 9806.0000 1.0000
61.5200 9891.0000 1.0000
61.5800 9858.0000 1.0000
61.6400 9787.0000 1.0000
61.7000 9794.0000 1.0000
61.7600 9880.0000 1.0000
61.8200 9834.0000 1.0000
61.8800 9978.0000 1.0000
61.9400 9752.0000 1.0000
62.0000 9880.0000 1.0000
62.0600 9786.0000 1.0000
62.1200 10086.0000 1.0000
62.1800 10168.0000 1.0000
62.2400 10061.0000 1.0000
62.3000 10531.0000 1.0000
62.3600 11285.0000 1.0000
62.4200 12873.0000 1.0000
62.4800 12881.0000 1.0000
62.5400 12316.0000 1.0000
62.6000 13862.0000 1.0000
62.6600 13402.0000 1.0000
62.7200 12121.0000 1.0000
62.7800 12059.0000 1.0000
62.8400 11370.0000 1.0000
62.9000 10581.0000 1.0000
62.9600 10288.0000 1.0000
63.0200 10157.0000 1.0000
63.0800 10071.0000 1.0000
63.1400 9886.0000 1.0000
63.2000 9901.0000 1.0000
63.2600 9928.0000 1.0000
63.3200 9731.0000 1.0000
63.3800 9904.0000 1.0000
63.4400 9823.0000 1.0000
63.5000 9846.0000 1.0000
63.5600 9928.0000 1.0000
63.6200 9799.0000 1.0000
63.6800 10095.0000 1.0000
63.7400 10010.0000 1.0000
63.8000 10239.0000 1.0000
63.8600 10396.0000 1.0000
63.9200 10919.0000 1.0000
63.9800 12707.0000 1.0000
64.0400 12684.0000 1.0000
64.1000 11418.0000 1.0000
64.1600 11550.0000 1.0000
64.2200 11151.0000 1.0000
64.2800 10272.0000 1.0000
64.3400 9991.0000 1.0000
64.4000 9860.0000 1.0000
64.4600 9858.0000 1.0000
64.5200 9956.0000 1.0000
64.5800 9875.0000 1.0000
64.6400 9874.0000 1.0000
64.7000 9846.0000 1.0000
64.7600 9696.0000 1.0000
64.8200 9790.0000 1.0000
64.8800 9628.0000 1.0000
64.9400 9705.0000 1.0000
65.0000 9886.0000 1.0000
65.0600 9799.0000 1.0000
65.1200 9804.0000 1.0000
65.1800 9704.0000 1.0000
65.2400 10053.0000 1.0000
65.3000 9877.0000 1.0000
65.3600 9756.0000 1.0000
65.4200 9674.0000 1.0000
65.4800 9682.0000 1.0000
65.5400 9720.0000 1.0000
65.6000 9763.0000 1.0000
65.6600 9638.0000 1.0000
65.7200 9853.0000 1.0000
65.7800 10000.0000 1.0000
65.8400 9835.0000 1.0000
65.9000 9694.0000 1.0000
65.9600 9905.0000 1.0000
66.0200 9751.0000 1.0000
66.0800 9874.0000 1.0000
66.1400 9973.0000 1.0000
66.2000 9960.0000 1.0000
66.2600 9872.0000 1.0000
66.3200 9952.0000 1.0000
66.3800 10160.0000 1.0000
66.4400 10254.0000 1.0000
66.5000 10590.0000 1.0000
66.5600 10363.0000 1.0000
66.6200 10196.0000 1.0000
66.6800 10385.0000 1.0000
66.7400 10433.0000 1.0000
66.8000 10011.0000 1.0000
66.8600 9892.0000 1.0000
66.9200 9681.0000 1.0000
66.9800 9681.0000 1.0000
67.0400 9616.0000 1.0000
67.1000 9849.0000 1.0000
67.1600 9837.0000 1.0000
67.2200 9817.0000 1.0000
67.2800 9956.0000 1.0000
67.3400 9771.0000 1.0000
67.4000 9947.0000 1.0000
67.4600 9792.0000 1.0000
67.5200 9957.0000 1.0000
67.5800 10019.0000 1.0000
67.6400 10035.0000 1.0000
67.7000 10542.0000 1.0000
67.7600 11230.0000 1.0000
67.8200 10313.0000 1.0000
67.8800 10220.0000 1.0000
67.9400 10705.0000 1.0000
68.0000 10554.0000 1.0000
68.0600 10622.0000 1.0000
68.1200 12673.0000 1.0000
68.1800 12275.0000 1.0000
68.2400 11594.0000 1.0000
68.3000 12344.0000 1.0000
68.3600 11899.0000 1.0000
68.4200 10821.0000 1.0000
68.4800 10668.0000 1.0000
68.5400 10328.0000 1.0000
68.6000 9987.0000 1.0000
68.6600 9913.0000 1.0000
68.7200 9683.0000 1.0000
68.7800 9806.0000 1.0000
68.8400 9660.0000 1.0000
68.9000 9980.0000 1.0000
68.9600 9918.0000 1.0000
69.0200 9926.0000 1.0000
69.0800 9806.0000 1.0000
69.1400 9766.0000 1.0000
69.2000 9794.0000 1.0000
69.2600 9871.0000 1.0000
69.3200 9869.0000 1.0000
69.3800 9923.0000 1.0000
69.4400 9769.0000 1.0000
69.5000 9891.0000 1.0000
69.5600 10020.0000 1.0000
69.6200 9969.0000 1.0000
69.6800 9981.0000 1.0000
69.7400 9951.0000 1.0000
69.8000 10097.0000 1.0000
69.8600 9999.0000 1.0000
69.9200 9735.0000 1.0000
69.9800 9793.0000 1.0000
70.0400 9792.0000 1.0000
70.1000 9858.0000 1.0000
70.1600 9983.0000 1.0000
70.2200 9854.0000 1.0000
70.2800 9904.0000 1.0000
70.3400 9730.0000 1.0000
70.4000 9889.0000 1.0000
70.4600 9978.0000 1.0000
70.5200 9744.0000 1.0000
70.5800 9796.0000 1.0000
70.6400 9974.0000 1.0000
70.7000 9881.0000 1.0000
70.7600 9840.0000 1.0000
70.8200 9838.0000 1.0000
70.8800 9758.0000 1.0000
70.9400 9833.0000 1.0000
71.0000 10143.0000 1.0000
71.0600 9850.0000 1.0000
71.1200 9974.0000 1.0000
71.1800 10195.0000 1.0000
71.2400 9796.0000 1.0000
71.3000 9754.0000 1.0000
71.3600 9971.0000 1.0000
71.4200 9885.0000 1.0000
71.4800 9779.0000 1.0000
71.5400 9798.0000 1.0000
71.6000 9895.0000 1.0000
71.6600 9831.0000 1.0000
71.7200 9883.0000 1.0000
71.7800 10055.0000 1.0000
71.8400 10257.0000 1.0000
71.9000 10481.0000 1.0000
71.9600 10731.0000 1.0000
72.0200 10395.0000 1.0000
72.0800 10044.0000 1.0000
72.1400 10230.0000 1.0000
72.2000 10271.0000 1.0000
72.2600 10168.0000 1.0000
72.3200 9920.0000 1.0000
72.3800 9956.0000 1.0000
72.4400 10039.0000 1.0000
72.5000 9902.0000 1.0000
72.5600 9855.0000 1.0000
72.6200 9858.0000 1.0000
72.6800 9965.0000 1.0000
72.7400 9839.0000 1.0000
72.8000 10033.0000 1.0000
72.8600 9914.0000 1.0000
72.9200 9818.0000 1.0000
72.9800 9767.0000 1.0000
73.0400 9849.0000 1.0000
73.1000 9833.0000 1.0000
73.1600 9809.0000 1.0000
73.2200 9850.0000 1.0000
73.2800 9874.0000 1.0000
73.3400 9905.0000 1.0000
73.4000 10036.0000 1.0000
73.4600 10423.0000 1.0000
73.5200 10063.0000 1.0000
73.5800 9868.0000 1.0000
73.6400 9757.0000 1.0000
73.7000 10140.0000 1.0000
73.7600 10028.0000 1.0000
73.8200 10015.0000 1.0000
73.8800 9748.0000 1.0000
73.9400 9964.0000 1.0000
74.0000 10106.0000 1.0000
74.0600 10191.0000 1.0000
74.1200 10183.0000 1.0000
74.1800 10153.0000 1.0000
74.2400 10194.0000 1.0000
74.3000 10144.0000 1.0000
74.3600 10055.0000 1.0000
74.4200 9994.0000 1.0000
74.4800 9905.0000 1.0000
74.5400 10108.0000 1.0000
74.6000 9723.0000 1.0000
74.6600 10007.0000 1.0000
74.7200 9929.0000 1.0000
74.7800 9954.0000 1.0000
74.8400 9838.0000 1.0000
74.9000 9960.0000 1.0000
74.9600 9879.0000 1.0000
75.0200 9938.0000 1.0000
75.0800 9891.0000 1.0000
75.1400 10006.0000 1.0000
75.2000 9991.0000 1.0000
75.2600 10154.0000 1.0000
75.3200 10061.0000 1.0000
75.3800 10271.0000 1.0000
75.4400 10544.0000 1.0000
75.5000 10394.0000 1.0000
75.5600 10279.0000 1.0000
75.6200 10291.0000 1.0000
75.6800 10461.0000 1.0000
75.7400 10096.0000 1.0000
75.8000 9889.0000 1.0000
75.8600 10329.0000 1.0000
75.9200 9917.0000 1.0000
75.9800 10005.0000 1.0000
76.0400 9937.0000 1.0000
76.1000 9903.0000 1.0000
76.1600 9884.0000 1.0000
76.2200 9769.0000 1.0000
76.2800 9752.0000 1.0000
76.3400 9833.0000 1.0000
76.4000 9872.0000 1.0000
76.4600 9903.0000 1.0000
76.5200 9967.0000 1.0000
76.5800 9778.0000 1.0000
76.6400 10013.0000 1.0000
76.7000 9869.0000 1.0000
76.7600 10132.0000 1.0000
76.8200 10050.0000 1.0000
76.8800 10229.0000 1.0000
76.9400 10114.0000 1.0000
77.0000 10115.0000 1.0000
77.0600 10117.0000 1.0000
77.1200 10055.0000 1.0000
77.1800 9917.0000 1.0000
77.2400 10164.0000 1.0000
77.3000 10061.0000 1.0000
77.3600 9961.0000 1.0000
77.4200 10045.0000 1.0000
77.4800 10072.0000 1.0000
77.5400 9858.0000 1.0000
77.6000 10030.0000 1.0000
77.6600 10286.0000 1.0000
77.7200 10103.0000 1.0000
77.7800 10142.0000 1.0000
77.8400 10104.0000 1.0000
77.9000 9961.0000 1.0000
77.9600 10001.0000 1.0000
78.0200 9899.0000 1.0000
78.0800 9798.0000 1.0000
78.1400 9988.0000 1.0000
78.2000 9833.0000 1.0000
78.2600 9867.0000 1.0000
78.3200 9831.0000 1.0000
78.3800 9922.0000 1.0000
78.4400 9803.0000 1.0000
78.5000 9872.0000 1.0000
78.5600 10101.0000 1.0000
78.6200 9918.0000 1.0000
78.6800 10016.0000 1.0000
78.7400 10173.0000 1.0000
78.8000 10080.0000 1.0000
78.8600 9975.0000 1.0000
78.9200 9924.0000 1.0000
78.9800 9800.0000 1.0000
79.0400 10024.0000 1.0000
79.1000 10214.0000 1.0000
79.1600 9937.0000 1.0000
79.2200 9955.0000 1.0000
79.2800 9882.0000 1.0000
79.3400 10012.0000 1.0000
79.4000 9994.0000 1.0000
79.4600 9973.0000 1.0000
79.5200 10012.0000 1.0000
79.5800 9953.0000 1.0000
79.6400 9797.0000 1.0000
79.7000 9919.0000 1.0000
79.7600 9963.0000 1.0000
79.8200 10178.0000 1.0000
79.8800 10212.0000 1.0000
79.9400 10072.0000 1.0000
80.0000 10102.0000 1.0000
80.0600 9887.0000 1.0000
80.1200 10016.0000 1.0000
80.1800 10018.0000 1.0000
80.2400 9829.0000 1.0000
80.3000 9897.0000 1.0000
80.3600 9843.0000 1.0000
80.4200 10057.0000 1.0000
80.4800 9985.0000 1.0000
80.5400 10194.0000 1.0000
80.6000 10262.0000 1.0000
80.6600 10320.0000 1.0000
80.7200 10519.0000 1.0000
80.7800 10273.0000 1.0000
80.8400 10228.0000 1.0000
80.9000 10243.0000 1.0000
80.9600 10163.0000 1.0000
81.0200 10067.0000 1.0000
81.0800 10278.0000 1.0000
81.1400 10732.0000 1.0000
81.2000 11063.0000 1.0000
81.2600 10060.0000 1.0000
81.3200 10215.0000 1.0000
81.3800 10552.0000 1.0000
81.4400 10917.0000 1.0000
81.5000 10691.0000 1.0000
81.5600 10133.0000 1.0000
81.6200 10069.0000 1.0000
81.6800 10226.0000 1.0000
81.7400 10084.0000 1.0000
81.8000 9859.0000 1.0000
81.8600 9910.0000 1.0000
81.9200 10092.0000 1.0000
81.9800 9788.0000 1.0000
82.0400 9974.0000 1.0000
82.1000 10008.0000 1.0000
82.1600 9894.0000 1.0000
82.2200 10041.0000 1.0000
82.2800 10031.0000 1.0000
82.3400 9907.0000 1.0000
82.4000 9994.0000 1.0000
82.4600 10015.0000 1.0000
82.5200 9987.0000 1.0000
82.5800 9987.0000 1.0000
82.6400 9735.0000 1.0000
82.7000 10132.0000 1.0000
82.7600 9887.0000 1.0000
82.8200 10172.0000 1.0000
82.8800 10249.0000 1.0000
82.9400 10327.0000 1.0000
83.0000 10236.0000 1.0000
83.0600 10302.0000 1.0000
83.1200 10165.0000 1.0000
83.1800 10162.0000 1.0000
83.2400 10249.0000 1.0000
83.3000 10149.0000 1.0000
83.3600 9989.0000 1.0000
83.4200 10027.0000 1.0000
83.4800 9884.0000 1.0000
83.5400 9973.0000 1.0000
83.6000 9794.0000 1.0000
83.6600 10228.0000 1.0000
83.7200 10078.0000 1.0000
83.7800 10070.0000 1.0000
83.8400 10389.0000 1.0000
83.9000 9973.0000 1.0000
83.9600 9951.0000 1.0000
84.0200 9981.0000 1.0000
84.0800 10209.0000 1.0000
84.1400 10209.0000 1.0000
84.2000 10155.0000 1.0000
84.2600 9962.0000 1.0000
84.3200 10149.0000 1.0000
84.3800 10116.0000 1.0000
84.4400 9996.0000 1.0000
84.5000 10182.0000 1.0000
84.5600 9942.0000 1.0000
84.6200 9932.0000 1.0000
84.6800 9976.0000 1.0000
84.7400 9968.0000 1.0000
84.8000 10160.0000 1.0000
84.8600 10403.0000 1.0000
84.9200 10797.0000 1.0000
84.9800 10637.0000 1.0000
85.0400 10412.0000 1.0000
85.1000 10302.0000 1.0000
85.1600 10234.0000 1.0000
85.2200 10279.0000 1.0000
85.2800 10136.0000 1.0000
85.3400 10123.0000 1.0000
85.4000 9926.0000 1.0000
85.4600 9960.0000 1.0000
85.5200 10073.0000 1.0000
85.5800 9880.0000 1.0000
85.6400 9955.0000 1.0000
85.7000 9761.0000 1.0000
85.7600 10040.0000 1.0000
85.8200 10066.0000 1.0000
85.8800 9762.0000 1.0000
85.9400 9900.0000 1.0000
86.0000 10016.0000 1.0000
86.0600 9958.0000 1.0000
86.1200 10049.0000 1.0000
86.1800 9991.0000 1.0000
86.2400 10135.0000 1.0000
86.3000 9977.0000 1.0000
86.3600 10027.0000 1.0000
86.4200 9942.0000 1.0000
86.4800 10154.0000 1.0000
86.5400 10063.0000 1.0000
86.6000 10197.0000 1.0000
86.6600 10022.0000 1.0000
86.7200 10028.0000 1.0000
86.7800 10113.0000 1.0000
86.8400 10083.0000 1.0000
86.9000 10141.0000 1.0000
86.9600 10061.0000 1.0000
87.0200 9986.0000 1.0000
87.0800 10018.0000 1.0000
87.1400 10029.0000 1.0000
87.2000 9966.0000 1.0000
87.2600 10022.0000 1.0000
87.3200 10079.0000 1.0000
87.3800 9910.0000 1.0000
87.4400 10015.0000 1.0000
87.5000 10028.0000 1.0000
87.5600 9897.0000 1.0000
87.6200 10120.0000 1.0000
87.6800 10016.0000 1.0000
87.7400 9834.0000 1.0000
87.8000 9936.0000 1.0000
87.8600 10048.0000 1.0000
87.9200 10111.0000 1.0000
87.9800 9881.0000 1.0000
88.0400 9884.0000 1.0000
88.1000 9975.0000 1.0000
88.1600 10075.0000 1.0000
88.2200 9909.0000 1.0000
88.2800 10113.0000 1.0000
88.3400 10163.0000 1.0000
88.4000 10189.0000 1.0000
88.4600 10193.0000 1.0000
88.5200 10588.0000 1.0000
88.5800 10650.0000 1.0000
88.6400 10412.0000 1.0000
88.7000 10214.0000 1.0000
88.7600 10501.0000 1.0000
88.8200 10363.0000 1.0000
88.8800 10339.0000 1.0000
88.9400 10228.0000 1.0000
89.0000 10258.0000 1.0000
89.0600 10108.0000 1.0000
89.1200 9932.0000 1.0000
89.1800 10108.0000 1.0000
89.2400 10153.0000 1.0000
89.3000 9975.0000 1.0000
89.3600 10072.0000 1.0000
89.4200 9968.0000 1.0000
89.4800 10085.0000 1.0000
89.5400 10034.0000 1.0000
89.6000 10296.0000 1.0000
89.6600 10348.0000 1.0000
89.7200 10490.0000 1.0000
89.7800 10586.0000 1.0000
89.8400 10479.0000 1.0000
89.9000 10427.0000 1.0000
89.9600 10414.0000 1.0000
90.0000 10336.0000 1.0000
*RAS_INT_END
*RAS_TEMPERATURE_START
*RAS_TEMPERATURE_END
*RAS_DATA_END