File: XRD/Data/20200918_mix_11.ras
*RAS_DATA_START
*RAS_HEADER_START
*DISP_FMT_X "%.2f"
*DISP_FMT_Y "%.0f"
*DISP_FULLSCALE "28381.0000000000"
*DISP_LINE_COLOR "255.0000000000"
*DISP_LINE_STYLE "0.0000000000"
*DISP_LINE_WIDTH "0.2500000000"
*DISP_NOTE "測定データ-2"
*DISP_OFFSET_Y "0.0000000000"
*DISP_PEAKSEARCH_UNIT_Y "cps"
*DISP_RANGE_BOTTOM "0.0000000000"
*DISP_RANGE_LEFT "20.0000000000"
*DISP_RANGE_LOGCUTOFF "0.0100000000"
*DISP_RANGE_RIGHT "90.0000000000"
*DISP_RANGE_TOP "28381.0000000000"
*DISP_SCALE_MODE_Y "0.0000000000"
*DISP_TAB_NAME "2θ/θ"
*DISP_TITLE_Y "強度"
*DISP_UNIT_Y "cps"
*DISP_WINDOW_NAME "MSG_MACROENGINE"
*FILE_COMMENT " "
*FILE_MD5 ""
*FILE_MEMO " "
*FILE_OPERATOR "Administrator"
*FILE_SAMPLE " "
*FILE_TYPE "RAS_RAW"
*FILE_USERGROUP "システムマネージャ"
*FILE_VERSION "1.0000000000"
*HW_ATTACHMENT_ID "ATT0025"
*HW_ATTACHMENT_NAME "標準|Standard"
*HW_COUNTER_ID-0 "CUT0025"
*HW_COUNTER_ID-1 "CUT0020"
*HW_COUNTER_ID-2 "CUT0020"
*HW_COUNTER_ID-3 "CSL0021"
*HW_COUNTER_ID-4 "CMC0021"
*HW_COUNTER_NAME-0 "D/teX Ultra|D/teX Ultra"
*HW_COUNTER_NAME-1 "None|None"
*HW_COUNTER_NAME-2 "None|None"
*HW_COUNTER_NAME-3 "BBM|BBM"
*HW_COUNTER_NAME-4 "検出器モノクロメータ|Detector monochromator"
*HW_COUNTER_SELECT_NAME "D/teX Ultra|D/teX Ultra"
*HW_GONIOMETER_ID "GON0023"
*HW_GONIOMETER_NAME "SmartLab|SmartLab"
*HW_GONIOMETER_RADIUS-0 "90.0"
*HW_GONIOMETER_RADIUS-1 "114.0"
*HW_GONIOMETER_RADIUS-2 "190.0"
*HW_GONIOMETER_RADIUS-3 "300.0"
*HW_GONIOMETER_RADIUS-4 "187.0"
*HW_GONIOMETER_RADIUS-5 "300.0"
*HW_GONIOMETER_RADIUS-6 "113.0"
*HW_GONIOMETER_RADIUS-7 "331.0"
*HW_I_OPT_ID-0 "CBO0021"
*HW_I_OPT_ID-1 "ICR0023"
*HW_I_OPT_ID-2 "ISL0021"
*HW_I_OPT_ID-3 "ISO0021"
*HW_I_OPT_ID-4 "IAD0021"
*HW_I_OPT_ID-5 "IPR0001"
*HW_I_OPT_NAME-0 "CBOユニット|CBO unit"
*HW_I_OPT_NAME-1 "標準入射光学ユニット|Standard incident optical unit"
*HW_I_OPT_NAME-2 "標準入射スリットボックス|Standard incident slit box"
*HW_I_OPT_NAME-3 "入射平行スリット|Incident parallel slit"
*HW_I_OPT_NAME-4 "長手制限スリット|Length limiting slit"
*HW_I_OPT_NAME-5 "None|None"
*HW_R_ATTENUATER_AUTOMODE "0"
*HW_R_OPT_ID-0 "RSS0021"
*HW_R_OPT_ID-1 "RCR0023"
*HW_R_OPT_ID-2 "RSO0021"
*HW_R_OPT_ID-3 "RRS0021"
*HW_R_OPT_ID-4 "ATN0021"
*HW_R_OPT_ID-5 "RFL0021"
*HW_R_OPT_ID-6 "RAD0021"
*HW_R_OPT_NAME-0 "標準受光スリットボックス1|Standard receiving slit box # 1"
*HW_R_OPT_NAME-1 "標準受光光学ユニット1|Standard receiving unit # 1"
*HW_R_OPT_NAME-2 "標準受光光学ユニット2|Standard receiving optical unit # 2"
*HW_R_OPT_NAME-3 "標準受光スリットボックス2|Standard receiving slit box # 2"
*HW_R_OPT_NAME-4 "標準アッテネータ|Standard Attenuator"
*HW_R_OPT_NAME-5 "Cu Kβ|Cu K-beta"
*HW_R_OPT_NAME-6 "調整用受光スリット|Alignment receiving slit"
*HW_SAMPLE_HOLDER_ID "SMP0023"
*HW_SAMPLE_HOLDER_NAME "標準Zステージ|Standard Z stage"
*HW_XG_CURRENT_MAX "50"
*HW_XG_CURRENT_MIN "2"
*HW_XG_CURRENT_RESOLUTION "2"
*HW_XG_CURRENT_UNIT "mA"
*HW_XG_FOCUS "1mm x 10mm"
*HW_XG_FOCUS_TYPE "Normal"
*HW_XG_ID ""
*HW_XG_NAME "3kW 封入管(ID:1200)|3kW Sealed tube(ID:1200)"
*HW_XG_TARGET_ATOMIC_NUMBER "29.0000000000"
*HW_XG_TARGET_NAME "Cu"
*HW_XG_TYPE "Hermetic"
*HW_XG_VOLTAGE_MAX "60"
*HW_XG_VOLTAGE_MIN "20"
*HW_XG_VOLTAGE_RESOLUTION "2"
*HW_XG_VOLTAGE_UNIT "kV"
*HW_XG_WATT_MAX "2"
*HW_XG_WATT_UNIT "kW"
*HW_XG_WAVE_LENGTH_ALPHA1 "1.540593"
*HW_XG_WAVE_LENGTH_ALPHA2 "1.544414"
*HW_XG_WAVE_LENGTH_BETA "1.392250"
*MEAS_COND_AXIS_NAME-0 "2θ/θ"
*MEAS_COND_AXIS_NAME-1 "2θ"
*MEAS_COND_AXIS_NAME-2 "ω"
*MEAS_COND_AXIS_NAME-3 "Z"
*MEAS_COND_AXIS_NAME-4 "2θ/ω"
*MEAS_COND_AXIS_NAME-5 "θs"
*MEAS_COND_AXIS_NAME-6 "θd"
*MEAS_COND_AXIS_NAME-7 "Ts"
*MEAS_COND_AXIS_NAME-8 "CBO選択スリット"
*MEAS_COND_AXIS_NAME-9 "M"
*MEAS_COND_AXIS_NAME-10 "入射平行スリット"
*MEAS_COND_AXIS_NAME-11 "入射スリット"
*MEAS_COND_AXIS_NAME-12 ""
*MEAS_COND_AXIS_NAME-13 "Zs"
*MEAS_COND_AXIS_NAME-14 "入射光学素子"
*MEAS_COND_AXIS_NAME-15 "長手制限スリット"
*MEAS_COND_AXIS_NAME-16 "センタースリット"
*MEAS_COND_AXIS_NAME-17 "フィルター"
*MEAS_COND_AXIS_NAME-18 "受光スリット1"
*MEAS_COND_AXIS_NAME-19 "受光スリット2"
*MEAS_COND_AXIS_NAME-20 "受光光学素子"
*MEAS_COND_AXIS_NAME-21 "受光平行スリット"
*MEAS_COND_AXIS_NAME-22 "調整用受光スリット"
*MEAS_COND_AXIS_NAME-23 ""
*MEAS_COND_AXIS_NAME-24 ""
*MEAS_COND_AXIS_NAME-25 "Zd"
*MEAS_COND_AXIS_NAME-26 "アッテネータ"
*MEAS_COND_AXIS_NAME-27 "検出器モノクロメータ"
*MEAS_COND_AXIS_NAME-28 "モノクロメータスリット"
*MEAS_COND_AXIS_NAME-29 "プライマリビーム"
*MEAS_COND_AXIS_NAME-30 "PHA"
*MEAS_COND_AXIS_NAME_INTERNAL-0 "TwoThetaTheta"
*MEAS_COND_AXIS_NAME_INTERNAL-1 "TwoTheta"
*MEAS_COND_AXIS_NAME_INTERNAL-2 "Omega"
*MEAS_COND_AXIS_NAME_INTERNAL-3 "Z"
*MEAS_COND_AXIS_NAME_INTERNAL-4 "TwoThetaOmega"
*MEAS_COND_AXIS_NAME_INTERNAL-5 "ThetaS"
*MEAS_COND_AXIS_NAME_INTERNAL-6 "ThetaD"
*MEAS_COND_AXIS_NAME_INTERNAL-7 "Ts"
*MEAS_COND_AXIS_NAME_INTERNAL-8 "CBO"
*MEAS_COND_AXIS_NAME_INTERNAL-9 "CBO-M"
*MEAS_COND_AXIS_NAME_INTERNAL-10 "IncidentSollerSlit"
*MEAS_COND_AXIS_NAME_INTERNAL-11 "IncidentSlitBox"
*MEAS_COND_AXIS_NAME_INTERNAL-12 "IncidentSlitBox-_Axis"
*MEAS_COND_AXIS_NAME_INTERNAL-13 "Zs"
*MEAS_COND_AXIS_NAME_INTERNAL-14 "IncidentMonochromator"
*MEAS_COND_AXIS_NAME_INTERNAL-15 "IncidentAxdSlit"
*MEAS_COND_AXIS_NAME_INTERNAL-16 "CenterSlit"
*MEAS_COND_AXIS_NAME_INTERNAL-17 "Filter"
*MEAS_COND_AXIS_NAME_INTERNAL-18 "ReceivingSlitBox1"
*MEAS_COND_AXIS_NAME_INTERNAL-19 "ReceivingSlitBox2"
*MEAS_COND_AXIS_NAME_INTERNAL-20 "ReceivingOptics"
*MEAS_COND_AXIS_NAME_INTERNAL-21 "ReceivingSollerSlit"
*MEAS_COND_AXIS_NAME_INTERNAL-22 "ReceivingAxdSlit"
*MEAS_COND_AXIS_NAME_INTERNAL-23 "ReceivingSlitBox1-_Axis"
*MEAS_COND_AXIS_NAME_INTERNAL-24 "ReceivingSlitBox2-_Axis"
*MEAS_COND_AXIS_NAME_INTERNAL-25 "ReceivingSlitBox2-Zd"
*MEAS_COND_AXIS_NAME_INTERNAL-26 "Attenuator"
*MEAS_COND_AXIS_NAME_INTERNAL-27 "CounterMonochromator"
*MEAS_COND_AXIS_NAME_INTERNAL-28 "CounterSlit"
*MEAS_COND_AXIS_NAME_INTERNAL-29 "IncidentPrimary"
*MEAS_COND_AXIS_NAME_INTERNAL-30 "PHA"
*MEAS_COND_AXIS_NAME_MAGICNO-0 "83951616.0000000000"
*MEAS_COND_AXIS_NAME_MAGICNO-1 "268632064.0000000000"
*MEAS_COND_AXIS_NAME_MAGICNO-2 "268500992.0000000000"
*MEAS_COND_AXIS_NAME_MAGICNO-3 "285278208.0000000000"
*MEAS_COND_AXIS_NAME_MAGICNO-4 "83951616.0000000000"
*MEAS_COND_AXIS_NAME_MAGICNO-5 "131072.0000000000"
*MEAS_COND_AXIS_NAME_MAGICNO-6 "131072.0000000000"
*MEAS_COND_AXIS_NAME_MAGICNO-7 "318898176.0000000000"
*MEAS_COND_AXIS_NAME_MAGICNO-8 "20971521.0000000000"
*MEAS_COND_AXIS_NAME_MAGICNO-9 "285343744.0000000000"
*MEAS_COND_AXIS_NAME_MAGICNO-10 "20971521.0000000000"
*MEAS_COND_AXIS_NAME_MAGICNO-11 "22020097.0000000000"
*MEAS_COND_AXIS_NAME_MAGICNO-12 "25165824.0000000000"
*MEAS_COND_AXIS_NAME_MAGICNO-13 "318898176.0000000000"
*MEAS_COND_AXIS_NAME_MAGICNO-14 "1.0000000000"
*MEAS_COND_AXIS_NAME_MAGICNO-15 "20971521.0000000000"
*MEAS_COND_AXIS_NAME_MAGICNO-16 "20971521.0000000000"
*MEAS_COND_AXIS_NAME_MAGICNO-17 "20971521.0000000000"
*MEAS_COND_AXIS_NAME_MAGICNO-18 "23068673.0000000000"
*MEAS_COND_AXIS_NAME_MAGICNO-19 "23068673.0000000000"
*MEAS_COND_AXIS_NAME_MAGICNO-20 "20971521.0000000000"
*MEAS_COND_AXIS_NAME_MAGICNO-21 "20971521.0000000000"
*MEAS_COND_AXIS_NAME_MAGICNO-22 "20971521.0000000000"
*MEAS_COND_AXIS_NAME_MAGICNO-23 "25165824.0000000000"
*MEAS_COND_AXIS_NAME_MAGICNO-24 "25165824.0000000000"
*MEAS_COND_AXIS_NAME_MAGICNO-25 "285343744.0000000000"
*MEAS_COND_AXIS_NAME_MAGICNO-26 "17301505.0000000000"
*MEAS_COND_AXIS_NAME_MAGICNO-27 "20971521.0000000000"
*MEAS_COND_AXIS_NAME_MAGICNO-28 "20971521.0000000000"
*MEAS_COND_AXIS_NAME_MAGICNO-29 "20971521.0000000000"
*MEAS_COND_AXIS_NAME_MAGICNO-30 "0.0000000000"
*MEAS_COND_AXIS_OFFSET-0 "-"
*MEAS_COND_AXIS_OFFSET-1 "-0.1081000000"
*MEAS_COND_AXIS_OFFSET-2 "0.3758000000"
*MEAS_COND_AXIS_OFFSET-3 "-"
*MEAS_COND_AXIS_OFFSET-4 "-"
*MEAS_COND_AXIS_OFFSET-5 "0.3758000000"
*MEAS_COND_AXIS_OFFSET-6 "-0.4839000000"
*MEAS_COND_AXIS_OFFSET-7 "-"
*MEAS_COND_AXIS_OFFSET-8 "-"
*MEAS_COND_AXIS_OFFSET-9 "-"
*MEAS_COND_AXIS_OFFSET-10 "-"
*MEAS_COND_AXIS_OFFSET-11 "-"
*MEAS_COND_AXIS_OFFSET-12 "-"
*MEAS_COND_AXIS_OFFSET-13 "-"
*MEAS_COND_AXIS_OFFSET-14 "-"
*MEAS_COND_AXIS_OFFSET-15 "-"
*MEAS_COND_AXIS_OFFSET-16 "-"
*MEAS_COND_AXIS_OFFSET-17 "-"
*MEAS_COND_AXIS_OFFSET-18 "-"
*MEAS_COND_AXIS_OFFSET-19 "-"
*MEAS_COND_AXIS_OFFSET-20 "-"
*MEAS_COND_AXIS_OFFSET-21 "-"
*MEAS_COND_AXIS_OFFSET-22 "-"
*MEAS_COND_AXIS_OFFSET-23 "-"
*MEAS_COND_AXIS_OFFSET-24 "-"
*MEAS_COND_AXIS_OFFSET-25 "-"
*MEAS_COND_AXIS_OFFSET-26 "-"
*MEAS_COND_AXIS_OFFSET-27 "-"
*MEAS_COND_AXIS_OFFSET-28 "-"
*MEAS_COND_AXIS_OFFSET-29 "-"
*MEAS_COND_AXIS_OFFSET-30 "-"
*MEAS_COND_AXIS_POSITION-0 "0.0000000000"
*MEAS_COND_AXIS_POSITION-1 "0.0000000000"
*MEAS_COND_AXIS_POSITION-2 "0.0000000000"
*MEAS_COND_AXIS_POSITION-3 "-0.5500000000"
*MEAS_COND_AXIS_POSITION-4 "0.0000000000"
*MEAS_COND_AXIS_POSITION-5 "0.0000000000"
*MEAS_COND_AXIS_POSITION-6 "0.0000000000"
*MEAS_COND_AXIS_POSITION-7 "-0.4278800000"
*MEAS_COND_AXIS_POSITION-8 "BB"
*MEAS_COND_AXIS_POSITION-9 "0.0000000000"
*MEAS_COND_AXIS_POSITION-10 "Soller_slit_5.0deg"
*MEAS_COND_AXIS_POSITION-11 "2/3deg"
*MEAS_COND_AXIS_POSITION-12 "2.2088000000"
*MEAS_COND_AXIS_POSITION-13 "-0.4140600000"
*MEAS_COND_AXIS_POSITION-14 "0.0000000000"
*MEAS_COND_AXIS_POSITION-15 "10.0mm"
*MEAS_COND_AXIS_POSITION-16 "None"
*MEAS_COND_AXIS_POSITION-17 "Cu_K-beta"
*MEAS_COND_AXIS_POSITION-18 "13.000mm"
*MEAS_COND_AXIS_POSITION-19 "13.000mm"
*MEAS_COND_AXIS_POSITION-20 "No_unit"
*MEAS_COND_AXIS_POSITION-21 "Soller_slit_5.0deg"
*MEAS_COND_AXIS_POSITION-22 "None"
*MEAS_COND_AXIS_POSITION-23 "13.0000000000"
*MEAS_COND_AXIS_POSITION-24 "13.0000000000"
*MEAS_COND_AXIS_POSITION-25 "0.0109400000"
*MEAS_COND_AXIS_POSITION-26 "Open"
*MEAS_COND_AXIS_POSITION-27 "None"
*MEAS_COND_AXIS_POSITION-28 "None"
*MEAS_COND_AXIS_POSITION-29 "None"
*MEAS_COND_AXIS_POSITION-30 "38.0000000000"
*MEAS_COND_AXIS_UNIT-0 "deg"
*MEAS_COND_AXIS_UNIT-1 "deg"
*MEAS_COND_AXIS_UNIT-2 "deg"
*MEAS_COND_AXIS_UNIT-3 "mm"
*MEAS_COND_AXIS_UNIT-4 "deg"
*MEAS_COND_AXIS_UNIT-5 "deg"
*MEAS_COND_AXIS_UNIT-6 "deg"
*MEAS_COND_AXIS_UNIT-7 "mm"
*MEAS_COND_AXIS_UNIT-8 ""
*MEAS_COND_AXIS_UNIT-9 "pulse"
*MEAS_COND_AXIS_UNIT-10 ""
*MEAS_COND_AXIS_UNIT-11 ""
*MEAS_COND_AXIS_UNIT-12 "mm"
*MEAS_COND_AXIS_UNIT-13 "mm"
*MEAS_COND_AXIS_UNIT-14 ""
*MEAS_COND_AXIS_UNIT-15 ""
*MEAS_COND_AXIS_UNIT-16 ""
*MEAS_COND_AXIS_UNIT-17 ""
*MEAS_COND_AXIS_UNIT-18 ""
*MEAS_COND_AXIS_UNIT-19 ""
*MEAS_COND_AXIS_UNIT-20 ""
*MEAS_COND_AXIS_UNIT-21 ""
*MEAS_COND_AXIS_UNIT-22 ""
*MEAS_COND_AXIS_UNIT-23 "mm"
*MEAS_COND_AXIS_UNIT-24 "mm"
*MEAS_COND_AXIS_UNIT-25 "mm"
*MEAS_COND_AXIS_UNIT-26 ""
*MEAS_COND_AXIS_UNIT-27 ""
*MEAS_COND_AXIS_UNIT-28 ""
*MEAS_COND_AXIS_UNIT-29 ""
*MEAS_COND_AXIS_UNIT-30 "div"
*MEAS_COND_COUNTER_CNTLOSS_CORR "0.0000000000"
*MEAS_COND_COUNTER_PHABASE "38.0000000000"
*MEAS_COND_COUNTER_PHAWINDOW "16.0000000000"
*MEAS_COND_COUNTER_PHA_UNIT "div"
*MEAS_COND_COUNTER_TAUDIFF "30.0000000000"
*MEAS_COND_COUNTER_TAUINT "0.0000000000"
*MEAS_COND_IRRADIATION_MODE "OFF"
*MEAS_COND_IRRADIATION_WIDTH ""
*MEAS_COND_OPT_ATTR "集中法"
*MEAS_COND_OPT_NAME "@集中法"
*MEAS_COND_UNSYMMETRIC_MODE "OFF"
*MEAS_COND_XG_CURRENT "30.0000000000"
*MEAS_COND_XG_VOLTAGE "40.0000000000"
*MEAS_COND_XG_WAVE_TYPE "Ka"
*MEAS_DATA_COUNT "3501.0000000000"
*MEAS_SCAN_AXIS_X "2θ/θ"
*MEAS_SCAN_AXIS_X_INTERNAL "TwoThetaTheta"
*MEAS_SCAN_END_TIME "09/18/20 15:03:28"
*MEAS_SCAN_MODE "CONTINUOUS"
*MEAS_SCAN_MONITOR "0"
*MEAS_SCAN_RESOLUTION_X "0.0002"
*MEAS_SCAN_SPEED "1.0"
*MEAS_SCAN_SPEED_UNIT "deg/min"
*MEAS_SCAN_START "20.0000000000"
*MEAS_SCAN_START_TIME "09/18/20 13:50:34"
*MEAS_SCAN_STEP "0.0200000000"
*MEAS_SCAN_STOP "90.0000000000"
*MEAS_SCAN_UNIT_X "deg"
*MEAS_SCAN_UNIT_Y "counts"
*RAS_HEADER_END
*RAS_INT_START
20.0000 13449.0000 1.0000
20.0600 13991.0000 1.0000
20.1200 14021.0000 1.0000
20.1800 13916.0000 1.0000
20.2400 14130.0000 1.0000
20.3000 13952.0000 1.0000
20.3600 13870.0000 1.0000
20.4200 14387.0000 1.0000
20.4800 14052.0000 1.0000
20.5400 13928.0000 1.0000
20.6000 14133.0000 1.0000
20.6600 13897.0000 1.0000
20.7200 14136.0000 1.0000
20.7800 14349.0000 1.0000
20.8400 14535.0000 1.0000
20.9000 14500.0000 1.0000
20.9600 14375.0000 1.0000
21.0200 14082.0000 1.0000
21.0800 13900.0000 1.0000
21.1400 13993.0000 1.0000
21.2000 14095.0000 1.0000
21.2600 13958.0000 1.0000
21.3200 14351.0000 1.0000
21.3800 14013.0000 1.0000
21.4400 14287.0000 1.0000
21.5000 14258.0000 1.0000
21.5600 14016.0000 1.0000
21.6200 14241.0000 1.0000
21.6800 14081.0000 1.0000
21.7400 13840.0000 1.0000
21.8000 14242.0000 1.0000
21.8600 14398.0000 1.0000
21.9200 14026.0000 1.0000
21.9800 13952.0000 1.0000
22.0400 14150.0000 1.0000
22.1000 14171.0000 1.0000
22.1600 14034.0000 1.0000
22.2200 14079.0000 1.0000
22.2800 14069.0000 1.0000
22.3400 14105.0000 1.0000
22.4000 14265.0000 1.0000
22.4600 14193.0000 1.0000
22.5200 14252.0000 1.0000
22.5800 14075.0000 1.0000
22.6400 13976.0000 1.0000
22.7000 14073.0000 1.0000
22.7600 14096.0000 1.0000
22.8200 14338.0000 1.0000
22.8800 14239.0000 1.0000
22.9400 14153.0000 1.0000
23.0000 13994.0000 1.0000
23.0600 14153.0000 1.0000
23.1200 14052.0000 1.0000
23.1800 14215.0000 1.0000
23.2400 13958.0000 1.0000
23.3000 13924.0000 1.0000
23.3600 14080.0000 1.0000
23.4200 14389.0000 1.0000
23.4800 14238.0000 1.0000
23.5400 14019.0000 1.0000
23.6000 14394.0000 1.0000
23.6600 14098.0000 1.0000
23.7200 14277.0000 1.0000
23.7800 14306.0000 1.0000
23.8400 14370.0000 1.0000
23.9000 14422.0000 1.0000
23.9600 14459.0000 1.0000
24.0200 14780.0000 1.0000
24.0800 15646.0000 1.0000
24.1400 16848.0000 1.0000
24.2000 16603.0000 1.0000
24.2600 14923.0000 1.0000
24.3200 14685.0000 1.0000
24.3800 14235.0000 1.0000
24.4400 14122.0000 1.0000
24.5000 14122.0000 1.0000
24.5600 14055.0000 1.0000
24.6200 14018.0000 1.0000
24.6800 13919.0000 1.0000
24.7400 13989.0000 1.0000
24.8000 13944.0000 1.0000
24.8600 13986.0000 1.0000
24.9200 14260.0000 1.0000
24.9800 14179.0000 1.0000
25.0400 14111.0000 1.0000
25.1000 14136.0000 1.0000
25.1600 14179.0000 1.0000
25.2200 14085.0000 1.0000
25.2800 13919.0000 1.0000
25.3400 14143.0000 1.0000
25.4000 14214.0000 1.0000
25.4600 14284.0000 1.0000
25.5200 14510.0000 1.0000
25.5800 14696.0000 1.0000
25.6400 14627.0000 1.0000
25.7000 14394.0000 1.0000
25.7600 14288.0000 1.0000
25.8200 14034.0000 1.0000
25.8800 14068.0000 1.0000
25.9400 14212.0000 1.0000
26.0000 13935.0000 1.0000
26.0600 13992.0000 1.0000
26.1200 13914.0000 1.0000
26.1800 13972.0000 1.0000
26.2400 14106.0000 1.0000
26.3000 14206.0000 1.0000
26.3600 14006.0000 1.0000
26.4200 14432.0000 1.0000
26.4800 14862.0000 1.0000
26.5400 15596.0000 1.0000
26.6000 18614.0000 1.0000
26.6600 19995.0000 1.0000
26.7200 16590.0000 1.0000
26.7800 14562.0000 1.0000
26.8400 14191.0000 1.0000
26.9000 13954.0000 1.0000
26.9600 13845.0000 1.0000
27.0200 14030.0000 1.0000
27.0800 13999.0000 1.0000
27.1400 13715.0000 1.0000
27.2000 13917.0000 1.0000
27.2600 14104.0000 1.0000
27.3200 14179.0000 1.0000
27.3800 13819.0000 1.0000
27.4400 14018.0000 1.0000
27.5000 13947.0000 1.0000
27.5600 13776.0000 1.0000
27.6200 13758.0000 1.0000
27.6800 14206.0000 1.0000
27.7400 13994.0000 1.0000
27.8000 13951.0000 1.0000
27.8600 14007.0000 1.0000
27.9200 13996.0000 1.0000
27.9800 13703.0000 1.0000
28.0400 14001.0000 1.0000
28.1000 14017.0000 1.0000
28.1600 13734.0000 1.0000
28.2200 14065.0000 1.0000
28.2800 13747.0000 1.0000
28.3400 13956.0000 1.0000
28.4000 13965.0000 1.0000
28.4600 14134.0000 1.0000
28.5200 14053.0000 1.0000
28.5800 13927.0000 1.0000
28.6400 13808.0000 1.0000
28.7000 14037.0000 1.0000
28.7600 13914.0000 1.0000
28.8200 13850.0000 1.0000
28.8800 13748.0000 1.0000
28.9400 13874.0000 1.0000
29.0000 13721.0000 1.0000
29.0600 13849.0000 1.0000
29.1200 13919.0000 1.0000
29.1800 13809.0000 1.0000
29.2400 13811.0000 1.0000
29.3000 13923.0000 1.0000
29.3600 14030.0000 1.0000
29.4200 14005.0000 1.0000
29.4800 13779.0000 1.0000
29.5400 13870.0000 1.0000
29.6000 13901.0000 1.0000
29.6600 13793.0000 1.0000
29.7200 14000.0000 1.0000
29.7800 13763.0000 1.0000
29.8400 13923.0000 1.0000
29.9000 14223.0000 1.0000
29.9600 14245.0000 1.0000
30.0200 15240.0000 1.0000
30.0800 16636.0000 1.0000
30.1400 17750.0000 1.0000
30.2000 16725.0000 1.0000
30.2600 15539.0000 1.0000
30.3200 14666.0000 1.0000
30.3800 14158.0000 1.0000
30.4400 14134.0000 1.0000
30.5000 13736.0000 1.0000
30.5600 14105.0000 1.0000
30.6200 13794.0000 1.0000
30.6800 13962.0000 1.0000
30.7400 13757.0000 1.0000
30.8000 13833.0000 1.0000
30.8600 13828.0000 1.0000
30.9200 13807.0000 1.0000
30.9800 13646.0000 1.0000
31.0400 13736.0000 1.0000
31.1000 13872.0000 1.0000
31.1600 13792.0000 1.0000
31.2200 13615.0000 1.0000
31.2800 13685.0000 1.0000
31.3400 13789.0000 1.0000
31.4000 13840.0000 1.0000
31.4600 13712.0000 1.0000
31.5200 13661.0000 1.0000
31.5800 13588.0000 1.0000
31.6400 13787.0000 1.0000
31.7000 13923.0000 1.0000
31.7600 13726.0000 1.0000
31.8200 13835.0000 1.0000
31.8800 13970.0000 1.0000
31.9400 13786.0000 1.0000
32.0000 14073.0000 1.0000
32.0600 13910.0000 1.0000
32.1200 13931.0000 1.0000
32.1800 13811.0000 1.0000
32.2400 13789.0000 1.0000
32.3000 13794.0000 1.0000
32.3600 13743.0000 1.0000
32.4200 13805.0000 1.0000
32.4800 13829.0000 1.0000
32.5400 13832.0000 1.0000
32.6000 13909.0000 1.0000
32.6600 13818.0000 1.0000
32.7200 13862.0000 1.0000
32.7800 14019.0000 1.0000
32.8400 13998.0000 1.0000
32.9000 14267.0000 1.0000
32.9600 14689.0000 1.0000
33.0200 15547.0000 1.0000
33.0800 17237.0000 1.0000
33.1400 21875.0000 1.0000
33.2000 22037.0000 1.0000
33.2600 19145.0000 1.0000
33.3200 15851.0000 1.0000
33.3800 14496.0000 1.0000
33.4400 14070.0000 1.0000
33.5000 14063.0000 1.0000
33.5600 13900.0000 1.0000
33.6200 13753.0000 1.0000
33.6800 13926.0000 1.0000
33.7400 13837.0000 1.0000
33.8000 13751.0000 1.0000
33.8600 13854.0000 1.0000
33.9200 14036.0000 1.0000
33.9800 13600.0000 1.0000
34.0400 13794.0000 1.0000
34.1000 13883.0000 1.0000
34.1600 13854.0000 1.0000
34.2200 13712.0000 1.0000
34.2800 13824.0000 1.0000
34.3400 13808.0000 1.0000
34.4000 13702.0000 1.0000
34.4600 13962.0000 1.0000
34.5200 13734.0000 1.0000
34.5800 13982.0000 1.0000
34.6400 13957.0000 1.0000
34.7000 13921.0000 1.0000
34.7600 13873.0000 1.0000
34.8200 13880.0000 1.0000
34.8800 13862.0000 1.0000
34.9400 13867.0000 1.0000
35.0000 14151.0000 1.0000
35.0600 14492.0000 1.0000
35.1200 15160.0000 1.0000
35.1800 15554.0000 1.0000
35.2400 15637.0000 1.0000
35.3000 15837.0000 1.0000
35.3600 17253.0000 1.0000
35.4200 21666.0000 1.0000
35.4800 27984.0000 1.0000
35.5400 27582.0000 1.0000
35.6000 27013.0000 1.0000
35.6600 23845.0000 1.0000
35.7200 19837.0000 1.0000
35.7800 16751.0000 1.0000
35.8400 15072.0000 1.0000
35.9000 14211.0000 1.0000
35.9600 14181.0000 1.0000
36.0200 13959.0000 1.0000
36.0800 13988.0000 1.0000
36.1400 13982.0000 1.0000
36.2000 13769.0000 1.0000
36.2600 13781.0000 1.0000
36.3200 13703.0000 1.0000
36.3800 13708.0000 1.0000
36.4400 13943.0000 1.0000
36.5000 13858.0000 1.0000
36.5600 14073.0000 1.0000
36.6200 13862.0000 1.0000
36.6800 13829.0000 1.0000
36.7400 13935.0000 1.0000
36.8000 13865.0000 1.0000
36.8600 13495.0000 1.0000
36.9200 13835.0000 1.0000
36.9800 13905.0000 1.0000
37.0400 14014.0000 1.0000
37.1000 14584.0000 1.0000
37.1600 14618.0000 1.0000
37.2200 14257.0000 1.0000
37.2800 13806.0000 1.0000
37.3400 13690.0000 1.0000
37.4000 13641.0000 1.0000
37.4600 13451.0000 1.0000
37.5200 13510.0000 1.0000
37.5800 13770.0000 1.0000
37.6400 13717.0000 1.0000
37.7000 13938.0000 1.0000
37.7600 14015.0000 1.0000
37.8200 14105.0000 1.0000
37.8800 13839.0000 1.0000
37.9400 13728.0000 1.0000
38.0000 13771.0000 1.0000
38.0600 13594.0000 1.0000
38.1200 13615.0000 1.0000
38.1800 13611.0000 1.0000
38.2400 13676.0000 1.0000
38.3000 13613.0000 1.0000
38.3600 13407.0000 1.0000
38.4200 13552.0000 1.0000
38.4800 13599.0000 1.0000
38.5400 13517.0000 1.0000
38.6000 13645.0000 1.0000
38.6600 13522.0000 1.0000
38.7200 13509.0000 1.0000
38.7800 13756.0000 1.0000
38.8400 13498.0000 1.0000
38.9000 13441.0000 1.0000
38.9600 13671.0000 1.0000
39.0200 13548.0000 1.0000
39.0800 13826.0000 1.0000
39.1400 13540.0000 1.0000
39.2000 13801.0000 1.0000
39.2600 13664.0000 1.0000
39.3200 13654.0000 1.0000
39.3800 13866.0000 1.0000
39.4400 13613.0000 1.0000
39.5000 13783.0000 1.0000
39.5600 13679.0000 1.0000
39.6200 13463.0000 1.0000
39.6800 13649.0000 1.0000
39.7400 13696.0000 1.0000
39.8000 13507.0000 1.0000
39.8600 13543.0000 1.0000
39.9200 13394.0000 1.0000
39.9800 13461.0000 1.0000
40.0400 13400.0000 1.0000
40.1000 13632.0000 1.0000
40.1600 13628.0000 1.0000
40.2200 13696.0000 1.0000
40.2800 13934.0000 1.0000
40.3400 14004.0000 1.0000
40.4000 13972.0000 1.0000
40.4600 13590.0000 1.0000
40.5200 13805.0000 1.0000
40.5800 13674.0000 1.0000
40.6400 13795.0000 1.0000
40.7000 13853.0000 1.0000
40.7600 14179.0000 1.0000
40.8200 14873.0000 1.0000
40.8800 15628.0000 1.0000
40.9400 14807.0000 1.0000
41.0000 14519.0000 1.0000
41.0600 14064.0000 1.0000
41.1200 13810.0000 1.0000
41.1800 13721.0000 1.0000
41.2400 13682.0000 1.0000
41.3000 13569.0000 1.0000
41.3600 13445.0000 1.0000
41.4200 13467.0000 1.0000
41.4800 13522.0000 1.0000
41.5400 13457.0000 1.0000
41.6000 13467.0000 1.0000
41.6600 13645.0000 1.0000
41.7200 13592.0000 1.0000
41.7800 13534.0000 1.0000
41.8400 13655.0000 1.0000
41.9000 13586.0000 1.0000
41.9600 13715.0000 1.0000
42.0200 13477.0000 1.0000
42.0800 13638.0000 1.0000
42.1400 13591.0000 1.0000
42.2000 13599.0000 1.0000
42.2600 13623.0000 1.0000
42.3200 13732.0000 1.0000
42.3800 13670.0000 1.0000
42.4400 13719.0000 1.0000
42.5000 13888.0000 1.0000
42.5600 13588.0000 1.0000
42.6200 13653.0000 1.0000
42.6800 13599.0000 1.0000
42.7400 13544.0000 1.0000
42.8000 13658.0000 1.0000
42.8600 13834.0000 1.0000
42.9200 13722.0000 1.0000
42.9800 13986.0000 1.0000
43.0400 14640.0000 1.0000
43.1000 16123.0000 1.0000
43.1600 16117.0000 1.0000
43.2200 15923.0000 1.0000
43.2800 15645.0000 1.0000
43.3400 15545.0000 1.0000
43.4000 14962.0000 1.0000
43.4600 14590.0000 1.0000
43.5200 14389.0000 1.0000
43.5800 13936.0000 1.0000
43.6400 13686.0000 1.0000
43.7000 13631.0000 1.0000
43.7600 13539.0000 1.0000
43.8200 13728.0000 1.0000
43.8800 13623.0000 1.0000
43.9400 13502.0000 1.0000
44.0000 13246.0000 1.0000
44.0600 13519.0000 1.0000
44.1200 13561.0000 1.0000
44.1800 13399.0000 1.0000
44.2400 13326.0000 1.0000
44.3000 13502.0000 1.0000
44.3600 13546.0000 1.0000
44.4200 13496.0000 1.0000
44.4800 13367.0000 1.0000
44.5400 13299.0000 1.0000
44.6000 13559.0000 1.0000
44.6600 13663.0000 1.0000
44.7200 13661.0000 1.0000
44.7800 13306.0000 1.0000
44.8400 13480.0000 1.0000
44.9000 13475.0000 1.0000
44.9600 13558.0000 1.0000
45.0200 13436.0000 1.0000
45.0800 13608.0000 1.0000
45.1400 13543.0000 1.0000
45.2000 13434.0000 1.0000
45.2600 13254.0000 1.0000
45.3200 13471.0000 1.0000
45.3800 13440.0000 1.0000
45.4400 13416.0000 1.0000
45.5000 13323.0000 1.0000
45.5600 13349.0000 1.0000
45.6200 13434.0000 1.0000
45.6800 13479.0000 1.0000
45.7400 13356.0000 1.0000
45.8000 13496.0000 1.0000
45.8600 13481.0000 1.0000
45.9200 13526.0000 1.0000
45.9800 13659.0000 1.0000
46.0400 13338.0000 1.0000
46.1000 13257.0000 1.0000
46.1600 13423.0000 1.0000
46.2200 13523.0000 1.0000
46.2800 13597.0000 1.0000
46.3400 13615.0000 1.0000
46.4000 13387.0000 1.0000
46.4600 13636.0000 1.0000
46.5200 13432.0000 1.0000
46.5800 13629.0000 1.0000
46.6400 13499.0000 1.0000
46.7000 13501.0000 1.0000
46.7600 13479.0000 1.0000
46.8200 13387.0000 1.0000
46.8800 13644.0000 1.0000
46.9400 13512.0000 1.0000
47.0000 13553.0000 1.0000
47.0600 13371.0000 1.0000
47.1200 13424.0000 1.0000
47.1800 13264.0000 1.0000
47.2400 13276.0000 1.0000
47.3000 13358.0000 1.0000
47.3600 13622.0000 1.0000
47.4200 13555.0000 1.0000
47.4800 13489.0000 1.0000
47.5400 13426.0000 1.0000
47.6000 13494.0000 1.0000
47.6600 13421.0000 1.0000
47.7200 13478.0000 1.0000
47.7800 13371.0000 1.0000
47.8400 13601.0000 1.0000
47.9000 13523.0000 1.0000
47.9600 13411.0000 1.0000
48.0200 13417.0000 1.0000
48.0800 13703.0000 1.0000
48.1400 13573.0000 1.0000
48.2000 13290.0000 1.0000
48.2600 13496.0000 1.0000
48.3200 13412.0000 1.0000
48.3800 13333.0000 1.0000
48.4400 13514.0000 1.0000
48.5000 13399.0000 1.0000
48.5600 13520.0000 1.0000
48.6200 13306.0000 1.0000
48.6800 13456.0000 1.0000
48.7400 13455.0000 1.0000
48.8000 13795.0000 1.0000
48.8600 13399.0000 1.0000
48.9200 13360.0000 1.0000
48.9800 13505.0000 1.0000
49.0400 13541.0000 1.0000
49.1000 13615.0000 1.0000
49.1600 13383.0000 1.0000
49.2200 13808.0000 1.0000
49.2800 13729.0000 1.0000
49.3400 14372.0000 1.0000
49.4000 15161.0000 1.0000
49.4600 16545.0000 1.0000
49.5200 15859.0000 1.0000
49.5800 15453.0000 1.0000
49.6400 14794.0000 1.0000
49.7000 14012.0000 1.0000
49.7600 13644.0000 1.0000
49.8200 13454.0000 1.0000
49.8800 13591.0000 1.0000
49.9400 13634.0000 1.0000
50.0000 13471.0000 1.0000
50.0600 13654.0000 1.0000
50.1200 13929.0000 1.0000
50.1800 14458.0000 1.0000
50.2400 13851.0000 1.0000
50.3000 13815.0000 1.0000
50.3600 13621.0000 1.0000
50.4200 13588.0000 1.0000
50.4800 13301.0000 1.0000
50.5400 13559.0000 1.0000
50.6000 13463.0000 1.0000
50.6600 13410.0000 1.0000
50.7200 13459.0000 1.0000
50.7800 13469.0000 1.0000
50.8400 13435.0000 1.0000
50.9000 13233.0000 1.0000
50.9600 13642.0000 1.0000
51.0200 13330.0000 1.0000
51.0800 13533.0000 1.0000
51.1400 13635.0000 1.0000
51.2000 13505.0000 1.0000
51.2600 13289.0000 1.0000
51.3200 13574.0000 1.0000
51.3800 13370.0000 1.0000
51.4400 13400.0000 1.0000
51.5000 13567.0000 1.0000
51.5600 13774.0000 1.0000
51.6200 13516.0000 1.0000
51.6800 13557.0000 1.0000
51.7400 13522.0000 1.0000
51.8000 13581.0000 1.0000
51.8600 13418.0000 1.0000
51.9200 13297.0000 1.0000
51.9800 13242.0000 1.0000
52.0400 13288.0000 1.0000
52.1000 13476.0000 1.0000
52.1600 13419.0000 1.0000
52.2200 13310.0000 1.0000
52.2800 13521.0000 1.0000
52.3400 13473.0000 1.0000
52.4000 13396.0000 1.0000
52.4600 13781.0000 1.0000
52.5200 13966.0000 1.0000
52.5800 13927.0000 1.0000
52.6400 13607.0000 1.0000
52.7000 13750.0000 1.0000
52.7600 13556.0000 1.0000
52.8200 13473.0000 1.0000
52.8800 13529.0000 1.0000
52.9400 13478.0000 1.0000
53.0000 13641.0000 1.0000
53.0600 13483.0000 1.0000
53.1200 13659.0000 1.0000
53.1800 13477.0000 1.0000
53.2400 13588.0000 1.0000
53.3000 13689.0000 1.0000
53.3600 13523.0000 1.0000
53.4200 13929.0000 1.0000
53.4800 14379.0000 1.0000
53.5400 14292.0000 1.0000
53.6000 14346.0000 1.0000
53.6600 14292.0000 1.0000
53.7200 14010.0000 1.0000
53.7800 13801.0000 1.0000
53.8400 13966.0000 1.0000
53.9000 14138.0000 1.0000
53.9600 14449.0000 1.0000
54.0200 15962.0000 1.0000
54.0800 17104.0000 1.0000
54.1400 15864.0000 1.0000
54.2000 15692.0000 1.0000
54.2600 15201.0000 1.0000
54.3200 13872.0000 1.0000
54.3800 13774.0000 1.0000
54.4400 13804.0000 1.0000
54.5000 13493.0000 1.0000
54.5600 13592.0000 1.0000
54.6200 13569.0000 1.0000
54.6800 13562.0000 1.0000
54.7400 13555.0000 1.0000
54.8000 13546.0000 1.0000
54.8600 13681.0000 1.0000
54.9200 13499.0000 1.0000
54.9800 13419.0000 1.0000
55.0400 13567.0000 1.0000
55.1000 13397.0000 1.0000
55.1600 13520.0000 1.0000
55.2200 13577.0000 1.0000
55.2800 13537.0000 1.0000
55.3400 13451.0000 1.0000
55.4000 13407.0000 1.0000
55.4600 13327.0000 1.0000
55.5200 13279.0000 1.0000
55.5800 13523.0000 1.0000
55.6400 13440.0000 1.0000
55.7000 13628.0000 1.0000
55.7600 13520.0000 1.0000
55.8200 13316.0000 1.0000
55.8800 13360.0000 1.0000
55.9400 13523.0000 1.0000
56.0000 13521.0000 1.0000
56.0600 13567.0000 1.0000
56.1200 13693.0000 1.0000
56.1800 13367.0000 1.0000
56.2400 13280.0000 1.0000
56.3000 13585.0000 1.0000
56.3600 13454.0000 1.0000
56.4200 13494.0000 1.0000
56.4800 13582.0000 1.0000
56.5400 13383.0000 1.0000
56.6000 13612.0000 1.0000
56.6600 13683.0000 1.0000
56.7200 13635.0000 1.0000
56.7800 13772.0000 1.0000
56.8400 13882.0000 1.0000
56.9000 14311.0000 1.0000
56.9600 15234.0000 1.0000
57.0200 16566.0000 1.0000
57.0800 16025.0000 1.0000
57.1400 16115.0000 1.0000
57.2000 15754.0000 1.0000
57.2600 15309.0000 1.0000
57.3200 14629.0000 1.0000
57.3800 14555.0000 1.0000
57.4400 14476.0000 1.0000
57.5000 15038.0000 1.0000
57.5600 15010.0000 1.0000
57.6200 15072.0000 1.0000
57.6800 14707.0000 1.0000
57.7400 14025.0000 1.0000
57.8000 13905.0000 1.0000
57.8600 13448.0000 1.0000
57.9200 13703.0000 1.0000
57.9800 13363.0000 1.0000
58.0400 13405.0000 1.0000
58.1000 13355.0000 1.0000
58.1600 13541.0000 1.0000
58.2200 13392.0000 1.0000
58.2800 13346.0000 1.0000
58.3400 13437.0000 1.0000
58.4000 13577.0000 1.0000
58.4600 13489.0000 1.0000
58.5200 13192.0000 1.0000
58.5800 13366.0000 1.0000
58.6400 13494.0000 1.0000
58.7000 13362.0000 1.0000
58.7600 13436.0000 1.0000
58.8200 13436.0000 1.0000
58.8800 13680.0000 1.0000
58.9400 13363.0000 1.0000
59.0000 13499.0000 1.0000
59.0600 13359.0000 1.0000
59.1200 13599.0000 1.0000
59.1800 13448.0000 1.0000
59.2400 13395.0000 1.0000
59.3000 13472.0000 1.0000
59.3600 13386.0000 1.0000
59.4200 13378.0000 1.0000
59.4800 13338.0000 1.0000
59.5400 13285.0000 1.0000
59.6000 13392.0000 1.0000
59.6600 13424.0000 1.0000
59.7200 13382.0000 1.0000
59.7800 13024.0000 1.0000
59.8400 13432.0000 1.0000
59.9000 13528.0000 1.0000
59.9600 13883.0000 1.0000
60.0200 13508.0000 1.0000
60.0800 13503.0000 1.0000
60.1400 13552.0000 1.0000
60.2000 13410.0000 1.0000
60.2600 13346.0000 1.0000
60.3200 13566.0000 1.0000
60.3800 13248.0000 1.0000
60.4400 13387.0000 1.0000
60.5000 13663.0000 1.0000
60.5600 13376.0000 1.0000
60.6200 13484.0000 1.0000
60.6800 13405.0000 1.0000
60.7400 13395.0000 1.0000
60.8000 13553.0000 1.0000
60.8600 13299.0000 1.0000
60.9200 13409.0000 1.0000
60.9800 13531.0000 1.0000
61.0400 13510.0000 1.0000
61.1000 13379.0000 1.0000
61.1600 13175.0000 1.0000
61.2200 13347.0000 1.0000
61.2800 13486.0000 1.0000
61.3400 13457.0000 1.0000
61.4000 13294.0000 1.0000
61.4600 13607.0000 1.0000
61.5200 13476.0000 1.0000
61.5800 13571.0000 1.0000
61.6400 13236.0000 1.0000
61.7000 13568.0000 1.0000
61.7600 13192.0000 1.0000
61.8200 13561.0000 1.0000
61.8800 13554.0000 1.0000
61.9400 13557.0000 1.0000
62.0000 13536.0000 1.0000
62.0600 13530.0000 1.0000
62.1200 13525.0000 1.0000
62.1800 13693.0000 1.0000
62.2400 13776.0000 1.0000
62.3000 14080.0000 1.0000
62.3600 14915.0000 1.0000
62.4200 16210.0000 1.0000
62.4800 16190.0000 1.0000
62.5400 16421.0000 1.0000
62.6000 18848.0000 1.0000
62.6600 18587.0000 1.0000
62.7200 16867.0000 1.0000
62.7800 16874.0000 1.0000
62.8400 16027.0000 1.0000
62.9000 14879.0000 1.0000
62.9600 14239.0000 1.0000
63.0200 14059.0000 1.0000
63.0800 13808.0000 1.0000
63.1400 13729.0000 1.0000
63.2000 13670.0000 1.0000
63.2600 13297.0000 1.0000
63.3200 13275.0000 1.0000
63.3800 13469.0000 1.0000
63.4400 13590.0000 1.0000
63.5000 13342.0000 1.0000
63.5600 13518.0000 1.0000
63.6200 13406.0000 1.0000
63.6800 13654.0000 1.0000
63.7400 13619.0000 1.0000
63.8000 13555.0000 1.0000
63.8600 13738.0000 1.0000
63.9200 14444.0000 1.0000
63.9800 15624.0000 1.0000
64.0400 15471.0000 1.0000
64.1000 14499.0000 1.0000
64.1600 14776.0000 1.0000
64.2200 14277.0000 1.0000
64.2800 13533.0000 1.0000
64.3400 13494.0000 1.0000
64.4000 13581.0000 1.0000
64.4600 13547.0000 1.0000
64.5200 13496.0000 1.0000
64.5800 13467.0000 1.0000
64.6400 13496.0000 1.0000
64.7000 13272.0000 1.0000
64.7600 13261.0000 1.0000
64.8200 13388.0000 1.0000
64.8800 13373.0000 1.0000
64.9400 13317.0000 1.0000
65.0000 13549.0000 1.0000
65.0600 13346.0000 1.0000
65.1200 13476.0000 1.0000
65.1800 13553.0000 1.0000
65.2400 13357.0000 1.0000
65.3000 13443.0000 1.0000
65.3600 13571.0000 1.0000
65.4200 13400.0000 1.0000
65.4800 13371.0000 1.0000
65.5400 13656.0000 1.0000
65.6000 13293.0000 1.0000
65.6600 13604.0000 1.0000
65.7200 13565.0000 1.0000
65.7800 13356.0000 1.0000
65.8400 13410.0000 1.0000
65.9000 13434.0000 1.0000
65.9600 13470.0000 1.0000
66.0200 13473.0000 1.0000
66.0800 13448.0000 1.0000
66.1400 13452.0000 1.0000
66.2000 13709.0000 1.0000
66.2600 13417.0000 1.0000
66.3200 13445.0000 1.0000
66.3800 13564.0000 1.0000
66.4400 13506.0000 1.0000
66.5000 13730.0000 1.0000
66.5600 13648.0000 1.0000
66.6200 13484.0000 1.0000
66.6800 13660.0000 1.0000
66.7400 13501.0000 1.0000
66.8000 13488.0000 1.0000
66.8600 13490.0000 1.0000
66.9200 13438.0000 1.0000
66.9800 13524.0000 1.0000
67.0400 13332.0000 1.0000
67.1000 13305.0000 1.0000
67.1600 13484.0000 1.0000
67.2200 13354.0000 1.0000
67.2800 13422.0000 1.0000
67.3400 13396.0000 1.0000
67.4000 13515.0000 1.0000
67.4600 13613.0000 1.0000
67.5200 13496.0000 1.0000
67.5800 13586.0000 1.0000
67.6400 13273.0000 1.0000
67.7000 13468.0000 1.0000
67.7600 13573.0000 1.0000
67.8200 13616.0000 1.0000
67.8800 13508.0000 1.0000
67.9400 13781.0000 1.0000
68.0000 13681.0000 1.0000
68.0600 13581.0000 1.0000
68.1200 13858.0000 1.0000
68.1800 14501.0000 1.0000
68.2400 13913.0000 1.0000
68.3000 13921.0000 1.0000
68.3600 13875.0000 1.0000
68.4200 13836.0000 1.0000
68.4800 13640.0000 1.0000
68.5400 13664.0000 1.0000
68.6000 13428.0000 1.0000
68.6600 13233.0000 1.0000
68.7200 13328.0000 1.0000
68.7800 13461.0000 1.0000
68.8400 13391.0000 1.0000
68.9000 13477.0000 1.0000
68.9600 13504.0000 1.0000
69.0200 13568.0000 1.0000
69.0800 13444.0000 1.0000
69.1400 13339.0000 1.0000
69.2000 13501.0000 1.0000
69.2600 13343.0000 1.0000
69.3200 13421.0000 1.0000
69.3800 13315.0000 1.0000
69.4400 13292.0000 1.0000
69.5000 13557.0000 1.0000
69.5600 13493.0000 1.0000
69.6200 13618.0000 1.0000
69.6800 13513.0000 1.0000
69.7400 13537.0000 1.0000
69.8000 13589.0000 1.0000
69.8600 13530.0000 1.0000
69.9200 13452.0000 1.0000
69.9800 13349.0000 1.0000
70.0400 13265.0000 1.0000
70.1000 13398.0000 1.0000
70.1600 13364.0000 1.0000
70.2200 13073.0000 1.0000
70.2800 13494.0000 1.0000
70.3400 13375.0000 1.0000
70.4000 13643.0000 1.0000
70.4600 13306.0000 1.0000
70.5200 13516.0000 1.0000
70.5800 13427.0000 1.0000
70.6400 13560.0000 1.0000
70.7000 13353.0000 1.0000
70.7600 13467.0000 1.0000
70.8200 13256.0000 1.0000
70.8800 13434.0000 1.0000
70.9400 13461.0000 1.0000
71.0000 13574.0000 1.0000
71.0600 13749.0000 1.0000
71.1200 13727.0000 1.0000
71.1800 13573.0000 1.0000
71.2400 13649.0000 1.0000
71.3000 13627.0000 1.0000
71.3600 13519.0000 1.0000
71.4200 13495.0000 1.0000
71.4800 13430.0000 1.0000
71.5400 13292.0000 1.0000
71.6000 13342.0000 1.0000
71.6600 13310.0000 1.0000
71.7200 13490.0000 1.0000
71.7800 13468.0000 1.0000
71.8400 13502.0000 1.0000
71.9000 13852.0000 1.0000
71.9600 14148.0000 1.0000
72.0200 13890.0000 1.0000
72.0800 13722.0000 1.0000
72.1400 13876.0000 1.0000
72.2000 13821.0000 1.0000
72.2600 13370.0000 1.0000
72.3200 13447.0000 1.0000
72.3800 13375.0000 1.0000
72.4400 13098.0000 1.0000
72.5000 13272.0000 1.0000
72.5600 13357.0000 1.0000
72.6200 13391.0000 1.0000
72.6800 13462.0000 1.0000
72.7400 13463.0000 1.0000
72.8000 13508.0000 1.0000
72.8600 13354.0000 1.0000
72.9200 13352.0000 1.0000
72.9800 13409.0000 1.0000
73.0400 13463.0000 1.0000
73.1000 13295.0000 1.0000
73.1600 13265.0000 1.0000
73.2200 13340.0000 1.0000
73.2800 13237.0000 1.0000
73.3400 13355.0000 1.0000
73.4000 13515.0000 1.0000
73.4600 13369.0000 1.0000
73.5200 13349.0000 1.0000
73.5800 13318.0000 1.0000
73.6400 13230.0000 1.0000
73.7000 13452.0000 1.0000
73.7600 13167.0000 1.0000
73.8200 13344.0000 1.0000
73.8800 13291.0000 1.0000
73.9400 13541.0000 1.0000
74.0000 13532.0000 1.0000
74.0600 14286.0000 1.0000
74.1200 14158.0000 1.0000
74.1800 13857.0000 1.0000
74.2400 14010.0000 1.0000
74.3000 14170.0000 1.0000
74.3600 13882.0000 1.0000
74.4200 13701.0000 1.0000
74.4800 13702.0000 1.0000
74.5400 13759.0000 1.0000
74.6000 13509.0000 1.0000
74.6600 13215.0000 1.0000
74.7200 13467.0000 1.0000
74.7800 13353.0000 1.0000
74.8400 13365.0000 1.0000
74.9000 13495.0000 1.0000
74.9600 13341.0000 1.0000
75.0200 13557.0000 1.0000
75.0800 13764.0000 1.0000
75.1400 13573.0000 1.0000
75.2000 13510.0000 1.0000
75.2600 13724.0000 1.0000
75.3200 13791.0000 1.0000
75.3800 13674.0000 1.0000
75.4400 14003.0000 1.0000
75.5000 13841.0000 1.0000
75.5600 13695.0000 1.0000
75.6200 13604.0000 1.0000
75.6800 13727.0000 1.0000
75.7400 13471.0000 1.0000
75.8000 13393.0000 1.0000
75.8600 13388.0000 1.0000
75.9200 13563.0000 1.0000
75.9800 13133.0000 1.0000
76.0400 13156.0000 1.0000
76.1000 13365.0000 1.0000
76.1600 13299.0000 1.0000
76.2200 13235.0000 1.0000
76.2800 13366.0000 1.0000
76.3400 13494.0000 1.0000
76.4000 13347.0000 1.0000
76.4600 13234.0000 1.0000
76.5200 13436.0000 1.0000
76.5800 13437.0000 1.0000
76.6400 13257.0000 1.0000
76.7000 13436.0000 1.0000
76.7600 13246.0000 1.0000
76.8200 13472.0000 1.0000
76.8800 13476.0000 1.0000
76.9400 13424.0000 1.0000
77.0000 13353.0000 1.0000
77.0600 13508.0000 1.0000
77.1200 13554.0000 1.0000
77.1800 13597.0000 1.0000
77.2400 13563.0000 1.0000
77.3000 13433.0000 1.0000
77.3600 13416.0000 1.0000
77.4200 13518.0000 1.0000
77.4800 13543.0000 1.0000
77.5400 13309.0000 1.0000
77.6000 13534.0000 1.0000
77.6600 13446.0000 1.0000
77.7200 13489.0000 1.0000
77.7800 13477.0000 1.0000
77.8400 13357.0000 1.0000
77.9000 13306.0000 1.0000
77.9600 13282.0000 1.0000
78.0200 13305.0000 1.0000
78.0800 13334.0000 1.0000
78.1400 13347.0000 1.0000
78.2000 13470.0000 1.0000
78.2600 13321.0000 1.0000
78.3200 13200.0000 1.0000
78.3800 13372.0000 1.0000
78.4400 13299.0000 1.0000
78.5000 13328.0000 1.0000
78.5600 13362.0000 1.0000
78.6200 13379.0000 1.0000
78.6800 13187.0000 1.0000
78.7400 13193.0000 1.0000
78.8000 13302.0000 1.0000
78.8600 13390.0000 1.0000
78.9200 13348.0000 1.0000
78.9800 13515.0000 1.0000
79.0400 13623.0000 1.0000
79.1000 13662.0000 1.0000
79.1600 13615.0000 1.0000
79.2200 13352.0000 1.0000
79.2800 13405.0000 1.0000
79.3400 13528.0000 1.0000
79.4000 13421.0000 1.0000
79.4600 13627.0000 1.0000
79.5200 13636.0000 1.0000
79.5800 13393.0000 1.0000
79.6400 13115.0000 1.0000
79.7000 13374.0000 1.0000
79.7600 13313.0000 1.0000
79.8200 13182.0000 1.0000
79.8800 13443.0000 1.0000
79.9400 13435.0000 1.0000
80.0000 13455.0000 1.0000
80.0600 13362.0000 1.0000
80.1200 13309.0000 1.0000
80.1800 13330.0000 1.0000
80.2400 13283.0000 1.0000
80.3000 13260.0000 1.0000
80.3600 13293.0000 1.0000
80.4200 13356.0000 1.0000
80.4800 13586.0000 1.0000
80.5400 13559.0000 1.0000
80.6000 13693.0000 1.0000
80.6600 13720.0000 1.0000
80.7200 13892.0000 1.0000
80.7800 13738.0000 1.0000
80.8400 13643.0000 1.0000
80.9000 13461.0000 1.0000
80.9600 13624.0000 1.0000
81.0200 13493.0000 1.0000
81.0800 13373.0000 1.0000
81.1400 13348.0000 1.0000
81.2000 13260.0000 1.0000
81.2600 13268.0000 1.0000
81.3200 13275.0000 1.0000
81.3800 13404.0000 1.0000
81.4400 13452.0000 1.0000
81.5000 13316.0000 1.0000
81.5600 13275.0000 1.0000
81.6200 13396.0000 1.0000
81.6800 13380.0000 1.0000
81.7400 13577.0000 1.0000
81.8000 13375.0000 1.0000
81.8600 13236.0000 1.0000
81.9200 13376.0000 1.0000
81.9800 13179.0000 1.0000
82.0400 13176.0000 1.0000
82.1000 13117.0000 1.0000
82.1600 13226.0000 1.0000
82.2200 13171.0000 1.0000
82.2800 13357.0000 1.0000
82.3400 13372.0000 1.0000
82.4000 13324.0000 1.0000
82.4600 13279.0000 1.0000
82.5200 13238.0000 1.0000
82.5800 13431.0000 1.0000
82.6400 13295.0000 1.0000
82.7000 13264.0000 1.0000
82.7600 13451.0000 1.0000
82.8200 13317.0000 1.0000
82.8800 13416.0000 1.0000
82.9400 13635.0000 1.0000
83.0000 13492.0000 1.0000
83.0600 13685.0000 1.0000
83.1200 13501.0000 1.0000
83.1800 13433.0000 1.0000
83.2400 13523.0000 1.0000
83.3000 13121.0000 1.0000
83.3600 13465.0000 1.0000
83.4200 13403.0000 1.0000
83.4800 13195.0000 1.0000
83.5400 13507.0000 1.0000
83.6000 13349.0000 1.0000
83.6600 13362.0000 1.0000
83.7200 13211.0000 1.0000
83.7800 13290.0000 1.0000
83.8400 13506.0000 1.0000
83.9000 13383.0000 1.0000
83.9600 13306.0000 1.0000
84.0200 13279.0000 1.0000
84.0800 13342.0000 1.0000
84.1400 13398.0000 1.0000
84.2000 13285.0000 1.0000
84.2600 13349.0000 1.0000
84.3200 13241.0000 1.0000
84.3800 13407.0000 1.0000
84.4400 13228.0000 1.0000
84.5000 13134.0000 1.0000
84.5600 13275.0000 1.0000
84.6200 13482.0000 1.0000
84.6800 13332.0000 1.0000
84.7400 13286.0000 1.0000
84.8000 13386.0000 1.0000
84.8600 13673.0000 1.0000
84.9200 13966.0000 1.0000
84.9800 13683.0000 1.0000
85.0400 13258.0000 1.0000
85.1000 13466.0000 1.0000
85.1600 13528.0000 1.0000
85.2200 13554.0000 1.0000
85.2800 13219.0000 1.0000
85.3400 13513.0000 1.0000
85.4000 13461.0000 1.0000
85.4600 13218.0000 1.0000
85.5200 13246.0000 1.0000
85.5800 13061.0000 1.0000
85.6400 13222.0000 1.0000
85.7000 12961.0000 1.0000
85.7600 13369.0000 1.0000
85.8200 13238.0000 1.0000
85.8800 13253.0000 1.0000
85.9400 13063.0000 1.0000
86.0000 13091.0000 1.0000
86.0600 13157.0000 1.0000
86.1200 13507.0000 1.0000
86.1800 13223.0000 1.0000
86.2400 13148.0000 1.0000
86.3000 13378.0000 1.0000
86.3600 13448.0000 1.0000
86.4200 13319.0000 1.0000
86.4800 13602.0000 1.0000
86.5400 13428.0000 1.0000
86.6000 13348.0000 1.0000
86.6600 13247.0000 1.0000
86.7200 13451.0000 1.0000
86.7800 13386.0000 1.0000
86.8400 13534.0000 1.0000
86.9000 13517.0000 1.0000
86.9600 13632.0000 1.0000
87.0200 13478.0000 1.0000
87.0800 13434.0000 1.0000
87.1400 13492.0000 1.0000
87.2000 13653.0000 1.0000
87.2600 13296.0000 1.0000
87.3200 13258.0000 1.0000
87.3800 13324.0000 1.0000
87.4400 13170.0000 1.0000
87.5000 13209.0000 1.0000
87.5600 13340.0000 1.0000
87.6200 13465.0000 1.0000
87.6800 13222.0000 1.0000
87.7400 13157.0000 1.0000
87.8000 13040.0000 1.0000
87.8600 13127.0000 1.0000
87.9200 13281.0000 1.0000
87.9800 13306.0000 1.0000
88.0400 13109.0000 1.0000
88.1000 13471.0000 1.0000
88.1600 13219.0000 1.0000
88.2200 13258.0000 1.0000
88.2800 13121.0000 1.0000
88.3400 13316.0000 1.0000
88.4000 13323.0000 1.0000
88.4600 13603.0000 1.0000
88.5200 13756.0000 1.0000
88.5800 13678.0000 1.0000
88.6400 13417.0000 1.0000
88.7000 13439.0000 1.0000
88.7600 13647.0000 1.0000
88.8200 13655.0000 1.0000
88.8800 13515.0000 1.0000
88.9400 13330.0000 1.0000
89.0000 13378.0000 1.0000
89.0600 13433.0000 1.0000
89.1200 13169.0000 1.0000
89.1800 13251.0000 1.0000
89.2400 13264.0000 1.0000
89.3000 13351.0000 1.0000
89.3600 13294.0000 1.0000
89.4200 13279.0000 1.0000
89.4800 13244.0000 1.0000
89.5400 13469.0000 1.0000
89.6000 13579.0000 1.0000
89.6600 13859.0000 1.0000
89.7200 14127.0000 1.0000
89.7800 14212.0000 1.0000
89.8400 14007.0000 1.0000
89.9000 14075.0000 1.0000
89.9600 14057.0000 1.0000
90.0000 14031.0000 1.0000
*RAS_INT_END
*RAS_TEMPERATURE_START
*RAS_TEMPERATURE_END
*RAS_DATA_END