File: XRD/Data/20200819_mix_01.ras
*RAS_DATA_START
*RAS_HEADER_START
*DISP_FMT_X "%.2f"
*DISP_FMT_Y "%.0f"
*DISP_FULLSCALE "29324.0000000000"
*DISP_LINE_COLOR "255.0000000000"
*DISP_LINE_STYLE "0.0000000000"
*DISP_LINE_WIDTH "0.2500000000"
*DISP_NOTE "測定データ-2"
*DISP_OFFSET_Y "0.0000000000"
*DISP_PEAKSEARCH_UNIT_Y "cps"
*DISP_RANGE_BOTTOM "0.0000000000"
*DISP_RANGE_LEFT "20.0000000000"
*DISP_RANGE_LOGCUTOFF "0.0100000000"
*DISP_RANGE_RIGHT "90.0000000000"
*DISP_RANGE_TOP "29324.0000000000"
*DISP_SCALE_MODE_Y "0.0000000000"
*DISP_TAB_NAME "2θ/θ"
*DISP_TITLE_Y "強度"
*DISP_UNIT_Y "cps"
*DISP_WINDOW_NAME "MSG_MACROENGINE"
*FILE_COMMENT " "
*FILE_MD5 ""
*FILE_MEMO " "
*FILE_OPERATOR "Administrator"
*FILE_SAMPLE " "
*FILE_TYPE "RAS_RAW"
*FILE_USERGROUP "システムマネージャ"
*FILE_VERSION "1.0000000000"
*HW_ATTACHMENT_ID "ATT0025"
*HW_ATTACHMENT_NAME "標準|Standard"
*HW_COUNTER_ID-0 "CUT0025"
*HW_COUNTER_ID-1 "CUT0020"
*HW_COUNTER_ID-2 "CUT0020"
*HW_COUNTER_ID-3 "CSL0021"
*HW_COUNTER_ID-4 "CMC0021"
*HW_COUNTER_NAME-0 "D/teX Ultra|D/teX Ultra"
*HW_COUNTER_NAME-1 "None|None"
*HW_COUNTER_NAME-2 "None|None"
*HW_COUNTER_NAME-3 "BBM|BBM"
*HW_COUNTER_NAME-4 "検出器モノクロメータ|Detector monochromator"
*HW_COUNTER_SELECT_NAME "D/teX Ultra|D/teX Ultra"
*HW_GONIOMETER_ID "GON0023"
*HW_GONIOMETER_NAME "SmartLab|SmartLab"
*HW_GONIOMETER_RADIUS-0 "90.0"
*HW_GONIOMETER_RADIUS-1 "114.0"
*HW_GONIOMETER_RADIUS-2 "190.0"
*HW_GONIOMETER_RADIUS-3 "300.0"
*HW_GONIOMETER_RADIUS-4 "187.0"
*HW_GONIOMETER_RADIUS-5 "300.0"
*HW_GONIOMETER_RADIUS-6 "113.0"
*HW_GONIOMETER_RADIUS-7 "331.0"
*HW_I_OPT_ID-0 "CBO0021"
*HW_I_OPT_ID-1 "ICR0023"
*HW_I_OPT_ID-2 "ISL0021"
*HW_I_OPT_ID-3 "ISO0021"
*HW_I_OPT_ID-4 "IAD0021"
*HW_I_OPT_ID-5 "IPR0001"
*HW_I_OPT_NAME-0 "CBOユニット|CBO unit"
*HW_I_OPT_NAME-1 "標準入射光学ユニット|Standard incident optical unit"
*HW_I_OPT_NAME-2 "標準入射スリットボックス|Standard incident slit box"
*HW_I_OPT_NAME-3 "入射平行スリット|Incident parallel slit"
*HW_I_OPT_NAME-4 "長手制限スリット|Length limiting slit"
*HW_I_OPT_NAME-5 "None|None"
*HW_R_ATTENUATER_AUTOMODE "0"
*HW_R_OPT_ID-0 "RSS0021"
*HW_R_OPT_ID-1 "RCR0023"
*HW_R_OPT_ID-2 "RSO0021"
*HW_R_OPT_ID-3 "RRS0021"
*HW_R_OPT_ID-4 "ATN0021"
*HW_R_OPT_ID-5 "RFL0021"
*HW_R_OPT_ID-6 "RAD0021"
*HW_R_OPT_NAME-0 "標準受光スリットボックス1|Standard receiving slit box # 1"
*HW_R_OPT_NAME-1 "標準受光光学ユニット1|Standard receiving unit # 1"
*HW_R_OPT_NAME-2 "標準受光光学ユニット2|Standard receiving optical unit # 2"
*HW_R_OPT_NAME-3 "標準受光スリットボックス2|Standard receiving slit box # 2"
*HW_R_OPT_NAME-4 "標準アッテネータ|Standard Attenuator"
*HW_R_OPT_NAME-5 "Cu Kβ|Cu K-beta"
*HW_R_OPT_NAME-6 "調整用受光スリット|Alignment receiving slit"
*HW_SAMPLE_HOLDER_ID "SMP0023"
*HW_SAMPLE_HOLDER_NAME "標準Zステージ|Standard Z stage"
*HW_XG_CURRENT_MAX "50"
*HW_XG_CURRENT_MIN "2"
*HW_XG_CURRENT_RESOLUTION "2"
*HW_XG_CURRENT_UNIT "mA"
*HW_XG_FOCUS "1mm x 10mm"
*HW_XG_FOCUS_TYPE "Normal"
*HW_XG_ID ""
*HW_XG_NAME "3kW 封入管(ID:1200)|3kW Sealed tube(ID:1200)"
*HW_XG_TARGET_ATOMIC_NUMBER "29.0000000000"
*HW_XG_TARGET_NAME "Cu"
*HW_XG_TYPE "Hermetic"
*HW_XG_VOLTAGE_MAX "60"
*HW_XG_VOLTAGE_MIN "20"
*HW_XG_VOLTAGE_RESOLUTION "2"
*HW_XG_VOLTAGE_UNIT "kV"
*HW_XG_WATT_MAX "2"
*HW_XG_WATT_UNIT "kW"
*HW_XG_WAVE_LENGTH_ALPHA1 "1.540593"
*HW_XG_WAVE_LENGTH_ALPHA2 "1.544414"
*HW_XG_WAVE_LENGTH_BETA "1.392250"
*MEAS_COND_AXIS_NAME-0 "2θ/θ"
*MEAS_COND_AXIS_NAME-1 "2θ"
*MEAS_COND_AXIS_NAME-2 "ω"
*MEAS_COND_AXIS_NAME-3 "Z"
*MEAS_COND_AXIS_NAME-4 "2θ/ω"
*MEAS_COND_AXIS_NAME-5 "θs"
*MEAS_COND_AXIS_NAME-6 "θd"
*MEAS_COND_AXIS_NAME-7 "Ts"
*MEAS_COND_AXIS_NAME-8 "CBO選択スリット"
*MEAS_COND_AXIS_NAME-9 "M"
*MEAS_COND_AXIS_NAME-10 "入射平行スリット"
*MEAS_COND_AXIS_NAME-11 "入射スリット"
*MEAS_COND_AXIS_NAME-12 ""
*MEAS_COND_AXIS_NAME-13 "Zs"
*MEAS_COND_AXIS_NAME-14 "入射光学素子"
*MEAS_COND_AXIS_NAME-15 "長手制限スリット"
*MEAS_COND_AXIS_NAME-16 "センタースリット"
*MEAS_COND_AXIS_NAME-17 "フィルター"
*MEAS_COND_AXIS_NAME-18 "受光スリット1"
*MEAS_COND_AXIS_NAME-19 "受光スリット2"
*MEAS_COND_AXIS_NAME-20 "受光光学素子"
*MEAS_COND_AXIS_NAME-21 "受光平行スリット"
*MEAS_COND_AXIS_NAME-22 "調整用受光スリット"
*MEAS_COND_AXIS_NAME-23 ""
*MEAS_COND_AXIS_NAME-24 ""
*MEAS_COND_AXIS_NAME-25 "Zd"
*MEAS_COND_AXIS_NAME-26 "アッテネータ"
*MEAS_COND_AXIS_NAME-27 "検出器モノクロメータ"
*MEAS_COND_AXIS_NAME-28 "モノクロメータスリット"
*MEAS_COND_AXIS_NAME-29 "プライマリビーム"
*MEAS_COND_AXIS_NAME-30 "PHA"
*MEAS_COND_AXIS_NAME_INTERNAL-0 "TwoThetaTheta"
*MEAS_COND_AXIS_NAME_INTERNAL-1 "TwoTheta"
*MEAS_COND_AXIS_NAME_INTERNAL-2 "Omega"
*MEAS_COND_AXIS_NAME_INTERNAL-3 "Z"
*MEAS_COND_AXIS_NAME_INTERNAL-4 "TwoThetaOmega"
*MEAS_COND_AXIS_NAME_INTERNAL-5 "ThetaS"
*MEAS_COND_AXIS_NAME_INTERNAL-6 "ThetaD"
*MEAS_COND_AXIS_NAME_INTERNAL-7 "Ts"
*MEAS_COND_AXIS_NAME_INTERNAL-8 "CBO"
*MEAS_COND_AXIS_NAME_INTERNAL-9 "CBO-M"
*MEAS_COND_AXIS_NAME_INTERNAL-10 "IncidentSollerSlit"
*MEAS_COND_AXIS_NAME_INTERNAL-11 "IncidentSlitBox"
*MEAS_COND_AXIS_NAME_INTERNAL-12 "IncidentSlitBox-_Axis"
*MEAS_COND_AXIS_NAME_INTERNAL-13 "Zs"
*MEAS_COND_AXIS_NAME_INTERNAL-14 "IncidentMonochromator"
*MEAS_COND_AXIS_NAME_INTERNAL-15 "IncidentAxdSlit"
*MEAS_COND_AXIS_NAME_INTERNAL-16 "CenterSlit"
*MEAS_COND_AXIS_NAME_INTERNAL-17 "Filter"
*MEAS_COND_AXIS_NAME_INTERNAL-18 "ReceivingSlitBox1"
*MEAS_COND_AXIS_NAME_INTERNAL-19 "ReceivingSlitBox2"
*MEAS_COND_AXIS_NAME_INTERNAL-20 "ReceivingOptics"
*MEAS_COND_AXIS_NAME_INTERNAL-21 "ReceivingSollerSlit"
*MEAS_COND_AXIS_NAME_INTERNAL-22 "ReceivingAxdSlit"
*MEAS_COND_AXIS_NAME_INTERNAL-23 "ReceivingSlitBox1-_Axis"
*MEAS_COND_AXIS_NAME_INTERNAL-24 "ReceivingSlitBox2-_Axis"
*MEAS_COND_AXIS_NAME_INTERNAL-25 "ReceivingSlitBox2-Zd"
*MEAS_COND_AXIS_NAME_INTERNAL-26 "Attenuator"
*MEAS_COND_AXIS_NAME_INTERNAL-27 "CounterMonochromator"
*MEAS_COND_AXIS_NAME_INTERNAL-28 "CounterSlit"
*MEAS_COND_AXIS_NAME_INTERNAL-29 "IncidentPrimary"
*MEAS_COND_AXIS_NAME_INTERNAL-30 "PHA"
*MEAS_COND_AXIS_NAME_MAGICNO-0 "83951616.0000000000"
*MEAS_COND_AXIS_NAME_MAGICNO-1 "268632064.0000000000"
*MEAS_COND_AXIS_NAME_MAGICNO-2 "268500992.0000000000"
*MEAS_COND_AXIS_NAME_MAGICNO-3 "285278208.0000000000"
*MEAS_COND_AXIS_NAME_MAGICNO-4 "83951616.0000000000"
*MEAS_COND_AXIS_NAME_MAGICNO-5 "131072.0000000000"
*MEAS_COND_AXIS_NAME_MAGICNO-6 "131072.0000000000"
*MEAS_COND_AXIS_NAME_MAGICNO-7 "318898176.0000000000"
*MEAS_COND_AXIS_NAME_MAGICNO-8 "20971521.0000000000"
*MEAS_COND_AXIS_NAME_MAGICNO-9 "285343744.0000000000"
*MEAS_COND_AXIS_NAME_MAGICNO-10 "20971521.0000000000"
*MEAS_COND_AXIS_NAME_MAGICNO-11 "22020097.0000000000"
*MEAS_COND_AXIS_NAME_MAGICNO-12 "25165824.0000000000"
*MEAS_COND_AXIS_NAME_MAGICNO-13 "318898176.0000000000"
*MEAS_COND_AXIS_NAME_MAGICNO-14 "1.0000000000"
*MEAS_COND_AXIS_NAME_MAGICNO-15 "20971521.0000000000"
*MEAS_COND_AXIS_NAME_MAGICNO-16 "20971521.0000000000"
*MEAS_COND_AXIS_NAME_MAGICNO-17 "20971521.0000000000"
*MEAS_COND_AXIS_NAME_MAGICNO-18 "23068673.0000000000"
*MEAS_COND_AXIS_NAME_MAGICNO-19 "23068673.0000000000"
*MEAS_COND_AXIS_NAME_MAGICNO-20 "20971521.0000000000"
*MEAS_COND_AXIS_NAME_MAGICNO-21 "20971521.0000000000"
*MEAS_COND_AXIS_NAME_MAGICNO-22 "20971521.0000000000"
*MEAS_COND_AXIS_NAME_MAGICNO-23 "25165824.0000000000"
*MEAS_COND_AXIS_NAME_MAGICNO-24 "25165824.0000000000"
*MEAS_COND_AXIS_NAME_MAGICNO-25 "285343744.0000000000"
*MEAS_COND_AXIS_NAME_MAGICNO-26 "17301505.0000000000"
*MEAS_COND_AXIS_NAME_MAGICNO-27 "20971521.0000000000"
*MEAS_COND_AXIS_NAME_MAGICNO-28 "20971521.0000000000"
*MEAS_COND_AXIS_NAME_MAGICNO-29 "20971521.0000000000"
*MEAS_COND_AXIS_NAME_MAGICNO-30 "0.0000000000"
*MEAS_COND_AXIS_OFFSET-0 "-"
*MEAS_COND_AXIS_OFFSET-1 "-0.1081000000"
*MEAS_COND_AXIS_OFFSET-2 "0.3758000000"
*MEAS_COND_AXIS_OFFSET-3 "-"
*MEAS_COND_AXIS_OFFSET-4 "-"
*MEAS_COND_AXIS_OFFSET-5 "0.3758000000"
*MEAS_COND_AXIS_OFFSET-6 "-0.4839000000"
*MEAS_COND_AXIS_OFFSET-7 "-"
*MEAS_COND_AXIS_OFFSET-8 "-"
*MEAS_COND_AXIS_OFFSET-9 "-"
*MEAS_COND_AXIS_OFFSET-10 "-"
*MEAS_COND_AXIS_OFFSET-11 "-"
*MEAS_COND_AXIS_OFFSET-12 "-"
*MEAS_COND_AXIS_OFFSET-13 "-"
*MEAS_COND_AXIS_OFFSET-14 "-"
*MEAS_COND_AXIS_OFFSET-15 "-"
*MEAS_COND_AXIS_OFFSET-16 "-"
*MEAS_COND_AXIS_OFFSET-17 "-"
*MEAS_COND_AXIS_OFFSET-18 "-"
*MEAS_COND_AXIS_OFFSET-19 "-"
*MEAS_COND_AXIS_OFFSET-20 "-"
*MEAS_COND_AXIS_OFFSET-21 "-"
*MEAS_COND_AXIS_OFFSET-22 "-"
*MEAS_COND_AXIS_OFFSET-23 "-"
*MEAS_COND_AXIS_OFFSET-24 "-"
*MEAS_COND_AXIS_OFFSET-25 "-"
*MEAS_COND_AXIS_OFFSET-26 "-"
*MEAS_COND_AXIS_OFFSET-27 "-"
*MEAS_COND_AXIS_OFFSET-28 "-"
*MEAS_COND_AXIS_OFFSET-29 "-"
*MEAS_COND_AXIS_OFFSET-30 "-"
*MEAS_COND_AXIS_POSITION-0 "0.0000000000"
*MEAS_COND_AXIS_POSITION-1 "0.0000000000"
*MEAS_COND_AXIS_POSITION-2 "0.0000000000"
*MEAS_COND_AXIS_POSITION-3 "-0.5500000000"
*MEAS_COND_AXIS_POSITION-4 "0.0000000000"
*MEAS_COND_AXIS_POSITION-5 "0.0000000000"
*MEAS_COND_AXIS_POSITION-6 "0.0000000000"
*MEAS_COND_AXIS_POSITION-7 "-0.4278800000"
*MEAS_COND_AXIS_POSITION-8 "BB"
*MEAS_COND_AXIS_POSITION-9 "0.0000000000"
*MEAS_COND_AXIS_POSITION-10 "Soller_slit_5.0deg"
*MEAS_COND_AXIS_POSITION-11 "2/3deg"
*MEAS_COND_AXIS_POSITION-12 "2.2088000000"
*MEAS_COND_AXIS_POSITION-13 "-0.4140600000"
*MEAS_COND_AXIS_POSITION-14 "0.0000000000"
*MEAS_COND_AXIS_POSITION-15 "10.0mm"
*MEAS_COND_AXIS_POSITION-16 "None"
*MEAS_COND_AXIS_POSITION-17 "Cu_K-beta"
*MEAS_COND_AXIS_POSITION-18 "13.000mm"
*MEAS_COND_AXIS_POSITION-19 "13.000mm"
*MEAS_COND_AXIS_POSITION-20 "No_unit"
*MEAS_COND_AXIS_POSITION-21 "Soller_slit_5.0deg"
*MEAS_COND_AXIS_POSITION-22 "None"
*MEAS_COND_AXIS_POSITION-23 "13.0000000000"
*MEAS_COND_AXIS_POSITION-24 "13.0000000000"
*MEAS_COND_AXIS_POSITION-25 "0.0109400000"
*MEAS_COND_AXIS_POSITION-26 "Open"
*MEAS_COND_AXIS_POSITION-27 "None"
*MEAS_COND_AXIS_POSITION-28 "None"
*MEAS_COND_AXIS_POSITION-29 "None"
*MEAS_COND_AXIS_POSITION-30 "38.0000000000"
*MEAS_COND_AXIS_UNIT-0 "deg"
*MEAS_COND_AXIS_UNIT-1 "deg"
*MEAS_COND_AXIS_UNIT-2 "deg"
*MEAS_COND_AXIS_UNIT-3 "mm"
*MEAS_COND_AXIS_UNIT-4 "deg"
*MEAS_COND_AXIS_UNIT-5 "deg"
*MEAS_COND_AXIS_UNIT-6 "deg"
*MEAS_COND_AXIS_UNIT-7 "mm"
*MEAS_COND_AXIS_UNIT-8 ""
*MEAS_COND_AXIS_UNIT-9 "pulse"
*MEAS_COND_AXIS_UNIT-10 ""
*MEAS_COND_AXIS_UNIT-11 ""
*MEAS_COND_AXIS_UNIT-12 "mm"
*MEAS_COND_AXIS_UNIT-13 "mm"
*MEAS_COND_AXIS_UNIT-14 ""
*MEAS_COND_AXIS_UNIT-15 ""
*MEAS_COND_AXIS_UNIT-16 ""
*MEAS_COND_AXIS_UNIT-17 ""
*MEAS_COND_AXIS_UNIT-18 ""
*MEAS_COND_AXIS_UNIT-19 ""
*MEAS_COND_AXIS_UNIT-20 ""
*MEAS_COND_AXIS_UNIT-21 ""
*MEAS_COND_AXIS_UNIT-22 ""
*MEAS_COND_AXIS_UNIT-23 "mm"
*MEAS_COND_AXIS_UNIT-24 "mm"
*MEAS_COND_AXIS_UNIT-25 "mm"
*MEAS_COND_AXIS_UNIT-26 ""
*MEAS_COND_AXIS_UNIT-27 ""
*MEAS_COND_AXIS_UNIT-28 ""
*MEAS_COND_AXIS_UNIT-29 ""
*MEAS_COND_AXIS_UNIT-30 "div"
*MEAS_COND_COUNTER_CNTLOSS_CORR "0.0000000000"
*MEAS_COND_COUNTER_PHABASE "38.0000000000"
*MEAS_COND_COUNTER_PHAWINDOW "16.0000000000"
*MEAS_COND_COUNTER_PHA_UNIT "div"
*MEAS_COND_COUNTER_TAUDIFF "30.0000000000"
*MEAS_COND_COUNTER_TAUINT "0.0000000000"
*MEAS_COND_IRRADIATION_MODE "OFF"
*MEAS_COND_IRRADIATION_WIDTH ""
*MEAS_COND_OPT_ATTR "集中法"
*MEAS_COND_OPT_NAME "@集中法"
*MEAS_COND_UNSYMMETRIC_MODE "OFF"
*MEAS_COND_XG_CURRENT "30.0000000000"
*MEAS_COND_XG_VOLTAGE "40.0000000000"
*MEAS_COND_XG_WAVE_TYPE "Ka"
*MEAS_DATA_COUNT "3501.0000000000"
*MEAS_SCAN_AXIS_X "2θ/θ"
*MEAS_SCAN_AXIS_X_INTERNAL "TwoThetaTheta"
*MEAS_SCAN_END_TIME "08/19/20 15:29:15"
*MEAS_SCAN_MODE "CONTINUOUS"
*MEAS_SCAN_MONITOR "0"
*MEAS_SCAN_RESOLUTION_X "0.0002"
*MEAS_SCAN_SPEED "1.0"
*MEAS_SCAN_SPEED_UNIT "deg/min"
*MEAS_SCAN_START "20.0000000000"
*MEAS_SCAN_START_TIME "08/19/20 14:16:21"
*MEAS_SCAN_STEP "0.0200000000"
*MEAS_SCAN_STOP "90.0000000000"
*MEAS_SCAN_UNIT_X "deg"
*MEAS_SCAN_UNIT_Y "counts"
*RAS_HEADER_END
*RAS_INT_START
20.0000 12379.0000 1.0000
20.0600 12177.0000 1.0000
20.1200 12238.0000 1.0000
20.1800 12198.0000 1.0000
20.2400 12153.0000 1.0000
20.3000 12263.0000 1.0000
20.3600 12345.0000 1.0000
20.4200 12211.0000 1.0000
20.4800 12325.0000 1.0000
20.5400 12164.0000 1.0000
20.6000 12080.0000 1.0000
20.6600 12615.0000 1.0000
20.7200 12774.0000 1.0000
20.7800 12822.0000 1.0000
20.8400 13118.0000 1.0000
20.9000 13916.0000 1.0000
20.9600 12802.0000 1.0000
21.0200 12162.0000 1.0000
21.0800 12246.0000 1.0000
21.1400 12313.0000 1.0000
21.2000 12163.0000 1.0000
21.2600 12102.0000 1.0000
21.3200 12252.0000 1.0000
21.3800 12135.0000 1.0000
21.4400 12363.0000 1.0000
21.5000 12097.0000 1.0000
21.5600 12396.0000 1.0000
21.6200 12206.0000 1.0000
21.6800 12336.0000 1.0000
21.7400 12236.0000 1.0000
21.8000 12162.0000 1.0000
21.8600 12092.0000 1.0000
21.9200 12210.0000 1.0000
21.9800 12081.0000 1.0000
22.0400 12071.0000 1.0000
22.1000 12265.0000 1.0000
22.1600 12251.0000 1.0000
22.2200 12102.0000 1.0000
22.2800 12066.0000 1.0000
22.3400 11975.0000 1.0000
22.4000 12143.0000 1.0000
22.4600 12246.0000 1.0000
22.5200 12123.0000 1.0000
22.5800 12143.0000 1.0000
22.6400 12191.0000 1.0000
22.7000 12187.0000 1.0000
22.7600 12095.0000 1.0000
22.8200 12019.0000 1.0000
22.8800 11918.0000 1.0000
22.9400 12033.0000 1.0000
23.0000 11989.0000 1.0000
23.0600 12094.0000 1.0000
23.1200 12248.0000 1.0000
23.1800 12160.0000 1.0000
23.2400 12047.0000 1.0000
23.3000 12183.0000 1.0000
23.3600 11985.0000 1.0000
23.4200 11966.0000 1.0000
23.4800 12139.0000 1.0000
23.5400 12129.0000 1.0000
23.6000 12155.0000 1.0000
23.6600 12136.0000 1.0000
23.7200 12125.0000 1.0000
23.7800 12351.0000 1.0000
23.8400 12158.0000 1.0000
23.9000 12243.0000 1.0000
23.9600 12194.0000 1.0000
24.0200 12676.0000 1.0000
24.0800 12797.0000 1.0000
24.1400 13317.0000 1.0000
24.2000 13896.0000 1.0000
24.2600 12720.0000 1.0000
24.3200 12392.0000 1.0000
24.3800 12209.0000 1.0000
24.4400 11975.0000 1.0000
24.5000 12007.0000 1.0000
24.5600 11875.0000 1.0000
24.6200 12134.0000 1.0000
24.6800 11966.0000 1.0000
24.7400 11966.0000 1.0000
24.8000 12049.0000 1.0000
24.8600 12093.0000 1.0000
24.9200 12000.0000 1.0000
24.9800 12080.0000 1.0000
25.0400 11958.0000 1.0000
25.1000 12044.0000 1.0000
25.1600 11999.0000 1.0000
25.2200 11934.0000 1.0000
25.2800 12060.0000 1.0000
25.3400 11981.0000 1.0000
25.4000 12073.0000 1.0000
25.4600 12338.0000 1.0000
25.5200 12302.0000 1.0000
25.5800 12455.0000 1.0000
25.6400 12532.0000 1.0000
25.7000 11961.0000 1.0000
25.7600 12144.0000 1.0000
25.8200 12130.0000 1.0000
25.8800 12033.0000 1.0000
25.9400 11851.0000 1.0000
26.0000 11993.0000 1.0000
26.0600 11727.0000 1.0000
26.1200 12059.0000 1.0000
26.1800 12149.0000 1.0000
26.2400 11922.0000 1.0000
26.3000 11884.0000 1.0000
26.3600 12072.0000 1.0000
26.4200 12473.0000 1.0000
26.4800 12948.0000 1.0000
26.5400 14715.0000 1.0000
26.6000 16194.0000 1.0000
26.6600 25867.0000 1.0000
26.7200 19682.0000 1.0000
26.7800 14287.0000 1.0000
26.8400 12498.0000 1.0000
26.9000 12014.0000 1.0000
26.9600 11866.0000 1.0000
27.0200 11981.0000 1.0000
27.0800 11901.0000 1.0000
27.1400 11978.0000 1.0000
27.2000 11873.0000 1.0000
27.2600 11917.0000 1.0000
27.3200 11870.0000 1.0000
27.3800 11671.0000 1.0000
27.4400 11745.0000 1.0000
27.5000 11793.0000 1.0000
27.5600 11607.0000 1.0000
27.6200 11785.0000 1.0000
27.6800 11667.0000 1.0000
27.7400 11680.0000 1.0000
27.8000 11916.0000 1.0000
27.8600 11634.0000 1.0000
27.9200 11612.0000 1.0000
27.9800 11860.0000 1.0000
28.0400 11486.0000 1.0000
28.1000 11577.0000 1.0000
28.1600 11804.0000 1.0000
28.2200 11479.0000 1.0000
28.2800 11603.0000 1.0000
28.3400 11599.0000 1.0000
28.4000 11400.0000 1.0000
28.4600 11761.0000 1.0000
28.5200 11649.0000 1.0000
28.5800 11669.0000 1.0000
28.6400 11615.0000 1.0000
28.7000 11534.0000 1.0000
28.7600 11433.0000 1.0000
28.8200 11642.0000 1.0000
28.8800 11615.0000 1.0000
28.9400 11397.0000 1.0000
29.0000 11596.0000 1.0000
29.0600 11534.0000 1.0000
29.1200 11388.0000 1.0000
29.1800 11538.0000 1.0000
29.2400 11509.0000 1.0000
29.3000 11689.0000 1.0000
29.3600 11736.0000 1.0000
29.4200 11427.0000 1.0000
29.4800 11534.0000 1.0000
29.5400 11527.0000 1.0000
29.6000 11560.0000 1.0000
29.6600 11608.0000 1.0000
29.7200 11531.0000 1.0000
29.7800 11700.0000 1.0000
29.8400 11751.0000 1.0000
29.9000 12107.0000 1.0000
29.9600 12301.0000 1.0000
30.0200 12969.0000 1.0000
30.0800 14367.0000 1.0000
30.1400 16677.0000 1.0000
30.2000 16024.0000 1.0000
30.2600 14443.0000 1.0000
30.3200 12613.0000 1.0000
30.3800 12138.0000 1.0000
30.4400 11724.0000 1.0000
30.5000 11661.0000 1.0000
30.5600 11621.0000 1.0000
30.6200 11632.0000 1.0000
30.6800 11585.0000 1.0000
30.7400 11531.0000 1.0000
30.8000 11557.0000 1.0000
30.8600 11724.0000 1.0000
30.9200 11529.0000 1.0000
30.9800 11523.0000 1.0000
31.0400 11603.0000 1.0000
31.1000 11605.0000 1.0000
31.1600 11467.0000 1.0000
31.2200 11365.0000 1.0000
31.2800 11513.0000 1.0000
31.3400 11660.0000 1.0000
31.4000 11490.0000 1.0000
31.4600 11484.0000 1.0000
31.5200 11658.0000 1.0000
31.5800 11552.0000 1.0000
31.6400 11504.0000 1.0000
31.7000 11510.0000 1.0000
31.7600 11743.0000 1.0000
31.8200 11663.0000 1.0000
31.8800 11497.0000 1.0000
31.9400 11510.0000 1.0000
32.0000 11692.0000 1.0000
32.0600 11674.0000 1.0000
32.1200 11734.0000 1.0000
32.1800 11640.0000 1.0000
32.2400 11728.0000 1.0000
32.3000 11558.0000 1.0000
32.3600 11507.0000 1.0000
32.4200 11507.0000 1.0000
32.4800 11474.0000 1.0000
32.5400 11621.0000 1.0000
32.6000 11613.0000 1.0000
32.6600 11673.0000 1.0000
32.7200 11558.0000 1.0000
32.7800 11727.0000 1.0000
32.8400 11746.0000 1.0000
32.9000 11459.0000 1.0000
32.9600 12102.0000 1.0000
33.0200 12440.0000 1.0000
33.0800 13404.0000 1.0000
33.1400 15755.0000 1.0000
33.2000 17259.0000 1.0000
33.2600 15043.0000 1.0000
33.3200 13379.0000 1.0000
33.3800 12030.0000 1.0000
33.4400 11879.0000 1.0000
33.5000 11692.0000 1.0000
33.5600 11688.0000 1.0000
33.6200 11654.0000 1.0000
33.6800 11410.0000 1.0000
33.7400 11439.0000 1.0000
33.8000 11478.0000 1.0000
33.8600 11483.0000 1.0000
33.9200 11630.0000 1.0000
33.9800 11310.0000 1.0000
34.0400 11450.0000 1.0000
34.1000 11369.0000 1.0000
34.1600 11495.0000 1.0000
34.2200 11280.0000 1.0000
34.2800 11593.0000 1.0000
34.3400 11794.0000 1.0000
34.4000 11697.0000 1.0000
34.4600 11563.0000 1.0000
34.5200 11588.0000 1.0000
34.5800 11429.0000 1.0000
34.6400 11512.0000 1.0000
34.7000 11551.0000 1.0000
34.7600 11537.0000 1.0000
34.8200 11548.0000 1.0000
34.8800 11604.0000 1.0000
34.9400 11525.0000 1.0000
35.0000 11386.0000 1.0000
35.0600 11866.0000 1.0000
35.1200 12035.0000 1.0000
35.1800 12575.0000 1.0000
35.2400 12924.0000 1.0000
35.3000 13205.0000 1.0000
35.3600 14716.0000 1.0000
35.4200 18791.0000 1.0000
35.4800 27331.0000 1.0000
35.5400 28676.0000 1.0000
35.6000 25731.0000 1.0000
35.6600 21576.0000 1.0000
35.7200 17056.0000 1.0000
35.7800 14542.0000 1.0000
35.8400 12628.0000 1.0000
35.9000 12153.0000 1.0000
35.9600 11663.0000 1.0000
36.0200 11609.0000 1.0000
36.0800 11623.0000 1.0000
36.1400 11464.0000 1.0000
36.2000 11546.0000 1.0000
36.2600 11589.0000 1.0000
36.3200 11464.0000 1.0000
36.3800 11446.0000 1.0000
36.4400 11497.0000 1.0000
36.5000 11884.0000 1.0000
36.5600 12009.0000 1.0000
36.6200 11612.0000 1.0000
36.6800 11617.0000 1.0000
36.7400 11567.0000 1.0000
36.8000 11224.0000 1.0000
36.8600 11280.0000 1.0000
36.9200 11263.0000 1.0000
36.9800 11484.0000 1.0000
37.0400 11604.0000 1.0000
37.1000 12006.0000 1.0000
37.1600 12156.0000 1.0000
37.2200 12040.0000 1.0000
37.2800 11555.0000 1.0000
37.3400 11487.0000 1.0000
37.4000 11308.0000 1.0000
37.4600 11287.0000 1.0000
37.5200 11288.0000 1.0000
37.5800 11259.0000 1.0000
37.6400 11225.0000 1.0000
37.7000 11205.0000 1.0000
37.7600 11336.0000 1.0000
37.8200 11458.0000 1.0000
37.8800 11249.0000 1.0000
37.9400 11217.0000 1.0000
38.0000 11294.0000 1.0000
38.0600 11211.0000 1.0000
38.1200 11205.0000 1.0000
38.1800 11169.0000 1.0000
38.2400 11239.0000 1.0000
38.3000 11335.0000 1.0000
38.3600 11149.0000 1.0000
38.4200 11039.0000 1.0000
38.4800 11143.0000 1.0000
38.5400 11276.0000 1.0000
38.6000 11257.0000 1.0000
38.6600 11228.0000 1.0000
38.7200 11341.0000 1.0000
38.7800 11113.0000 1.0000
38.8400 11184.0000 1.0000
38.9000 11065.0000 1.0000
38.9600 11340.0000 1.0000
39.0200 11156.0000 1.0000
39.0800 11401.0000 1.0000
39.1400 11369.0000 1.0000
39.2000 11211.0000 1.0000
39.2600 11177.0000 1.0000
39.3200 11420.0000 1.0000
39.3800 11304.0000 1.0000
39.4400 11597.0000 1.0000
39.5000 11784.0000 1.0000
39.5600 11508.0000 1.0000
39.6200 11238.0000 1.0000
39.6800 11339.0000 1.0000
39.7400 11258.0000 1.0000
39.8000 11088.0000 1.0000
39.8600 11172.0000 1.0000
39.9200 11127.0000 1.0000
39.9800 11146.0000 1.0000
40.0400 11180.0000 1.0000
40.1000 11248.0000 1.0000
40.1600 11340.0000 1.0000
40.2200 11338.0000 1.0000
40.2800 11454.0000 1.0000
40.3400 11439.0000 1.0000
40.4000 11500.0000 1.0000
40.4600 11169.0000 1.0000
40.5200 11139.0000 1.0000
40.5800 11376.0000 1.0000
40.6400 11398.0000 1.0000
40.7000 11437.0000 1.0000
40.7600 11469.0000 1.0000
40.8200 11767.0000 1.0000
40.8800 12437.0000 1.0000
40.9400 12181.0000 1.0000
41.0000 11978.0000 1.0000
41.0600 11456.0000 1.0000
41.1200 11236.0000 1.0000
41.1800 11269.0000 1.0000
41.2400 11153.0000 1.0000
41.3000 11267.0000 1.0000
41.3600 11191.0000 1.0000
41.4200 11206.0000 1.0000
41.4800 11184.0000 1.0000
41.5400 11055.0000 1.0000
41.6000 11178.0000 1.0000
41.6600 11041.0000 1.0000
41.7200 11121.0000 1.0000
41.7800 11190.0000 1.0000
41.8400 11259.0000 1.0000
41.9000 11148.0000 1.0000
41.9600 11134.0000 1.0000
42.0200 11301.0000 1.0000
42.0800 11179.0000 1.0000
42.1400 11329.0000 1.0000
42.2000 11075.0000 1.0000
42.2600 11241.0000 1.0000
42.3200 11183.0000 1.0000
42.3800 11244.0000 1.0000
42.4400 11365.0000 1.0000
42.5000 11710.0000 1.0000
42.5600 11347.0000 1.0000
42.6200 11279.0000 1.0000
42.6800 11365.0000 1.0000
42.7400 11357.0000 1.0000
42.8000 11367.0000 1.0000
42.8600 11411.0000 1.0000
42.9200 11295.0000 1.0000
42.9800 11846.0000 1.0000
43.0400 12256.0000 1.0000
43.1000 13645.0000 1.0000
43.1600 14765.0000 1.0000
43.2200 14232.0000 1.0000
43.2800 13735.0000 1.0000
43.3400 12910.0000 1.0000
43.4000 12460.0000 1.0000
43.4600 11958.0000 1.0000
43.5200 11706.0000 1.0000
43.5800 11404.0000 1.0000
43.6400 11385.0000 1.0000
43.7000 11040.0000 1.0000
43.7600 11230.0000 1.0000
43.8200 11325.0000 1.0000
43.8800 11236.0000 1.0000
43.9400 11376.0000 1.0000
44.0000 11404.0000 1.0000
44.0600 11271.0000 1.0000
44.1200 11418.0000 1.0000
44.1800 11140.0000 1.0000
44.2400 11171.0000 1.0000
44.3000 11275.0000 1.0000
44.3600 11247.0000 1.0000
44.4200 11105.0000 1.0000
44.4800 11427.0000 1.0000
44.5400 11197.0000 1.0000
44.6000 11279.0000 1.0000
44.6600 11216.0000 1.0000
44.7200 11290.0000 1.0000
44.7800 11152.0000 1.0000
44.8400 11355.0000 1.0000
44.9000 11242.0000 1.0000
44.9600 11100.0000 1.0000
45.0200 11093.0000 1.0000
45.0800 11351.0000 1.0000
45.1400 11141.0000 1.0000
45.2000 11290.0000 1.0000
45.2600 11141.0000 1.0000
45.3200 11328.0000 1.0000
45.3800 11346.0000 1.0000
45.4400 11247.0000 1.0000
45.5000 11325.0000 1.0000
45.5600 11312.0000 1.0000
45.6200 11103.0000 1.0000
45.6800 11186.0000 1.0000
45.7400 11242.0000 1.0000
45.8000 11467.0000 1.0000
45.8600 11465.0000 1.0000
45.9200 11453.0000 1.0000
45.9800 11250.0000 1.0000
46.0400 11265.0000 1.0000
46.1000 11113.0000 1.0000
46.1600 11194.0000 1.0000
46.2200 11313.0000 1.0000
46.2800 11155.0000 1.0000
46.3400 11013.0000 1.0000
46.4000 11302.0000 1.0000
46.4600 11278.0000 1.0000
46.5200 11378.0000 1.0000
46.5800 11355.0000 1.0000
46.6400 11348.0000 1.0000
46.7000 11291.0000 1.0000
46.7600 11214.0000 1.0000
46.8200 11197.0000 1.0000
46.8800 11266.0000 1.0000
46.9400 11267.0000 1.0000
47.0000 11401.0000 1.0000
47.0600 11464.0000 1.0000
47.1200 11353.0000 1.0000
47.1800 11197.0000 1.0000
47.2400 11461.0000 1.0000
47.3000 11271.0000 1.0000
47.3600 11299.0000 1.0000
47.4200 11146.0000 1.0000
47.4800 11260.0000 1.0000
47.5400 11214.0000 1.0000
47.6000 11301.0000 1.0000
47.6600 11373.0000 1.0000
47.7200 11166.0000 1.0000
47.7800 11247.0000 1.0000
47.8400 11300.0000 1.0000
47.9000 11298.0000 1.0000
47.9600 11270.0000 1.0000
48.0200 11356.0000 1.0000
48.0800 11315.0000 1.0000
48.1400 11210.0000 1.0000
48.2000 11061.0000 1.0000
48.2600 11191.0000 1.0000
48.3200 11082.0000 1.0000
48.3800 11364.0000 1.0000
48.4400 11297.0000 1.0000
48.5000 11103.0000 1.0000
48.5600 11456.0000 1.0000
48.6200 11308.0000 1.0000
48.6800 11320.0000 1.0000
48.7400 11226.0000 1.0000
48.8000 11323.0000 1.0000
48.8600 11133.0000 1.0000
48.9200 11401.0000 1.0000
48.9800 11246.0000 1.0000
49.0400 10939.0000 1.0000
49.1000 11220.0000 1.0000
49.1600 11241.0000 1.0000
49.2200 11349.0000 1.0000
49.2800 11443.0000 1.0000
49.3400 11806.0000 1.0000
49.4000 11932.0000 1.0000
49.4600 13148.0000 1.0000
49.5200 12929.0000 1.0000
49.5800 12456.0000 1.0000
49.6400 12235.0000 1.0000
49.7000 11853.0000 1.0000
49.7600 11383.0000 1.0000
49.8200 11497.0000 1.0000
49.8800 11231.0000 1.0000
49.9400 11337.0000 1.0000
50.0000 11498.0000 1.0000
50.0600 11841.0000 1.0000
50.1200 12209.0000 1.0000
50.1800 12643.0000 1.0000
50.2400 11933.0000 1.0000
50.3000 11838.0000 1.0000
50.3600 11485.0000 1.0000
50.4200 11348.0000 1.0000
50.4800 11212.0000 1.0000
50.5400 11250.0000 1.0000
50.6000 11366.0000 1.0000
50.6600 11157.0000 1.0000
50.7200 11344.0000 1.0000
50.7800 11256.0000 1.0000
50.8400 11154.0000 1.0000
50.9000 11281.0000 1.0000
50.9600 11090.0000 1.0000
51.0200 11377.0000 1.0000
51.0800 11260.0000 1.0000
51.1400 11294.0000 1.0000
51.2000 11312.0000 1.0000
51.2600 11223.0000 1.0000
51.3200 11059.0000 1.0000
51.3800 11044.0000 1.0000
51.4400 11035.0000 1.0000
51.5000 11049.0000 1.0000
51.5600 11146.0000 1.0000
51.6200 11150.0000 1.0000
51.6800 11328.0000 1.0000
51.7400 11335.0000 1.0000
51.8000 11089.0000 1.0000
51.8600 11215.0000 1.0000
51.9200 11145.0000 1.0000
51.9800 10968.0000 1.0000
52.0400 11245.0000 1.0000
52.1000 10963.0000 1.0000
52.1600 11351.0000 1.0000
52.2200 11150.0000 1.0000
52.2800 11173.0000 1.0000
52.3400 11348.0000 1.0000
52.4000 11271.0000 1.0000
52.4600 11154.0000 1.0000
52.5200 11474.0000 1.0000
52.5800 11487.0000 1.0000
52.6400 11383.0000 1.0000
52.7000 11490.0000 1.0000
52.7600 11349.0000 1.0000
52.8200 11345.0000 1.0000
52.8800 11193.0000 1.0000
52.9400 11195.0000 1.0000
53.0000 11043.0000 1.0000
53.0600 11200.0000 1.0000
53.1200 11184.0000 1.0000
53.1800 11309.0000 1.0000
53.2400 11290.0000 1.0000
53.3000 11407.0000 1.0000
53.3600 11505.0000 1.0000
53.4200 11898.0000 1.0000
53.4800 12346.0000 1.0000
53.5400 12576.0000 1.0000
53.6000 12333.0000 1.0000
53.6600 12173.0000 1.0000
53.7200 11882.0000 1.0000
53.7800 11423.0000 1.0000
53.8400 11529.0000 1.0000
53.9000 11446.0000 1.0000
53.9600 11664.0000 1.0000
54.0200 12380.0000 1.0000
54.0800 13643.0000 1.0000
54.1400 12848.0000 1.0000
54.2000 12697.0000 1.0000
54.2600 12385.0000 1.0000
54.3200 11711.0000 1.0000
54.3800 11193.0000 1.0000
54.4400 11130.0000 1.0000
54.5000 11395.0000 1.0000
54.5600 11314.0000 1.0000
54.6200 11115.0000 1.0000
54.6800 11175.0000 1.0000
54.7400 11085.0000 1.0000
54.8000 11412.0000 1.0000
54.8600 11670.0000 1.0000
54.9200 12360.0000 1.0000
54.9800 11619.0000 1.0000
55.0400 11947.0000 1.0000
55.1000 11284.0000 1.0000
55.1600 11287.0000 1.0000
55.2200 11211.0000 1.0000
55.2800 11290.0000 1.0000
55.3400 11339.0000 1.0000
55.4000 11177.0000 1.0000
55.4600 11236.0000 1.0000
55.5200 11207.0000 1.0000
55.5800 11284.0000 1.0000
55.6400 11149.0000 1.0000
55.7000 11242.0000 1.0000
55.7600 11321.0000 1.0000
55.8200 11176.0000 1.0000
55.8800 11189.0000 1.0000
55.9400 11372.0000 1.0000
56.0000 11236.0000 1.0000
56.0600 11324.0000 1.0000
56.1200 11210.0000 1.0000
56.1800 11237.0000 1.0000
56.2400 11302.0000 1.0000
56.3000 11191.0000 1.0000
56.3600 11255.0000 1.0000
56.4200 11107.0000 1.0000
56.4800 11373.0000 1.0000
56.5400 11157.0000 1.0000
56.6000 11235.0000 1.0000
56.6600 11420.0000 1.0000
56.7200 11411.0000 1.0000
56.7800 11352.0000 1.0000
56.8400 11731.0000 1.0000
56.9000 12095.0000 1.0000
56.9600 12997.0000 1.0000
57.0200 14884.0000 1.0000
57.0800 15491.0000 1.0000
57.1400 14540.0000 1.0000
57.2000 14327.0000 1.0000
57.2600 13280.0000 1.0000
57.3200 12577.0000 1.0000
57.3800 12204.0000 1.0000
57.4400 12136.0000 1.0000
57.5000 12364.0000 1.0000
57.5600 12080.0000 1.0000
57.6200 12100.0000 1.0000
57.6800 12041.0000 1.0000
57.7400 11834.0000 1.0000
57.8000 11518.0000 1.0000
57.8600 11307.0000 1.0000
57.9200 11422.0000 1.0000
57.9800 11241.0000 1.0000
58.0400 11305.0000 1.0000
58.1000 11269.0000 1.0000
58.1600 11296.0000 1.0000
58.2200 11378.0000 1.0000
58.2800 11260.0000 1.0000
58.3400 11165.0000 1.0000
58.4000 11176.0000 1.0000
58.4600 11317.0000 1.0000
58.5200 11202.0000 1.0000
58.5800 11451.0000 1.0000
58.6400 11100.0000 1.0000
58.7000 11224.0000 1.0000
58.7600 10938.0000 1.0000
58.8200 11357.0000 1.0000
58.8800 11174.0000 1.0000
58.9400 11260.0000 1.0000
59.0000 11285.0000 1.0000
59.0600 11280.0000 1.0000
59.1200 11212.0000 1.0000
59.1800 11380.0000 1.0000
59.2400 11466.0000 1.0000
59.3000 11316.0000 1.0000
59.3600 11337.0000 1.0000
59.4200 11148.0000 1.0000
59.4800 11093.0000 1.0000
59.5400 11262.0000 1.0000
59.6000 11062.0000 1.0000
59.6600 11443.0000 1.0000
59.7200 11335.0000 1.0000
59.7800 11206.0000 1.0000
59.8400 11435.0000 1.0000
59.9000 11582.0000 1.0000
59.9600 12390.0000 1.0000
60.0200 11683.0000 1.0000
60.0800 11604.0000 1.0000
60.1400 11914.0000 1.0000
60.2000 11359.0000 1.0000
60.2600 11421.0000 1.0000
60.3200 11273.0000 1.0000
60.3800 11277.0000 1.0000
60.4400 11298.0000 1.0000
60.5000 11146.0000 1.0000
60.5600 11430.0000 1.0000
60.6200 11529.0000 1.0000
60.6800 11241.0000 1.0000
60.7400 11254.0000 1.0000
60.8000 11363.0000 1.0000
60.8600 11232.0000 1.0000
60.9200 11289.0000 1.0000
60.9800 11246.0000 1.0000
61.0400 11306.0000 1.0000
61.1000 11188.0000 1.0000
61.1600 11219.0000 1.0000
61.2200 11223.0000 1.0000
61.2800 11424.0000 1.0000
61.3400 11192.0000 1.0000
61.4000 11512.0000 1.0000
61.4600 11417.0000 1.0000
61.5200 11340.0000 1.0000
61.5800 11221.0000 1.0000
61.6400 11129.0000 1.0000
61.7000 11260.0000 1.0000
61.7600 11324.0000 1.0000
61.8200 11368.0000 1.0000
61.8800 11248.0000 1.0000
61.9400 11392.0000 1.0000
62.0000 11332.0000 1.0000
62.0600 11357.0000 1.0000
62.1200 11282.0000 1.0000
62.1800 11415.0000 1.0000
62.2400 11682.0000 1.0000
62.3000 11903.0000 1.0000
62.3600 12084.0000 1.0000
62.4200 13093.0000 1.0000
62.4800 13470.0000 1.0000
62.5400 14222.0000 1.0000
62.6000 16906.0000 1.0000
62.6600 17798.0000 1.0000
62.7200 15749.0000 1.0000
62.7800 15477.0000 1.0000
62.8400 14947.0000 1.0000
62.9000 13649.0000 1.0000
62.9600 12503.0000 1.0000
63.0200 11904.0000 1.0000
63.0800 11749.0000 1.0000
63.1400 11587.0000 1.0000
63.2000 11597.0000 1.0000
63.2600 11256.0000 1.0000
63.3200 11409.0000 1.0000
63.3800 11367.0000 1.0000
63.4400 11616.0000 1.0000
63.5000 11448.0000 1.0000
63.5600 11333.0000 1.0000
63.6200 11429.0000 1.0000
63.6800 11310.0000 1.0000
63.7400 11437.0000 1.0000
63.8000 11552.0000 1.0000
63.8600 11604.0000 1.0000
63.9200 11821.0000 1.0000
63.9800 12596.0000 1.0000
64.0400 12913.0000 1.0000
64.1000 12288.0000 1.0000
64.1600 12122.0000 1.0000
64.2200 12314.0000 1.0000
64.2800 11861.0000 1.0000
64.3400 11577.0000 1.0000
64.4000 11614.0000 1.0000
64.4600 11396.0000 1.0000
64.5200 11297.0000 1.0000
64.5800 11104.0000 1.0000
64.6400 11339.0000 1.0000
64.7000 11281.0000 1.0000
64.7600 11229.0000 1.0000
64.8200 11367.0000 1.0000
64.8800 11446.0000 1.0000
64.9400 11286.0000 1.0000
65.0000 11427.0000 1.0000
65.0600 11216.0000 1.0000
65.1200 11259.0000 1.0000
65.1800 11383.0000 1.0000
65.2400 11363.0000 1.0000
65.3000 11377.0000 1.0000
65.3600 11367.0000 1.0000
65.4200 11389.0000 1.0000
65.4800 11398.0000 1.0000
65.5400 11289.0000 1.0000
65.6000 11443.0000 1.0000
65.6600 11293.0000 1.0000
65.7200 11430.0000 1.0000
65.7800 11491.0000 1.0000
65.8400 11486.0000 1.0000
65.9000 11534.0000 1.0000
65.9600 11610.0000 1.0000
66.0200 11500.0000 1.0000
66.0800 11409.0000 1.0000
66.1400 11351.0000 1.0000
66.2000 11308.0000 1.0000
66.2600 11355.0000 1.0000
66.3200 11313.0000 1.0000
66.3800 11393.0000 1.0000
66.4400 11568.0000 1.0000
66.5000 11625.0000 1.0000
66.5600 11592.0000 1.0000
66.6200 11693.0000 1.0000
66.6800 11607.0000 1.0000
66.7400 11527.0000 1.0000
66.8000 11428.0000 1.0000
66.8600 11155.0000 1.0000
66.9200 11533.0000 1.0000
66.9800 11174.0000 1.0000
67.0400 11428.0000 1.0000
67.1000 11432.0000 1.0000
67.1600 11393.0000 1.0000
67.2200 11375.0000 1.0000
67.2800 11297.0000 1.0000
67.3400 11461.0000 1.0000
67.4000 11314.0000 1.0000
67.4600 11437.0000 1.0000
67.5200 11540.0000 1.0000
67.5800 11407.0000 1.0000
67.6400 11338.0000 1.0000
67.7000 11633.0000 1.0000
67.7600 11944.0000 1.0000
67.8200 11500.0000 1.0000
67.8800 11555.0000 1.0000
67.9400 11834.0000 1.0000
68.0000 11614.0000 1.0000
68.0600 11686.0000 1.0000
68.1200 11976.0000 1.0000
68.1800 12114.0000 1.0000
68.2400 11648.0000 1.0000
68.3000 11948.0000 1.0000
68.3600 11966.0000 1.0000
68.4200 11706.0000 1.0000
68.4800 11757.0000 1.0000
68.5400 11504.0000 1.0000
68.6000 11323.0000 1.0000
68.6600 11484.0000 1.0000
68.7200 11389.0000 1.0000
68.7800 11396.0000 1.0000
68.8400 11232.0000 1.0000
68.9000 11483.0000 1.0000
68.9600 11372.0000 1.0000
69.0200 11571.0000 1.0000
69.0800 11295.0000 1.0000
69.1400 11376.0000 1.0000
69.2000 11452.0000 1.0000
69.2600 11320.0000 1.0000
69.3200 11462.0000 1.0000
69.3800 11594.0000 1.0000
69.4400 11159.0000 1.0000
69.5000 11418.0000 1.0000
69.5600 11583.0000 1.0000
69.6200 11583.0000 1.0000
69.6800 11519.0000 1.0000
69.7400 11347.0000 1.0000
69.8000 11391.0000 1.0000
69.8600 11291.0000 1.0000
69.9200 11390.0000 1.0000
69.9800 11469.0000 1.0000
70.0400 11483.0000 1.0000
70.1000 11477.0000 1.0000
70.1600 11475.0000 1.0000
70.2200 11296.0000 1.0000
70.2800 11506.0000 1.0000
70.3400 11475.0000 1.0000
70.4000 11332.0000 1.0000
70.4600 11348.0000 1.0000
70.5200 11313.0000 1.0000
70.5800 11478.0000 1.0000
70.6400 11464.0000 1.0000
70.7000 11346.0000 1.0000
70.7600 11450.0000 1.0000
70.8200 11421.0000 1.0000
70.8800 11656.0000 1.0000
70.9400 11634.0000 1.0000
71.0000 11745.0000 1.0000
71.0600 11922.0000 1.0000
71.1200 11753.0000 1.0000
71.1800 11575.0000 1.0000
71.2400 11852.0000 1.0000
71.3000 11691.0000 1.0000
71.3600 11592.0000 1.0000
71.4200 11617.0000 1.0000
71.4800 11473.0000 1.0000
71.5400 11507.0000 1.0000
71.6000 11365.0000 1.0000
71.6600 11513.0000 1.0000
71.7200 11514.0000 1.0000
71.7800 11622.0000 1.0000
71.8400 11641.0000 1.0000
71.9000 11890.0000 1.0000
71.9600 11777.0000 1.0000
72.0200 11860.0000 1.0000
72.0800 11632.0000 1.0000
72.1400 11479.0000 1.0000
72.2000 11788.0000 1.0000
72.2600 11537.0000 1.0000
72.3200 11627.0000 1.0000
72.3800 11459.0000 1.0000
72.4400 11500.0000 1.0000
72.5000 11647.0000 1.0000
72.5600 11498.0000 1.0000
72.6200 11341.0000 1.0000
72.6800 11441.0000 1.0000
72.7400 11492.0000 1.0000
72.8000 11544.0000 1.0000
72.8600 11410.0000 1.0000
72.9200 11494.0000 1.0000
72.9800 11571.0000 1.0000
73.0400 11552.0000 1.0000
73.1000 11521.0000 1.0000
73.1600 11531.0000 1.0000
73.2200 11501.0000 1.0000
73.2800 11643.0000 1.0000
73.3400 11481.0000 1.0000
73.4000 11391.0000 1.0000
73.4600 11873.0000 1.0000
73.5200 11505.0000 1.0000
73.5800 11620.0000 1.0000
73.6400 11669.0000 1.0000
73.7000 11671.0000 1.0000
73.7600 11632.0000 1.0000
73.8200 11458.0000 1.0000
73.8800 11639.0000 1.0000
73.9400 11653.0000 1.0000
74.0000 11719.0000 1.0000
74.0600 12227.0000 1.0000
74.1200 12519.0000 1.0000
74.1800 12266.0000 1.0000
74.2400 12225.0000 1.0000
74.3000 12125.0000 1.0000
74.3600 12148.0000 1.0000
74.4200 11817.0000 1.0000
74.4800 11790.0000 1.0000
74.5400 11605.0000 1.0000
74.6000 11508.0000 1.0000
74.6600 11655.0000 1.0000
74.7200 11578.0000 1.0000
74.7800 11569.0000 1.0000
74.8400 11489.0000 1.0000
74.9000 11499.0000 1.0000
74.9600 11567.0000 1.0000
75.0200 11825.0000 1.0000
75.0800 12086.0000 1.0000
75.1400 11882.0000 1.0000
75.2000 11914.0000 1.0000
75.2600 11916.0000 1.0000
75.3200 11990.0000 1.0000
75.3800 11637.0000 1.0000
75.4400 11983.0000 1.0000
75.5000 11846.0000 1.0000
75.5600 11852.0000 1.0000
75.6200 11731.0000 1.0000
75.6800 11840.0000 1.0000
75.7400 11629.0000 1.0000
75.8000 11378.0000 1.0000
75.8600 11597.0000 1.0000
75.9200 11698.0000 1.0000
75.9800 11494.0000 1.0000
76.0400 11697.0000 1.0000
76.1000 11532.0000 1.0000
76.1600 11632.0000 1.0000
76.2200 11644.0000 1.0000
76.2800 11602.0000 1.0000
76.3400 11749.0000 1.0000
76.4000 11583.0000 1.0000
76.4600 11485.0000 1.0000
76.5200 11626.0000 1.0000
76.5800 11478.0000 1.0000
76.6400 11490.0000 1.0000
76.7000 11388.0000 1.0000
76.7600 11655.0000 1.0000
76.8200 11531.0000 1.0000
76.8800 11530.0000 1.0000
76.9400 11636.0000 1.0000
77.0000 11682.0000 1.0000
77.0600 11492.0000 1.0000
77.1200 11413.0000 1.0000
77.1800 11737.0000 1.0000
77.2400 11650.0000 1.0000
77.3000 11582.0000 1.0000
77.3600 11441.0000 1.0000
77.4200 11457.0000 1.0000
77.4800 11667.0000 1.0000
77.5400 11572.0000 1.0000
77.6000 11549.0000 1.0000
77.6600 11850.0000 1.0000
77.7200 11727.0000 1.0000
77.7800 11580.0000 1.0000
77.8400 11684.0000 1.0000
77.9000 11573.0000 1.0000
77.9600 11777.0000 1.0000
78.0200 11764.0000 1.0000
78.0800 11568.0000 1.0000
78.1400 11275.0000 1.0000
78.2000 11437.0000 1.0000
78.2600 11483.0000 1.0000
78.3200 11413.0000 1.0000
78.3800 11307.0000 1.0000
78.4400 11619.0000 1.0000
78.5000 11560.0000 1.0000
78.5600 11339.0000 1.0000
78.6200 11604.0000 1.0000
78.6800 11745.0000 1.0000
78.7400 11756.0000 1.0000
78.8000 11574.0000 1.0000
78.8600 11691.0000 1.0000
78.9200 11534.0000 1.0000
78.9800 11658.0000 1.0000
79.0400 11825.0000 1.0000
79.1000 11767.0000 1.0000
79.1600 11649.0000 1.0000
79.2200 11905.0000 1.0000
79.2800 11807.0000 1.0000
79.3400 11714.0000 1.0000
79.4000 11615.0000 1.0000
79.4600 11620.0000 1.0000
79.5200 11590.0000 1.0000
79.5800 11596.0000 1.0000
79.6400 11530.0000 1.0000
79.7000 11714.0000 1.0000
79.7600 11585.0000 1.0000
79.8200 11796.0000 1.0000
79.8800 11839.0000 1.0000
79.9400 11675.0000 1.0000
80.0000 11574.0000 1.0000
80.0600 11879.0000 1.0000
80.1200 11900.0000 1.0000
80.1800 11599.0000 1.0000
80.2400 11567.0000 1.0000
80.3000 11593.0000 1.0000
80.3600 11682.0000 1.0000
80.4200 11583.0000 1.0000
80.4800 11601.0000 1.0000
80.5400 11683.0000 1.0000
80.6000 11630.0000 1.0000
80.6600 11607.0000 1.0000
80.7200 11941.0000 1.0000
80.7800 11715.0000 1.0000
80.8400 11627.0000 1.0000
80.9000 11558.0000 1.0000
80.9600 11732.0000 1.0000
81.0200 11745.0000 1.0000
81.0800 11642.0000 1.0000
81.1400 11859.0000 1.0000
81.2000 11687.0000 1.0000
81.2600 11660.0000 1.0000
81.3200 11788.0000 1.0000
81.3800 11753.0000 1.0000
81.4400 11789.0000 1.0000
81.5000 12215.0000 1.0000
81.5600 11829.0000 1.0000
81.6200 11708.0000 1.0000
81.6800 11678.0000 1.0000
81.7400 11967.0000 1.0000
81.8000 11621.0000 1.0000
81.8600 11525.0000 1.0000
81.9200 11485.0000 1.0000
81.9800 11586.0000 1.0000
82.0400 11665.0000 1.0000
82.1000 11690.0000 1.0000
82.1600 11678.0000 1.0000
82.2200 11649.0000 1.0000
82.2800 11612.0000 1.0000
82.3400 11619.0000 1.0000
82.4000 11565.0000 1.0000
82.4600 11459.0000 1.0000
82.5200 11636.0000 1.0000
82.5800 11656.0000 1.0000
82.6400 11568.0000 1.0000
82.7000 11595.0000 1.0000
82.7600 11632.0000 1.0000
82.8200 11601.0000 1.0000
82.8800 11680.0000 1.0000
82.9400 11872.0000 1.0000
83.0000 11754.0000 1.0000
83.0600 11342.0000 1.0000
83.1200 11759.0000 1.0000
83.1800 11772.0000 1.0000
83.2400 11828.0000 1.0000
83.3000 11666.0000 1.0000
83.3600 11536.0000 1.0000
83.4200 11564.0000 1.0000
83.4800 11626.0000 1.0000
83.5400 11668.0000 1.0000
83.6000 11535.0000 1.0000
83.6600 11504.0000 1.0000
83.7200 11555.0000 1.0000
83.7800 11499.0000 1.0000
83.8400 11847.0000 1.0000
83.9000 11638.0000 1.0000
83.9600 11623.0000 1.0000
84.0200 11594.0000 1.0000
84.0800 11651.0000 1.0000
84.1400 11649.0000 1.0000
84.2000 11626.0000 1.0000
84.2600 11550.0000 1.0000
84.3200 11698.0000 1.0000
84.3800 11667.0000 1.0000
84.4400 11708.0000 1.0000
84.5000 11573.0000 1.0000
84.5600 11640.0000 1.0000
84.6200 11907.0000 1.0000
84.6800 11595.0000 1.0000
84.7400 11755.0000 1.0000
84.8000 11615.0000 1.0000
84.8600 11885.0000 1.0000
84.9200 12030.0000 1.0000
84.9800 11934.0000 1.0000
85.0400 11844.0000 1.0000
85.1000 11815.0000 1.0000
85.1600 11965.0000 1.0000
85.2200 11830.0000 1.0000
85.2800 11568.0000 1.0000
85.3400 11631.0000 1.0000
85.4000 11711.0000 1.0000
85.4600 11618.0000 1.0000
85.5200 11654.0000 1.0000
85.5800 11805.0000 1.0000
85.6400 11706.0000 1.0000
85.7000 11667.0000 1.0000
85.7600 11782.0000 1.0000
85.8200 11764.0000 1.0000
85.8800 11717.0000 1.0000
85.9400 11796.0000 1.0000
86.0000 11731.0000 1.0000
86.0600 11698.0000 1.0000
86.1200 11707.0000 1.0000
86.1800 11875.0000 1.0000
86.2400 11761.0000 1.0000
86.3000 11563.0000 1.0000
86.3600 11859.0000 1.0000
86.4200 11768.0000 1.0000
86.4800 11792.0000 1.0000
86.5400 11668.0000 1.0000
86.6000 11608.0000 1.0000
86.6600 11698.0000 1.0000
86.7200 11860.0000 1.0000
86.7800 11878.0000 1.0000
86.8400 11972.0000 1.0000
86.9000 11987.0000 1.0000
86.9600 12118.0000 1.0000
87.0200 12103.0000 1.0000
87.0800 11958.0000 1.0000
87.1400 11893.0000 1.0000
87.2000 11947.0000 1.0000
87.2600 11751.0000 1.0000
87.3200 11639.0000 1.0000
87.3800 11675.0000 1.0000
87.4400 11815.0000 1.0000
87.5000 11869.0000 1.0000
87.5600 11640.0000 1.0000
87.6200 11637.0000 1.0000
87.6800 11579.0000 1.0000
87.7400 11564.0000 1.0000
87.8000 11756.0000 1.0000
87.8600 11813.0000 1.0000
87.9200 11660.0000 1.0000
87.9800 11767.0000 1.0000
88.0400 11735.0000 1.0000
88.1000 11599.0000 1.0000
88.1600 11888.0000 1.0000
88.2200 11617.0000 1.0000
88.2800 11630.0000 1.0000
88.3400 11980.0000 1.0000
88.4000 11864.0000 1.0000
88.4600 11795.0000 1.0000
88.5200 12014.0000 1.0000
88.5800 12016.0000 1.0000
88.6400 11996.0000 1.0000
88.7000 11758.0000 1.0000
88.7600 11694.0000 1.0000
88.8200 11898.0000 1.0000
88.8800 11940.0000 1.0000
88.9400 11738.0000 1.0000
89.0000 11759.0000 1.0000
89.0600 11795.0000 1.0000
89.1200 11849.0000 1.0000
89.1800 11791.0000 1.0000
89.2400 11760.0000 1.0000
89.3000 11842.0000 1.0000
89.3600 11619.0000 1.0000
89.4200 11777.0000 1.0000
89.4800 11811.0000 1.0000
89.5400 12023.0000 1.0000
89.6000 12143.0000 1.0000
89.6600 12361.0000 1.0000
89.7200 12805.0000 1.0000
89.7800 12894.0000 1.0000
89.8400 12938.0000 1.0000
89.9000 12468.0000 1.0000
89.9600 12455.0000 1.0000
90.0000 12544.0000 1.0000
*RAS_INT_END
*RAS_TEMPERATURE_START
*RAS_TEMPERATURE_END
*RAS_DATA_END